Workbook

Sheet GRUPOS INFANTIL
C1: XVIII Campeonato Nacional de Fútbol Infantil
C2: “COPA SOCCER MELGAR”
C4: NACIDOS 2017 2018
D6: GRUPO A | H6: GRUPO B
D7: ASTON HUILA | H7: CANUTO F.C.
D8: INTER F. C. | F8: 2024 | H8: HUITACA FUTBOL CLUB CHIA
D9: ATHLETIC MELGAR | H9: CLUB PROMOTOR DEPORTIVO SCORPION
D10: CLUB DEPORTIVO NUEVAS GENERACIONES | F10: DICIEMBRE 09 AL 11 DEL 2024

Sheet GRUPO A
A1: =+'GRUPOS INFANTIL'!C1 -> XVIII Campeonato Nacional de Fútbol Infantil
A2: “COPA FUTURO TALENTO”
B3: =+'GRUPOS INFANTIL'!C3 -> 0 | F3: =+'GRUPOS INFANTIL'!C4 -> NACIDOS 2017 2018
B4: =+'GRUPOS INFANTIL'!D6 -> GRUPO A
B6: PARTIDOS | P6: POSICIONES | AJ6: =COUNT(G8,I8,G11,I11,G14,I14,G17,I17,G20,I20,G23,I23,G26,I26,G29,I29,G32,I32,G35,I35) -> 12
A7: Tj | N7: Tj
F8: =IF(AND(G8<>"",I8<>""),IF(G8=I8,"E",IF(G8>I8,"G","P")),"") | H8: - | J8: =IF(AND(I8<>"",G8<>""),IF(I8=G8,"E",IF(I8>G8,"G","P")),"") | Q8: Pts. | R8: PJ | S8: Gan. | T8: Emp. | U8: Per. | V8: GF | W8: GC | X8: Dif. | Y8: Tj | AF8: GF | AG8: GC | AH8: DG | AJ8: =IF(AJ6=12,IF(INDEX(Z22:AK29,MATCH(2,Z21:Z29,0),11)=INDEX(Z22:AK29,MATCH(1,Z21:Z29,0),11),1,0),0) -> 0
P10: =" 1) " & VLOOKUP(1,$Z$10:$AI$17,2,0) -> 1) ASTON HUILA | Q10: =VLOOKUP(1,$Z$10:$AI$17,3,0) -> 7 | R10: =+SUM(S10:U11) -> 3 | S10: =VLOOKUP(1,$Z$10:$AI$17,4,0) -> 2 | T10: =VLOOKUP(1,$Z$10:$AI$17,5,0) -> 1 | U10: =VLOOKUP(1,$Z$10:$AI$17,6,0) -> 0 | V10: =VLOOKUP(1,$Z$10:$AI$17,7,0) -> 12 | W10: =VLOOKUP(1,$Z$10:$AI$17,8,0) -> 2 | X10: =VLOOKUP(1,$Z$10:$AH$17,9,0) -> 10 | Y10: =VLOOKUP(1,$Z$10:$AI$17,10,0) -> 0 | Z10: =RANK(AJ10,$AJ$10:$AJ$17,0) -> 1 | AA10: =+'GRUPOS INFANTIL'!D7 -> ASTON HUILA | AB10: =(AC10*3)+AD10 -> 7 | AC10: =COUNTIF(Q58:T58,"G")+AC19 -> 2 | AD10: =COUNTIF(Q58:T58,"E")+AD19 -> 1 | AE10: =COUNTIF(Q58:T58,"P")+AE19 -> 0 | AF10: =+G8+G20+G26+G35+AF19 -> 12 | AG10: =+I8+I20+I26+I35+AG19 -> 2 | AH10: =AF10-AG10 -> 10 | AI10: =+A8+A20+A26+A35+AI19 -> 0 | AJ10: =(AB10*1000)+(AH10*100)+(AF10*10)-AI10+0.1 -> 8120.1 | AK10: =AJ10+X10 -> 8130.1
F11: =IF(AND(G11<>"",I11<>""),IF(G11=I11,"E",IF(G11>I11,"G","P")),"") | H11: - | J11: =IF(AND(I11<>"",G11<>""),IF(I11=G11,"E",IF(I11>G11,"G","P")),"")
P12: =" 2) " & VLOOKUP(2,$Z$10:$AI$17,2,0) -> 2) CLUB DEPORTIVO NUEVAS GENERACIONES | Q12: =VLOOKUP(2,$Z$10:$AI$17,3,0) -> 5 | R12: =+SUM(S12:U13) -> 3 | S12: =VLOOKUP(2,$Z$10:$AI$17,4,0) -> 1 | T12: =VLOOKUP(2,$Z$10:$AI$17,5,0) -> 2 | U12: =VLOOKUP(2,$Z$10:$AI$17,6,0) -> 0 | V12: =VLOOKUP(2,$Z$10:$AI$17,7,0) -> 7 | W12: =VLOOKUP(2,$Z$10:$AI$17,8,0) -> 6 | X12: =VLOOKUP(2,$Z$10:$AH$17,9,0) -> 1 | Y12: =VLOOKUP(2,$Z$10:$AI$17,10,0) -> 0 | Z12: =RANK(AJ12,$AJ$10:$AJ$17,0) -> 3 | AA12: =+'GRUPOS INFANTIL'!D8 -> INTER F. C. | AB12: =(AC12*3)+AD12 -> 2 | AC12: =COUNTIF(Q59:T59,"G")+AC20 -> 0 | AD12: =COUNTIF(Q59:T59,"E")+AD20 -> 2 | AE12: =COUNTIF(Q59:T59,"P")+AE20 -> 1 | AF12: =+G11+I20+G29+G32+AF20 -> 3 | AG12: =+I11+I29+G23+I32+AG20 -> 4 | AH12: =AF12-AG12 -> -1 | AI12: =+A29+A11+N20+A32+AI20 -> 0 | AJ12: =(AB12*1000)+(AH12*100)+(AF12*10)-AI12+0.2 -> 1930.2 | AK12: =AJ12+X12 -> 1931.2
F14: =IF(AND(G14<>"",I14<>""),IF(G14=I14,"E",IF(G14>I14,"G","P")),"") | H14: - | J14: =IF(AND(I14<>"",G14<>""),IF(I14=G14,"E",IF(I14>G14,"G","P")),"") | P14: =" 3) " & VLOOKUP(3,$Z$10:$AI$17,2,0) -> 3) INTER F. C. | Q14: =VLOOKUP(3,$Z$10:$AI$17,3,0) -> 2 | R14: =+SUM(S14:U15) -> 3 | S14: =VLOOKUP(3,$Z$10:$AI$17,4,0) -> 0 | T14: =VLOOKUP(3,$Z$10:$AI$17,5,0) -> 2 | U14: =VLOOKUP(3,$Z$10:$AI$17,6,0) -> 1 | V14: =VLOOKUP(3,$Z$10:$AI$17,7,0) -> 3 | W14: =VLOOKUP(3,$Z$10:$AI$17,8,0) -> 4 | X14: =VLOOKUP(3,$Z$10:$AI$17,9,0) -> -1 | Y14: =VLOOKUP(3,$Z$10:$AI$17,10,0) -> 0 | Z14: =RANK(AJ14,$AJ$10:$AJ$17,0) -> 4 | AA14: =+'GRUPOS INFANTIL'!D9 -> ATHLETIC MELGAR | AB14: =(AC14*3)+AD14 -> 1 | AC14: =COUNTIF(Q60:T60,"G")+AC21 -> 0 | AD14: =COUNTIF(Q60:T60,"E")+AD21 -> 1 | AE14: =COUNTIF(Q60:T60,"P")+AE21 -> 2 | AF14: =+G14+I26+G23+I32+AF21 -> 1 | AG14: =+G26+I14+I23+G32+AG21 -> 5 | AH14: =AF14-AG14 -> -4 | AI14: =+A14+A23+N26+N32+AI21 -> 0 | AJ14: =(AB14*1000)+(AH14*100)+(AF14*10)-AI14+0.3 -> 610.3 | AK14: =+X14 -> -1
P16: =" 4) " & VLOOKUP(4,$Z$10:$AI$17,2,0) -> 4) ATHLETIC MELGAR | Q16: =VLOOKUP(4,$Z$10:$AI$17,3,0) -> 1 | R16: =+SUM(S16:U17) -> 3 | S16: =VLOOKUP(4,$Z$10:$AI$17,4,0) -> 0 | T16: =VLOOKUP(4,$Z$10:$AI$17,5,0) -> 1 | U16: =VLOOKUP(4,$Z$10:$AI$17,6,0) -> 2 | V16: =VLOOKUP(4,$Z$10:$AI$17,7,0) -> 1 | W16: =VLOOKUP(4,$Z$10:$AI$17,8,0) -> 5 | X16: =VLOOKUP(4,$Z$10:$AI$17,9,0) -> -4 | Y16: =VLOOKUP(4,$Z$10:$AI$17,10,0) -> 0 | Z16: =RANK(AJ16,$AJ$10:$AJ$17,0) -> 2 | AA16: =+'GRUPOS INFANTIL'!D10 -> CLUB DEPORTIVO NUEVAS GENERACIONES | AB16: =(AC16*3)+AD16 -> 5 | AC16: =COUNTIF(Q61:T61,"G")+AC22 -> 1 | AD16: =COUNTIF(Q61:T61,"E")+AD22 -> 2 | AE16: =COUNTIF(Q61:T61,"P")+AE22 -> 0 | AF16: =+G17+I29+I23+I35+AF22 -> 7 | AG16: =+G29+G23+G35+AG22 -> 6 | AH16: =AF16-AG16 -> 1 | AI16: =+A17+N23+N29+N35+AI22 -> 0 | AJ16: =(AB16*1000)+(AH16*100)+(AF16*10)-AI16+0.4 -> 5170.4 | AK16: =+X16 -> -4
F17: =IF(AND(G17<>"",I17<>""),IF(G17=I17,"E",IF(G17>I17,"G","P")),"") | H17: - | J17: =IF(AND(I17<>"",G17<>""),IF(I17=G17,"E",IF(I17>G17,"G","P")),"")
Z19: =+'GRUPO B'!Z10 -> 4 | AA19: =+'GRUPO B'!AA10 -> CANUTO F.C. | AB19: =+'GRUPO B'!AB10 -> 0 | AC19: =+'GRUPO B'!AC10 -> 0 | AD19: =+'GRUPO B'!AD10 -> 0 | AE19: =+'GRUPO B'!AE10 -> 0 | AF19: =+'GRUPO B'!AF10 -> 0 | AG19: =+'GRUPO B'!AG10 -> 0 | ... AK19: =+'GRUPO B'!AK10 -> 0.1
B20: 42812 | C20: 07:15. a.m. | E20: =+'GRUPOS INFANTIL'!D7 -> ASTON HUILA | F20: =IF(AND(G20<>"",I20<>""),IF(G20=I20,"E",IF(G20>I20,"G","P")),"") -> G | G20: 7 | H20: - | I20: 0 | J20: =IF(AND(I20<>"",G20<>""),IF(I20=G20,"E",IF(I20>G20,"G","P")),"") -> P | K20: =+'GRUPOS INFANTIL'!D8 -> INTER F. C. | M20: CANCHA 2 | Z20: =+'GRUPO B'!Z12 -> 3 | AA20: =+'GRUPO B'!AA12 -> HUITACA FUTBOL CLUB CHIA | AB20: =+'GRUPO B'!AB12 -> 0 | AC20: =+'GRUPO B'!AC12 -> 0 | AD20: =+'GRUPO B'!AD12 -> 0 | AE20: =+'GRUPO B'!AE12 -> 0 | AF20: =+'GRUPO B'!AF12 -> 0 | AG20: =+'GRUPO B'!AG12 -> 0 | ... AK20: =+'GRUPO B'!AK12 -> 0.2
Z21: =+'GRUPO B'!Z14 -> 2 | AA21: =+'GRUPO B'!AA14 -> CLUB PROMOTOR DEPORTIVO SCORPION | AB21: =+'GRUPO B'!AB14 -> 0 | AC21: =+'GRUPO B'!AC14 -> 0 | AD21: =+'GRUPO B'!AD14 -> 0 | AE21: =+'GRUPO B'!AE14 -> 0 | AF21: =+'GRUPO B'!AF14 -> 0 | AG21: =+'GRUPO B'!AG14 -> 0 | ... AK21: =+'GRUPO B'!AK14 -> 0
Z22: =+'GRUPO B'!Z16 -> 1 | AA22: =+'GRUPO B'!AA16 -> #REF! | AB22: =+'GRUPO B'!AB16 -> 0 | AC22: =+'GRUPO B'!AC16 -> 0 | AD22: =+'GRUPO B'!AD16 -> 0 | AE22: =+'GRUPO B'!AE16 -> 0 | AF22: =+'GRUPO B'!AF16 -> 0 | AG22: =+'GRUPO B'!AG16 -> 0 | ... AK22: =+'GRUPO B'!AK16 -> 0
B23: 42812 | C23: 08:20. a.m. | E23: =+'GRUPOS INFANTIL'!D9 -> ATHLETIC MELGAR | F23: =IF(AND(G23<>"",I23<>""),IF(G23=I23,"E",IF(G23>I23,"G","P")),"") -> P | G23: 1 | H23: - | I23: 2 | J23: =IF(AND(I23<>"",G23<>""),IF(I23=G23,"E",IF(I23>G23,"G","P")),"") -> G | K23: =+'GRUPOS INFANTIL'!D10 -> CLUB DEPORTIVO NUEVAS GENERACIONES | M23: LAS VEGAS
B26: 42812 | C26: 03:00. p.m. | E26: =+'GRUPOS INFANTIL'!D7 -> ASTON HUILA | F26: =IF(AND(G26<>"",I26<>""),IF(G26=I26,"E",IF(G26>I26,"G","P")),"") -> G | G26: 3 | H26: - | I26: 0 | J26: =IF(AND(I26<>"",G26<>""),IF(I26=G26,"E",IF(I26>G26,"G","P")),"") -> P | K26: =+'GRUPOS INFANTIL'!D9 -> ATHLETIC MELGAR | M26: LAS VEGAS
B29: 42812 | C29: 04:00. p.m. | E29: =+'GRUPOS INFANTIL'!D8 -> INTER F. C. | F29: =IF(AND(G29<>"",I29<>""),IF(G29=I29,"E",IF(G29>I29,"G","P")),"") -> E | G29: 3 | H29: - | I29: 3 | J29: =IF(AND(I29<>"",G29<>""),IF(I29=G29,"E",IF(I29>G29,"G","P")),"") -> E | K29: =+'GRUPOS INFANTIL'!D10 -> CLUB DEPORTIVO NUEVAS GENERACIONES | M29: LAS VEGAS
B32: 42813 | C32: 01:15. p.m. | E32: =+'GRUPOS INFANTIL'!D8 -> INTER F. C. | F32: =IF(AND(G32<>"",I32<>""),IF(G32=I32,"E",IF(G32>I32,"G","P")),"") -> E | G32: 0 | H32: - | I32: 0 | J32: =IF(AND(I32<>"",G32<>""),IF(I32=G32,"E",IF(I32>G32,"G","P")),"") -> E | K32: =+'GRUPOS INFANTIL'!D9 -> ATHLETIC MELGAR | M32: CANCHA 2
W34: =IF(AJ8=1,IF(P33="","",P33),IF(SUM(Q10:Q17)>0,VLOOKUP(1,Z10:AA17,2,0),"")) -> ASTON HUILA
B35: 42813 | C35: 02:30. p.m. | E35: =+'GRUPOS INFANTIL'!D7 -> ASTON HUILA | F35: =IF(AND(G35<>"",I35<>""),IF(G35=I35,"E",IF(G35>I35,"G","P")),"") -> E | G35: 2 | H35: - | I35: 2 | J35: =IF(AND(I35<>"",G35<>""),IF(I35=G35,"E",IF(I35>G35,"G","P")),"") -> E | K35: =+'GRUPOS INFANTIL'!D10 -> CLUB DEPORTIVO NUEVAS GENERACIONES | M35: CANCHA 1 | W35: =IF(AJ8=1,IF(P36="","",P36),IF(SUM(Q10:Q17)>0,VLOOKUP(2,Z10:AA17,2,0),"")) -> CLUB DEPORTIVO NUEVAS GENERACIONES
J43: =IF(AG20=1,"Indique el primero y segundo equipos clasificados de la serie:","") | L43: =IF(AG20=1,"Primero:","")
J46: =IF(AG20=1,"(Debido a la paridad de los resultados, no pueden deducirse de forma automática.)","") | L46: =IF(AG20=1,"Segundo:","")
P58: =+'GRUPOS INFANTIL'!D7 -> ASTON HUILA | Q58: =+F8 | R58: =+F20 -> G | S58: =+F26 -> G | T58: =+F35 -> E
P59: =+'GRUPOS INFANTIL'!D8 -> INTER F. C. | Q59: =+F11 | R59: =+J20 -> P | S59: =+F29 -> E | T59: =+F32 -> E
P60: =+'GRUPOS INFANTIL'!D9 -> ATHLETIC MELGAR | Q60: =+F14 | R60: =+F23 -> P | S60: =+J26 -> P | T60: =+J32 -> E
P61: =+'GRUPOS INFANTIL'!D10 -> CLUB DEPORTIVO NUEVAS GENERACIONES | Q61: =+F17 | R61: =+J23 -> G | S61: =+J29 -> E | T61: =+J35 -> E

Sheet GRUPO B
A1: =+'GRUPOS INFANTIL'!C1 -> XVIII Campeonato Nacional de Fútbol Infantil
A2: “COPA FUTURO TALENTO”
B3: =+'GRUPOS INFANTIL'!C3 -> 0 | F3: =+'GRUPOS INFANTIL'!C4 -> NACIDOS 2017 2018
B4: =+'GRUPOS INFANTIL'!H6 -> GRUPO B
B6: PARTIDOS | P6: POSICIONES | AJ6: =COUNT(G8,I8,G11,I11,G14,I14,G17,I17,G20,I20,G23,I23,G26,I26,G29,I29,G32,I32,G35,I35) -> 0
A7: Tj | N7: Tj
F8: =IF(AND(G8<>"",I8<>""),IF(G8=I8,"E",IF(G8>I8,"G","P")),"") | H8: - | J8: =IF(AND(I8<>"",G8<>""),IF(I8=G8,"E",IF(I8>G8,"G","P")),"") | Q8: Pts. | R8: PJ | S8: Gan. | T8: Emp. | U8: Per. | V8: GF | W8: GC | X8: Dif. | Y8: Tj | AJ8: =IF(AJ6=12,IF(INDEX(Z10:AK17,MATCH(2,Z10:Z17,0),11)=INDEX(Z10:AK17,MATCH(1,Z10:Z17,0),11),1,0),0) -> 0
P10: =" 1) " & VLOOKUP(1,$Z$10:$AI$17,2,0) -> #REF! | Q10: =VLOOKUP(1,$Z$10:$AI$17,3,0) -> 0 | R10: =+SUM(S10:U11) -> 0 | S10: =VLOOKUP(1,$Z$10:$AI$17,4,0) -> 0 | T10: =VLOOKUP(1,$Z$10:$AI$17,5,0) -> 0 | U10: =VLOOKUP(1,$Z$10:$AI$17,6,0) -> 0 | V10: =VLOOKUP(1,$Z$10:$AI$17,7,0) -> 0 | W10: =VLOOKUP(1,$Z$10:$AI$17,8,0) -> 0 | X10: =VLOOKUP(1,$Z$10:$AH$17,9,0) -> 0 | Y10: =VLOOKUP(1,$Z$10:$AI$17,10,0) -> 0 | Z10: =RANK(AJ10,$AJ$10:$AJ$17,0) -> 4 | AA10: =+'GRUPOS INFANTIL'!H7 -> CANUTO F.C. | AB10: =(AC10*3)+AD10 -> 0 | AC10: =COUNTIF(Q58:T58,"G") -> 0 | AD10: =COUNTIF(Q58:T58,"E") -> 0 | AE10: =COUNTIF(Q58:T58,"P") -> 0 | AF10: =+I8+G20+G26+G32 -> 0 | AG10: =+I20+I26+I32+G8 -> 0 | AH10: =AF10-AG10 -> 0 | AI10: =+A20+A26+A32+N8 -> 0 | AJ10: =(AB10*1000)+(AH10*100)+(AF10*10)-AI10+0.1 -> 0.1 | AK10: =AJ10+X10 -> 0.1
F11: =IF(AND(G11<>"",I11<>""),IF(G11=I11,"E",IF(G11>I11,"G","P")),"") | H11: - | J11: =IF(AND(I11<>"",G11<>""),IF(I11=G11,"E",IF(I11>G11,"G","P")),"")
P12: =" 2) " & VLOOKUP(2,$Z$10:$AI$17,2,0) -> 2) CLUB PROMOTOR DEPORTIVO SCORPION | Q12: =VLOOKUP(2,$Z$10:$AI$17,3,0) -> 0 | R12: =+SUM(S12:U13) -> 0 | S12: =VLOOKUP(2,$Z$10:$AI$17,4,0) -> 0 | T12: =VLOOKUP(2,$Z$10:$AI$17,5,0) -> 0 | U12: =VLOOKUP(2,$Z$10:$AI$17,6,0) -> 0 | V12: =VLOOKUP(2,$Z$10:$AI$17,7,0) -> 0 | W12: =VLOOKUP(2,$Z$10:$AI$17,8,0) -> 0 | X12: =VLOOKUP(2,$Z$10:$AH$17,9,0) -> 0 | Y12: =VLOOKUP(2,$Z$10:$AI$17,10,0) -> 0 | Z12: =RANK(AJ12,$AJ$10:$AJ$17,0) -> 3 | AA12: =+'GRUPOS INFANTIL'!H8 -> HUITACA FUTBOL CLUB CHIA | AB12: =(AC12*3)+AD12 -> 0 | AC12: =COUNTIF(Q59:T59,"G") -> 0 | AD12: =COUNTIF(Q59:T59,"E") -> 0 | AE12: =COUNTIF(Q59:T59,"P") -> 0 | AF12: =+I20+G29+G35+I11 -> 0 | AG12: =+G20+I29+I35+G11 -> 0 | AH12: =AF12-AG12 -> 0 | AI12: =+N20+A29+A35+N11 -> 0 | AJ12: =(AB12*1000)+(AH12*100)+(AF12*10)-AI12+0.2 -> 0.2 | AK12: =AJ12+X12 -> 0.2
F14: =IF(AND(G14<>"",I14<>""),IF(G14=I14,"E",IF(G14>I14,"G","P")),"") | H14: - | J14: =IF(AND(I14<>"",G14<>""),IF(I14=G14,"E",IF(I14>G14,"G","P")),"") | P14: =" 3) " & VLOOKUP(3,$Z$10:$AI$17,2,0) -> 3) HUITACA FUTBOL CLUB CHIA | Q14: =VLOOKUP(3,$Z$10:$AI$17,3,0) -> 0 | R14: =+SUM(S14:U15) -> 0 | S14: =VLOOKUP(3,$Z$10:$AI$17,4,0) -> 0 | T14: =VLOOKUP(3,$Z$10:$AI$17,5,0) -> 0 | U14: =VLOOKUP(3,$Z$10:$AI$17,6,0) -> 0 | V14: =VLOOKUP(3,$Z$10:$AI$17,7,0) -> 0 | W14: =VLOOKUP(3,$Z$10:$AI$17,8,0) -> 0 | X14: =VLOOKUP(3,$Z$10:$AI$17,9,0) -> 0 | Y14: =VLOOKUP(3,$Z$10:$AI$17,10,0) -> 0 | Z14: =RANK(AJ14,$AJ$10:$AJ$17,0) -> 2 | AA14: =+'GRUPOS INFANTIL'!H9 -> CLUB PROMOTOR DEPORTIVO SCORPION | AB14: =(AC14*3)+AD14 -> 0 | AC14: =COUNTIF(Q60:T60,"G") -> 0 | AD14: =COUNTIF(Q60:T60,"E") -> 0 | AE14: =COUNTIF(Q60:T60,"P") -> 0 | AF14: =+G23+I26+I35+I14 -> 0 | AG14: =+I23+G26+G35+G14 -> 0 | AH14: =AF14-AG14 -> 0 | AI14: =+A23+N26+N35+N14 -> 0 | AJ14: =(AB14*1000)+(AH14*100)+(AF14*10)-AI14+0.3 -> 0.3 | AK14: =+X14 -> 0
P16: =" 4) " & VLOOKUP(4,$Z$10:$AI$17,2,0) -> 4) CANUTO F.C. | Q16: =VLOOKUP(4,$Z$10:$AI$17,3,0) -> 0 | R16: =+SUM(S16:U17) -> 0 | S16: =VLOOKUP(4,$Z$10:$AI$17,4,0) -> 0 | T16: =VLOOKUP(4,$Z$10:$AI$17,5,0) -> 0 | U16: =VLOOKUP(4,$Z$10:$AI$17,6,0) -> 0 | V16: =VLOOKUP(4,$Z$10:$AI$17,7,0) -> 0 | W16: =VLOOKUP(4,$Z$10:$AI$17,8,0) -> 0 | X16: =VLOOKUP(4,$Z$10:$AI$17,9,0) -> 0 | Y16: =VLOOKUP(4,$Z$10:$AI$17,10,0) -> 0 | Z16: =RANK(AJ16,$AJ$10:$AJ$17,0) -> 1 | AA16: =+'GRUPOS INFANTIL'!#REF! -> #REF! | AB16: =(AC16*3)+AD16 -> 0 | AC16: =COUNTIF(Q61:T61,"G") -> 0 | AD16: =COUNTIF(Q61:T61,"E") -> 0 | AE16: =COUNTIF(Q61:T61,"P") -> 0 | AF16: =+I23+I29+I32+I17 -> 0 | AG16: =+G23+G29+G32+G17 -> 0 | AH16: =AF16-AG16 -> 0 | AI16: =+N23+N29+N32+N17 -> 0 | AJ16: =(AB16*1000)+(AH16*100)+(AF16*10)-AI16+0.4 -> 0.4 | AK16: =+X16 -> 0
F17: =IF(AND(G17<>"",I17<>""),IF(G17=I17,"E",IF(G17>I17,"G","P")),"") | H17: - | J17: =IF(AND(I17<>"",G17<>""),IF(I17=G17,"E",IF(I17>G17,"G","P")),"")
B20: 42812 | C20: 12:00. m.d. | E20: =+'GRUPOS INFANTIL'!H7 -> CANUTO F.C. | F20: =IF(AND(G20<>"",I20<>""),IF(G20=I20,"E",IF(G20>I20,"G","P")),"") | H20: - | J20: =IF(AND(I20<>"",G20<>""),IF(I20=G20,"E",IF(I20>G20,"G","P")),"") | K20: =+'GRUPOS INFANTIL'!D8 -> INTER F. C. | M20: CANCHA 2
B23: 42812 | C23: 01:10. p.m. | E23: =+'GRUPOS INFANTIL'!H9 -> CLUB PROMOTOR DEPORTIVO SCORPION | F23: =IF(AND(G23<>"",I23<>""),IF(G23=I23,"E",IF(G23>I23,"G","P")),"") | H23: - | J23: =IF(AND(I23<>"",G23<>""),IF(I23=G23,"E",IF(I23>G23,"G","P")),"") | K23: =+'GRUPOS INFANTIL'!#REF! -> #REF! | M23: CANCHA 2
B26: 42813 | C26: 09:50. a.m. | E26: =+'GRUPOS INFANTIL'!H7 -> CANUTO F.C. | F26: =IF(AND(G26<>"",I26<>""),IF(G26=I26,"E",IF(G26>I26,"G","P")),"") | H26: - | J26: =IF(AND(I26<>"",G26<>""),IF(I26=G26,"E",IF(I26>G26,"G","P")),"") | K26: =+'GRUPOS INFANTIL'!H9 -> CLUB PROMOTOR DEPORTIVO SCORPION | M26: CANCHA 1
B29: 42813 | C29: 10:50. a.m. | E29: =+'GRUPOS INFANTIL'!H8 -> HUITACA FUTBOL CLUB CHIA | F29: =IF(AND(G29<>"",I29<>""),IF(G29=I29,"E",IF(G29>I29,"G","P")),"") | H29: - | J29: =IF(AND(I29<>"",G29<>""),IF(I29=G29,"E",IF(I29>G29,"G","P")),"") | K29: =+'GRUPOS INFANTIL'!#REF! -> #REF! | M29: CANCHA 1
B32: 42813 | C32: 04:30. p.m. | E32: =+'GRUPOS INFANTIL'!H7 -> CANUTO F.C. | F32: =IF(AND(G32<>"",I32<>""),IF(G32=I32,"E",IF(G32>I32,"G","P")),"") | H32: - | J32: =IF(AND(I32<>"",G32<>""),IF(I32=G32,"E",IF(I32>G32,"G","P")),"") | K32: =+'GRUPOS INFANTIL'!#REF! -> #REF! | M32: CANCHA 1
W34: =IF(AJ8=1,IF(P33="","",P33),IF(SUM(Q10:Q17)>0,VLOOKUP(1,Z10:AA17,2,0),""))
B35: 42813 | C35: 03:25. p.m. | E35: =+'GRUPOS INFANTIL'!H8 -> HUITACA FUTBOL CLUB CHIA | F35: =IF(AND(G35<>"",I35<>""),IF(G35=I35,"E",IF(G35>I35,"G","P")),"") | H35: - | J35: =IF(AND(I35<>"",G35<>""),IF(I35=G35,"E",IF(I35>G35,"G","P")),"") | K35: =+'GRUPOS INFANTIL'!H9 -> CLUB PROMOTOR DEPORTIVO SCORPION | M35: CANCHA 2 | W35: =IF(AJ8=1,IF(P36="","",P36),IF(SUM(Q10:Q17)>0,VLOOKUP(2,Z10:AA17,2,0),""))
J43: =IF(AG8=1,"Indique el primero y segundo equipos clasificados de la serie:","") | L43: =IF(AG8=1,"Primero:","")
J46: =IF(AG8=1,"(Debido a la paridad de los resultados, no pueden deducirse de forma automática.)","") | L46: =IF(AG8=1,"Segundo:","")
P58: =+'GRUPOS INFANTIL'!H7 -> CANUTO F.C. | Q58: =+F20 | R58: =+J8 | S58: =+F26 | T58: =+F32
P59: =+'GRUPOS INFANTIL'!H8 -> HUITACA FUTBOL CLUB CHIA | Q59: =+J20 | R59: =+J11 | S59: =+F29 | T59: =+F35
P60: =+'GRUPOS INFANTIL'!H9 -> CLUB PROMOTOR DEPORTIVO SCORPION | Q60: =+F23 | R60: =+J14 | S60: =+J26 | T60: =+J35
P61: =+'GRUPOS INFANTIL'!#REF! -> #REF! | Q61: =+J23 | R61: =+J17 | S61: =+J29 | T61: =+J32

Sheet CUARTOS DE FINAL.
H1: Campeonato Nacional de Futbol
B2: CUARTOS DE FINAL | H2: “COPA FUTURO TALENTO”
B3: Observación: Si el partido se define por penales, éstos deben sumarse al resultado.
B4: PARTIDOS | P4: Ganador
B6: 42596 | C6: LLAVE A | D6: 03:00. p.m. | F6: =IF(AND(H6<>"",J6<>""),IF(H6=J6,"E",IF(H6>J6,"G","P")),"") -> P | G6: =+'GRUPO A'!$W$34 -> ASTON HUILA | H6: 1 | I6: - | J6: 2 | K6: =IF(AND(J6<>"",H6<>""),IF(J6=H6,"E",IF(J6>H6,"G","P")),"") -> G | L6: =+#REF! -> #REF! | N6: PALMARA | P6: =IF(OR(F6="E",F6=""),"",IF(F6="G",G6,L6)) -> #REF!
B9: 42596 | C9: LLAVE B | D9: 04:20. p.m. | F9: =IF(AND(H9<>"",J9<>""),IF(H9=J9,"E",IF(H9>J9,"G","P")),"") -> G | G9: =+'GRUPO B'!$W$34 | H9: 2 | I9: - | J9: 1 | K9: =IF(AND(J9<>"",H9<>""),IF(J9=H9,"E",IF(J9>H9,"G","P")),"") -> P | L9: =+#REF! -> #REF! | N9: CANCHA 2 | P9: =IF(OR(F9="E",F9=""),"",IF(F9="G",G9,L9))
B12: 42596 | C12: LLAVE C | D12: 03:00. p.m. | F12: =IF(AND(H12<>"",J12<>""),IF(H12=J12,"E",IF(H12>J12,"G","P")),"") -> P | G12: =+#REF! -> #REF! | H12: 1 | I12: - | J12: 2 | K12: =IF(AND(J12<>"",H12<>""),IF(J12=H12,"E",IF(J12>H12,"G","P")),"") -> G | L12: =+'GRUPO A'!$W$35 -> CLUB DEPORTIVO NUEVAS GENERACIONES | N12: CANCHA 2 | P12: =IF(OR(F12="E",F12=""),"",IF(F12="G",G12,L12)) -> CLUB DEPORTIVO NUEVAS GENERACIONES
B15: 42596 | C15: LLAVE D | D15: 04:20. p.m. | F15: =IF(AND(H15<>"",J15<>""),IF(H15=J15,"E",IF(H15>J15,"G","P")),"") -> G | G15: =+#REF! -> #REF! | H15: 2 | I15: - | J15: 1 | K15: =IF(AND(J15<>"",H15<>""),IF(J15=H15,"E",IF(J15>H15,"G","P")),"") -> P | L15: =+'GRUPO B'!W35 | N15: PALMARA | P15: =IF(OR(F15="E",F15=""),"",IF(F15="G",G15,L15)) -> #REF!
B18: =+'GRUPOS INFANTIL'!C3 -> 0
B21: =+'GRUPOS INFANTIL'!C4 -> NACIDOS 2017 2018

Sheet DEFINICION
A1: =+'GRUPOS INFANTIL'!C1 -> XVIII Campeonato Nacional de Fútbol Infantil
A2: “COPA FUTURO TALENTO”
A3: =+'GRUPOS INFANTIL'!C3 -> 0
A4: =+'GRUPOS INFANTIL'!C4 -> NACIDOS 2017 2018
B5: SEMIFINALES
B6: Observación: Si el partido se define por penales, éstos deben sumarse al resultado.
B7: SEMIFINALES | S7: Ganador
B9: 42814 | C9: LLAVE 1 | D9: 07:00. a.m. | F9: =+'GRUPO A'!$W$34 -> ASTON HUILA | G9: =IF(AND(J9<>"",L9<>""),IF(J9=L9,"E",IF(J9>L9,"G","P")),"") -> G | J9: 2 | K9: - | L9: 0 | M9: =IF(AND(L9<>"",J9<>""),IF(L9=J9,"E",IF(L9>J9,"G","P")),"") -> P | O9: =+'GRUPO B'!$W$35 | Q9: CANCHA 2 | S9: =IF(OR(G9="E",G9=""),"",IF(G9="G",F9,O9)) -> ASTON HUILA | U9: =IF(OR(G9="E",G9=""),"",IF(G9="P",F9,O9))
B12: 42814 | C12: LLAVE 2 | D12: 08:00. a.m. | F12: =+'GRUPO B'!$W$34 | G12: =IF(AND(J12<>"",L12<>""),IF(J12=L12,"E",IF(J12>L12,"G","P")),"") -> G | I12: 4 | J12: 1 | K12: - | L12: 0 | M12: =IF(AND(L12<>"",J12<>""),IF(L12=J12,"E",IF(L12>J12,"G","P")),"") -> P | N12: 3 | O12: =+'GRUPO A'!$W$35 -> CLUB DEPORTIVO NUEVAS GENERACIONES | Q12: CANCHA 2 | S12: =IF(OR(G12="E",G12=""),"",IF(G12="G",F12,O12)) | U12: =IF(OR(G12="E",G12=""),"",IF(G12="P",F12,O12)) -> CLUB DEPORTIVO NUEVAS GENERACIONES

Sheet FINAL
A1: =+DEFINICION!A1 -> XVIII Campeonato Nacional de Fútbol Infantil
A2: =+DEFINICION!A2 -> “COPA FUTURO TALENTO”
A3: =+'GRUPOS INFANTIL'!C3 -> 0
A4: =+'GRUPOS INFANTIL'!C4 -> NACIDOS 2017 2018
B5: FINAL DEL TORNEO
B6: Observación: Si el partido se define por penales, éstos deben sumarse al resultado.
B7: Partido por el TERCER PUESTO | Q7: TERCER PUESTO
Q8: =IF(OR(G9="E",G9=""),"",IF(G9="G",H9,M9))
B9: 42814 | D9: 12:30. p.m. | G9: =IF(AND(I9<>"",K9<>""),IF(I9=K9,"E",IF(I9>K9,"G","P")),"") -> E | H9: =+DEFINICION!U9 | I9: . | J9: - | K9: . | L9: =IF(AND(K9<>"",I9<>""),IF(K9=I9,"E",IF(K9>I9,"G","P")),"") -> E | M9: =+DEFINICION!U12 -> CLUB DEPORTIVO NUEVAS GENERACIONES | O9: CANCHA 2
B13: FINAL DEL CAMPEONATO | Q13: SEGUNDO PUESTO
Q14: =IF(OR(G15="E",G15=""),"",IF(G15="P",H15,M15))
B15: 42814 | D15: 01:40. p.m. | G15: =IF(AND(I15<>"",K15<>""),IF(I15=K15,"E",IF(I15>K15,"G","P")),"") -> E | H15: =+DEFINICION!S9 -> ASTON HUILA | I15: , | J15: - | K15: , | L15: =IF(AND(K15<>"",I15<>""),IF(K15=I15,"E",IF(K15>I15,"G","P")),"") -> E | M15: =+DEFINICION!S12 | O15: CANCHA 2
C19: CAMPEÓN “COPA FUTURO TALENTO”
C21: =IF(OR(G15="E",G15=""),"",IF(G15="G",H15,M15))

Sheet IMPRIMIR
A1: Campeonato Nacional de Futbol
A2: “COPA FUTURO TALENTO”
B4: =+'GRUPOS INFANTIL'!D6 -> GRUPO A | D4: =+'GRUPOS INFANTIL'!H6 -> GRUPO B | G4: =+'GRUPOS INFANTIL'!F6 -> 0 | N4: =+'GRUPOS INFANTIL'!#REF! -> #REF!
B5: =+'GRUPOS INFANTIL'!D7 -> ASTON HUILA | D5: =+'GRUPOS INFANTIL'!H7 -> CANUTO F.C. | G5: =+'GRUPOS INFANTIL'!F7 -> 0 | N5: =+'GRUPOS INFANTIL'!#REF! -> #REF!
B6: =+'GRUPOS INFANTIL'!D8 -> INTER F. C. | D6: =+'GRUPOS INFANTIL'!H8 -> HUITACA FUTBOL CLUB CHIA | G6: =+'GRUPOS INFANTIL'!#REF! -> #REF! | N6: =+'GRUPOS INFANTIL'!#REF! -> #REF!
B7: =+'GRUPOS INFANTIL'!D9 -> ATHLETIC MELGAR | D7: =+'GRUPOS INFANTIL'!H9 -> CLUB PROMOTOR DEPORTIVO SCORPION | G7: =+'GRUPOS INFANTIL'!F9 -> 0 | N7: =+'GRUPOS INFANTIL'!#REF! -> #REF!
B8: =+'GRUPOS INFANTIL'!D10 -> CLUB DEPORTIVO NUEVAS GENERACIONES | D8: =+'GRUPOS INFANTIL'!#REF! -> #REF! | G8: =+'GRUPOS INFANTIL'!#REF! -> #REF! | N8: =+'GRUPOS INFANTIL'!#REF! -> #REF!
B10: =+'GRUPOS INFANTIL'!C3 -> 0 | N10: =+'GRUPOS INFANTIL'!F8 -> 2024
B11: =+'GRUPOS INFANTIL'!C4 -> NACIDOS 2017 2018
A12: =+'GRUPO A'!B4 -> GRUPO A
A14: PARTIDOS fecha 1
A16: =+'GRUPO A'!B20 -> 42812 | B16: =+'GRUPO A'!C20 -> 07:15. a.m. | D16: =+'GRUPO A'!E20 -> ASTON HUILA | F16: =IF(AND(G16<>"",I16<>""),IF(G16=I16,"E",IF(G16>I16,"G","P")),"") | H16: - | J16: =IF(AND(I16<>"",G16<>""),IF(I16=G16,"E",IF(I16>G16,"G","P")),"") | K16: =+'GRUPO A'!K20 -> INTER F. C. | O16: =+'GRUPO A'!M20 -> CANCHA 2
A18: =+'GRUPO A'!B23 -> 42812 | B18: =+'GRUPO A'!C23 -> 08:20. a.m. | D18: =+'GRUPO A'!E23 -> ATHLETIC MELGAR | F18: =IF(AND(G18<>"",I18<>""),IF(G18=I18,"E",IF(G18>I18,"G","P")),"") | H18: - | J18: =IF(AND(I18<>"",G18<>""),IF(I18=G18,"E",IF(I18>G18,"G","P")),"") | K18: =+'GRUPO A'!K23 -> CLUB DEPORTIVO NUEVAS GENERACIONES | O18: =+'GRUPO A'!M23 -> LAS VEGAS
A20: =+'GRUPO B'!B4 -> GRUPO B
A22: PARTIDOS fecha 1
A24: =+'GRUPO B'!B20 -> 42812 | B24: =+'GRUPO B'!C20 -> 12:00. m.d. | D24: =+'GRUPO B'!E20 -> CANUTO F.C. | F24: =IF(AND(G24<>"",I24<>""),IF(G24=I24,"E",IF(G24>I24,"G","P")),"") | H24: - | J24: =IF(AND(I24<>"",G24<>""),IF(I24=G24,"E",IF(I24>G24,"G","P")),"") | K24: =+'GRUPO B'!K20 -> INTER F. C. | O24: =+'GRUPO B'!M20 -> CANCHA 2
A26: =+'GRUPO B'!B23 -> 42812 | B26: =+'GRUPO B'!C23 -> 01:10. p.m. | D26: =+'GRUPO B'!E23 -> CLUB PROMOTOR DEPORTIVO SCORPION | F26: =IF(AND(G26<>"",I26<>""),IF(G26=I26,"E",IF(G26>I26,"G","P")),"") | H26: - | J26: =IF(AND(I26<>"",G26<>""),IF(I26=G26,"E",IF(I26>G26,"G","P")),"") | K26: =+'GRUPO B'!K23 -> #REF! | O26: =+'GRUPO B'!M23 -> CANCHA 2
A27: =+#REF! -> #REF!
A29: PARTIDOS fecha 1
A31: =+#REF! -> #REF! | B31: =+#REF! -> #REF! | D31: =+#REF! -> #REF! | F31: =IF(AND(G31<>"",I31<>""),IF(G31=I31,"E",IF(G31>I31,"G","P")),"") | H31: - | J31: =IF(AND(I31<>"",G31<>""),IF(I31=G31,"E",IF(I31>G31,"G","P")),"") | K31: =+#REF! -> #REF! | O31: =+#REF! -> #REF!
A33: =+#REF! -> #REF! | B33: =+#REF! -> #REF! | D33: =+#REF! -> #REF! | F33: =IF(AND(G33<>"",I33<>""),IF(G33=I33,"E",IF(G33>I33,"G","P")),"") | H33: - | J33: =IF(AND(I33<>"",G33<>""),IF(I33=G33,"E",IF(I33>G33,"G","P")),"") | K33: =+#REF! -> #REF! | O33: =+#REF! -> #REF!
A34: =+#REF! -> #REF!
A36: PARTIDOS fecha 1
A38: =+#REF! -> #REF! | B38: =+#REF! -> #REF! | D38: =+#REF! -> #REF! | F38: =IF(AND(G38<>"",I38<>""),IF(G38=I38,"E",IF(G38>I38,"G","P")),"") | H38: - | J38: =IF(AND(I38<>"",G38<>""),IF(I38=G38,"E",IF(I38>G38,"G","P")),"") | K38: =+#REF! -> #REF! | O38: =+#REF! -> #REF!
A40: =+#REF! -> #REF! | B40: =+#REF! -> #REF! | D40: =+#REF! -> #REF! | F40: =IF(AND(G40<>"",I40<>""),IF(G40=I40,"E",IF(G40>I40,"G","P")),"") | H40: - | J40: =IF(AND(I40<>"",G40<>""),IF(I40=G40,"E",IF(I40>G40,"G","P")),"") | K40: =+#REF! -> #REF! | O40: =+#REF! -> #REF!
A41: NOTA: LA ORGANIZACIÓN DEL TORNEO NO SE HACE RESPONSABLE DE ACCIDENTES O PERDIDA DE ELEMENTOS DURANTE EL TRANSCURSO DEL TORNEO. Les recordamos traer el seguro de salud de los deportistas. Tarjeta de identidad Original, Registro Civil.
A46: Sede Administrativa Cra 13 No 6-43 Barrio La Florida
A47: Celular 310 241 33 76 Fijo 2 450 593
A48: soccermelgar@outlook.com
A49: Melgar - Tolima

Sheet IMPRIMIR 2
A1: Campeonato Nacional de Futbol
A2: “COPA FUTURO TALENTO”
B4: =+'GRUPOS INFANTIL'!D6 -> GRUPO A | D4: =+'GRUPOS INFANTIL'!H6 -> GRUPO B | G4: =+'GRUPOS INFANTIL'!F6 -> 0 | N4: =+'GRUPOS INFANTIL'!#REF! -> #REF!
B5: =+'GRUPOS INFANTIL'!D7 -> ASTON HUILA | D5: =+'GRUPOS INFANTIL'!H7 -> CANUTO F.C. | G5: =+'GRUPOS INFANTIL'!F7 -> 0 | N5: =+'GRUPOS INFANTIL'!#REF! -> #REF!
B6: =+'GRUPOS INFANTIL'!D8 -> INTER F. C. | D6: =+'GRUPOS INFANTIL'!H8 -> HUITACA FUTBOL CLUB CHIA | G6: =+'GRUPOS INFANTIL'!#REF! -> #REF! | N6: =+'GRUPOS INFANTIL'!#REF! -> #REF!
B7: =+'GRUPOS INFANTIL'!D9 -> ATHLETIC MELGAR | D7: =+'GRUPOS INFANTIL'!H9 -> CLUB PROMOTOR DEPORTIVO SCORPION | G7: =+'GRUPOS INFANTIL'!F9 -> 0 | N7: =+'GRUPOS INFANTIL'!#REF! -> #REF!
B8: =+'GRUPOS INFANTIL'!D10 -> CLUB DEPORTIVO NUEVAS GENERACIONES | D8: =+'GRUPOS INFANTIL'!#REF! -> #REF! | G8: =+'GRUPOS INFANTIL'!#REF! -> #REF! | N8: =+'GRUPOS INFANTIL'!#REF! -> #REF!
B10: =+'GRUPOS INFANTIL'!C3 -> 0 | N10: =+'GRUPOS INFANTIL'!F8 -> 2024
B11: =+'GRUPOS INFANTIL'!C4 -> NACIDOS 2017 2018
A12: =+'GRUPO A'!B4 -> GRUPO A
A14: PARTIDOS fecha 2
A16: =+'GRUPO A'!B26 -> 42812 | B16: =+'GRUPO A'!C26 -> 03:00. p.m. | D16: =+'GRUPO A'!E26 -> ASTON HUILA | F16: =IF(AND(G16<>"",I16<>""),IF(G16=I16,"E",IF(G16>I16,"G","P")),"") | H16: - | J16: =IF(AND(I16<>"",G16<>""),IF(I16=G16,"E",IF(I16>G16,"G","P")),"") | K16: =+'GRUPO A'!K26 -> ATHLETIC MELGAR | O16: =+'GRUPO A'!M26 -> LAS VEGAS
A18: =+'GRUPO A'!B29 -> 42812 | B18: =+'GRUPO A'!C29 -> 04:00. p.m. | D18: =+'GRUPO A'!E29 -> INTER F. C. | F18: =IF(AND(G18<>"",I18<>""),IF(G18=I18,"E",IF(G18>I18,"G","P")),"") | H18: - | J18: =IF(AND(I18<>"",G18<>""),IF(I18=G18,"E",IF(I18>G18,"G","P")),"") | K18: =+'GRUPO A'!K29 -> CLUB DEPORTIVO NUEVAS GENERACIONES | O18: =+'GRUPO A'!M29 -> LAS VEGAS
A20: =+'GRUPO B'!B4 -> GRUPO B
A22: PARTIDOS fecha 2
A24: =+'GRUPO B'!B26 -> 42813 | B24: =+'GRUPO B'!C26 -> 09:50. a.m. | D24: =+'GRUPO B'!E26 -> CANUTO F.C. | F24: =IF(AND(G24<>"",I24<>""),IF(G24=I24,"E",IF(G24>I24,"G","P")),"") | H24: - | J24: =IF(AND(I24<>"",G24<>""),IF(I24=G24,"E",IF(I24>G24,"G","P")),"") | K24: =+'GRUPO B'!K26 -> CLUB PROMOTOR DEPORTIVO SCORPION | O24: =+'GRUPO B'!M26 -> CANCHA 1
A26: =+'GRUPO B'!B29 -> 42813 | B26: =+'GRUPO B'!C29 -> 10:50. a.m. | D26: =+'GRUPO B'!E29 -> HUITACA FUTBOL CLUB CHIA | F26: =IF(AND(G26<>"",I26<>""),IF(G26=I26,"E",IF(G26>I26,"G","P")),"") | H26: - | J26: =IF(AND(I26<>"",G26<>""),IF(I26=G26,"E",IF(I26>G26,"G","P")),"") | K26: =+'GRUPO B'!K29 -> #REF! | O26: =+'GRUPO B'!M29 -> CANCHA 1
A27: =+#REF! -> #REF!
A29: PARTIDOS fecha 2
A31: =+#REF! -> #REF! | B31: =+#REF! -> #REF! | D31: =+#REF! -> #REF! | F31: =IF(AND(G31<>"",I31<>""),IF(G31=I31,"E",IF(G31>I31,"G","P")),"") | H31: - | J31: =IF(AND(I31<>"",G31<>""),IF(I31=G31,"E",IF(I31>G31,"G","P")),"") | K31: =+#REF! -> #REF! | O31: =+#REF! -> #REF!
A33: =+#REF! -> #REF! | B33: =+#REF! -> #REF! | D33: =+#REF! -> #REF! | F33: =IF(AND(G33<>"",I33<>""),IF(G33=I33,"E",IF(G33>I33,"G","P")),"") | H33: - | J33: =IF(AND(I33<>"",G33<>""),IF(I33=G33,"E",IF(I33>G33,"G","P")),"") | K33: =+#REF! -> #REF! | O33: =+#REF! -> #REF!
A34: =+#REF! -> #REF!
A36: PARTIDOS fecha 2
A38: =+#REF! -> #REF! | B38: =+#REF! -> #REF! | D38: =+#REF! -> #REF! | F38: =IF(AND(G38<>"",I38<>""),IF(G38=I38,"E",IF(G38>I38,"G","P")),"") | H38: - | J38: =IF(AND(I38<>"",G38<>""),IF(I38=G38,"E",IF(I38>G38,"G","P")),"") | K38: =+#REF! -> #REF! | O38: =+#REF! -> #REF!
A40: =+#REF! -> #REF! | B40: =+#REF! -> #REF! | D40: =+#REF! -> #REF! | F40: =IF(AND(G40<>"",I40<>""),IF(G40=I40,"E",IF(G40>I40,"G","P")),"") | H40: - | J40: =IF(AND(I40<>"",G40<>""),IF(I40=G40,"E",IF(I40>G40,"G","P")),"") | K40: =+#REF! -> #REF! | O40: =+#REF! -> #REF!
A41: NOTA: LA ORGANIZACIÓN DEL TORNEO NO SE HACE RESPONSABLE DE ACCIDENTES O PERDIDA DE ELEMENTOS DURANTE EL TRANSCURSO DEL TORNEO. Les recordamos traer el seguro de salud de los deportistas. Tarjeta de identidad Original, Registro Civil.
A46: Sede Administrativa Cra 13 No 6-43 Barrio La Florida
A47: Celular 310 241 33 76 Fijo 2 450 593
A48: soccermelgar@outlook.com
A49: Melgar - Tolima

Sheet IMPRIMIR 3
B1: Campeonato Nacional de Futbol
B2: “COPA FUTURO TALENTO”
G3: =+'GRUPOS INFANTIL'!C3 -> 0
G4: =+'GRUPOS INFANTIL'!C4 -> NACIDOS 2017 2018
B6: =+'GRUPOS INFANTIL'!D6 -> GRUPO A | D6: =+'GRUPO A'!Q20:Q21 -> #VALUE! | E6: =+'GRUPO A'!R20:R21 -> #VALUE! | F6: =+'GRUPO A'!S20:S21 -> #VALUE! | G6: =+'GRUPO A'!T20:T21 -> #VALUE! | H6: =+'GRUPO A'!U20:U21 -> #VALUE! | I6: =+'GRUPO A'!V20:V21 -> #VALUE! | J6: =+'GRUPO A'!W20:W21 -> #VALUE! | K6: =+'GRUPO A'!X20:X21 -> #VALUE! | L6: =+'GRUPO A'!Y20:Y21 -> #VALUE!
B8: =+'GRUPO A'!P22:P23 -> #VALUE! | D8: =+'GRUPO A'!Q22:Q23 -> #VALUE! | E8: =+'GRUPO A'!R22:R23 -> #VALUE! | F8: =+'GRUPO A'!S22:S23 -> #VALUE! | G8: =+'GRUPO A'!T22:T23 -> #VALUE! | H8: =+'GRUPO A'!U22:U23 -> #VALUE! | I8: =+'GRUPO A'!V22:V23 -> #VALUE! | J8: =+'GRUPO A'!W22:W23 -> #VALUE! | K8: =+'GRUPO A'!X22:X23 -> #VALUE! | L8: =+'GRUPO A'!Y22:Y23 -> #VALUE!
B10: =+'GRUPO A'!P24:P25 -> #VALUE! | D10: =+'GRUPO A'!Q24:Q25 -> #VALUE! | E10: =+'GRUPO A'!R24:R25 -> #VALUE! | F10: =+'GRUPO A'!S24:S25 -> #VALUE! | G10: =+'GRUPO A'!T24:T25 -> #VALUE! | H10: =+'GRUPO A'!U24:U25 -> #VALUE! | I10: =+'GRUPO A'!V24:V25 -> #VALUE! | J10: =+'GRUPO A'!W24:W25 -> #VALUE! | K10: =+'GRUPO A'!X24:X25 -> #VALUE! | L10: =+'GRUPO A'!Y24:Y25 -> #VALUE!
B12: =+'GRUPO A'!P26:P27 -> #VALUE! | D12: =+'GRUPO A'!Q26:Q27 -> #VALUE! | E12: =+'GRUPO A'!R26:R27 -> #VALUE! | F12: =+'GRUPO A'!S26:S27 -> #VALUE! | G12: =+'GRUPO A'!T26:T27 -> #VALUE! | H12: =+'GRUPO A'!U26:U27 -> #VALUE! | I12: =+'GRUPO A'!V26:V27 -> #VALUE! | J12: =+'GRUPO A'!W26:W27 -> #VALUE! | K12: =+'GRUPO A'!X26:X27 -> #VALUE! | L12: =+'GRUPO A'!Y26:Y27 -> #VALUE!
B14: =+'GRUPO A'!P28:P29 -> #VALUE! | D14: =+'GRUPO A'!Q28:Q29 -> #VALUE! | E14: =+'GRUPO A'!R28:R29 -> #VALUE! | F14: =+'GRUPO A'!S28:S29 -> #VALUE! | G14: =+'GRUPO A'!T28:T29 -> #VALUE! | H14: =+'GRUPO A'!U28:U29 -> #VALUE! | I14: =+'GRUPO A'!V28:V29 -> #VALUE! | J14: =+'GRUPO A'!W28:W29 -> #VALUE! | K14: =+'GRUPO A'!X28:X29 -> #VALUE! | L14: =+'GRUPO A'!Y28:Y29 -> #VALUE!
A17: PARTIDOS fecha 3 ULTIMA
A19: =+'GRUPO A'!B32 -> 42813 | B19: =+'GRUPO A'!C32 -> 01:15. p.m. | C19: =+'GRUPO A'!E32 -> INTER F. C. | E19: - | G19: =+'GRUPO A'!K32 -> ATHLETIC MELGAR | K19: =+'GRUPO A'!M32 -> CANCHA 2
A21: =+'GRUPO A'!B35 -> 42813 | B21: =+'GRUPO A'!C35 -> 02:30. p.m. | C21: =+'GRUPO A'!E35 -> ASTON HUILA | E21: - | G21: =+'GRUPO A'!K35 -> CLUB DEPORTIVO NUEVAS GENERACIONES | K21: =+'GRUPO A'!M35 -> CANCHA 1
B23: =+'GRUPOS INFANTIL'!H6 -> GRUPO B | D23: =+'GRUPO B'!Q8 -> Pts. | E23: =+'GRUPO B'!R8 -> PJ | F23: =+'GRUPO B'!S8 -> Gan. | G23: =+'GRUPO B'!T8 -> Emp. | H23: =+'GRUPO B'!U8 -> Per. | I23: =+'GRUPO B'!V8 -> GF | J23: =+'GRUPO B'!W8 -> GC | K23: =+'GRUPO B'!X8 -> Dif. | L23: =+'GRUPO B'!Y8 -> Tj
B25: =+'GRUPO B'!P10 -> #REF! | D25: =+'GRUPO B'!Q10 -> 0 | E25: =+'GRUPO B'!R10 -> 0 | F25: =+'GRUPO B'!S10 -> 0 | G25: =+'GRUPO B'!T10 -> 0 | H25: =+'GRUPO B'!U10 -> 0 | I25: =+'GRUPO B'!V10 -> 0 | J25: =+'GRUPO B'!W10 -> 0 | K25: =+'GRUPO B'!X10 -> 0 | L25: =+'GRUPO B'!Y10 -> 0
B27: =+'GRUPO B'!P12 -> 2) CLUB PROMOTOR DEPORTIVO SCORPION | D27: =+'GRUPO B'!Q12 -> 0 | E27: =+'GRUPO B'!R12 -> 0 | F27: =+'GRUPO B'!S12 -> 0 | G27: =+'GRUPO B'!T12 -> 0 | H27: =+'GRUPO B'!U12 -> 0 | I27: =+'GRUPO B'!V12 -> 0 | J27: =+'GRUPO B'!W12 -> 0 | K27: =+'GRUPO B'!X12 -> 0 | L27: =+'GRUPO B'!Y12 -> 0
B29: =+'GRUPO B'!P14 -> 3) HUITACA FUTBOL CLUB CHIA | D29: =+'GRUPO B'!Q14 -> 0 | E29: =+'GRUPO B'!R14 -> 0 | F29: =+'GRUPO B'!S14 -> 0 | G29: =+'GRUPO B'!T14 -> 0 | H29: =+'GRUPO B'!U14 -> 0 | I29: =+'GRUPO B'!V14 -> 0 | J29: =+'GRUPO B'!W14 -> 0 | K29: =+'GRUPO B'!X14 -> 0 | L29: =+'GRUPO B'!Y14 -> 0
B31: =+'GRUPO B'!P16 -> 4) CANUTO F.C. | D31: =+'GRUPO B'!Q16 -> 0 | E31: =+'GRUPO B'!R16 -> 0 | F31: =+'GRUPO B'!S16 -> 0 | G31: =+'GRUPO B'!T16 -> 0 | H31: =+'GRUPO B'!U16 -> 0 | I31: =+'GRUPO B'!V16 -> 0 | J31: =+'GRUPO B'!W16 -> 0 | K31: =+'GRUPO B'!X16 -> 0 | L31: =+'GRUPO B'!Y16 -> 0
A34: PARTIDOS fecha 3 ULTIMA
A36: =+'GRUPO B'!B32 -> 42813 | B36: =+'GRUPO B'!C32 -> 04:30. p.m. | C36: =+'GRUPO B'!E32 -> CANUTO F.C. | E36: - | G36: =+'GRUPO B'!K32 -> #REF! | K36: =+'GRUPO B'!M32 -> CANCHA 1
A38: =+'GRUPO B'!B35 -> 42813 | B38: =+'GRUPO B'!C32 -> 04:30. p.m. | C38: =+'GRUPO B'!E35 -> HUITACA FUTBOL CLUB CHIA | E38: - | G38: =+'GRUPO B'!K35 -> CLUB PROMOTOR DEPORTIVO SCORPION | K38: =+'GRUPO B'!M35 -> CANCHA 2
B41: =+'GRUPOS INFANTIL'!F6 -> 0 | D41: =+'GRUPO B'!Q8 -> Pts. | E41: =+'GRUPO B'!R8 -> PJ | F41: =+'GRUPO B'!S8 -> Gan. | G41: =+'GRUPO B'!T8 -> Emp. | H41: =+'GRUPO B'!U8 -> Per. | I41: =+'GRUPO B'!V8 -> GF | J41: =+'GRUPO B'!W8 -> GC | K41: =+'GRUPO B'!X8 -> Dif. | L41: =+'GRUPO B'!Y8 -> Tj
B43: =+'GRUPO B'!P10 -> #REF! | D43: =+'GRUPO B'!Q10 -> 0 | E43: =+'GRUPO B'!R10 -> 0 | F43: =+'GRUPO B'!S10 -> 0 | G43: =+'GRUPO B'!T10 -> 0 | H43: =+'GRUPO B'!U10 -> 0 | I43: =+'GRUPO B'!V10 -> 0 | J43: =+'GRUPO B'!W10 -> 0 | K43: =+'GRUPO B'!X10 -> 0 | L43: =+'GRUPO B'!Y10 -> 0
B45: =+'GRUPO B'!P12 -> 2) CLUB PROMOTOR DEPORTIVO SCORPION | D45: =+'GRUPO B'!Q12 -> 0 | E45: =+'GRUPO B'!R12 -> 0 | F45: =+'GRUPO B'!S12 -> 0 | G45: =+'GRUPO B'!T12 -> 0 | H45: =+'GRUPO B'!U12 -> 0 | I45: =+'GRUPO B'!V12 -> 0 | J45: =+'GRUPO B'!W12 -> 0 | K45: =+'GRUPO B'!X12 -> 0 | L45: =+'GRUPO B'!Y12 -> 0
B47: =+'GRUPO B'!P14 -> 3) HUITACA FUTBOL CLUB CHIA | D47: =+'GRUPO B'!Q14 -> 0 | E47: =+'GRUPO B'!R14 -> 0 | F47: =+'GRUPO B'!S14 -> 0 | G47: =+'GRUPO B'!T14 -> 0 | H47: =+'GRUPO B'!U14 -> 0 | I47: =+'GRUPO B'!V14 -> 0 | J47: =+'GRUPO B'!W14 -> 0 | K47: =+'GRUPO B'!X14 -> 0 | L47: =+'GRUPO B'!Y14 -> 0
B49: =+'GRUPO B'!P16 -> 4) CANUTO F.C. | D49: =+'GRUPO B'!Q16 -> 0 | E49: =+'GRUPO B'!R16 -> 0 | F49: =+'GRUPO B'!S16 -> 0 | G49: =+'GRUPO B'!T16 -> 0 | H49: =+'GRUPO B'!U16 -> 0 | I49: =+'GRUPO B'!V16 -> 0 | J49: =+'GRUPO B'!W16 -> 0 | K49: =+'GRUPO B'!X16 -> 0 | L49: =+'GRUPO B'!Y16 -> 0
A52: PARTIDOS fecha 3 ULTIMA
A54: =+#REF! -> #REF! | B54: =+#REF! -> #REF! | C54: =+#REF! -> #REF! | E54: - | G54: =+#REF! -> #REF! | K54: =+#REF! -> #REF!
A56: =+#REF! -> #REF! | B56: =+#REF! -> #REF! | C56: =+#REF! -> #REF! | E56: - | G56: =+#REF! -> #REF! | K56: =+#REF! -> #REF!
B59: =+'GRUPOS INFANTIL'!#REF! -> #REF! | D59: =+#REF! -> #REF! | E59: =+#REF! -> #REF! | F59: =+#REF! -> #REF! | G59: =+#REF! -> #REF! | H59: =+#REF! -> #REF! | I59: =+#REF! -> #REF! | J59: =+#REF! -> #REF! | K59: =+#REF! -> #REF! | L59: =+#REF! -> #REF!
B61: =+#REF! -> #REF! | D61: =+#REF! -> #REF! | E61: =+#REF! -> #REF! | F61: =+#REF! -> #REF! | G61: =+#REF! -> #REF! | H61: =+#REF! -> #REF! | I61: =+#REF! -> #REF! | J61: =+#REF! -> #REF! | K61: =+#REF! -> #REF! | L61: =+#REF! -> #REF!
B63: =+#REF! -> #REF! | D63: =+#REF! -> #REF! | E63: =+#REF! -> #REF! | F63: =+#REF! -> #REF! | G63: =+#REF! -> #REF! | H63: =+#REF! -> #REF! | I63: =+#REF! -> #REF! | J63: =+#REF! -> #REF! | K63: =+#REF! -> #REF! | L63: =+#REF! -> #REF!
B65: =+#REF! -> #REF! | D65: =+#REF! -> #REF! | E65: =+#REF! -> #REF! | F65: =+#REF! -> #REF! | G65: =+#REF! -> #REF! | H65: =+#REF! -> #REF! | I65: =+#REF! -> #REF! | J65: =+#REF! -> #REF! | K65: =+#REF! -> #REF! | L65: =+#REF! -> #REF!
B67: =+#REF! -> #REF! | D67: =+#REF! -> #REF! | E67: =+#REF! -> #REF! | F67: =+#REF! -> #REF! | G67: =+#REF! -> #REF! | H67: =+#REF! -> #REF! | I67: =+#REF! -> #REF! | J67: =+#REF! -> #REF! | K67: =+#REF! -> #REF! | L67: =+#REF! -> #REF!
A70: PARTIDOS fecha 3 ULTIMA
A72: =+#REF! -> #REF! | B72: =+#REF! -> #REF! | C72: =+#REF! -> #REF! | E72: - | G72: =+#REF! -> #REF! | K72: =+#REF! -> #REF!
A74: =+#REF! -> #REF! | B74: =+#REF! -> #REF! | C74: =+#REF! -> #REF! | E74: - | G74: =+#REF! -> #REF! | K74: =+#REF! -> #REF!
A75: La organización no se hace responsable de las posibles lesiones ocasionadas dentro y fuera del campo de juego, accidentes o perdidas de elementos durante el transcurso del torneo.
A78: Sede Administrativa Cra 13 No 6-43 Barrio La Florida
A79: Celular 310 241 33 76 Fijo 2 450 593
A80: soccermelgar@outlook.com
...

Sheet IMPRIMIR 3 (2)
B1: Campeonato Nacional de Futbol
B2: “COPA FUTURO TALENTO”
G3: =+'GRUPOS INFANTIL'!C3 -> 0
G4: =+'GRUPOS INFANTIL'!C4 -> NACIDOS 2017 2018
B6: =+'GRUPOS INFANTIL'!D6 -> GRUPO A | D6: =+'GRUPO A'!Q20:Q21 -> #VALUE! | E6: =+'GRUPO A'!R20:R21 -> #VALUE! | F6: =+'GRUPO A'!S20:S21 -> #VALUE! | G6: =+'GRUPO A'!T20:T21 -> #VALUE! | H6: =+'GRUPO A'!U20:U21 -> #VALUE! | I6: =+'GRUPO A'!V20:V21 -> #VALUE! | J6: =+'GRUPO A'!W20:W21 -> #VALUE! | K6: =+'GRUPO A'!X20:X21 -> #VALUE! | L6: =+'GRUPO A'!Y20:Y21 -> #VALUE!
B8: =+'GRUPO A'!P22:P23 -> #VALUE! | D8: =+'GRUPO A'!Q22:Q23 -> #VALUE! | E8: =+'GRUPO A'!R22:R23 -> #VALUE! | F8: =+'GRUPO A'!S22:S23 -> #VALUE! | G8: =+'GRUPO A'!T22:T23 -> #VALUE! | H8: =+'GRUPO A'!U22:U23 -> #VALUE! | I8: =+'GRUPO A'!V22:V23 -> #VALUE! | J8: =+'GRUPO A'!W22:W23 -> #VALUE! | K8: =+'GRUPO A'!X22:X23 -> #VALUE! | L8: =+'GRUPO A'!Y22:Y23 -> #VALUE!
B10: =+'GRUPO A'!P24:P25 -> #VALUE! | D10: =+'GRUPO A'!Q24:Q25 -> #VALUE! | E10: =+'GRUPO A'!R24:R25 -> #VALUE! | F10: =+'GRUPO A'!S24:S25 -> #VALUE! | G10: =+'GRUPO A'!T24:T25 -> #VALUE! | H10: =+'GRUPO A'!U24:U25 -> #VALUE! | I10: =+'GRUPO A'!V24:V25 -> #VALUE! | J10: =+'GRUPO A'!W24:W25 -> #VALUE! | K10: =+'GRUPO A'!X24:X25 -> #VALUE! | L10: =+'GRUPO A'!Y24:Y25 -> #VALUE!
B12: =+'GRUPO A'!P26:P27 -> #VALUE! | D12: =+'GRUPO A'!Q26:Q27 -> #VALUE! | E12: =+'GRUPO A'!R26:R27 -> #VALUE! | F12: =+'GRUPO A'!S26:S27 -> #VALUE! | G12: =+'GRUPO A'!T26:T27 -> #VALUE! | H12: =+'GRUPO A'!U26:U27 -> #VALUE! | I12: =+'GRUPO A'!V26:V27 -> #VALUE! | J12: =+'GRUPO A'!W26:W27 -> #VALUE! | K12: =+'GRUPO A'!X26:X27 -> #VALUE! | L12: =+'GRUPO A'!Y26:Y27 -> #VALUE!
B14: =+'GRUPO A'!P28:P29 -> #VALUE! | D14: =+'GRUPO A'!Q28:Q29 -> #VALUE! | E14: =+'GRUPO A'!R28:R29 -> #VALUE! | F14: =+'GRUPO A'!S28:S29 -> #VALUE! | G14: =+'GRUPO A'!T28:T29 -> #VALUE! | H14: =+'GRUPO A'!U28:U29 -> #VALUE! | I14: =+'GRUPO A'!V28:V29 -> #VALUE! | J14: =+'GRUPO A'!W28:W29 -> #VALUE! | K14: =+'GRUPO A'!X28:X29 -> #VALUE! | L14: =+'GRUPO A'!Y28:Y29 -> #VALUE!
A17: PARTIDOS fecha 3 ULTIMA
A19: =+'GRUPO A'!B32 -> 42813 | B19: =+'GRUPO A'!C32 -> 01:15. p.m. | C19: =+'GRUPO A'!E32 -> INTER F. C. | E19: - | G19: =+'GRUPO A'!K32 -> ATHLETIC MELGAR | K19: =+'GRUPO A'!M32 -> CANCHA 2
A21: =+'GRUPO A'!B35 -> 42813 | B21: =+'GRUPO A'!C35 -> 02:30. p.m. | C21: =+'GRUPO A'!E35 -> ASTON HUILA | E21: - | G21: =+'GRUPO A'!K35 -> CLUB DEPORTIVO NUEVAS GENERACIONES | K21: =+'GRUPO A'!M35 -> CANCHA 1
B23: =+'GRUPOS INFANTIL'!H6 -> GRUPO B | D23: =+'GRUPO B'!Q8 -> Pts. | E23: =+'GRUPO B'!R8 -> PJ | F23: =+'GRUPO B'!S8 -> Gan. | G23: =+'GRUPO B'!T8 -> Emp. | H23: =+'GRUPO B'!U8 -> Per. | I23: =+'GRUPO B'!V8 -> GF | J23: =+'GRUPO B'!W8 -> GC | K23: =+'GRUPO B'!X8 -> Dif. | L23: =+'GRUPO B'!Y8 -> Tj
B25: =+'GRUPO B'!P10 -> #REF! | D25: =+'GRUPO B'!Q10 -> 0 | E25: =+'GRUPO B'!R10 -> 0 | F25: =+'GRUPO B'!S10 -> 0 | G25: =+'GRUPO B'!T10 -> 0 | H25: =+'GRUPO B'!U10 -> 0 | I25: =+'GRUPO B'!V10 -> 0 | J25: =+'GRUPO B'!W10 -> 0 | K25: =+'GRUPO B'!X10 -> 0 | L25: =+'GRUPO B'!Y10 -> 0
B27: =+'GRUPO B'!P12 -> 2) CLUB PROMOTOR DEPORTIVO SCORPION | D27: =+'GRUPO B'!Q12 -> 0 | E27: =+'GRUPO B'!R12 -> 0 | F27: =+'GRUPO B'!S12 -> 0 | G27: =+'GRUPO B'!T12 -> 0 | H27: =+'GRUPO B'!U12 -> 0 | I27: =+'GRUPO B'!V12 -> 0 | J27: =+'GRUPO B'!W12 -> 0 | K27: =+'GRUPO B'!X12 -> 0 | L27: =+'GRUPO B'!Y12 -> 0
B29: =+'GRUPO B'!P14 -> 3) HUITACA FUTBOL CLUB CHIA | D29: =+'GRUPO B'!Q14 -> 0 | E29: =+'GRUPO B'!R14 -> 0 | F29: =+'GRUPO B'!S14 -> 0 | G29: =+'GRUPO B'!T14 -> 0 | H29: =+'GRUPO B'!U14 -> 0 | I29: =+'GRUPO B'!V14 -> 0 | J29: =+'GRUPO B'!W14 -> 0 | K29: =+'GRUPO B'!X14 -> 0 | L29: =+'GRUPO B'!Y14 -> 0
B31: =+'GRUPO B'!P16 -> 4) CANUTO F.C. | D31: =+'GRUPO B'!Q16 -> 0 | E31: =+'GRUPO B'!R16 -> 0 | F31: =+'GRUPO B'!S16 -> 0 | G31: =+'GRUPO B'!T16 -> 0 | H31: =+'GRUPO B'!U16 -> 0 | I31: =+'GRUPO B'!V16 -> 0 | J31: =+'GRUPO B'!W16 -> 0 | K31: =+'GRUPO B'!X16 -> 0 | L31: =+'GRUPO B'!Y16 -> 0
A34: PARTIDOS fecha 3 ULTIMA
A36: =+'GRUPO B'!B32 -> 42813 | B36: =+'GRUPO B'!C32 -> 04:30. p.m. | C36: =+'GRUPO B'!E32 -> CANUTO F.C. | E36: - | G36: =+'GRUPO B'!K32 -> #REF! | K36: =+'GRUPO B'!M32 -> CANCHA 1
A38: =+'GRUPO B'!B35 -> 42813 | B38: =+'GRUPO B'!C32 -> 04:30. p.m. | C38: =+'GRUPO B'!E35 -> HUITACA FUTBOL CLUB CHIA | E38: - | G38: =+'GRUPO B'!K35 -> CLUB PROMOTOR DEPORTIVO SCORPION | K38: =+'GRUPO B'!M35 -> CANCHA 2
B41: =+'GRUPOS INFANTIL'!F6 -> 0 | D41: =+'GRUPO B'!Q8 -> Pts. | E41: =+'GRUPO B'!R8 -> PJ | F41: =+'GRUPO B'!S8 -> Gan. | G41: =+'GRUPO B'!T8 -> Emp. | H41: =+'GRUPO B'!U8 -> Per. | I41: =+'GRUPO B'!V8 -> GF | J41: =+'GRUPO B'!W8 -> GC | K41: =+'GRUPO B'!X8 -> Dif. | L41: =+'GRUPO B'!Y8 -> Tj
B43: =+'GRUPO B'!P10 -> #REF! | D43: =+'GRUPO B'!Q10 -> 0 | E43: =+'GRUPO B'!R10 -> 0 | F43: =+'GRUPO B'!S10 -> 0 | G43: =+'GRUPO B'!T10 -> 0 | H43: =+'GRUPO B'!U10 -> 0 | I43: =+'GRUPO B'!V10 -> 0 | J43: =+'GRUPO B'!W10 -> 0 | K43: =+'GRUPO B'!X10 -> 0 | L43: =+'GRUPO B'!Y10 -> 0
B45: =+'GRUPO B'!P12 -> 2) CLUB PROMOTOR DEPORTIVO SCORPION | D45: =+'GRUPO B'!Q12 -> 0 | E45: =+'GRUPO B'!R12 -> 0 | F45: =+'GRUPO B'!S12 -> 0 | G45: =+'GRUPO B'!T12 -> 0 | H45: =+'GRUPO B'!U12 -> 0 | I45: =+'GRUPO B'!V12 -> 0 | J45: =+'GRUPO B'!W12 -> 0 | K45: =+'GRUPO B'!X12 -> 0 | L45: =+'GRUPO B'!Y12 -> 0
B47: =+'GRUPO B'!P14 -> 3) HUITACA FUTBOL CLUB CHIA | D47: =+'GRUPO B'!Q14 -> 0 | E47: =+'GRUPO B'!R14 -> 0 | F47: =+'GRUPO B'!S14 -> 0 | G47: =+'GRUPO B'!T14 -> 0 | H47: =+'GRUPO B'!U14 -> 0 | I47: =+'GRUPO B'!V14 -> 0 | J47: =+'GRUPO B'!W14 -> 0 | K47: =+'GRUPO B'!X14 -> 0 | L47: =+'GRUPO B'!Y14 -> 0
B49: =+'GRUPO B'!P16 -> 4) CANUTO F.C. | D49: =+'GRUPO B'!Q16 -> 0 | E49: =+'GRUPO B'!R16 -> 0 | F49: =+'GRUPO B'!S16 -> 0 | G49: =+'GRUPO B'!T16 -> 0 | H49: =+'GRUPO B'!U16 -> 0 | I49: =+'GRUPO B'!V16 -> 0 | J49: =+'GRUPO B'!W16 -> 0 | K49: =+'GRUPO B'!X16 -> 0 | L49: =+'GRUPO B'!Y16 -> 0
A52: PARTIDOS fecha 3 ULTIMA
A54: =+#REF! -> #REF! | B54: =+#REF! -> #REF! | C54: =+#REF! -> #REF! | E54: - | G54: =+#REF! -> #REF! | K54: =+#REF! -> #REF!
A56: =+#REF! -> #REF! | B56: =+#REF! -> #REF! | C56: =+#REF! -> #REF! | E56: - | G56: =+#REF! -> #REF! | K56: =+#REF! -> #REF!
B59: =+'GRUPOS INFANTIL'!#REF! -> #REF! | D59: =+#REF! -> #REF! | E59: =+#REF! -> #REF! | F59: =+#REF! -> #REF! | G59: =+#REF! -> #REF! | H59: =+#REF! -> #REF! | I59: =+#REF! -> #REF! | J59: =+#REF! -> #REF! | K59: =+#REF! -> #REF! | L59: =+#REF! -> #REF!
B61: =+#REF! -> #REF! | D61: =+#REF! -> #REF! | E61: =+#REF! -> #REF! | F61: =+#REF! -> #REF! | G61: =+#REF! -> #REF! | H61: =+#REF! -> #REF! | I61: =+#REF! -> #REF! | J61: =+#REF! -> #REF! | K61: =+#REF! -> #REF! | L61: =+#REF! -> #REF!
B63: =+#REF! -> #REF! | D63: =+#REF! -> #REF! | E63: =+#REF! -> #REF! | F63: =+#REF! -> #REF! | G63: =+#REF! -> #REF! | H63: =+#REF! -> #REF! | I63: =+#REF! -> #REF! | J63: =+#REF! -> #REF! | K63: =+#REF! -> #REF! | L63: =+#REF! -> #REF!
B65: =+#REF! -> #REF! | D65: =+#REF! -> #REF! | E65: =+#REF! -> #REF! | F65: =+#REF! -> #REF! | G65: =+#REF! -> #REF! | H65: =+#REF! -> #REF! | I65: =+#REF! -> #REF! | J65: =+#REF! -> #REF! | K65: =+#REF! -> #REF! | L65: =+#REF! -> #REF!
B67: =+#REF! -> #REF! | D67: =+#REF! -> #REF! | E67: =+#REF! -> #REF! | F67: =+#REF! -> #REF! | G67: =+#REF! -> #REF! | H67: =+#REF! -> #REF! | I67: =+#REF! -> #REF! | J67: =+#REF! -> #REF! | K67: =+#REF! -> #REF! | L67: =+#REF! -> #REF!
A70: PARTIDOS fecha 3 ULTIMA
A72: =+#REF! -> #REF! | B72: =+#REF! -> #REF! | C72: =+#REF! -> #REF! | E72: - | G72: =+#REF! -> #REF! | K72: =+#REF! -> #REF!
A74: =+#REF! -> #REF! | B74: =+#REF! -> #REF! | C74: =+#REF! -> #REF! | E74: - | G74: =+#REF! -> #REF! | K74: =+#REF! -> #REF!
A75: La organización no se hace responsable de las posibles lesiones ocasionadas dentro y fuera del campo de juego, accidentes o perdidas de elementos durante el transcurso del torneo.
A78: Sede Administrativa Cra 13 No 6-43 Barrio La Florida
A79: Celular 310 241 33 76 Fijo 2 450 593
A80: soccermelgar@outlook.com
...

Sheet CUARTOS DE FINAL
H1: Campeonato Nacional de Futbol
B2: CUARTOS DE FINAL | H2: “COPA FUTURO TALENTO”
B3: Observación: Si el partido se define por penales, éstos deben sumarse al resultado.
B4: PARTIDOS | P4: Ganador
B6: =+'CUARTOS DE FINAL.'!B6:B7 -> 42596 | C6: =+'CUARTOS DE FINAL.'!C6:C7 -> LLAVE A | D6: =+'CUARTOS DE FINAL.'!D6:D7 -> 03:00. p.m. | F6: =IF(AND(H6<>"",J6<>""),IF(H6=J6,"E",IF(H6>J6,"G","P")),"") -> E | G6: =+'CUARTOS DE FINAL.'!G6:G7 -> ASTON HUILA | H6: . | I6: - | J6: . | K6: =IF(AND(J6<>"",H6<>""),IF(J6=H6,"E",IF(J6>H6,"G","P")),"") -> E | L6: =+'CUARTOS DE FINAL.'!L6:L7 -> #REF! | N6: =+'CUARTOS DE FINAL.'!N6:N7 -> PALMARA | P6: =IF(OR(F6="E",F6=""),"",IF(F6="G",G6,L6))
B9: =+'CUARTOS DE FINAL.'!B9:B10 -> 42596 | C9: =+'CUARTOS DE FINAL.'!C9:C10 -> LLAVE B | D9: =+'CUARTOS DE FINAL.'!D9:D10 -> 04:20. p.m. | F9: =IF(AND(H9<>"",J9<>""),IF(H9=J9,"E",IF(H9>J9,"G","P")),"") -> E | G9: =+'CUARTOS DE FINAL.'!G9:G10 | H9: . | I9: - | J9: . | K9: =IF(AND(J9<>"",H9<>""),IF(J9=H9,"E",IF(J9>H9,"G","P")),"") -> E | L9: =+'CUARTOS DE FINAL.'!L9:L10 -> #REF! | N9: =+'CUARTOS DE FINAL.'!N9:N10 -> CANCHA 2 | P9: =IF(OR(F9="E",F9=""),"",IF(F9="G",G9,L9))
B12: =+'CUARTOS DE FINAL.'!B12:B13 -> 42596 | C12: =+'CUARTOS DE FINAL.'!C12:C13 -> LLAVE C | D12: =+'CUARTOS DE FINAL.'!D12:D13 -> 03:00. p.m. | F12: =IF(AND(H12<>"",J12<>""),IF(H12=J12,"E",IF(H12>J12,"G","P")),"") -> E | G12: =+'CUARTOS DE FINAL.'!G12:G13 -> #REF! | H12: . | I12: - | J12: . | K12: =IF(AND(J12<>"",H12<>""),IF(J12=H12,"E",IF(J12>H12,"G","P")),"") -> E | L12: =+'CUARTOS DE FINAL.'!L12:L13 -> CLUB DEPORTIVO NUEVAS GENERACIONES | N12: =+'CUARTOS DE FINAL.'!N12:N13 -> CANCHA 2 | P12: =IF(OR(F12="E",F12=""),"",IF(F12="G",G12,L12))
B15: =+'CUARTOS DE FINAL.'!B15:B16 -> 42596 | C15: =+'CUARTOS DE FINAL.'!C15:C16 -> LLAVE D | D15: =+'CUARTOS DE FINAL.'!D15:D16 -> 04:20. p.m. | F15: =IF(AND(H15<>"",J15<>""),IF(H15=J15,"E",IF(H15>J15,"G","P")),"") -> E | G15: =+'CUARTOS DE FINAL.'!G15:G16 -> #REF! | H15: . | I15: - | J15: . | K15: =IF(AND(J15<>"",H15<>""),IF(J15=H15,"E",IF(J15>H15,"G","P")),"") -> E | L15: =+'CUARTOS DE FINAL.'!L15:L16 | N15: =+'CUARTOS DE FINAL.'!N15:N16 -> PALMARA | P15: =IF(OR(F15="E",F15=""),"",IF(F15="G",G15,L15))
B18: BABY FUTBOL
B21: Nacidos Año 2005-2006

Sheet IMPRIMIR 4
A1: Campeonato Nacional de Futbol
A2: “COPA FUTURO TALENTO”
A3: DEFINICIÓN DEL TORNEO
B4: Observación: Si el partido se define por penales, éstos deben sumarse al resultado.
B5: SEMIFINALES | Q5: Ganador
B7: =+DEFINICION!B9 -> 42814 | C7: =+DEFINICION!C9 -> LLAVE 1 | D7: =+DEFINICION!D9 -> 07:00. a.m. | E7: =+DEFINICION!F9 -> ASTON HUILA | G7: =IF(AND(I7<>"",K7<>""),IF(I7=K7,"E",IF(I7>K7,"G","P")),"") -> G | I7: =+DEFINICION!J9 -> 2 | J7: - | K7: =+DEFINICION!L9 -> 0 | L7: =IF(AND(K7<>"",I7<>""),IF(K7=I7,"E",IF(K7>I7,"G","P")),"") -> P | M7: =+DEFINICION!O9 | O7: =+DEFINICION!Q9 -> CANCHA 2 | Q7: =IF(OR(G7="E",G7=""),"",IF(G7="G",E7,M7)) -> ASTON HUILA | S7: =IF(OR(G7="E",G7=""),"",IF(G7="P",E7,M7))
B10: =+DEFINICION!B12 -> 42814 | C10: =+DEFINICION!C12 -> LLAVE 2 | D10: =+DEFINICION!D12 -> 08:00. a.m. | E10: =+DEFINICION!F12 | G10: =IF(AND(I10<>"",K10<>""),IF(I10=K10,"E",IF(I10>K10,"G","P")),"") -> G | I10: =+DEFINICION!J12 -> 1 | J10: - | K10: =+DEFINICION!L12 -> 0 | L10: =IF(AND(K10<>"",I10<>""),IF(K10=I10,"E",IF(K10>I10,"G","P")),"") -> P | M10: =+DEFINICION!O12 -> CLUB DEPORTIVO NUEVAS GENERACIONES | O10: =+DEFINICION!Q12 -> CANCHA 2 | Q10: =IF(OR(G10="E",G10=""),"",IF(G10="G",E10,M10)) | S10: =IF(OR(G10="E",G10=""),"",IF(G10="P",E10,M10)) -> CLUB DEPORTIVO NUEVAS GENERACIONES
C14: =+'GRUPOS INFANTIL'!C3 -> 0 | J14: =+'GRUPOS INFANTIL'!C4 -> NACIDOS 2017 2018

Sheet IMPRIMIR 5
A1: Campeonato Nacional de Futbol
A2: “COPA FUTURO TALENTO”
A3: FINAL DEL TORNEO
B4: Observación: Si el partido se define por penales, éstos deben sumarse al resultado.
B5: Partido por el TERCER PUESTO | Q5: TERCER PUESTO
Q6: =IF(OR(G7="E",G7=""),"",IF(G7="G",H7,M7))
B7: =+FINAL!B9 -> 42814 | D7: =+FINAL!D9 -> 12:30. p.m. | G7: =IF(AND(I7<>"",K7<>""),IF(I7=K7,"E",IF(I7>K7,"G","P")),"") -> E | H7: =+DEFINICION!U9 | I7: =+FINAL!I9 -> . | J7: - | K7: =+FINAL!K9 -> . | L7: =IF(AND(K7<>"",I7<>""),IF(K7=I7,"E",IF(K7>I7,"G","P")),"") -> E | M7: =+DEFINICION!U12 -> CLUB DEPORTIVO NUEVAS GENERACIONES | O7: =+FINAL!O9 -> CANCHA 2
B11: FINAL DEL CAMPEONATO | Q11: SEGUNDO PUESTO
Q12: =IF(OR(G13="E",G13=""),"",IF(G13="P",H13,M13))
B13: =+FINAL!B15 -> 42814 | D13: =+FINAL!D15 -> 01:40. p.m. | G13: =IF(AND(I13<>"",K13<>""),IF(I13=K13,"E",IF(I13>K13,"G","P")),"") -> E | H13: =+DEFINICION!S9 -> ASTON HUILA | I13: =+FINAL!I15 -> , | J13: - | K13: =+FINAL!K15 -> , | L13: =IF(AND(K13<>"",I13<>""),IF(K13=I13,"E",IF(K13>I13,"G","P")),"") -> E | M13: =+DEFINICION!S12 | O13: =+FINAL!O15 -> CANCHA 2
B17: CAMPEÓN “COPA FUTURO TALENTO”
B19: =IF(OR(G13="E",G13=""),"",IF(G13="G",H13,M13))
C22: =+'GRUPOS INFANTIL'!C3 -> 0 | O22: =+'GRUPOS INFANTIL'!C4 -> NACIDOS 2017 2018

Sheet Hoja1
C1: IV Campeonato Nacional de Futbol
C2: “COPA FUTURO TALENTO”
C4: FASE GRUPOS
C6: GRUPO A | E6: GRUPO B | G6: GRUPO C | I6: GRUPO D
C7: 1 | E7: 5 | G7: 9 | I7: 13
C8: 2 | E8: 6 | G8: 10 | I8: 14
C9: 3 | E9: 7 | G9: 11 | I9: 15
C10: 4 | E10: 8 | G10: 12 | I10: 16
B12: CUARTOS DE FINAL
B14: LLAVE A | C14: PRIMERO DEL GRUPO A | F14: vs | G14: SEGUNDO DEL GRUPO C
B16: LLAVE B | C16: PRIMERO DEL GRUPO B | F16: vs | G16: SEGUNDO DEL GRUPO D
B18: LLAVE C | C18: PRIMERO DEL GRUPO C | F18: vs | G18: SEGUNDO DEL GRUPO A
B20: LLAVE D | C20: PRIMERO DEL GRUPO D | F20: vs | G20: SEGUNDO DEL GRUPO B
B22: SEMIFINAL
B24: LLAVE 1 | C24: GANADOR LLAVE A | F24: vs | G24: GANADOR LLAVE B
B26: LLAVE 2 | C26: GANADOR LLAVE C | F26: vs | G26: GANADOR LLAVE D
C28: TERCER Y CUARTO LUGAR
C30: PERDEDOR LLAVE 1 | F30: vs | G30: PERDEDOR LLAVE 2
C32: FINAL
C34: GANADOR LLAVE 1 | F34: vs | G34: GANADOR LLAVE 2

Sheet SOLO IDA
A1: =+'GRUPOS INFANTIL'!C1 -> XVIII Campeonato Nacional de Fútbol Infantil
A2: =+'GRUPOS INFANTIL'!C2 -> “COPA SOCCER MELGAR”
A3: =+'GRUPOS INFANTIL'!C3 -> 0
A4: =+'GRUPOS INFANTIL'!C4 -> NACIDOS 2017 2018
A5: =+'GRUPOS INFANTIL'!F10 -> DICIEMBRE 09 AL 11 DEL 2024
A6: CALENDARIO OFICIAL
B7: PARTIDOS FECHA 1 | K7: =+'GRUPO A'!B4 -> GRUPO A | L7: =+'GRUPO A'!Q8 -> Pts. | M7: =+'GRUPO A'!R8 -> PJ | N7: =+'GRUPO A'!S8 -> Gan. | O7: =+'GRUPO A'!T8 -> Emp. | P7: =+'GRUPO A'!U8 -> Per. | Q7: =+'GRUPO A'!V8 -> GF | R7: =+'GRUPO A'!W8 -> GC | S7: =+'GRUPO A'!X8 -> Dif. | T7: =+'GRUPO A'!Y8 -> Tj
B8: CANCHA | C8: HORA | D8: EQUIPO | E8: MARCADOR | G8: EQUIPO | H8: GRUPO | I8: CATEGORIA | K8: =+'GRUPO A'!P10 -> 1) ASTON HUILA | L8: =+'GRUPO A'!Q10 -> 7 | M8: =+'GRUPO A'!R10 -> 3 | N8: =+'GRUPO A'!S10 -> 2 | O8: =+'GRUPO A'!T10 -> 1 | P8: =+'GRUPO A'!U10 -> 0 | Q8: =+'GRUPO A'!V10 -> 12 | R8: =+'GRUPO A'!W10 -> 2 | ... T8: =+'GRUPO A'!Y10 -> 0
A9: 45635 | B9: CANCHA SINTETICA CASETABLA NO GUAYOS | C9: 0.14583333 | D9: =+'GRUPO A'!E29 -> INTER F. C. | E9: =+'GRUPO A'!G29 -> 3 | F9: =+'GRUPO A'!I29 -> 3 | G9: =+'GRUPO A'!K29 -> CLUB DEPORTIVO NUEVAS GENERACIONES | H9: =+'GRUPO A'!B4 -> GRUPO A | I9: =+$A$4 -> NACIDOS 2017 2018 | K9: =+'GRUPO A'!P12 -> 2) CLUB DEPORTIVO NUEVAS GENERACIONES | L9: =+'GRUPO A'!Q12 -> 5 | M9: =+'GRUPO A'!R12 -> 3 | N9: =+'GRUPO A'!S12 -> 1 | O9: =+'GRUPO A'!T12 -> 2 | P9: =+'GRUPO A'!U12 -> 0 | Q9: =+'GRUPO A'!V12 -> 7 | R9: =+'GRUPO A'!W12 -> 6 | ... T9: =+'GRUPO A'!Y12 -> 0
A10: 45635 | B10: CANCHA SINTETICA CASETABLA NO GUAYOS | C10: 0.69444444 | D10: =+'GRUPO A'!E26 -> ASTON HUILA | E10: =+'GRUPO A'!G26 -> 3 | F10: =+'GRUPO A'!I26 -> 0 | G10: =+'GRUPO A'!K26 -> ATHLETIC MELGAR | H10: =+'GRUPO A'!B4 -> GRUPO A | I10: =+$A$4 -> NACIDOS 2017 2018 | K10: =+'GRUPO A'!P14 -> 3) INTER F. C. | L10: =+'GRUPO A'!Q14 -> 2 | M10: =+'GRUPO A'!R14 -> 3 | N10: =+'GRUPO A'!S14 -> 0 | O10: =+'GRUPO A'!T14 -> 2 | P10: =+'GRUPO A'!U14 -> 1 | Q10: =+'GRUPO A'!V14 -> 3 | R10: =+'GRUPO A'!W14 -> 4 | ... T10: =+'GRUPO A'!Y14 -> 0
K11: =+'GRUPO A'!P16 -> 4) ATHLETIC MELGAR | L11: =+'GRUPO A'!Q16 -> 1 | M11: =+'GRUPO A'!R16 -> 3 | N11: =+'GRUPO A'!S16 -> 0 | O11: =+'GRUPO A'!T16 -> 1 | P11: =+'GRUPO A'!U16 -> 2 | Q11: =+'GRUPO A'!V16 -> 1 | R11: =+'GRUPO A'!W16 -> 5 | ... T11: =+'GRUPO A'!Y16 -> 0
B12: =+'IMPRIMIR 2'!A14 -> PARTIDOS fecha 2
B13: CANCHA | C13: HORA | D13: EQUIPO | E13: MARCADOR | G13: EQUIPO | H13: GRUPO | I13: =+I8 -> CATEGORIA
A14: 45636 | B14: CANCHA SINTETICA CASETABLA NO GUAYOS | C14: 0.3125 | D14: =+'GRUPO A'!E23 -> ATHLETIC MELGAR | E14: =+'GRUPO A'!G23 -> 1 | F14: =+'GRUPO A'!I23 -> 2 | G14: =+'GRUPO A'!K23 -> CLUB DEPORTIVO NUEVAS GENERACIONES | H14: =+'GRUPO A'!B4 -> GRUPO A | I14: =+$A$4 -> NACIDOS 2017 2018 | W14: =+'GRUPO B'!P10 -> #REF! | X14: =+'GRUPO B'!Q10 -> 0 | Y14: =+'GRUPO B'!R10 -> 0 | Z14: =+'GRUPO B'!S10 -> 0 | AA14: =+'GRUPO B'!T10 -> 0 | AB14: =+'GRUPO B'!U10 -> 0 | AC14: =+'GRUPO B'!V10 -> 0 | AD14: =+'GRUPO B'!W10 -> 0 | ... AF14: =+'GRUPO B'!Y10 -> 0
A15: 45636 | B15: CANCHA SINTETICA CASETABLA NO GUAYOS | C15: 0.36111111 | D15: =+'GRUPO A'!E20 -> ASTON HUILA | E15: =+'GRUPO A'!G20 -> 7 | F15: =+'GRUPO A'!I20 -> 0 | G15: =+'GRUPO A'!K20 -> INTER F. C. | H15: =+'GRUPO A'!B4 -> GRUPO A | I15: =+$A$4 -> NACIDOS 2017 2018 | W15: =+'GRUPO B'!P12 -> 2) CLUB PROMOTOR DEPORTIVO SCORPION | X15: =+'GRUPO B'!Q12 -> 0 | Y15: =+'GRUPO B'!R12 -> 0 | Z15: =+'GRUPO B'!S12 -> 0 | AA15: =+'GRUPO B'!T12 -> 0 | AB15: =+'GRUPO B'!U12 -> 0 | AC15: =+'GRUPO B'!V12 -> 0 | AD15: =+'GRUPO B'!W12 -> 0 | ... AF15: =+'GRUPO B'!Y12 -> 0
B17: PARTIDOS FECHA 3
B18: CANCHA | C18: HORA | D18: EQUIPO | E18: MARCADOR | G18: EQUIPO | H18: GRUPO | I18: =+I13 -> CATEGORIA
A19: 45636 | B19: CANCHA SINTETICA CASETABLA NO GUAYOS | C19: 0.14583333 | D19: =+'GRUPO A'!E32 -> INTER F. C. | E19: =+'GRUPO A'!G32 -> 0 | F19: =+'GRUPO A'!I32 -> 0 | G19: =+'GRUPO A'!K32 -> ATHLETIC MELGAR | H19: =+'GRUPO A'!B4 -> GRUPO A | I19: =+$A$4 -> NACIDOS 2017 2018
A20: 45636 | B20: CANCHA SINTETICA CASETABLA NO GUAYOS | C20: 0.69444444 | D20: =+'GRUPO A'!E35 -> ASTON HUILA | E20: =+'GRUPO A'!G35 -> 2 | F20: =+'GRUPO A'!I35 -> 2 | G20: =+'GRUPO A'!K35 -> CLUB DEPORTIVO NUEVAS GENERACIONES | H20: =+'GRUPO A'!B4 -> GRUPO A | I20: =+$A$4 -> NACIDOS 2017 2018
B22: SEMIFINAL
B23: CANCHA | C23: HORA | D23: EQUIPO | E23: MARCADOR | G23: EQUIPO | H23: GRUPO | I23: CATEGORÍA
A24: 45637 | B24: CANCHA SINTETICA CASETABLA NO GUAYOS | C24: 0.3125 | D24: =+K8 -> 1) ASTON HUILA | E24: =+'[1]GRUPO A'!G53 -> 0 | F24: =+'[1]GRUPO A'!I53 -> 0 | G24: =+K11 -> 4) ATHLETIC MELGAR | H24: SEMIFINAL LLAVE 1 | I24: =+$A$4 -> NACIDOS 2017 2018
A25: 45637 | B25: CANCHA SINTETICA CASETABLA NO GUAYOS | C25: 0.36111111 | D25: =+K9 -> 2) CLUB DEPORTIVO NUEVAS GENERACIONES | E25: =+'[1]GRUPO A'!G50 -> 0 | F25: =+'[1]GRUPO A'!I50 -> 0 | G25: =+K10 -> 3) INTER F. C. | H25: SEMIFINAL LLAVE 2 | I25: =+$A$4 -> NACIDOS 2017 2018
B27: FINAL
B28: CANCHA | C28: HORA | D28: EQUIPO | E28: MARCADOR | G28: EQUIPO | H28: GRUPO | I28: CATEGORÍA
A29: 45637 | B29: CANCHA SINTETICA CASETABLA NO GUAYOS | C29: 0.54166667 | D29: PERDEDOR LLAVE 1 | E29: =+'[1]GRUPO A'!G57 -> 0 | F29: =+'[1]GRUPO A'!I57 -> 0 | G29: PERDEDOR LLAVE 2 | H29: FINAL COPA PLATA | I29: =+$A$4 -> NACIDOS 2017 2018
A30: 45637 | B30: CANCHA SINTETICA CASETABLA NO GUAYOS | C30: 0.59027778 | D30: GANADOR LLAVE 1 | E30: =+'[1]GRUPO A'!G54 -> 0 | F30: =+'[1]GRUPO A'!I54 -> 0 | G30: GANADOR LLAVE 2 | H30: FINAL COPA ORO | I30: =+$A$4 -> NACIDOS 2017 2018

Sheet IMPRIMIR HOJA 1
A1: =+'GRUPOS INFANTIL'!C1 -> XVIII Campeonato Nacional de Fútbol Infantil
A2: =+'GRUPOS INFANTIL'!C2 -> “COPA SOCCER MELGAR”
A3: =+'GRUPOS INFANTIL'!C3 -> 0
A4: =+'GRUPOS INFANTIL'!C4 -> NACIDOS 2017 2018
A5: =+'GRUPOS INFANTIL'!F10 -> DICIEMBRE 09 AL 11 DEL 2024
A6: CALENDARIO OFICIAL
B7: PARTIDOS FECHA 1 INTERGRUPOS | K7: =+'GRUPO A'!B4 -> GRUPO A | L7: =+'GRUPO A'!Q8 -> Pts. | M7: =+'GRUPO A'!R8 -> PJ | N7: =+'GRUPO A'!S8 -> Gan. | O7: =+'GRUPO A'!T8 -> Emp. | P7: =+'GRUPO A'!U8 -> Per. | Q7: =+'GRUPO A'!V8 -> GF | R7: =+'GRUPO A'!W8 -> GC | S7: =+'GRUPO A'!X8 -> Dif. | T7: =+'GRUPO A'!Y8 -> Tj
B8: CANCHA | C8: HORA | D8: EQUIPO | E8: MARCADOR | G8: EQUIPO | H8: GRUPO | I8: CATEGORIA | K8: =+'GRUPO A'!P10 -> 1) ASTON HUILA | L8: =+'GRUPO A'!Q10 -> 7 | M8: =+'GRUPO A'!R10 -> 3 | N8: =+'GRUPO A'!S10 -> 2 | O8: =+'GRUPO A'!T10 -> 1 | P8: =+'GRUPO A'!U10 -> 0 | Q8: =+'GRUPO A'!V10 -> 12 | R8: =+'GRUPO A'!W10 -> 2 | ... T8: =+'GRUPO A'!Y10 -> 0
A9: 43087 | B9: CANCHA 1 A | C9: 11:30 a.m. | D9: =+'GRUPO A'!E29 -> INTER F. C. | E9: =+'GRUPO A'!G29 -> 3 | F9: =+'GRUPO A'!I29 -> 3 | G9: =+'GRUPO A'!K29 -> CLUB DEPORTIVO NUEVAS GENERACIONES | H9: =+'GRUPO A'!B4 -> GRUPO A | I9: =+A3 -> 0 | K9: =+'GRUPO A'!P12 -> 2) CLUB DEPORTIVO NUEVAS GENERACIONES | L9: =+'GRUPO A'!Q12 -> 5 | M9: =+'GRUPO A'!R14 -> 3 | N9: =+'GRUPO A'!S12 -> 1 | O9: =+'GRUPO A'!T12 -> 2 | P9: =+'GRUPO A'!U12 -> 0 | Q9: =+'GRUPO A'!V12 -> 7 | R9: =+'GRUPO A'!W12 -> 6 | S9: =+'GRUPO A'!X12 -> 1 | T9: =+'GRUPO A'!Y12 -> 0
A10: 43087 | B10: CANCHA 1 C | C10: 11:30 a.m. | D10: =+'GRUPO A'!E26 -> ASTON HUILA | E10: =+'GRUPO A'!G26 -> 3 | F10: =+'GRUPO A'!I26 -> 0 | G10: =+'GRUPO A'!K26 -> ATHLETIC MELGAR | H10: =+'GRUPO A'!B4 -> GRUPO A | I10: =+A3 -> 0 | K10: =+'GRUPO A'!P14 -> 3) INTER F. C. | L10: =+'GRUPO A'!Q14 -> 2 | M10: =+'GRUPO A'!R14 -> 3 | N10: =+'GRUPO A'!S14 -> 0 | O10: =+'GRUPO A'!T14 -> 2 | P10: =+'GRUPO A'!U14 -> 1 | Q10: =+'GRUPO A'!V14 -> 3 | R10: =+'GRUPO A'!W14 -> 4 | ... T10: =+'GRUPO A'!Y14 -> 0
K11: =+'GRUPO A'!P16 -> 4) ATHLETIC MELGAR | L11: =+'GRUPO A'!Q16 -> 1 | M11: =+'GRUPO A'!R16 -> 3 | N11: =+'GRUPO A'!S16 -> 0 | O11: =+'GRUPO A'!T16 -> 1 | P11: =+'GRUPO A'!U16 -> 2 | Q11: =+'GRUPO A'!V16 -> 1 | R11: =+'GRUPO A'!W16 -> 5 | ... T11: =+'GRUPO A'!Y16 -> 0
B12: =+'IMPRIMIR 2'!A14 -> PARTIDOS fecha 2
B13: CANCHA | C13: HORA | D13: EQUIPO | E13: MARCADOR | G13: EQUIPO | H13: GRUPO | I13: =+I8 -> CATEGORIA | K13: SE JUGARA IDA Y VUELTA, CAMPEON EQUIPO CON MAYOR CANTIDAD DE PUNTOS
A14: 43088 | B14: CANCHA 1 A | C14: 10:50 a.m. | D14: =+'GRUPO A'!E20 -> ASTON HUILA | E14: =+'GRUPO A'!G20 -> 7 | F14: =+'GRUPO A'!I20 -> 0 | G14: =+'GRUPO A'!K20 -> INTER F. C. | H14: =+'GRUPO A'!B4 -> GRUPO A | I14: =+A3 -> 0 | W14: =+'GRUPO B'!P10 -> #REF! | X14: =+'GRUPO B'!Q10 -> 0 | Y14: =+'GRUPO B'!R10 -> 0 | Z14: =+'GRUPO B'!S10 -> 0 | AA14: =+'GRUPO B'!T10 -> 0 | AB14: =+'GRUPO B'!U10 -> 0 | AC14: =+'GRUPO B'!V10 -> 0 | AD14: =+'GRUPO B'!W10 -> 0 | ... AF14: =+'GRUPO B'!Y10 -> 0
A15: 43088 | B15: CANCHA 1 C | C15: 10:50 a.m. | D15: =+'GRUPO A'!E23 -> ATHLETIC MELGAR | E15: =+'GRUPO A'!G23 -> 1 | F15: =+'GRUPO A'!I23 -> 2 | G15: =+'GRUPO A'!K23 -> CLUB DEPORTIVO NUEVAS GENERACIONES | H15: =+'GRUPO A'!B4 -> GRUPO A | I15: =+A3 -> 0 | W15: =+'GRUPO B'!P12 -> 2) CLUB PROMOTOR DEPORTIVO SCORPION | X15: =+'GRUPO B'!Q12 -> 0 | Y15: =+'GRUPO B'!R12 -> 0 | Z15: =+'GRUPO B'!S12 -> 0 | AA15: =+'GRUPO B'!T12 -> 0 | AB15: =+'GRUPO B'!U12 -> 0 | AC15: =+'GRUPO B'!V12 -> 0 | AD15: =+'GRUPO B'!W12 -> 0 | ... AF15: =+'GRUPO B'!Y12 -> 0
