Workbook

Sheet PRE INFANTIL GRUPOS
C1: XVIII Campeonato Nacional de Fútbol Infantil
C2: “COPA SOCCER MELGAR”
C3: DICIEMBRE 4 AL 6 DEL 2024
C4: NACIDOS 2010 2011
E5: DICIEMBRE 18 AL 21 VERSIÓN UNO
C6: GRUPO A | E6: GRUPO B | G6: GRUPO C | I6: GRUPO D
C7: JAGUARES F. C. | E7: GOLDEN STEPS | G7: LE MAX TEAM | I7: IMPERIUM FÚTBOL CLUB
C8: TROYA F. C. | E8: ATHLETIC MELGAR | G8: CLUB DEPORTIVO NASSUAR | I8: E.D.F CHOCONTA
C9: JUDERCAR F. C. | E9: LIONTA F. C. | G9: SPORTING CLUB VILLAVICENCIO | I9: ACADEMIA F.C SEDE RESTREPO
D11: AGOSTO 12 AL 15 DEL 2022

Sheet GRUPO A
A1: =+'PRE INFANTIL GRUPOS'!C1 -> XVIII Campeonato Nacional de Fútbol Infantil
A2: “COPA FUTURO TALENTO”
B3: =+'PRE INFANTIL GRUPOS'!C3 -> DICIEMBRE 4 AL 6 DEL 2024 | F3: =+'PRE INFANTIL GRUPOS'!C4 -> NACIDOS 2010 2011
B4: =+'PRE INFANTIL GRUPOS'!C6 -> GRUPO A
B6: PARTIDOS | P6: POSICIONES | AJ6: =COUNT(G8,I8,G11,I11,G14,I14,G17,I17,G20,I20,G23,I23,G26,I26,G29,I29,G32,I32,G35,I35) -> 12
A7: Tj | N7: Tj
B8: 42966 | C8: 04:40. p.m. | E8: =+'PRE INFANTIL GRUPOS'!C7 -> JAGUARES F. C. | F8: =IF(AND(G8<>"",I8<>""),IF(G8=I8,"E",IF(G8>I8,"G","P")),"") -> E | G8: 0 | H8: - | I8: 0 | J8: =IF(AND(I8<>"",G8<>""),IF(I8=G8,"E",IF(I8>G8,"G","P")),"") -> E | K8: =+'PRE INFANTIL GRUPOS'!E7 -> GOLDEN STEPS | M8: CANCHA 1 C | Q8: Pts. | R8: PJ | S8: Gan. | T8: Emp. | U8: Per. | V8: GF | W8: GC | X8: Dif. | Y8: Tj | AJ8: =IF(AJ6=12,IF(INDEX(Z22:AK29,MATCH(2,Z22:Z29,0),11)=INDEX(Z22:AK29,MATCH(1,Z22:Z29,0),11),1,0),0) -> #N/A
P10: =" 1) " & VLOOKUP(1,$Z$10:$AI$17,2,0) -> 1) JUDERCAR F. C. | Q10: =VLOOKUP(1,$Z$10:$AI$17,3,0) -> 6 | R10: =+SUM(S10:U11) -> 3 | S10: =VLOOKUP(1,$Z$10:$AI$17,4,0) -> 2 | T10: =VLOOKUP(1,$Z$10:$AI$17,5,0) -> 0 | U10: =VLOOKUP(1,$Z$10:$AI$17,6,0) -> 1 | V10: =VLOOKUP(1,$Z$10:$AI$17,7,0) -> 9 | W10: =VLOOKUP(1,$Z$10:$AI$17,8,0) -> 1 | X10: =VLOOKUP(1,$Z$10:$AH$17,9,0) -> 8 | Y10: =VLOOKUP(1,$Z$10:$AI$17,10,0) -> 0 | Z10: =RANK(AJ10,$AJ$10:$AJ$17,0) -> 3 | AA10: =+'PRE INFANTIL GRUPOS'!C7 -> JAGUARES F. C. | AB10: =(AC10*3)+AD10 -> 4 | AC10: =COUNTIF(Q58:T58,"G") -> 1 | AD10: =COUNTIF(Q58:T58,"E") -> 1 | AE10: =COUNTIF(Q58:T58,"P") -> 1 | AF10: =+G8+G20+G17+G29 -> 3 | AG10: =+I8+I20+I17+I29 -> 5 | AH10: =AF10-AG10 -> -2 | AI10: =+A8+A20+A29+A17 -> 0 | AJ10: =(AB10*1000)+(AH10*100)+(AF10*10)-AI10+0.1 -> 3830.1 | AK10: =AJ10+X10 -> 3838.1
B11: 42965 | C11: 11:55. a.m. | E11: =+'PRE INFANTIL GRUPOS'!C8 -> TROYA F. C. | F11: =IF(AND(G11<>"",I11<>""),IF(G11=I11,"E",IF(G11>I11,"G","P")),"") -> G | G11: 1 | H11: - | I11: 0 | J11: =IF(AND(I11<>"",G11<>""),IF(I11=G11,"E",IF(I11>G11,"G","P")),"") -> P | K11: =+'PRE INFANTIL GRUPOS'!E8 -> ATHLETIC MELGAR | M11: CANCHA 1 A
P12: =" 2) " & VLOOKUP(2,$Z$10:$AI$17,2,0) -> 2) TROYA F. C. | Q12: =VLOOKUP(2,$Z$10:$AI$17,3,0) -> 6 | R12: =+SUM(S12:U13) -> 3 | S12: =VLOOKUP(2,$Z$10:$AI$17,4,0) -> 2 | T12: =VLOOKUP(2,$Z$10:$AI$17,5,0) -> 0 | U12: =VLOOKUP(2,$Z$10:$AI$17,6,0) -> 1 | V12: =VLOOKUP(2,$Z$10:$AI$17,7,0) -> 4 | W12: =VLOOKUP(2,$Z$10:$AI$17,8,0) -> 3 | X12: =VLOOKUP(2,$Z$10:$AH$17,9,0) -> 1 | Y12: =VLOOKUP(2,$Z$10:$AI$17,10,0) -> 0 | Z12: =RANK(AJ12,$AJ$10:$AJ$17,0) -> 2 | AA12: =+'PRE INFANTIL GRUPOS'!C8 -> TROYA F. C. | AB12: =(AC12*3)+AD12 -> 6 | AC12: =COUNTIF(Q59:T59,"G") -> 2 | AD12: =COUNTIF(Q59:T59,"E") -> 0 | AE12: =COUNTIF(Q59:T59,"P") -> 1 | AF12: =+G11+I17+G23+G32 -> 4 | AG12: =+I11+I23+G17+I32 -> 3 | AH12: =AF12-AG12 -> 1 | AI12: =+A23+A11+N17+A32 -> 0 | AJ12: =(AB12*1000)+(AH12*100)+(AF12*10)-AI12+0.2 -> 6140.2 | AK12: =AJ12+X12 -> 6141.2
B14: 42967 | C14: 02:55. p.m. | E14: =+'PRE INFANTIL GRUPOS'!C9 -> JUDERCAR F. C. | F14: =IF(AND(G14<>"",I14<>""),IF(G14=I14,"E",IF(G14>I14,"G","P")),"") -> G | G14: 6 | H14: - | I14: 0 | J14: =IF(AND(I14<>"",G14<>""),IF(I14=G14,"E",IF(I14>G14,"G","P")),"") -> P | K14: =+'PRE INFANTIL GRUPOS'!E9 -> LIONTA F. C. | M14: CANCHA 1 B | P14: =" 3) " & VLOOKUP(3,$Z$10:$AI$17,2,0) -> 3) JAGUARES F. C. | Q14: =VLOOKUP(3,$Z$10:$AI$17,3,0) -> 4 | R14: =+SUM(S14:U15) -> 3 | S14: =VLOOKUP(3,$Z$10:$AI$17,4,0) -> 1 | T14: =VLOOKUP(3,$Z$10:$AI$17,5,0) -> 1 | U14: =VLOOKUP(3,$Z$10:$AI$17,6,0) -> 1 | V14: =VLOOKUP(3,$Z$10:$AI$17,7,0) -> 3 | W14: =VLOOKUP(3,$Z$10:$AI$17,8,0) -> 5 | X14: =VLOOKUP(3,$Z$10:$AI$17,9,0) -> -2 | Y14: =VLOOKUP(3,$Z$10:$AI$17,10,0) -> 0 | Z14: =RANK(AJ14,$AJ$10:$AJ$17,0) -> 1 | AA14: =+'PRE INFANTIL GRUPOS'!C9 -> JUDERCAR F. C. | AB14: =(AC14*3)+AD14 -> 6 | AC14: =COUNTIF(Q60:T60,"G") -> 2 | AD14: =COUNTIF(Q60:T60,"E") -> 0 | AE14: =COUNTIF(Q60:T60,"P") -> 1 | AF14: =+G14+I29+G26+I32 -> 9 | AG14: =+G29+I14+I26+G32 -> 1 | AH14: =AF14-AG14 -> 8 | AI14: =+A14+A26+N29+N32 -> 0 | AJ14: =(AB14*1000)+(AH14*100)+(AF14*10)-AI14+0.3 -> 6890.3 | AK14: =+X14 -> -2
B17: 42967 | C17: 02:00. p.m. | E17: =+'PRE INFANTIL GRUPOS'!C7 -> JAGUARES F. C. | F17: =IF(AND(G17<>"",I17<>""),IF(G17=I17,"E",IF(G17>I17,"G","P")),"") -> G | G17: 3 | H17: - | I17: 2 | J17: =IF(AND(I17<>"",G17<>""),IF(I17=G17,"E",IF(I17>G17,"G","P")),"") -> P | K17: =+'PRE INFANTIL GRUPOS'!C8 -> TROYA F. C. | M17: CANCHA 1 A
F20: =IF(AND(G20<>"",I20<>""),IF(G20=I20,"E",IF(G20>I20,"G","P")),"") | H20: - | J20: =IF(AND(I20<>"",G20<>""),IF(I20=G20,"E",IF(I20>G20,"G","P")),"")
F23: =IF(AND(G23<>"",I23<>""),IF(G23=I23,"E",IF(G23>I23,"G","P")),"") | H23: - | J23: =IF(AND(I23<>"",G23<>""),IF(I23=G23,"E",IF(I23>G23,"G","P")),"")
F26: =IF(AND(G26<>"",I26<>""),IF(G26=I26,"E",IF(G26>I26,"G","P")),"") | H26: - | J26: =IF(AND(I26<>"",G26<>""),IF(I26=G26,"E",IF(I26>G26,"G","P")),"")
B29: 42965 | C29: 12:50. p.m. | E29: =+'PRE INFANTIL GRUPOS'!C7 -> JAGUARES F. C. | F29: =IF(AND(G29<>"",I29<>""),IF(G29=I29,"E",IF(G29>I29,"G","P")),"") -> P | G29: 0 | H29: - | I29: 3 | J29: =IF(AND(I29<>"",G29<>""),IF(I29=G29,"E",IF(I29>G29,"G","P")),"") -> G | K29: =+'PRE INFANTIL GRUPOS'!C9 -> JUDERCAR F. C. | M29: CANCHA 1 C
B32: 42967 | C32: 09:50. a.m. | E32: =+'PRE INFANTIL GRUPOS'!C8 -> TROYA F. C. | F32: =IF(AND(G32<>"",I32<>""),IF(G32=I32,"E",IF(G32>I32,"G","P")),"") -> G | G32: 1 | H32: - | I32: 0 | J32: =IF(AND(I32<>"",G32<>""),IF(I32=G32,"E",IF(I32>G32,"G","P")),"") -> P | K32: =+'PRE INFANTIL GRUPOS'!C9 -> JUDERCAR F. C. | M32: CANCHA 1 A
W34: =IF(AJ8=1,IF(P33="","",P33),IF(SUM(Q10:Q17)>0,VLOOKUP(1,Z10:AA17,2,0),"")) -> #N/A
W35: =IF(AJ8=1,IF(P36="","",P36),IF(SUM(Q22:Q29)>0,VLOOKUP(2,Z22:AA29,2,0),"")) -> #N/A
J43: =IF(AG20=1,"Indique el primero y segundo equipos clasificados de la serie:","") | L43: =IF(AG20=1,"Primero:","")
J46: =IF(AG20=1,"(Debido a la paridad de los resultados, no pueden deducirse de forma automática.)","") | L46: =IF(AG20=1,"Segundo:","")
P58: =+'PRE INFANTIL GRUPOS'!C7 -> JAGUARES F. C. | Q58: =+F8 -> E | R58: =+F17 -> G | S58: =+F20 | T58: =+F29 -> P
P59: =+'PRE INFANTIL GRUPOS'!C8 -> TROYA F. C. | Q59: =+F11 -> G | R59: =+J17 -> P | S59: =+F23 | T59: =+F32 -> G
P60: =+'PRE INFANTIL GRUPOS'!C9 -> JUDERCAR F. C. | Q60: =+F14 -> G | R60: =+F26 | S60: =+J29 -> G | T60: =+J32 -> P

Sheet GRUPO B
A1: =+'PRE INFANTIL GRUPOS'!C1 -> XVIII Campeonato Nacional de Fútbol Infantil
A2: “COPA FUTURO TALENTO”
B3: =+'PRE INFANTIL GRUPOS'!C3 -> DICIEMBRE 4 AL 6 DEL 2024 | F3: =+'PRE INFANTIL GRUPOS'!C4 -> NACIDOS 2010 2011
B4: =+'PRE INFANTIL GRUPOS'!E6 -> GRUPO B
B6: PARTIDOS | P6: POSICIONES | AJ6: =COUNT(G8,I8,G11,I11,G14,I14,G17,I17,G20,I20,G23,I23,G26,I26,G29,I29,G32,I32,G35,I35) -> 12
A7: Tj | N7: Tj
B8: =+'GRUPO A'!B8 -> 42966 | C8: =+'GRUPO A'!C8 -> 04:40. p.m. | E8: =+'GRUPO A'!E8:E9 -> JAGUARES F. C. | F8: =IF(AND(G8<>"",I8<>""),IF(G8=I8,"E",IF(G8>I8,"G","P")),"") -> E | G8: 0 | H8: - | I8: 0 | J8: =IF(AND(I8<>"",G8<>""),IF(I8=G8,"E",IF(I8>G8,"G","P")),"") -> E | K8: =+'GRUPO A'!K8:K9 -> GOLDEN STEPS | M8: =+'GRUPO A'!M8 -> CANCHA 1 C | Q8: Pts. | R8: PJ | S8: Gan. | T8: Emp. | U8: Per. | V8: GF | W8: GC | X8: Dif. | Y8: Tj | AJ8: =IF(AJ6=12,IF(INDEX(Z10:AK17,MATCH(2,Z10:Z17,0),11)=INDEX(Z10:AK17,MATCH(1,Z10:Z17,0),11),1,0),0) -> 0
P10: =" 1) " & VLOOKUP(1,$Z$10:$AI$17,2,0) -> 1) ATHLETIC MELGAR | Q10: =VLOOKUP(1,$Z$10:$AI$17,3,0) -> 6 | R10: =+SUM(S10:U11) -> 3 | S10: =VLOOKUP(1,$Z$10:$AI$17,4,0) -> 2 | T10: =VLOOKUP(1,$Z$10:$AI$17,5,0) -> 0 | U10: =VLOOKUP(1,$Z$10:$AI$17,6,0) -> 1 | V10: =VLOOKUP(1,$Z$10:$AI$17,7,0) -> 9 | W10: =VLOOKUP(1,$Z$10:$AI$17,8,0) -> 2 | X10: =VLOOKUP(1,$Z$10:$AH$17,9,0) -> 7 | Y10: =VLOOKUP(1,$Z$10:$AI$17,10,0) -> 0 | Z10: =RANK(AJ10,$AJ$10:$AJ$17,0) -> 2 | AA10: =+'PRE INFANTIL GRUPOS'!E7 -> GOLDEN STEPS | AB10: =(AC10*3)+AD10 -> 4 | AC10: =COUNTIF(Q58:T58,"G") -> 1 | AD10: =COUNTIF(Q58:T58,"E") -> 1 | AE10: =COUNTIF(Q58:T58,"P") -> 1 | AF10: =+I8+G20+G29+G17 -> 4 | AG10: =+I17+I20+I29+G8 -> 5 | AH10: =AF10-AG10 -> -1 | AI10: =+A17+A20+A29+N8 -> 0 | AJ10: =(AB10*1000)+(AH10*100)+(AF10*10)-AI10+0.1 -> 3940.1 | AK10: =AJ10+X10 -> 3947.1
B11: =+'GRUPO A'!B11 -> 42965 | C11: =+'GRUPO A'!C11 -> 11:55. a.m. | E11: =+'GRUPO A'!E11:E12 -> TROYA F. C. | F11: =IF(AND(G11<>"",I11<>""),IF(G11=I11,"E",IF(G11>I11,"G","P")),"") -> G | G11: 1 | H11: - | I11: 0 | J11: =IF(AND(I11<>"",G11<>""),IF(I11=G11,"E",IF(I11>G11,"G","P")),"") -> P | K11: =+'GRUPO A'!K11:K12 -> ATHLETIC MELGAR | M11: =+'GRUPO A'!M11 -> CANCHA 1 A
P12: =" 2) " & VLOOKUP(2,$Z$10:$AI$17,2,0) -> 2) GOLDEN STEPS | Q12: =VLOOKUP(2,$Z$10:$AI$17,3,0) -> 4 | R12: =+SUM(S12:U13) -> 3 | S12: =VLOOKUP(2,$Z$10:$AI$17,4,0) -> 1 | T12: =VLOOKUP(2,$Z$10:$AI$17,5,0) -> 1 | U12: =VLOOKUP(2,$Z$10:$AI$17,6,0) -> 1 | V12: =VLOOKUP(2,$Z$10:$AI$17,7,0) -> 4 | W12: =VLOOKUP(2,$Z$10:$AI$17,8,0) -> 5 | X12: =VLOOKUP(2,$Z$10:$AH$17,9,0) -> -1 | Y12: =VLOOKUP(2,$Z$10:$AI$17,10,0) -> 0 | Z12: =RANK(AJ12,$AJ$10:$AJ$17,0) -> 1 | AA12: =+'PRE INFANTIL GRUPOS'!E8 -> ATHLETIC MELGAR | AB12: =(AC12*3)+AD12 -> 6 | AC12: =COUNTIF(Q59:T59,"G") -> 2 | AD12: =COUNTIF(Q59:T59,"E") -> 0 | AE12: =COUNTIF(Q59:T59,"P") -> 1 | AF12: =+G23+I17+G32+I11 -> 9 | AG12: =+G17+I23+I32+G11 -> 2 | AH12: =AF12-AG12 -> 7 | AI12: =+N17+A23+A32+N11 -> 0 | AJ12: =(AB12*1000)+(AH12*100)+(AF12*10)-AI12+0.2 -> 6790.2 | AK12: =AJ12+X12 -> 6789.2
B14: =+'GRUPO A'!B14 -> 42967 | C14: =+'GRUPO A'!C14 -> 02:55. p.m. | E14: =+'GRUPO A'!E14:E15 -> JUDERCAR F. C. | F14: =IF(AND(G14<>"",I14<>""),IF(G14=I14,"E",IF(G14>I14,"G","P")),"") -> G | G14: 6 | H14: - | I14: 0 | J14: =IF(AND(I14<>"",G14<>""),IF(I14=G14,"E",IF(I14>G14,"G","P")),"") -> P | K14: =+'GRUPO A'!K14:K15 -> LIONTA F. C. | M14: =+'GRUPO A'!M14 -> CANCHA 1 B | P14: =" 3) " & VLOOKUP(3,$Z$10:$AI$17,2,0) -> 3) LIONTA F. C. | Q14: =VLOOKUP(3,$Z$10:$AI$17,3,0) -> 0 | R14: =+SUM(S14:U15) -> 3 | S14: =VLOOKUP(3,$Z$10:$AI$17,4,0) -> 0 | T14: =VLOOKUP(3,$Z$10:$AI$17,5,0) -> 0 | U14: =VLOOKUP(3,$Z$10:$AI$17,6,0) -> 3 | V14: =VLOOKUP(3,$Z$10:$AI$17,7,0) -> 0 | W14: =VLOOKUP(3,$Z$10:$AI$17,8,0) -> 13 | X14: =VLOOKUP(3,$Z$10:$AI$17,9,0) -> -13 | Y14: =VLOOKUP(3,$Z$10:$AI$17,10,0) -> 0 | Z14: =RANK(AJ14,$AJ$10:$AJ$17,0) -> 3 | AA14: =+'PRE INFANTIL GRUPOS'!E9 -> LIONTA F. C. | AB14: =(AC14*3)+AD14 -> 0 | AC14: =COUNTIF(Q60:T60,"G") -> 0 | AD14: =COUNTIF(Q60:T60,"E") -> 0 | AE14: =COUNTIF(Q60:T60,"P") -> 3 | AF14: =+G26+I29+I32+I14 -> 0 | AG14: =+G29+I26+G32+G14 -> 13 | AH14: =AF14-AG14 -> -13 | AI14: =+A26+N29+N32+N14 -> 0 | AJ14: =(AB14*1000)+(AH14*100)+(AF14*10)-AI14+0.3 -> -1299.7 | AK14: =+X14 -> -13
B17: 42967 | C17: 03:50. p.m. | E17: =+'PRE INFANTIL GRUPOS'!E7 -> GOLDEN STEPS | F17: =IF(AND(G17<>"",I17<>""),IF(G17=I17,"E",IF(G17>I17,"G","P")),"") -> P | G17: 1 | H17: - | I17: 5 | J17: =IF(AND(I17<>"",G17<>""),IF(I17=G17,"E",IF(I17>G17,"G","P")),"") -> G | K17: =+'PRE INFANTIL GRUPOS'!E8 -> ATHLETIC MELGAR | M17: CANCHA 1 A
F20: =IF(AND(G20<>"",I20<>""),IF(G20=I20,"E",IF(G20>I20,"G","P")),"") | H20: - | J20: =IF(AND(I20<>"",G20<>""),IF(I20=G20,"E",IF(I20>G20,"G","P")),"")
F23: =IF(AND(G23<>"",I23<>""),IF(G23=I23,"E",IF(G23>I23,"G","P")),"") | H23: - | J23: =IF(AND(I23<>"",G23<>""),IF(I23=G23,"E",IF(I23>G23,"G","P")),"")
F26: =IF(AND(G26<>"",I26<>""),IF(G26=I26,"E",IF(G26>I26,"G","P")),"") | H26: - | J26: =IF(AND(I26<>"",G26<>""),IF(I26=G26,"E",IF(I26>G26,"G","P")),"")
B29: 42967 | C29: 10:50. a.m. | E29: =+'PRE INFANTIL GRUPOS'!E7 -> GOLDEN STEPS | F29: =IF(AND(G29<>"",I29<>""),IF(G29=I29,"E",IF(G29>I29,"G","P")),"") -> G | G29: 3 | H29: - | I29: 0 | J29: =IF(AND(I29<>"",G29<>""),IF(I29=G29,"E",IF(I29>G29,"G","P")),"") -> P | K29: =+'PRE INFANTIL GRUPOS'!E9 -> LIONTA F. C. | M29: CANCHA 1 A
B32: 42965 | C32: 04:30. p.m. | E32: =+'PRE INFANTIL GRUPOS'!E8 -> ATHLETIC MELGAR | F32: =IF(AND(G32<>"",I32<>""),IF(G32=I32,"E",IF(G32>I32,"G","P")),"") -> G | G32: 4 | H32: - | I32: 0 | J32: =IF(AND(I32<>"",G32<>""),IF(I32=G32,"E",IF(I32>G32,"G","P")),"") -> P | K32: =+'PRE INFANTIL GRUPOS'!E9 -> LIONTA F. C. | M32: CANCHA 1 A
W34: =IF(AJ8=1,IF(P33="","",P33),IF(SUM(Q10:Q17)>0,VLOOKUP(1,Z10:AA17,2,0),"")) -> ATHLETIC MELGAR
W35: =IF(AJ8=1,IF(P36="","",P36),IF(SUM(Q10:Q17)>0,VLOOKUP(2,Z10:AA17,2,0),"")) -> GOLDEN STEPS
J43: =IF(AG8=1,"Indique el primero y segundo equipos clasificados de la serie:","") | L43: =IF(AG8=1,"Primero:","")
J46: =IF(AG8=1,"(Debido a la paridad de los resultados, no pueden deducirse de forma automática.)","") | L46: =IF(AG8=1,"Segundo:","")
P58: =+'PRE INFANTIL GRUPOS'!E7 -> GOLDEN STEPS | Q58: =+J8 -> E | R58: =+F17 -> P | S58: =+F20 | T58: =+F29 -> G
P59: =+'PRE INFANTIL GRUPOS'!E8 -> ATHLETIC MELGAR | Q59: =+J11 -> P | R59: =+J17 -> G | S59: =+F23 | T59: =+F32 -> G
P60: =+'PRE INFANTIL GRUPOS'!E9 -> LIONTA F. C. | Q60: =+J14 -> P | R60: =+F26 | S60: =+J29 -> P | T60: =+J32 -> P

Sheet GRUPO C
A1: =+'PRE INFANTIL GRUPOS'!C1 -> XVIII Campeonato Nacional de Fútbol Infantil
A2: “COPA FUTURO TALENTO”
B3: =+'PRE INFANTIL GRUPOS'!C3 -> DICIEMBRE 4 AL 6 DEL 2024 | F3: =+'PRE INFANTIL GRUPOS'!C4 -> NACIDOS 2010 2011
B4: =+'PRE INFANTIL GRUPOS'!G6 -> GRUPO C
B6: PARTIDOS | P6: POSICIONES | AJ6: =COUNT(G8,I8,G11,I11,G14,I14,G17,I17,G20,I20,G23,I23,G26,I26,G29,I29,G32,I32,G35,I35) -> 12
A7: Tj | N7: Tj
B8: 42967 | C8: 02:00. p.m. | E8: =+'PRE INFANTIL GRUPOS'!G7 -> LE MAX TEAM | F8: =IF(AND(G8<>"",I8<>""),IF(G8=I8,"E",IF(G8>I8,"G","P")),"") -> E | G8: 1 | H8: - | I8: 1 | J8: =IF(AND(I8<>"",G8<>""),IF(I8=G8,"E",IF(I8>G8,"G","P")),"") -> E | K8: =+'PRE INFANTIL GRUPOS'!I7 -> IMPERIUM FÚTBOL CLUB | M8: CANCHA 1 C | Q8: Pts. | R8: PJ | S8: Gan. | T8: Emp. | U8: Per. | V8: GF | W8: GC | X8: Dif. | Y8: Tj | AJ8: =IF(AJ6=12,IF(INDEX(Z10:AK17,MATCH(2,Z10:Z17,0),11)=INDEX(Z10:AK17,MATCH(1,Z10:Z17,0),11),1,0),0) -> 0
P10: =" 1) " & VLOOKUP(1,$Z$10:$AI$17,2,0) -> 1) CLUB DEPORTIVO NASSUAR | Q10: =VLOOKUP(1,$Z$10:$AI$17,3,0) -> 7 | R10: =+SUM(S10:U11) -> 3 | S10: =VLOOKUP(1,$Z$10:$AI$17,4,0) -> 2 | T10: =VLOOKUP(1,$Z$10:$AI$17,5,0) -> 1 | U10: =VLOOKUP(1,$Z$10:$AI$17,6,0) -> 0 | V10: =VLOOKUP(1,$Z$10:$AI$17,7,0) -> 5 | W10: =VLOOKUP(1,$Z$10:$AI$17,8,0) -> 1 | X10: =VLOOKUP(1,$Z$10:$AH$17,9,0) -> 4 | Y10: =VLOOKUP(1,$Z$10:$AI$17,10,0) -> 0 | Z10: =RANK(AJ10,$AJ$10:$AJ$17,0) -> 3 | AA10: =+'PRE INFANTIL GRUPOS'!G7 -> LE MAX TEAM | AB10: =(AC10*3)+AD10 -> 1 | AC10: =COUNTIF(Q58:T58,"G") -> 0 | AD10: =COUNTIF(Q58:T58,"E") -> 1 | AE10: =COUNTIF(Q58:T58,"P") -> 2 | AF10: =+I17+G26+G29+G8 -> 1 | AG10: =+G17+I26+I29+I8 -> 6 | AH10: =AF10-AG10 -> -5 | AI10: =+N17+A26+A29+A8 -> 0 | AJ10: =(AB10*1000)+(AH10*100)+(AF10*10)-AI10+0.1 -> 510.1 | AK10: =AJ10+X10 -> 514.1
B11: 42967 | C11: 02:00. p.m. | E11: =+'PRE INFANTIL GRUPOS'!G8 -> CLUB DEPORTIVO NASSUAR | F11: =IF(AND(G11<>"",I11<>""),IF(G11=I11,"E",IF(G11>I11,"G","P")),"") -> G | G11: 2 | H11: - | I11: 1 | J11: =IF(AND(I11<>"",G11<>""),IF(I11=G11,"E",IF(I11>G11,"G","P")),"") -> P | K11: =+'PRE INFANTIL GRUPOS'!I8 -> E.D.F CHOCONTA | M11: CANCHA 1 B
P12: =" 2) " & VLOOKUP(2,$Z$10:$AI$17,2,0) -> 2) SPORTING CLUB VILLAVICENCIO | Q12: =VLOOKUP(2,$Z$10:$AI$17,3,0) -> 7 | R12: =+SUM(S12:U13) -> 3 | S12: =VLOOKUP(2,$Z$10:$AI$17,4,0) -> 2 | T12: =VLOOKUP(2,$Z$10:$AI$17,5,0) -> 1 | U12: =VLOOKUP(2,$Z$10:$AI$17,6,0) -> 0 | V12: =VLOOKUP(2,$Z$10:$AI$17,7,0) -> 6 | W12: =VLOOKUP(2,$Z$10:$AI$17,8,0) -> 3 | X12: =VLOOKUP(2,$Z$10:$AH$17,9,0) -> 3 | Y12: =VLOOKUP(2,$Z$10:$AI$17,10,0) -> 0 | Z12: =RANK(AJ12,$AJ$10:$AJ$17,0) -> 1 | AA12: =+'PRE INFANTIL GRUPOS'!G8 -> CLUB DEPORTIVO NASSUAR | AB12: =(AC12*3)+AD12 -> 7 | AC12: =COUNTIF(Q59:T59,"G") -> 2 | AD12: =COUNTIF(Q59:T59,"E") -> 1 | AE12: =COUNTIF(Q59:T59,"P") -> 0 | AF12: =+I20+G32+I26+G11 -> 5 | AG12: =+G20+I32+G26+I11 -> 1 | AH12: =AF12-AG12 -> 4 | AI12: =+N20+N26+A32+A11 -> 0 | AJ12: =(AB12*1000)+(AH12*100)+(AF12*10)-AI12+0.2 -> 7450.2 | AK12: =AJ12+X12 -> 7453.2
B14: 42967 | C14: 02:55. p.m. | E14: =+'PRE INFANTIL GRUPOS'!G9 -> SPORTING CLUB VILLAVICENCIO | F14: =IF(AND(G14<>"",I14<>""),IF(G14=I14,"E",IF(G14>I14,"G","P")),"") -> G | G14: 4 | H14: - | I14: 3 | J14: =IF(AND(I14<>"",G14<>""),IF(I14=G14,"E",IF(I14>G14,"G","P")),"") -> P | K14: =+'PRE INFANTIL GRUPOS'!I9 -> ACADEMIA F.C SEDE RESTREPO | M14: CANCHA 1 A | P14: =" 3) " & VLOOKUP(3,$Z$10:$AI$17,2,0) -> 3) LE MAX TEAM | Q14: =VLOOKUP(3,$Z$10:$AI$17,3,0) -> 1 | R14: =+SUM(S14:U15) -> 3 | S14: =VLOOKUP(3,$Z$10:$AI$17,4,0) -> 0 | T14: =VLOOKUP(3,$Z$10:$AI$17,5,0) -> 1 | U14: =VLOOKUP(3,$Z$10:$AI$17,6,0) -> 2 | V14: =VLOOKUP(3,$Z$10:$AI$17,7,0) -> 1 | W14: =VLOOKUP(3,$Z$10:$AI$17,8,0) -> 6 | X14: =VLOOKUP(3,$Z$10:$AI$17,9,0) -> -5 | Y14: =VLOOKUP(3,$Z$10:$AI$17,10,0) -> 0 | Z14: =RANK(AJ14,$AJ$10:$AJ$17,0) -> 2 | AA14: =+'PRE INFANTIL GRUPOS'!G9 -> SPORTING CLUB VILLAVICENCIO | AB14: =(AC14*3)+AD14 -> 7 | AC14: =COUNTIF(Q60:T60,"G") -> 2 | AD14: =COUNTIF(Q60:T60,"E") -> 1 | AE14: =COUNTIF(Q60:T60,"P") -> 0 | AF14: =+I23+I29+I32+G14 -> 6 | AG14: =+G23+G29+G32+I14 -> 3 | AH14: =AF14-AG14 -> 3 | AI14: =+N23+N29+N32+A14 -> 0 | AJ14: =(AB14*1000)+(AH14*100)+(AF14*10)-AI14+0.3 -> 7360.3 | AK14: =+X14 -> -5
F17: =IF(AND(G17<>"",I17<>""),IF(G17=I17,"E",IF(G17>I17,"G","P")),"") | H17: - | J17: =IF(AND(I17<>"",G17<>""),IF(I17=G17,"E",IF(I17>G17,"G","P")),"")
F20: =IF(AND(G20<>"",I20<>""),IF(G20=I20,"E",IF(G20>I20,"G","P")),"") | H20: - | J20: =IF(AND(I20<>"",G20<>""),IF(I20=G20,"E",IF(I20>G20,"G","P")),"")
F23: =IF(AND(G23<>"",I23<>""),IF(G23=I23,"E",IF(G23>I23,"G","P")),"") | H23: - | J23: =IF(AND(I23<>"",G23<>""),IF(I23=G23,"E",IF(I23>G23,"G","P")),"")
B26: 42966 | C26: 03:50. p.m. | E26: =+'PRE INFANTIL GRUPOS'!G7 -> LE MAX TEAM | F26: =IF(AND(G26<>"",I26<>""),IF(G26=I26,"E",IF(G26>I26,"G","P")),"") -> P | G26: 0 | H26: - | I26: 3 | J26: =IF(AND(I26<>"",G26<>""),IF(I26=G26,"E",IF(I26>G26,"G","P")),"") -> G | K26: =+'PRE INFANTIL GRUPOS'!G8 -> CLUB DEPORTIVO NASSUAR | M26: CANCHA 1 C
B29: 42965 | C29: 12:50. p.m. | E29: =+'PRE INFANTIL GRUPOS'!G7 -> LE MAX TEAM | F29: =IF(AND(G29<>"",I29<>""),IF(G29=I29,"E",IF(G29>I29,"G","P")),"") -> P | G29: 0 | H29: - | I29: 2 | J29: =IF(AND(I29<>"",G29<>""),IF(I29=G29,"E",IF(I29>G29,"G","P")),"") -> G | K29: =+'PRE INFANTIL GRUPOS'!G9 -> SPORTING CLUB VILLAVICENCIO | M29: CANCHA 1 A
B32: 42967 | C32: 09:50. a.m. | E32: =+'PRE INFANTIL GRUPOS'!G8 -> CLUB DEPORTIVO NASSUAR | F32: =IF(AND(G32<>"",I32<>""),IF(G32=I32,"E",IF(G32>I32,"G","P")),"") -> E | G32: 0 | H32: - | I32: 0 | J32: =IF(AND(I32<>"",G32<>""),IF(I32=G32,"E",IF(I32>G32,"G","P")),"") -> E | K32: =+'PRE INFANTIL GRUPOS'!G9 -> SPORTING CLUB VILLAVICENCIO | M32: CANCHA 1 C
W34: =IF(AJ8=1,IF(P33="","",P33),IF(SUM(Q10:Q17)>0,VLOOKUP(1,Z10:AA17,2,0),"")) -> CLUB DEPORTIVO NASSUAR
W35: =IF(AJ8=1,IF(P36="","",P36),IF(SUM(Q10:Q17)>0,VLOOKUP(2,Z10:AA17,2,0),"")) -> SPORTING CLUB VILLAVICENCIO
J43: =IF(AG8=1,"Indique el primero y segundo equipos clasificados de la serie:","") | L43: =IF(AG8=1,"Primero:","")
J46: =IF(AG8=1,"(Debido a la paridad de los resultados, no pueden deducirse de forma automática.)","") | L46: =IF(AG8=1,"Segundo:","")
P58: =+'PRE INFANTIL GRUPOS'!G7 -> LE MAX TEAM | Q58: =+F8 -> E | R58: =+J17 | S58: =+F26 -> P | T58: =+F29 -> P
P59: =+'PRE INFANTIL GRUPOS'!G8 -> CLUB DEPORTIVO NASSUAR | Q59: =+F11 -> G | R59: =+J20 | S59: =+J26 -> G | T59: =+F32 -> E
P60: =+'PRE INFANTIL GRUPOS'!G9 -> SPORTING CLUB VILLAVICENCIO | Q60: =+F14 -> G | R60: =+J23 | S60: =+J29 -> G | T60: =+J32 -> E

Sheet GRUPO D
A1: =+'PRE INFANTIL GRUPOS'!C1 -> XVIII Campeonato Nacional de Fútbol Infantil
A2: “COPA FUTURO TALENTO”
B3: =+'PRE INFANTIL GRUPOS'!C3 -> DICIEMBRE 4 AL 6 DEL 2024 | F3: =+'PRE INFANTIL GRUPOS'!C4 -> NACIDOS 2010 2011
B4: =+'PRE INFANTIL GRUPOS'!I6 -> GRUPO D
B6: PARTIDOS | P6: POSICIONES | AJ6: =COUNT(G20,I20,G23,I23,G26,I26,G29,I29,G32,I32,G35,I35) -> 6
A7: Tj | N7: Tj
B8: =+'GRUPO C'!B8 -> 42967 | C8: =+'GRUPO C'!C8 -> 02:00. p.m. | E8: =+'GRUPO C'!E8:E9 -> LE MAX TEAM | F8: =IF(AND(G8<>"",I8<>""),IF(G8=I8,"E",IF(G8>I8,"G","P")),"") -> E | G8: 1 | H8: - | I8: 1 | J8: =IF(AND(I8<>"",G8<>""),IF(I8=G8,"E",IF(I8>G8,"G","P")),"") -> E | K8: =+'GRUPO C'!K8:K9 -> IMPERIUM FÚTBOL CLUB | M8: =+'GRUPO C'!M8 -> CANCHA 1 C | Q8: Pts. | R8: PJ | S8: Gan. | T8: Emp. | U8: Per. | V8: GF | W8: GC | X8: Dif. | Y8: Tj | AJ8: =IF(AJ6=12,IF(INDEX(Z10:AK17,MATCH(2,Z10:Z17,0),11)=INDEX(Z10:AK17,MATCH(1,Z10:Z17,0),11),1,0),0) -> 0
P10: =" 1) " & VLOOKUP(1,$Z$10:$AI$17,2,0) -> 1) IMPERIUM FÚTBOL CLUB | Q10: =VLOOKUP(1,$Z$10:$AI$17,3,0) -> 7 | R10: =+SUM(S10:U11) -> 3 | S10: =VLOOKUP(1,$Z$10:$AI$17,4,0) -> 2 | T10: =VLOOKUP(1,$Z$10:$AI$17,5,0) -> 1 | U10: =VLOOKUP(1,$Z$10:$AI$17,6,0) -> 0 | V10: =VLOOKUP(1,$Z$10:$AI$17,7,0) -> 7 | W10: =VLOOKUP(1,$Z$10:$AI$17,8,0) -> 3 | X10: =VLOOKUP(1,$Z$10:$AH$17,9,0) -> 4 | Y10: =VLOOKUP(1,$Z$10:$AI$17,10,0) -> 0 | Z10: =RANK(AJ10,$AJ$10:$AJ$17,0) -> 1 | AA10: =+'PRE INFANTIL GRUPOS'!I7 -> IMPERIUM FÚTBOL CLUB | AB10: =(AC10*3)+AD10 -> 7 | AC10: =COUNTIF(Q59:T59,"G") -> 2 | AD10: =COUNTIF(Q59:T59,"E") -> 1 | AE10: =COUNTIF(Q59:T59,"P") -> 0 | AF10: =+I17+I26+G32+I8 -> 7 | AG10: =+G17+G26+I32+G8 -> 3 | AH10: =AF10-AG10 -> 4 | AI10: =+N17+A26+A29+N8 -> 0 | AJ10: =(AB10*1000)+(AH10*100)+(AF10*10)-AI10+0.1 -> 7470.1 | AK10: =AJ10+X10 -> 7474.1
B11: =+'GRUPO C'!B11 -> 42967 | C11: =+'GRUPO C'!C11 -> 02:00. p.m. | E11: =+'GRUPO C'!E11:E12 -> CLUB DEPORTIVO NASSUAR | F11: =IF(AND(G11<>"",I11<>""),IF(G11=I11,"E",IF(G11>I11,"G","P")),"") -> G | G11: 2 | H11: - | I11: 1 | J11: =IF(AND(I11<>"",G11<>""),IF(I11=G11,"E",IF(I11>G11,"G","P")),"") -> P | K11: =+'GRUPO C'!K11:K12 -> E.D.F CHOCONTA | M11: =+'GRUPO C'!M11 -> CANCHA 1 B
P12: =" 2) " & VLOOKUP(2,$Z$10:$AI$17,2,0) -> 2) E.D.F CHOCONTA | Q12: =VLOOKUP(2,$Z$10:$AI$17,3,0) -> 1 | R12: =+SUM(S12:U13) -> 3 | S12: =VLOOKUP(2,$Z$10:$AI$17,4,0) -> 0 | T12: =VLOOKUP(2,$Z$10:$AI$17,5,0) -> 1 | U12: =VLOOKUP(2,$Z$10:$AI$17,6,0) -> 2 | V12: =VLOOKUP(2,$Z$10:$AI$17,7,0) -> 2 | W12: =VLOOKUP(2,$Z$10:$AI$17,8,0) -> 4 | X12: =VLOOKUP(2,$Z$10:$AH$17,9,0) -> -2 | Y12: =VLOOKUP(2,$Z$10:$AI$17,10,0) -> 0 | Z12: =RANK(AJ12,$AJ$10:$AJ$17,0) -> 2 | AA12: =+'PRE INFANTIL GRUPOS'!I8 -> E.D.F CHOCONTA | AB12: =(AC12*3)+AD12 -> 1 | AC12: =COUNTIF(Q58:T58,"G") -> 0 | AD12: =COUNTIF(Q58:T58,"E") -> 1 | AE12: =COUNTIF(Q58:T58,"P") -> 2 | AF12: =+I20+G26+G29+I11 -> 2 | AG12: =+G20+I26+I29+G11 -> 4 | AH12: =AF12-AG12 -> -2 | AI12: =+N20+N26+A32+N11 -> 0 | AJ12: =(AB12*1000)+(AH12*100)+(AF12*10)-AI12+0.2 -> 820.2 | AK12: =AJ12+X12 -> 818.2
B14: =+'GRUPO C'!B14 -> 42967 | C14: =+'GRUPO C'!C14 -> 02:55. p.m. | E14: =+'GRUPO C'!E14:E15 -> SPORTING CLUB VILLAVICENCIO | F14: =IF(AND(G14<>"",I14<>""),IF(G14=I14,"E",IF(G14>I14,"G","P")),"") -> G | G14: 4 | H14: - | I14: 3 | J14: =IF(AND(I14<>"",G14<>""),IF(I14=G14,"E",IF(I14>G14,"G","P")),"") -> P | K14: =+'GRUPO C'!K14:K15 -> ACADEMIA F.C SEDE RESTREPO | M14: =+'GRUPO C'!M14 -> CANCHA 1 A | P14: =" 3) " & VLOOKUP(3,$Z$10:$AI$17,2,0) -> 3) ACADEMIA F.C SEDE RESTREPO | Q14: =VLOOKUP(3,$Z$10:$AI$17,3,0) -> 1 | R14: =+SUM(S14:U15) -> 3 | S14: =VLOOKUP(3,$Z$10:$AI$17,4,0) -> 0 | T14: =VLOOKUP(3,$Z$10:$AI$17,5,0) -> 1 | U14: =VLOOKUP(3,$Z$10:$AI$17,6,0) -> 2 | V14: =VLOOKUP(3,$Z$10:$AI$17,7,0) -> 4 | W14: =VLOOKUP(3,$Z$10:$AI$17,8,0) -> 8 | X14: =VLOOKUP(3,$Z$10:$AI$17,9,0) -> -4 | Y14: =VLOOKUP(3,$Z$10:$AI$17,10,0) -> 0 | Z14: =RANK(AJ14,$AJ$10:$AJ$17,0) -> 3 | AA14: =+'PRE INFANTIL GRUPOS'!I9 -> ACADEMIA F.C SEDE RESTREPO | AB14: =(AC14*3)+AD14 -> 1 | AC14: =COUNTIF(Q60:T60,"G") -> 0 | AD14: =COUNTIF(Q60:T60,"E") -> 1 | AE14: =COUNTIF(Q60:T60,"P") -> 2 | AF14: =+I23+I29+I32+I14 -> 4 | AG14: =+G23+G29+G32+G14 -> 8 | AH14: =AF14-AG14 -> -4 | AI14: =+N23+N29+N32+N14 -> 0 | AJ14: =(AB14*1000)+(AH14*100)+(AF14*10)-AI14+0.3 -> 640.3 | AK14: =+X14 -> -4
F17: =IF(AND(G17<>"",I17<>""),IF(G17=I17,"E",IF(G17>I17,"G","P")),"") | H17: - | J17: =IF(AND(I17<>"",G17<>""),IF(I17=G17,"E",IF(I17>G17,"G","P")),"")
F20: =IF(AND(G20<>"",I20<>""),IF(G20=I20,"E",IF(G20>I20,"G","P")),"") | H20: - | J20: =IF(AND(I20<>"",G20<>""),IF(I20=G20,"E",IF(I20>G20,"G","P")),"")
F23: =IF(AND(G23<>"",I23<>""),IF(G23=I23,"E",IF(G23>I23,"G","P")),"") | H23: - | J23: =IF(AND(I23<>"",G23<>""),IF(I23=G23,"E",IF(I23>G23,"G","P")),"")
B26: 42967 | C26: 09:50. a.m. | E26: =+'PRE INFANTIL GRUPOS'!I8 -> E.D.F CHOCONTA | F26: =IF(AND(G26<>"",I26<>""),IF(G26=I26,"E",IF(G26>I26,"G","P")),"") -> P | G26: 1 | H26: - | I26: 2 | J26: =IF(AND(I26<>"",G26<>""),IF(I26=G26,"E",IF(I26>G26,"G","P")),"") -> G | K26: =+'PRE INFANTIL GRUPOS'!I7 -> IMPERIUM FÚTBOL CLUB | M26: CANCHA 1 B
B29: 42965 | C29: 11:55. a.m. | E29: =+'PRE INFANTIL GRUPOS'!I8 -> E.D.F CHOCONTA | F29: =IF(AND(G29<>"",I29<>""),IF(G29=I29,"E",IF(G29>I29,"G","P")),"") -> E | G29: 0 | H29: - | I29: 0 | J29: =IF(AND(I29<>"",G29<>""),IF(I29=G29,"E",IF(I29>G29,"G","P")),"") -> E | K29: =+'PRE INFANTIL GRUPOS'!I9 -> ACADEMIA F.C SEDE RESTREPO | M29: CANCHA 1 A
B32: 42966 | C32: 12:40. p.m. | E32: =+'PRE INFANTIL GRUPOS'!I7 -> IMPERIUM FÚTBOL CLUB | F32: =IF(AND(G32<>"",I32<>""),IF(G32=I32,"E",IF(G32>I32,"G","P")),"") -> G | G32: 4 | H32: - | I32: 1 | J32: =IF(AND(I32<>"",G32<>""),IF(I32=G32,"E",IF(I32>G32,"G","P")),"") -> P | K32: =+'PRE INFANTIL GRUPOS'!I9 -> ACADEMIA F.C SEDE RESTREPO | M32: CANCHA 1 A
W34: =IF(AJ8=1,IF(P33="","",P33),IF(SUM(Q10:Q17)>0,VLOOKUP(1,Z10:AA17,2,0),"")) -> IMPERIUM FÚTBOL CLUB
W35: =IF(AJ8=1,IF(P36="","",P36),IF(SUM(Q10:Q17)>0,VLOOKUP(2,Z10:AA17,2,0),"")) -> E.D.F CHOCONTA
J43: =IF(AG8=1,"Indique el primero y segundo equipos clasificados de la serie:","") | L43: =IF(AG8=1,"Primero:","")
J46: =IF(AG8=1,"(Debido a la paridad de los resultados, no pueden deducirse de forma automática.)","") | L46: =IF(AG8=1,"Segundo:","")
P58: =+'PRE INFANTIL GRUPOS'!I8 -> E.D.F CHOCONTA | Q58: =+J11 -> P | R58: =+F26 -> P | S58: =+F29 -> E
P59: =+'PRE INFANTIL GRUPOS'!I7 -> IMPERIUM FÚTBOL CLUB | Q59: =+J8 -> E | R59: =+J26 -> G | S59: =+F32 -> G
P60: =+'PRE INFANTIL GRUPOS'!I9 -> ACADEMIA F.C SEDE RESTREPO | Q60: =+J14 -> P | R60: =+J29 -> E | S60: =+J32 -> P

Sheet CUARTOS DE FINAL.
H1: Campeonato Nacional de Futbol
B2: CUARTOS DE FINAL | H2: “COPA FUTURO TALENTO”
B3: Observación: Si el partido se define por penales, éstos deben sumarse al resultado.
B4: PARTIDOS | P4: Ganador
B6: 42596 | C6: LLAVE A | D6: 03:00. p.m. | F6: =IF(AND(H6<>"",J6<>""),IF(H6=J6,"E",IF(H6>J6,"G","P")),"") -> P | G6: =+'GRUPO A'!$W$34 -> #N/A | H6: 1 | I6: - | J6: 2 | K6: =IF(AND(J6<>"",H6<>""),IF(J6=H6,"E",IF(J6>H6,"G","P")),"") -> G | L6: =+'GRUPO C'!$W$35 -> SPORTING CLUB VILLAVICENCIO | N6: PALMARA | P6: =IF(OR(F6="E",F6=""),"",IF(F6="G",G6,L6)) -> SPORTING CLUB VILLAVICENCIO
B9: 42596 | C9: LLAVE B | D9: 04:20. p.m. | F9: =IF(AND(H9<>"",J9<>""),IF(H9=J9,"E",IF(H9>J9,"G","P")),"") -> G | G9: =+'GRUPO B'!$W$34 -> ATHLETIC MELGAR | H9: 2 | I9: - | J9: 1 | K9: =IF(AND(J9<>"",H9<>""),IF(J9=H9,"E",IF(J9>H9,"G","P")),"") -> P | L9: =+'GRUPO D'!$W$35 -> E.D.F CHOCONTA | N9: CANCHA 2 | P9: =IF(OR(F9="E",F9=""),"",IF(F9="G",G9,L9)) -> ATHLETIC MELGAR
B12: 42596 | C12: LLAVE C | D12: 03:00. p.m. | F12: =IF(AND(H12<>"",J12<>""),IF(H12=J12,"E",IF(H12>J12,"G","P")),"") -> P | G12: =+'GRUPO C'!W34 -> CLUB DEPORTIVO NASSUAR | H12: 1 | I12: - | J12: 2 | K12: =IF(AND(J12<>"",H12<>""),IF(J12=H12,"E",IF(J12>H12,"G","P")),"") -> G | L12: =+'GRUPO A'!$W$35 -> #N/A | N12: CANCHA 2 | P12: =IF(OR(F12="E",F12=""),"",IF(F12="G",G12,L12)) -> #N/A
B15: 42596 | C15: LLAVE D | D15: 04:20. p.m. | F15: =IF(AND(H15<>"",J15<>""),IF(H15=J15,"E",IF(H15>J15,"G","P")),"") -> G | G15: =+'GRUPO D'!$W$34 -> IMPERIUM FÚTBOL CLUB | H15: 2 | I15: - | J15: 1 | K15: =IF(AND(J15<>"",H15<>""),IF(J15=H15,"E",IF(J15>H15,"G","P")),"") -> P | L15: =+'GRUPO B'!W35 -> GOLDEN STEPS | N15: PALMARA | P15: =IF(OR(F15="E",F15=""),"",IF(F15="G",G15,L15)) -> IMPERIUM FÚTBOL CLUB
B18: =+'PRE INFANTIL GRUPOS'!C3 -> DICIEMBRE 4 AL 6 DEL 2024
B21: =+'PRE INFANTIL GRUPOS'!C4 -> NACIDOS 2010 2011

Sheet IMPRIMIR
A1: Campeonato Nacional de Futbol
A2: “COPA FUTURO TALENTO”
B4: =+'PRE INFANTIL GRUPOS'!C6 -> GRUPO A | D4: =+'PRE INFANTIL GRUPOS'!E6 -> GRUPO B | G4: =+'PRE INFANTIL GRUPOS'!G6 -> GRUPO C | N4: =+'PRE INFANTIL GRUPOS'!I6 -> GRUPO D
B5: =+'PRE INFANTIL GRUPOS'!C7 -> JAGUARES F. C. | D5: =+'PRE INFANTIL GRUPOS'!E7 -> GOLDEN STEPS | G5: =+'PRE INFANTIL GRUPOS'!G7 -> LE MAX TEAM | N5: =+'PRE INFANTIL GRUPOS'!I8 -> E.D.F CHOCONTA
B6: =+'PRE INFANTIL GRUPOS'!C8 -> TROYA F. C. | D6: =+'PRE INFANTIL GRUPOS'!E8 -> ATHLETIC MELGAR | G6: =+'PRE INFANTIL GRUPOS'!G8 -> CLUB DEPORTIVO NASSUAR | N6: =+'PRE INFANTIL GRUPOS'!I7 -> IMPERIUM FÚTBOL CLUB
B7: =+'PRE INFANTIL GRUPOS'!C9 -> JUDERCAR F. C. | D7: =+'PRE INFANTIL GRUPOS'!E9 -> LIONTA F. C. | G7: =+'PRE INFANTIL GRUPOS'!G9 -> SPORTING CLUB VILLAVICENCIO | N7: =+'PRE INFANTIL GRUPOS'!I9 -> ACADEMIA F.C SEDE RESTREPO
B8: =+'PRE INFANTIL GRUPOS'!#REF! -> #REF! | D8: =+'PRE INFANTIL GRUPOS'!#REF! -> #REF! | G8: =+'PRE INFANTIL GRUPOS'!#REF! -> #REF! | N8: =+'PRE INFANTIL GRUPOS'!I10 -> 0
B10: =+'PRE INFANTIL GRUPOS'!C3 -> DICIEMBRE 4 AL 6 DEL 2024 | N10: =+'PRE INFANTIL GRUPOS'!C10 -> 0
B11: =+'PRE INFANTIL GRUPOS'!C4 -> NACIDOS 2010 2011
A12: =+'GRUPO A'!B4 -> GRUPO A
A14: PARTIDOS fecha 1
A16: =+'GRUPO A'!B20 -> 0 | B16: =+'GRUPO A'!C20 -> 0 | D16: =+'GRUPO A'!E20 -> 0 | F16: =IF(AND(G16<>"",I16<>""),IF(G16=I16,"E",IF(G16>I16,"G","P")),"") | H16: - | J16: =IF(AND(I16<>"",G16<>""),IF(I16=G16,"E",IF(I16>G16,"G","P")),"") | K16: =+'GRUPO A'!K20 -> 0 | O16: =+'GRUPO A'!M20 -> 0
A18: =+'GRUPO A'!B23 -> 0 | B18: =+'GRUPO A'!C23 -> 0 | D18: =+'GRUPO A'!E23 -> 0 | F18: =IF(AND(G18<>"",I18<>""),IF(G18=I18,"E",IF(G18>I18,"G","P")),"") | H18: - | J18: =IF(AND(I18<>"",G18<>""),IF(I18=G18,"E",IF(I18>G18,"G","P")),"") | K18: =+'GRUPO A'!K23 -> 0 | O18: =+'GRUPO A'!M23 -> 0
A20: =+'GRUPO B'!B4 -> GRUPO B
A22: PARTIDOS fecha 1
A24: =+'GRUPO B'!B20 -> 0 | B24: =+'GRUPO B'!C20 -> 0 | D24: =+'GRUPO B'!E20 -> 0 | F24: =IF(AND(G24<>"",I24<>""),IF(G24=I24,"E",IF(G24>I24,"G","P")),"") | H24: - | J24: =IF(AND(I24<>"",G24<>""),IF(I24=G24,"E",IF(I24>G24,"G","P")),"") | K24: =+'GRUPO B'!K20 -> 0 | O24: =+'GRUPO B'!M20 -> 0
A26: =+'GRUPO B'!B23 -> 0 | B26: =+'GRUPO B'!C23 -> 0 | D26: =+'GRUPO B'!E23 -> 0 | F26: =IF(AND(G26<>"",I26<>""),IF(G26=I26,"E",IF(G26>I26,"G","P")),"") | H26: - | J26: =IF(AND(I26<>"",G26<>""),IF(I26=G26,"E",IF(I26>G26,"G","P")),"") | K26: =+'GRUPO B'!K23 -> 0 | O26: =+'GRUPO B'!M23 -> 0
A27: =+'GRUPO C'!B4 -> GRUPO C
A29: PARTIDOS fecha 1
A31: =+'GRUPO C'!B20 -> 0 | B31: =+'GRUPO C'!C20 -> 0 | D31: =+'GRUPO C'!E20 -> 0 | F31: =IF(AND(G31<>"",I31<>""),IF(G31=I31,"E",IF(G31>I31,"G","P")),"") | H31: - | J31: =IF(AND(I31<>"",G31<>""),IF(I31=G31,"E",IF(I31>G31,"G","P")),"") | K31: =+'GRUPO C'!K20 -> 0 | O31: =+'GRUPO C'!M20 -> 0
A33: =+'GRUPO C'!B23 -> 0 | B33: =+'GRUPO C'!C23 -> 0 | D33: =+'GRUPO C'!E23 -> 0 | F33: =IF(AND(G33<>"",I33<>""),IF(G33=I33,"E",IF(G33>I33,"G","P")),"") | H33: - | J33: =IF(AND(I33<>"",G33<>""),IF(I33=G33,"E",IF(I33>G33,"G","P")),"") | K33: =+'GRUPO C'!K23 -> 0 | O33: =+'GRUPO C'!M23 -> 0
A34: =+'GRUPO D'!B4 -> GRUPO D
A36: PARTIDOS fecha 1
A38: =+'GRUPO D'!B20 -> 0 | B38: =+'GRUPO D'!C20 -> 0 | D38: =+'GRUPO D'!E20 -> 0 | F38: =IF(AND(G38<>"",I38<>""),IF(G38=I38,"E",IF(G38>I38,"G","P")),"") | H38: - | J38: =IF(AND(I38<>"",G38<>""),IF(I38=G38,"E",IF(I38>G38,"G","P")),"") | K38: =+'GRUPO D'!K20 -> 0 | O38: =+'GRUPO D'!M20 -> 0
A40: =+'GRUPO D'!B23 -> 0 | B40: =+'GRUPO D'!C23 -> 0 | D40: =+'GRUPO D'!E23 -> 0 | F40: =IF(AND(G40<>"",I40<>""),IF(G40=I40,"E",IF(G40>I40,"G","P")),"") | H40: - | J40: =IF(AND(I40<>"",G40<>""),IF(I40=G40,"E",IF(I40>G40,"G","P")),"") | K40: =+'GRUPO D'!K23 -> 0 | O40: =+'GRUPO D'!M23 -> 0
A41: NOTA: LA ORGANIZACIÓN DEL TORNEO NO SE HACE RESPONSABLE DE ACCIDENTES O PERDIDA DE ELEMENTOS DURANTE EL TRANSCURSO DEL TORNEO. Les recordamos traer el seguro de salud de los deportistas. Tarjeta de identidad Original, Registro Civil.
A46: Sede Administrativa Cra 13 No 6-43 Barrio La Florida
A47: Celular 310 241 33 76 Fijo 2 450 593
A48: soccermelgar@outlook.com
A49: Melgar - Tolima

Sheet IMPRIMIR 2
A1: Campeonato Nacional de Futbol
A2: “COPA FUTURO TALENTO”
B4: =+'PRE INFANTIL GRUPOS'!C6 -> GRUPO A | D4: =+'PRE INFANTIL GRUPOS'!E6 -> GRUPO B | G4: =+'PRE INFANTIL GRUPOS'!G6 -> GRUPO C | N4: =+'PRE INFANTIL GRUPOS'!I6 -> GRUPO D
B5: =+'PRE INFANTIL GRUPOS'!C7 -> JAGUARES F. C. | D5: =+'PRE INFANTIL GRUPOS'!E7 -> GOLDEN STEPS | G5: =+'PRE INFANTIL GRUPOS'!G7 -> LE MAX TEAM | N5: =+'PRE INFANTIL GRUPOS'!I8 -> E.D.F CHOCONTA
B6: =+'PRE INFANTIL GRUPOS'!C8 -> TROYA F. C. | D6: =+'PRE INFANTIL GRUPOS'!E8 -> ATHLETIC MELGAR | G6: =+'PRE INFANTIL GRUPOS'!G8 -> CLUB DEPORTIVO NASSUAR | N6: =+'PRE INFANTIL GRUPOS'!I7 -> IMPERIUM FÚTBOL CLUB
B7: =+'PRE INFANTIL GRUPOS'!C9 -> JUDERCAR F. C. | D7: =+'PRE INFANTIL GRUPOS'!E9 -> LIONTA F. C. | G7: =+'PRE INFANTIL GRUPOS'!G9 -> SPORTING CLUB VILLAVICENCIO | N7: =+'PRE INFANTIL GRUPOS'!I9 -> ACADEMIA F.C SEDE RESTREPO
B8: =+'PRE INFANTIL GRUPOS'!#REF! -> #REF! | D8: =+'PRE INFANTIL GRUPOS'!#REF! -> #REF! | G8: =+'PRE INFANTIL GRUPOS'!#REF! -> #REF! | N8: =+'PRE INFANTIL GRUPOS'!I10 -> 0
B10: =+'PRE INFANTIL GRUPOS'!C3 -> DICIEMBRE 4 AL 6 DEL 2024 | N10: =+'PRE INFANTIL GRUPOS'!C10 -> 0
B11: =+'PRE INFANTIL GRUPOS'!C4 -> NACIDOS 2010 2011
A12: =+'GRUPO A'!B4 -> GRUPO A
A14: PARTIDOS fecha 2
A16: =+'GRUPO A'!B26 -> 0 | B16: =+'GRUPO A'!C26 -> 0 | D16: =+'GRUPO A'!E26 -> 0 | F16: =IF(AND(G16<>"",I16<>""),IF(G16=I16,"E",IF(G16>I16,"G","P")),"") | H16: - | J16: =IF(AND(I16<>"",G16<>""),IF(I16=G16,"E",IF(I16>G16,"G","P")),"") | K16: =+'GRUPO A'!K26 -> 0 | O16: =+'GRUPO A'!M26 -> 0
A18: =+'GRUPO A'!B29 -> 42965 | B18: =+'GRUPO A'!C29 -> 12:50. p.m. | D18: =+'GRUPO A'!E29 -> JAGUARES F. C. | F18: =IF(AND(G18<>"",I18<>""),IF(G18=I18,"E",IF(G18>I18,"G","P")),"") | H18: - | J18: =IF(AND(I18<>"",G18<>""),IF(I18=G18,"E",IF(I18>G18,"G","P")),"") | K18: =+'GRUPO A'!K29 -> JUDERCAR F. C. | O18: =+'GRUPO A'!M29 -> CANCHA 1 C
A20: =+'GRUPO B'!B4 -> GRUPO B
A22: PARTIDOS fecha 2
A24: =+'GRUPO B'!B26 -> 0 | B24: =+'GRUPO B'!C26 -> 0 | D24: =+'GRUPO B'!E26 -> 0 | F24: =IF(AND(G24<>"",I24<>""),IF(G24=I24,"E",IF(G24>I24,"G","P")),"") | H24: - | J24: =IF(AND(I24<>"",G24<>""),IF(I24=G24,"E",IF(I24>G24,"G","P")),"") | K24: =+'GRUPO B'!K26 -> 0 | O24: =+'GRUPO B'!M26 -> 0
A26: =+'GRUPO B'!B29 -> 42967 | B26: =+'GRUPO B'!C29 -> 10:50. a.m. | D26: =+'GRUPO B'!E29 -> GOLDEN STEPS | F26: =IF(AND(G26<>"",I26<>""),IF(G26=I26,"E",IF(G26>I26,"G","P")),"") | H26: - | J26: =IF(AND(I26<>"",G26<>""),IF(I26=G26,"E",IF(I26>G26,"G","P")),"") | K26: =+'GRUPO B'!K29 -> LIONTA F. C. | O26: =+'GRUPO B'!M29 -> CANCHA 1 A
A27: =+'GRUPO C'!B4 -> GRUPO C
A29: PARTIDOS fecha 2
A31: =+'GRUPO C'!B26 -> 42966 | B31: =+'GRUPO C'!C26 -> 03:50. p.m. | D31: =+'GRUPO C'!E26 -> LE MAX TEAM | F31: =IF(AND(G31<>"",I31<>""),IF(G31=I31,"E",IF(G31>I31,"G","P")),"") | H31: - | J31: =IF(AND(I31<>"",G31<>""),IF(I31=G31,"E",IF(I31>G31,"G","P")),"") | K31: =+'GRUPO C'!K26 -> CLUB DEPORTIVO NASSUAR | O31: =+'GRUPO C'!M26 -> CANCHA 1 C
A33: =+'GRUPO C'!B29 -> 42965 | B33: =+'GRUPO C'!C29 -> 12:50. p.m. | D33: =+'GRUPO C'!E29 -> LE MAX TEAM | F33: =IF(AND(G33<>"",I33<>""),IF(G33=I33,"E",IF(G33>I33,"G","P")),"") | H33: - | J33: =IF(AND(I33<>"",G33<>""),IF(I33=G33,"E",IF(I33>G33,"G","P")),"") | K33: =+'GRUPO C'!K29 -> SPORTING CLUB VILLAVICENCIO | O33: =+'GRUPO C'!M29 -> CANCHA 1 A
A34: =+'GRUPO D'!B4 -> GRUPO D
A36: PARTIDOS fecha 2
A38: =+'GRUPO D'!B26 -> 42967 | B38: =+'GRUPO D'!C26 -> 09:50. a.m. | D38: =+'GRUPO D'!E26 -> E.D.F CHOCONTA | F38: =IF(AND(G38<>"",I38<>""),IF(G38=I38,"E",IF(G38>I38,"G","P")),"") | H38: - | J38: =IF(AND(I38<>"",G38<>""),IF(I38=G38,"E",IF(I38>G38,"G","P")),"") | K38: =+'GRUPO D'!K26 -> IMPERIUM FÚTBOL CLUB | O38: =+'GRUPO D'!M26 -> CANCHA 1 B
A40: =+'GRUPO D'!B29 -> 42965 | B40: =+'GRUPO D'!C29 -> 11:55. a.m. | D40: =+'GRUPO D'!E29 -> E.D.F CHOCONTA | F40: =IF(AND(G40<>"",I40<>""),IF(G40=I40,"E",IF(G40>I40,"G","P")),"") | H40: - | J40: =IF(AND(I40<>"",G40<>""),IF(I40=G40,"E",IF(I40>G40,"G","P")),"") | K40: =+'GRUPO D'!K29 -> ACADEMIA F.C SEDE RESTREPO | O40: =+'GRUPO D'!M29 -> CANCHA 1 A
A41: NOTA: LA ORGANIZACIÓN DEL TORNEO NO SE HACE RESPONSABLE DE ACCIDENTES O PERDIDA DE ELEMENTOS DURANTE EL TRANSCURSO DEL TORNEO. Les recordamos traer el seguro de salud de los deportistas. Tarjeta de identidad Original, Registro Civil.
A46: Sede Administrativa Cra 13 No 6-43 Barrio La Florida
A47: Celular 310 241 33 76 Fijo 2 450 593
A48: soccermelgar@outlook.com
A49: Melgar - Tolima

Sheet IMPRIMIR 3
B1: Campeonato Nacional de Futbol
B2: “COPA FUTURO TALENTO”
G3: =+'PRE INFANTIL GRUPOS'!C3 -> DICIEMBRE 4 AL 6 DEL 2024
G4: =+'PRE INFANTIL GRUPOS'!C4 -> NACIDOS 2010 2011
B6: =+'PRE INFANTIL GRUPOS'!C6 -> GRUPO A | D6: =+'GRUPO A'!Q20:Q21 -> #VALUE! | E6: =+'GRUPO A'!R20:R21 -> #VALUE! | F6: =+'GRUPO A'!S20:S21 -> #VALUE! | G6: =+'GRUPO A'!T20:T21 -> #VALUE! | H6: =+'GRUPO A'!U20:U21 -> #VALUE! | I6: =+'GRUPO A'!V20:V21 -> #VALUE! | J6: =+'GRUPO A'!W20:W21 -> #VALUE! | K6: =+'GRUPO A'!X20:X21 -> #VALUE! | L6: =+'GRUPO A'!Y20:Y21 -> #VALUE!
B8: =+'GRUPO A'!P22:P23 -> #VALUE! | D8: =+'GRUPO A'!Q22:Q23 -> #VALUE! | E8: =+'GRUPO A'!R22:R23 -> #VALUE! | F8: =+'GRUPO A'!S22:S23 -> #VALUE! | G8: =+'GRUPO A'!T22:T23 -> #VALUE! | H8: =+'GRUPO A'!U22:U23 -> #VALUE! | I8: =+'GRUPO A'!V22:V23 -> #VALUE! | J8: =+'GRUPO A'!W22:W23 -> #VALUE! | K8: =+'GRUPO A'!X22:X23 -> #VALUE! | L8: =+'GRUPO A'!Y22:Y23 -> #VALUE!
B10: =+'GRUPO A'!P24:P25 -> #VALUE! | D10: =+'GRUPO A'!Q24:Q25 -> #VALUE! | E10: =+'GRUPO A'!R24:R25 -> #VALUE! | F10: =+'GRUPO A'!S24:S25 -> #VALUE! | G10: =+'GRUPO A'!T24:T25 -> #VALUE! | H10: =+'GRUPO A'!U24:U25 -> #VALUE! | I10: =+'GRUPO A'!V24:V25 -> #VALUE! | J10: =+'GRUPO A'!W24:W25 -> #VALUE! | K10: =+'GRUPO A'!X24:X25 -> #VALUE! | L10: =+'GRUPO A'!Y24:Y25 -> #VALUE!
B12: =+'GRUPO A'!P26:P27 -> #VALUE! | D12: =+'GRUPO A'!Q26:Q27 -> #VALUE! | E12: =+'GRUPO A'!R26:R27 -> #VALUE! | F12: =+'GRUPO A'!S26:S27 -> #VALUE! | G12: =+'GRUPO A'!T26:T27 -> #VALUE! | H12: =+'GRUPO A'!U26:U27 -> #VALUE! | I12: =+'GRUPO A'!V26:V27 -> #VALUE! | J12: =+'GRUPO A'!W26:W27 -> #VALUE! | K12: =+'GRUPO A'!X26:X27 -> #VALUE! | L12: =+'GRUPO A'!Y26:Y27 -> #VALUE!
B14: =+'GRUPO A'!P28:P29 -> #VALUE! | D14: =+'GRUPO A'!Q28:Q29 -> #VALUE! | E14: =+'GRUPO A'!R28:R29 -> #VALUE! | F14: =+'GRUPO A'!S28:S29 -> #VALUE! | G14: =+'GRUPO A'!T28:T29 -> #VALUE! | H14: =+'GRUPO A'!U28:U29 -> #VALUE! | I14: =+'GRUPO A'!V28:V29 -> #VALUE! | J14: =+'GRUPO A'!W28:W29 -> #VALUE! | K14: =+'GRUPO A'!X28:X29 -> #VALUE! | L14: =+'GRUPO A'!Y28:Y29 -> #VALUE!
A17: PARTIDOS fecha 3 ULTIMA
A19: =+'GRUPO A'!B32 -> 42967 | B19: =+'GRUPO A'!C32 -> 09:50. a.m. | C19: =+'GRUPO A'!E32 -> TROYA F. C. | E19: - | G19: =+'GRUPO A'!K32 -> JUDERCAR F. C. | K19: =+'GRUPO A'!M32 -> CANCHA 1 A
A21: =+'GRUPO A'!B35 -> 0 | B21: =+'GRUPO A'!C35 -> 0 | C21: =+'GRUPO A'!E35 -> 0 | E21: - | G21: =+'GRUPO A'!K35 -> 0 | K21: =+'GRUPO A'!M35 -> 0
B23: =+'PRE INFANTIL GRUPOS'!E6 -> GRUPO B | D23: =+'GRUPO B'!Q8 -> Pts. | E23: =+'GRUPO B'!R8 -> PJ | F23: =+'GRUPO B'!S8 -> Gan. | G23: =+'GRUPO B'!T8 -> Emp. | H23: =+'GRUPO B'!U8 -> Per. | I23: =+'GRUPO B'!V8 -> GF | J23: =+'GRUPO B'!W8 -> GC | K23: =+'GRUPO B'!X8 -> Dif. | L23: =+'GRUPO B'!Y8 -> Tj
B25: =+'GRUPO B'!P10 -> 1) ATHLETIC MELGAR | D25: =+'GRUPO B'!Q10 -> 6 | E25: =+'GRUPO B'!R10 -> 3 | F25: =+'GRUPO B'!S10 -> 2 | G25: =+'GRUPO B'!T10 -> 0 | H25: =+'GRUPO B'!U10 -> 1 | I25: =+'GRUPO B'!V10 -> 9 | J25: =+'GRUPO B'!W10 -> 2 | K25: =+'GRUPO B'!X10 -> 7 | L25: =+'GRUPO B'!Y10 -> 0
B27: =+'GRUPO B'!P12 -> 2) GOLDEN STEPS | D27: =+'GRUPO B'!Q12 -> 4 | E27: =+'GRUPO B'!R12 -> 3 | F27: =+'GRUPO B'!S12 -> 1 | G27: =+'GRUPO B'!T12 -> 1 | H27: =+'GRUPO B'!U12 -> 1 | I27: =+'GRUPO B'!V12 -> 4 | J27: =+'GRUPO B'!W12 -> 5 | K27: =+'GRUPO B'!X12 -> -1 | L27: =+'GRUPO B'!Y12 -> 0
B29: =+'GRUPO B'!P14 -> 3) LIONTA F. C. | D29: =+'GRUPO B'!Q14 -> 0 | E29: =+'GRUPO B'!R14 -> 3 | F29: =+'GRUPO B'!S14 -> 0 | G29: =+'GRUPO B'!T14 -> 0 | H29: =+'GRUPO B'!U14 -> 3 | I29: =+'GRUPO B'!V14 -> 0 | J29: =+'GRUPO B'!W14 -> 13 | K29: =+'GRUPO B'!X14 -> -13 | L29: =+'GRUPO B'!Y14 -> 0
B31: =+'GRUPO B'!P16 -> 0 | D31: =+'GRUPO B'!Q16 -> 0 | E31: =+'GRUPO B'!R16 -> 0 | F31: =+'GRUPO B'!S16 -> 0 | G31: =+'GRUPO B'!T16 -> 0 | H31: =+'GRUPO B'!U16 -> 0 | I31: =+'GRUPO B'!V16 -> 0 | J31: =+'GRUPO B'!W16 -> 0 | K31: =+'GRUPO B'!X16 -> 0 | L31: =+'GRUPO B'!Y16 -> 0
A34: PARTIDOS fecha 3 ULTIMA
A36: =+'GRUPO B'!B32 -> 42965 | B36: =+'GRUPO B'!C32 -> 04:30. p.m. | C36: =+'GRUPO B'!E32 -> ATHLETIC MELGAR | E36: - | G36: =+'GRUPO B'!K32 -> LIONTA F. C. | K36: =+'GRUPO B'!M32 -> CANCHA 1 A
A38: =+'GRUPO B'!B35 -> 0 | B38: =+'GRUPO B'!C32 -> 04:30. p.m. | C38: =+'GRUPO B'!E35 -> 0 | E38: - | G38: =+'GRUPO B'!K35 -> 0 | K38: =+'GRUPO B'!M35 -> 0
B41: =+'PRE INFANTIL GRUPOS'!G6 -> GRUPO C | D41: =+'GRUPO B'!Q8 -> Pts. | E41: =+'GRUPO B'!R8 -> PJ | F41: =+'GRUPO B'!S8 -> Gan. | G41: =+'GRUPO B'!T8 -> Emp. | H41: =+'GRUPO B'!U8 -> Per. | I41: =+'GRUPO B'!V8 -> GF | J41: =+'GRUPO B'!W8 -> GC | K41: =+'GRUPO B'!X8 -> Dif. | L41: =+'GRUPO B'!Y8 -> Tj
B43: =+'GRUPO B'!P10 -> 1) ATHLETIC MELGAR | D43: =+'GRUPO B'!Q10 -> 6 | E43: =+'GRUPO B'!R10 -> 3 | F43: =+'GRUPO B'!S10 -> 2 | G43: =+'GRUPO B'!T10 -> 0 | H43: =+'GRUPO B'!U10 -> 1 | I43: =+'GRUPO B'!V10 -> 9 | J43: =+'GRUPO B'!W10 -> 2 | K43: =+'GRUPO B'!X10 -> 7 | L43: =+'GRUPO B'!Y10 -> 0
B45: =+'GRUPO B'!P12 -> 2) GOLDEN STEPS | D45: =+'GRUPO B'!Q12 -> 4 | E45: =+'GRUPO B'!R12 -> 3 | F45: =+'GRUPO B'!S12 -> 1 | G45: =+'GRUPO B'!T12 -> 1 | H45: =+'GRUPO B'!U12 -> 1 | I45: =+'GRUPO B'!V12 -> 4 | J45: =+'GRUPO B'!W12 -> 5 | K45: =+'GRUPO B'!X12 -> -1 | L45: =+'GRUPO B'!Y12 -> 0
B47: =+'GRUPO B'!P14 -> 3) LIONTA F. C. | D47: =+'GRUPO B'!Q14 -> 0 | E47: =+'GRUPO B'!R14 -> 3 | F47: =+'GRUPO B'!S14 -> 0 | G47: =+'GRUPO B'!T14 -> 0 | H47: =+'GRUPO B'!U14 -> 3 | I47: =+'GRUPO B'!V14 -> 0 | J47: =+'GRUPO B'!W14 -> 13 | K47: =+'GRUPO B'!X14 -> -13 | L47: =+'GRUPO B'!Y14 -> 0
B49: =+'GRUPO B'!P16 -> 0 | D49: =+'GRUPO B'!Q16 -> 0 | E49: =+'GRUPO B'!R16 -> 0 | F49: =+'GRUPO B'!S16 -> 0 | G49: =+'GRUPO B'!T16 -> 0 | H49: =+'GRUPO B'!U16 -> 0 | I49: =+'GRUPO B'!V16 -> 0 | J49: =+'GRUPO B'!W16 -> 0 | K49: =+'GRUPO B'!X16 -> 0 | L49: =+'GRUPO B'!Y16 -> 0
A52: PARTIDOS fecha 3 ULTIMA
A54: =+'GRUPO C'!B32 -> 42967 | B54: =+'GRUPO C'!C32 -> 09:50. a.m. | C54: =+'GRUPO C'!E32 -> CLUB DEPORTIVO NASSUAR | E54: - | G54: =+'GRUPO C'!K32 -> SPORTING CLUB VILLAVICENCIO | K54: =+'GRUPO C'!M32 -> CANCHA 1 C
A56: =+'GRUPO C'!B35 -> 0 | B56: =+'GRUPO C'!C35 -> 0 | C56: =+'GRUPO C'!E35 -> 0 | E56: - | G56: =+'GRUPO C'!K35 -> 0 | K56: =+'GRUPO C'!M35 -> 0
B59: =+'PRE INFANTIL GRUPOS'!I6 -> GRUPO D | D59: =+'GRUPO D'!Q8 -> Pts. | E59: =+'GRUPO D'!R8 -> PJ | F59: =+'GRUPO D'!S8 -> Gan. | G59: =+'GRUPO D'!T8 -> Emp. | H59: =+'GRUPO D'!U8 -> Per. | I59: =+'GRUPO D'!V8 -> GF | J59: =+'GRUPO D'!W8 -> GC | K59: =+'GRUPO D'!X8 -> Dif. | L59: =+'GRUPO D'!Y8 -> Tj
B61: =+'GRUPO D'!P10 -> 1) IMPERIUM FÚTBOL CLUB | D61: =+'GRUPO D'!Q10 -> 7 | E61: =+'GRUPO D'!R10 -> 3 | F61: =+'GRUPO D'!S10 -> 2 | G61: =+'GRUPO D'!T10 -> 1 | H61: =+'GRUPO D'!U10 -> 0 | I61: =+'GRUPO D'!V10 -> 7 | J61: =+'GRUPO D'!W10 -> 3 | K61: =+'GRUPO D'!X10 -> 4 | L61: =+'GRUPO D'!Y10 -> 0
B63: =+'GRUPO D'!P12 -> 2) E.D.F CHOCONTA | D63: =+'GRUPO D'!Q12 -> 1 | E63: =+'GRUPO D'!R12 -> 3 | F63: =+'GRUPO D'!S12 -> 0 | G63: =+'GRUPO D'!T12 -> 1 | H63: =+'GRUPO D'!U12 -> 2 | I63: =+'GRUPO D'!V12 -> 2 | J63: =+'GRUPO D'!W12 -> 4 | K63: =+'GRUPO D'!X12 -> -2 | L63: =+'GRUPO D'!Y12 -> 0
B65: =+'GRUPO D'!P14 -> 3) ACADEMIA F.C SEDE RESTREPO | D65: =+'GRUPO D'!Q14 -> 1 | E65: =+'GRUPO D'!R14 -> 3 | F65: =+'GRUPO D'!S14 -> 0 | G65: =+'GRUPO D'!T14 -> 1 | H65: =+'GRUPO D'!U14 -> 2 | I65: =+'GRUPO D'!V14 -> 4 | J65: =+'GRUPO D'!W14 -> 8 | K65: =+'GRUPO D'!X14 -> -4 | L65: =+'GRUPO D'!Y14 -> 0
B67: =+'GRUPO D'!P16 -> 0 | D67: =+'GRUPO D'!Q16 -> 0 | E67: =+'GRUPO D'!R16 -> 0 | F67: =+'GRUPO D'!S16 -> 0 | G67: =+'GRUPO D'!T16 -> 0 | H67: =+'GRUPO D'!U16 -> 0 | I67: =+'GRUPO D'!V16 -> 0 | J67: =+'GRUPO D'!W16 -> 0 | K67: =+'GRUPO D'!X16 -> 0 | L67: =+'GRUPO D'!Y16 -> 0
A70: PARTIDOS fecha 3 ULTIMA
A72: =+'GRUPO D'!B32 -> 42966 | B72: =+'GRUPO D'!C32 -> 12:40. p.m. | C72: =+'GRUPO D'!E32 -> IMPERIUM FÚTBOL CLUB | E72: - | G72: =+'GRUPO D'!K32 -> ACADEMIA F.C SEDE RESTREPO | K72: =+'GRUPO D'!M32 -> CANCHA 1 A
A74: =+'GRUPO D'!B35 -> 0 | B74: =+'GRUPO D'!C32 -> 12:40. p.m. | C74: =+'GRUPO D'!E35 -> 0 | E74: - | G74: =+'GRUPO D'!K35 -> 0 | K74: =+'GRUPO D'!M35 -> 0
A75: La organización no se hace responsable de las posibles lesiones ocasionadas dentro y fuera del campo de juego, accidentes o perdidas de elementos durante el transcurso del torneo.
A78: Sede Administrativa Cra 13 No 6-43 Barrio La Florida
A79: Celular 310 241 33 76 Fijo 2 450 593
A80: soccermelgar@outlook.com
...

Sheet IMPRIMIR 3 (2)
B1: Campeonato Nacional de Futbol
B2: “COPA FUTURO TALENTO”
G3: =+'PRE INFANTIL GRUPOS'!C3 -> DICIEMBRE 4 AL 6 DEL 2024
G4: =+'PRE INFANTIL GRUPOS'!C4 -> NACIDOS 2010 2011
B6: =+'PRE INFANTIL GRUPOS'!C6 -> GRUPO A | D6: =+'GRUPO A'!Q20:Q21 -> #VALUE! | E6: =+'GRUPO A'!R20:R21 -> #VALUE! | F6: =+'GRUPO A'!S20:S21 -> #VALUE! | G6: =+'GRUPO A'!T20:T21 -> #VALUE! | H6: =+'GRUPO A'!U20:U21 -> #VALUE! | I6: =+'GRUPO A'!V20:V21 -> #VALUE! | J6: =+'GRUPO A'!W20:W21 -> #VALUE! | K6: =+'GRUPO A'!X20:X21 -> #VALUE! | L6: =+'GRUPO A'!Y20:Y21 -> #VALUE!
B8: =+'GRUPO A'!P22:P23 -> #VALUE! | D8: =+'GRUPO A'!Q22:Q23 -> #VALUE! | E8: =+'GRUPO A'!R22:R23 -> #VALUE! | F8: =+'GRUPO A'!S22:S23 -> #VALUE! | G8: =+'GRUPO A'!T22:T23 -> #VALUE! | H8: =+'GRUPO A'!U22:U23 -> #VALUE! | I8: =+'GRUPO A'!V22:V23 -> #VALUE! | J8: =+'GRUPO A'!W22:W23 -> #VALUE! | K8: =+'GRUPO A'!X22:X23 -> #VALUE! | L8: =+'GRUPO A'!Y22:Y23 -> #VALUE!
B10: =+'GRUPO A'!P24:P25 -> #VALUE! | D10: =+'GRUPO A'!Q24:Q25 -> #VALUE! | E10: =+'GRUPO A'!R24:R25 -> #VALUE! | F10: =+'GRUPO A'!S24:S25 -> #VALUE! | G10: =+'GRUPO A'!T24:T25 -> #VALUE! | H10: =+'GRUPO A'!U24:U25 -> #VALUE! | I10: =+'GRUPO A'!V24:V25 -> #VALUE! | J10: =+'GRUPO A'!W24:W25 -> #VALUE! | K10: =+'GRUPO A'!X24:X25 -> #VALUE! | L10: =+'GRUPO A'!Y24:Y25 -> #VALUE!
B12: =+'GRUPO A'!P26:P27 -> #VALUE! | D12: =+'GRUPO A'!Q26:Q27 -> #VALUE! | E12: =+'GRUPO A'!R26:R27 -> #VALUE! | F12: =+'GRUPO A'!S26:S27 -> #VALUE! | G12: =+'GRUPO A'!T26:T27 -> #VALUE! | H12: =+'GRUPO A'!U26:U27 -> #VALUE! | I12: =+'GRUPO A'!V26:V27 -> #VALUE! | J12: =+'GRUPO A'!W26:W27 -> #VALUE! | K12: =+'GRUPO A'!X26:X27 -> #VALUE! | L12: =+'GRUPO A'!Y26:Y27 -> #VALUE!
B14: =+'GRUPO A'!P28:P29 -> #VALUE! | D14: =+'GRUPO A'!Q28:Q29 -> #VALUE! | E14: =+'GRUPO A'!R28:R29 -> #VALUE! | F14: =+'GRUPO A'!S28:S29 -> #VALUE! | G14: =+'GRUPO A'!T28:T29 -> #VALUE! | H14: =+'GRUPO A'!U28:U29 -> #VALUE! | I14: =+'GRUPO A'!V28:V29 -> #VALUE! | J14: =+'GRUPO A'!W28:W29 -> #VALUE! | K14: =+'GRUPO A'!X28:X29 -> #VALUE! | L14: =+'GRUPO A'!Y28:Y29 -> #VALUE!
A17: PARTIDOS fecha 3 ULTIMA
A19: =+'GRUPO A'!B32 -> 42967 | B19: =+'GRUPO A'!C32 -> 09:50. a.m. | C19: =+'GRUPO A'!E32 -> TROYA F. C. | E19: - | G19: =+'GRUPO A'!K32 -> JUDERCAR F. C. | K19: =+'GRUPO A'!M32 -> CANCHA 1 A
A21: =+'GRUPO A'!B35 -> 0 | B21: =+'GRUPO A'!C35 -> 0 | C21: =+'GRUPO A'!E35 -> 0 | E21: - | G21: =+'GRUPO A'!K35 -> 0 | K21: =+'GRUPO A'!M35 -> 0
B23: =+'PRE INFANTIL GRUPOS'!E6 -> GRUPO B | D23: =+'GRUPO B'!Q8 -> Pts. | E23: =+'GRUPO B'!R8 -> PJ | F23: =+'GRUPO B'!S8 -> Gan. | G23: =+'GRUPO B'!T8 -> Emp. | H23: =+'GRUPO B'!U8 -> Per. | I23: =+'GRUPO B'!V8 -> GF | J23: =+'GRUPO B'!W8 -> GC | K23: =+'GRUPO B'!X8 -> Dif. | L23: =+'GRUPO B'!Y8 -> Tj
B25: =+'GRUPO B'!P10 -> 1) ATHLETIC MELGAR | D25: =+'GRUPO B'!Q10 -> 6 | E25: =+'GRUPO B'!R10 -> 3 | F25: =+'GRUPO B'!S10 -> 2 | G25: =+'GRUPO B'!T10 -> 0 | H25: =+'GRUPO B'!U10 -> 1 | I25: =+'GRUPO B'!V10 -> 9 | J25: =+'GRUPO B'!W10 -> 2 | K25: =+'GRUPO B'!X10 -> 7 | L25: =+'GRUPO B'!Y10 -> 0
B27: =+'GRUPO B'!P12 -> 2) GOLDEN STEPS | D27: =+'GRUPO B'!Q12 -> 4 | E27: =+'GRUPO B'!R12 -> 3 | F27: =+'GRUPO B'!S12 -> 1 | G27: =+'GRUPO B'!T12 -> 1 | H27: =+'GRUPO B'!U12 -> 1 | I27: =+'GRUPO B'!V12 -> 4 | J27: =+'GRUPO B'!W12 -> 5 | K27: =+'GRUPO B'!X12 -> -1 | L27: =+'GRUPO B'!Y12 -> 0
B29: =+'GRUPO B'!P14 -> 3) LIONTA F. C. | D29: =+'GRUPO B'!Q14 -> 0 | E29: =+'GRUPO B'!R14 -> 3 | F29: =+'GRUPO B'!S14 -> 0 | G29: =+'GRUPO B'!T14 -> 0 | H29: =+'GRUPO B'!U14 -> 3 | I29: =+'GRUPO B'!V14 -> 0 | J29: =+'GRUPO B'!W14 -> 13 | K29: =+'GRUPO B'!X14 -> -13 | L29: =+'GRUPO B'!Y14 -> 0
B31: =+'GRUPO B'!P16 -> 0 | D31: =+'GRUPO B'!Q16 -> 0 | E31: =+'GRUPO B'!R16 -> 0 | F31: =+'GRUPO B'!S16 -> 0 | G31: =+'GRUPO B'!T16 -> 0 | H31: =+'GRUPO B'!U16 -> 0 | I31: =+'GRUPO B'!V16 -> 0 | J31: =+'GRUPO B'!W16 -> 0 | K31: =+'GRUPO B'!X16 -> 0 | L31: =+'GRUPO B'!Y16 -> 0
A34: PARTIDOS fecha 3 ULTIMA
A36: =+'GRUPO B'!B32 -> 42965 | B36: =+'GRUPO B'!C32 -> 04:30. p.m. | C36: =+'GRUPO B'!E32 -> ATHLETIC MELGAR | E36: - | G36: =+'GRUPO B'!K32 -> LIONTA F. C. | K36: =+'GRUPO B'!M32 -> CANCHA 1 A
A38: =+'GRUPO B'!B35 -> 0 | B38: =+'GRUPO B'!C32 -> 04:30. p.m. | C38: =+'GRUPO B'!E35 -> 0 | E38: - | G38: =+'GRUPO B'!K35 -> 0 | K38: =+'GRUPO B'!M35 -> 0
B41: =+'PRE INFANTIL GRUPOS'!G6 -> GRUPO C | D41: =+'GRUPO B'!Q8 -> Pts. | E41: =+'GRUPO B'!R8 -> PJ | F41: =+'GRUPO B'!S8 -> Gan. | G41: =+'GRUPO B'!T8 -> Emp. | H41: =+'GRUPO B'!U8 -> Per. | I41: =+'GRUPO B'!V8 -> GF | J41: =+'GRUPO B'!W8 -> GC | K41: =+'GRUPO B'!X8 -> Dif. | L41: =+'GRUPO B'!Y8 -> Tj
B43: =+'GRUPO B'!P10 -> 1) ATHLETIC MELGAR | D43: =+'GRUPO B'!Q10 -> 6 | E43: =+'GRUPO B'!R10 -> 3 | F43: =+'GRUPO B'!S10 -> 2 | G43: =+'GRUPO B'!T10 -> 0 | H43: =+'GRUPO B'!U10 -> 1 | I43: =+'GRUPO B'!V10 -> 9 | J43: =+'GRUPO B'!W10 -> 2 | K43: =+'GRUPO B'!X10 -> 7 | L43: =+'GRUPO B'!Y10 -> 0
B45: =+'GRUPO B'!P12 -> 2) GOLDEN STEPS | D45: =+'GRUPO B'!Q12 -> 4 | E45: =+'GRUPO B'!R12 -> 3 | F45: =+'GRUPO B'!S12 -> 1 | G45: =+'GRUPO B'!T12 -> 1 | H45: =+'GRUPO B'!U12 -> 1 | I45: =+'GRUPO B'!V12 -> 4 | J45: =+'GRUPO B'!W12 -> 5 | K45: =+'GRUPO B'!X12 -> -1 | L45: =+'GRUPO B'!Y12 -> 0
B47: =+'GRUPO B'!P14 -> 3) LIONTA F. C. | D47: =+'GRUPO B'!Q14 -> 0 | E47: =+'GRUPO B'!R14 -> 3 | F47: =+'GRUPO B'!S14 -> 0 | G47: =+'GRUPO B'!T14 -> 0 | H47: =+'GRUPO B'!U14 -> 3 | I47: =+'GRUPO B'!V14 -> 0 | J47: =+'GRUPO B'!W14 -> 13 | K47: =+'GRUPO B'!X14 -> -13 | L47: =+'GRUPO B'!Y14 -> 0
B49: =+'GRUPO B'!P16 -> 0 | D49: =+'GRUPO B'!Q16 -> 0 | E49: =+'GRUPO B'!R16 -> 0 | F49: =+'GRUPO B'!S16 -> 0 | G49: =+'GRUPO B'!T16 -> 0 | H49: =+'GRUPO B'!U16 -> 0 | I49: =+'GRUPO B'!V16 -> 0 | J49: =+'GRUPO B'!W16 -> 0 | K49: =+'GRUPO B'!X16 -> 0 | L49: =+'GRUPO B'!Y16 -> 0
A52: PARTIDOS fecha 3 ULTIMA
A54: =+'GRUPO C'!B32 -> 42967 | B54: =+'GRUPO C'!C32 -> 09:50. a.m. | C54: =+'GRUPO C'!E32 -> CLUB DEPORTIVO NASSUAR | E54: - | G54: =+'GRUPO C'!K32 -> SPORTING CLUB VILLAVICENCIO | K54: =+'GRUPO C'!M32 -> CANCHA 1 C
A56: =+'GRUPO C'!B35 -> 0 | B56: =+'GRUPO C'!C35 -> 0 | C56: =+'GRUPO C'!E35 -> 0 | E56: - | G56: =+'GRUPO C'!K35 -> 0 | K56: =+'GRUPO C'!M35 -> 0
B59: =+'PRE INFANTIL GRUPOS'!I6 -> GRUPO D | D59: =+'GRUPO D'!Q8 -> Pts. | E59: =+'GRUPO D'!R8 -> PJ | F59: =+'GRUPO D'!S8 -> Gan. | G59: =+'GRUPO D'!T8 -> Emp. | H59: =+'GRUPO D'!U8 -> Per. | I59: =+'GRUPO D'!V8 -> GF | J59: =+'GRUPO D'!W8 -> GC | K59: =+'GRUPO D'!X8 -> Dif. | L59: =+'GRUPO D'!Y8 -> Tj
B61: =+'GRUPO D'!P10 -> 1) IMPERIUM FÚTBOL CLUB | D61: =+'GRUPO D'!Q10 -> 7 | E61: =+'GRUPO D'!R10 -> 3 | F61: =+'GRUPO D'!S10 -> 2 | G61: =+'GRUPO D'!T10 -> 1 | H61: =+'GRUPO D'!U10 -> 0 | I61: =+'GRUPO D'!V10 -> 7 | J61: =+'GRUPO D'!W10 -> 3 | K61: =+'GRUPO D'!X10 -> 4 | L61: =+'GRUPO D'!Y10 -> 0
B63: =+'GRUPO D'!P12 -> 2) E.D.F CHOCONTA | D63: =+'GRUPO D'!Q12 -> 1 | E63: =+'GRUPO D'!R12 -> 3 | F63: =+'GRUPO D'!S12 -> 0 | G63: =+'GRUPO D'!T12 -> 1 | H63: =+'GRUPO D'!U12 -> 2 | I63: =+'GRUPO D'!V12 -> 2 | J63: =+'GRUPO D'!W12 -> 4 | K63: =+'GRUPO D'!X12 -> -2 | L63: =+'GRUPO D'!Y12 -> 0
B65: =+'GRUPO D'!P14 -> 3) ACADEMIA F.C SEDE RESTREPO | D65: =+'GRUPO D'!Q14 -> 1 | E65: =+'GRUPO D'!R14 -> 3 | F65: =+'GRUPO D'!S14 -> 0 | G65: =+'GRUPO D'!T14 -> 1 | H65: =+'GRUPO D'!U14 -> 2 | I65: =+'GRUPO D'!V14 -> 4 | J65: =+'GRUPO D'!W14 -> 8 | K65: =+'GRUPO D'!X14 -> -4 | L65: =+'GRUPO D'!Y14 -> 0
B67: =+'GRUPO D'!P16 -> 0 | D67: =+'GRUPO D'!Q16 -> 0 | E67: =+'GRUPO D'!R16 -> 0 | F67: =+'GRUPO D'!S16 -> 0 | G67: =+'GRUPO D'!T16 -> 0 | H67: =+'GRUPO D'!U16 -> 0 | I67: =+'GRUPO D'!V16 -> 0 | J67: =+'GRUPO D'!W16 -> 0 | K67: =+'GRUPO D'!X16 -> 0 | L67: =+'GRUPO D'!Y16 -> 0
A70: PARTIDOS fecha 3 ULTIMA
A72: =+'GRUPO D'!B32 -> 42966 | B72: =+'GRUPO D'!C32 -> 12:40. p.m. | C72: =+'GRUPO D'!E32 -> IMPERIUM FÚTBOL CLUB | E72: - | G72: =+'GRUPO D'!K32 -> ACADEMIA F.C SEDE RESTREPO | K72: =+'GRUPO D'!M32 -> CANCHA 1 A
A74: =+'GRUPO D'!B35 -> 0 | B74: =+'GRUPO D'!C32 -> 12:40. p.m. | C74: =+'GRUPO D'!E35 -> 0 | E74: - | G74: =+'GRUPO D'!K35 -> 0 | K74: =+'GRUPO D'!M35 -> 0
A75: La organización no se hace responsable de las posibles lesiones ocasionadas dentro y fuera del campo de juego, accidentes o perdidas de elementos durante el transcurso del torneo.
A78: Sede Administrativa Cra 13 No 6-43 Barrio La Florida
A79: Celular 310 241 33 76 Fijo 2 450 593
A80: soccermelgar@outlook.com
...

Sheet CUARTOS DE FINAL
H1: Campeonato Nacional de Futbol
B2: CUARTOS DE FINAL | H2: “COPA FUTURO TALENTO”
B3: Observación: Si el partido se define por penales, éstos deben sumarse al resultado.
B4: PARTIDOS | P4: Ganador
B6: =+'CUARTOS DE FINAL.'!B6:B7 -> 42596 | C6: =+'CUARTOS DE FINAL.'!C6:C7 -> LLAVE A | D6: =+'CUARTOS DE FINAL.'!D6:D7 -> 03:00. p.m. | F6: =IF(AND(H6<>"",J6<>""),IF(H6=J6,"E",IF(H6>J6,"G","P")),"") -> E | G6: =+'CUARTOS DE FINAL.'!G6:G7 -> #N/A | H6: . | I6: - | J6: . | K6: =IF(AND(J6<>"",H6<>""),IF(J6=H6,"E",IF(J6>H6,"G","P")),"") -> E | L6: =+'CUARTOS DE FINAL.'!L6:L7 -> SPORTING CLUB VILLAVICENCIO | N6: =+'CUARTOS DE FINAL.'!N6:N7 -> PALMARA | P6: =IF(OR(F6="E",F6=""),"",IF(F6="G",G6,L6))
B9: =+'CUARTOS DE FINAL.'!B9:B10 -> 42596 | C9: =+'CUARTOS DE FINAL.'!C9:C10 -> LLAVE B | D9: =+'CUARTOS DE FINAL.'!D9:D10 -> 04:20. p.m. | F9: =IF(AND(H9<>"",J9<>""),IF(H9=J9,"E",IF(H9>J9,"G","P")),"") -> E | G9: =+'CUARTOS DE FINAL.'!G9:G10 -> ATHLETIC MELGAR | H9: . | I9: - | J9: . | K9: =IF(AND(J9<>"",H9<>""),IF(J9=H9,"E",IF(J9>H9,"G","P")),"") -> E | L9: =+'CUARTOS DE FINAL.'!L9:L10 -> E.D.F CHOCONTA | N9: =+'CUARTOS DE FINAL.'!N9:N10 -> CANCHA 2 | P9: =IF(OR(F9="E",F9=""),"",IF(F9="G",G9,L9))
B12: =+'CUARTOS DE FINAL.'!B12:B13 -> 42596 | C12: =+'CUARTOS DE FINAL.'!C12:C13 -> LLAVE C | D12: =+'CUARTOS DE FINAL.'!D12:D13 -> 03:00. p.m. | F12: =IF(AND(H12<>"",J12<>""),IF(H12=J12,"E",IF(H12>J12,"G","P")),"") -> E | G12: =+'CUARTOS DE FINAL.'!G12:G13 -> CLUB DEPORTIVO NASSUAR | H12: . | I12: - | J12: . | K12: =IF(AND(J12<>"",H12<>""),IF(J12=H12,"E",IF(J12>H12,"G","P")),"") -> E | L12: =+'CUARTOS DE FINAL.'!L12:L13 -> #N/A | N12: =+'CUARTOS DE FINAL.'!N12:N13 -> CANCHA 2 | P12: =IF(OR(F12="E",F12=""),"",IF(F12="G",G12,L12))
B15: =+'CUARTOS DE FINAL.'!B15:B16 -> 42596 | C15: =+'CUARTOS DE FINAL.'!C15:C16 -> LLAVE D | D15: =+'CUARTOS DE FINAL.'!D15:D16 -> 04:20. p.m. | F15: =IF(AND(H15<>"",J15<>""),IF(H15=J15,"E",IF(H15>J15,"G","P")),"") -> E | G15: =+'CUARTOS DE FINAL.'!G15:G16 -> IMPERIUM FÚTBOL CLUB | H15: . | I15: - | J15: . | K15: =IF(AND(J15<>"",H15<>""),IF(J15=H15,"E",IF(J15>H15,"G","P")),"") -> E | L15: =+'CUARTOS DE FINAL.'!L15:L16 -> GOLDEN STEPS | N15: =+'CUARTOS DE FINAL.'!N15:N16 -> PALMARA | P15: =IF(OR(F15="E",F15=""),"",IF(F15="G",G15,L15))
B18: BABY FUTBOL
B21: Nacidos Año 2005-2006

Sheet IMPRIMIR 4
A1: Campeonato Nacional de Futbol
A2: “COPA FUTURO TALENTO”
A3: DEFINICIÓN DEL TORNEO
B4: Observación: Si el partido se define por penales, éstos deben sumarse al resultado.
B5: SEMIFINALES | Q5: Ganador
B7: =+#REF! -> #REF! | C7: =+#REF! -> #REF! | D7: =+#REF! -> #REF! | E7: =+#REF! -> #REF! | G7: =IF(AND(I7<>"",K7<>""),IF(I7=K7,"E",IF(I7>K7,"G","P")),"") -> #REF! | I7: =+#REF! -> #REF! | J7: - | K7: =+#REF! -> #REF! | L7: =IF(AND(K7<>"",I7<>""),IF(K7=I7,"E",IF(K7>I7,"G","P")),"") -> #REF! | M7: =+#REF! -> #REF! | O7: =+#REF! -> #REF! | Q7: =IF(OR(G7="E",G7=""),"",IF(G7="G",E7,M7)) -> #REF! | S7: =IF(OR(G7="E",G7=""),"",IF(G7="P",E7,M7)) -> #REF!
B10: =+#REF! -> #REF! | C10: =+#REF! -> #REF! | D10: =+#REF! -> #REF! | E10: =+#REF! -> #REF! | G10: =IF(AND(I10<>"",K10<>""),IF(I10=K10,"E",IF(I10>K10,"G","P")),"") -> #REF! | I10: =+#REF! -> #REF! | J10: - | K10: =+#REF! -> #REF! | L10: =IF(AND(K10<>"",I10<>""),IF(K10=I10,"E",IF(K10>I10,"G","P")),"") -> #REF! | M10: =+#REF! -> #REF! | O10: =+#REF! -> #REF! | Q10: =IF(OR(G10="E",G10=""),"",IF(G10="G",E10,M10)) -> #REF! | S10: =IF(OR(G10="E",G10=""),"",IF(G10="P",E10,M10)) -> #REF!
C14: =+'PRE INFANTIL GRUPOS'!C3 -> DICIEMBRE 4 AL 6 DEL 2024 | J14: =+'PRE INFANTIL GRUPOS'!C4 -> NACIDOS 2010 2011

Sheet IMPRIMIR 5
A1: Campeonato Nacional de Futbol
A2: “COPA FUTURO TALENTO”
A3: FINAL DEL TORNEO
B4: Observación: Si el partido se define por penales, éstos deben sumarse al resultado.
B5: Partido por el TERCER PUESTO | Q5: TERCER PUESTO
Q6: =IF(OR(G7="E",G7=""),"",IF(G7="G",H7,M7)) -> #REF!
B7: =+#REF! -> #REF! | D7: =+#REF! -> #REF! | G7: =IF(AND(I7<>"",K7<>""),IF(I7=K7,"E",IF(I7>K7,"G","P")),"") -> #REF! | H7: =+#REF! -> #REF! | I7: =+#REF! -> #REF! | J7: - | K7: =+#REF! -> #REF! | L7: =IF(AND(K7<>"",I7<>""),IF(K7=I7,"E",IF(K7>I7,"G","P")),"") -> #REF! | M7: =+#REF! -> #REF! | O7: =+#REF! -> #REF!
B11: FINAL DEL CAMPEONATO | Q11: SEGUNDO PUESTO
Q12: =IF(OR(G13="E",G13=""),"",IF(G13="P",H13,M13)) -> #REF!
B13: =+#REF! -> #REF! | D13: =+#REF! -> #REF! | G13: =IF(AND(I13<>"",K13<>""),IF(I13=K13,"E",IF(I13>K13,"G","P")),"") -> #REF! | H13: =+#REF! -> #REF! | I13: =+#REF! -> #REF! | J13: - | K13: =+#REF! -> #REF! | L13: =IF(AND(K13<>"",I13<>""),IF(K13=I13,"E",IF(K13>I13,"G","P")),"") -> #REF! | M13: =+#REF! -> #REF! | O13: =+#REF! -> #REF!
B17: CAMPEÓN “COPA FUTURO TALENTO”
B19: =IF(OR(G13="E",G13=""),"",IF(G13="G",H13,M13)) -> #REF!
C22: =+'PRE INFANTIL GRUPOS'!C3 -> DICIEMBRE 4 AL 6 DEL 2024 | O22: =+'PRE INFANTIL GRUPOS'!C4 -> NACIDOS 2010 2011

Sheet Hoja1
C1: IV Campeonato Nacional de Futbol
C2: “COPA FUTURO TALENTO”
C4: FASE GRUPOS
C6: GRUPO A | E6: GRUPO B | G6: GRUPO C | I6: GRUPO D
C7: 1 | E7: 5 | G7: 9 | I7: 13
C8: 2 | E8: 6 | G8: 10 | I8: 14
C9: 3 | E9: 7 | G9: 11 | I9: 15
C10: 4 | E10: 8 | G10: 12 | I10: 16
B12: CUARTOS DE FINAL
B14: LLAVE A | C14: PRIMERO DEL GRUPO A | F14: vs | G14: SEGUNDO DEL GRUPO C
B16: LLAVE B | C16: PRIMERO DEL GRUPO B | F16: vs | G16: SEGUNDO DEL GRUPO D
B18: LLAVE C | C18: PRIMERO DEL GRUPO C | F18: vs | G18: SEGUNDO DEL GRUPO A
B20: LLAVE D | C20: PRIMERO DEL GRUPO D | F20: vs | G20: SEGUNDO DEL GRUPO B
B22: SEMIFINAL
B24: LLAVE 1 | C24: GANADOR LLAVE A | F24: vs | G24: GANADOR LLAVE B
B26: LLAVE 2 | C26: GANADOR LLAVE C | F26: vs | G26: GANADOR LLAVE D
C28: TERCER Y CUARTO LUGAR
C30: PERDEDOR LLAVE 1 | F30: vs | G30: PERDEDOR LLAVE 2
C32: FINAL
C34: GANADOR LLAVE 1 | F34: vs | G34: GANADOR LLAVE 2

Sheet Hoja2 (2)
A1: =+'PRE INFANTIL GRUPOS'!B1:I1 -> #VALUE!
A2: =+'PRE INFANTIL GRUPOS'!B2:I2 -> #VALUE!
A3: =+'PRE INFANTIL GRUPOS'!C3 -> DICIEMBRE 4 AL 6 DEL 2024
A4: =+'PRE INFANTIL GRUPOS'!C4 -> NACIDOS 2010 2011
A5: CALENDARIO OFICIAL
