Workbook

Sheet GRUPOS PRE JUVENIL
D1: XVIII Torneo Nacional de Fútbol Infantil
D2: “COPA SOCCER MELGAR"
D3: NACIDOS 2016 2017
D4: NOV 30 1 Y 2 DICIEMBRE 2024
E6: GRUPO A | G6: GRUPO B | I6: GRUPO C
E7: ATHETIC MELGAR | G7: IVÁN VÉLEZ PROFESIONALES PALMIRA | I7: CD INDEPENDIENTE
E8: CLUB ESTUDIANTES CK | G8: UNION TOLIMENSE | I8: ATHLETIC SPORT
E9: GENERACION TOLIMA | G9: SAETA REDEC | I9: ATHETIC CLUB MUNICIPAL | K9: 2024
I10: ACADEMIA REAL

Sheet GRUPO A
A1: IV Campeonato Nacional de Futbol
A2: “COPA FUTURO TALENTO”
B3: =+'GRUPOS PRE JUVENIL'!D3 -> NACIDOS 2016 2017 | F3: =+'GRUPOS PRE JUVENIL'!D4 -> NOV 30 1 Y 2 DICIEMBRE 2024
B4: =+'GRUPOS PRE JUVENIL'!E6 -> GRUPO A
B6: PARTIDOS | P6: POSICIONES | AJ6: =COUNT(G14,I14,G8,I8,G11,I11,G20,I20,G17,I17,G26,I26,G23,I23,G35,I35,G32,I32,G29,I29) -> 12
A7: Tj | N7: Tj
E8: =+'GRUPOS PRE JUVENIL'!E7 -> ATHETIC MELGAR | F8: =IF(AND(G8<>"",I8<>""),IF(G8=I8,"E",IF(G8>I8,"G","P")),"") | H8: - | J8: =IF(AND(I8<>"",G8<>""),IF(I8=G8,"E",IF(I8>G8,"G","P")),"") | K8: =+'GRUPOS PRE JUVENIL'!G8 -> UNION TOLIMENSE | P8: GRUPO A | Q8: Pts. | R8: PJ | S8: Gan. | T8: Emp. | U8: Per. | V8: GF | W8: GC | X8: Dif. | Y8: Tj | AC8: win | AD8: empate | AE8: perdido | AJ8: =IF(AJ6=12,IF(INDEX(Z10:AK19,MATCH(2,Z10:Z17,0),11)=INDEX(Z10:AK17,MATCH(1,Z10:Z17,0),11),1,0),0) -> 0
P10: =" 1) " & VLOOKUP(1,$Z$10:$AI$19,2,0) -> 1) ATHETIC MELGAR | Q10: =VLOOKUP(1,$Z$10:$AI$19,3,0) -> 4 | R10: =+SUM(S10:U11) -> 3 | S10: =VLOOKUP(1,$Z$10:$AI$19,4,0) -> 1 | T10: =VLOOKUP(1,$Z$10:$AI$19,5,0) -> 1 | U10: =VLOOKUP(1,$Z$10:$AI$19,6,0) -> 1 | V10: =VLOOKUP(1,$Z$10:$AI$19,7,0) -> 2 | W10: =VLOOKUP(1,$Z$10:$AI$19,8,0) -> 2 | X10: =VLOOKUP(1,$Z$10:$AH$19,9,0) -> 0 | Y10: =VLOOKUP(1,$Z$10:$AI$19,10,0) -> 0 | Z10: =RANK(AJ10,$AJ$10:$AJ$19,0) -> 1 | AA10: =+'GRUPOS PRE JUVENIL'!E7 -> ATHETIC MELGAR | AB10: =(AC10*3)+AD10 -> 4 | AC10: =COUNTIF(Q44:T44,"G") -> 1 | AD10: =COUNTIF(Q44:T44,"E") -> 1 | AE10: =COUNTIF(Q44:T44,"P") -> 1 | AF10: =+G17+G8+G23+I32 -> 2 | AG10: =+I17+I8+I23+G32 -> 2 | AH10: =AF10-AG10 -> 0 | AI10: =+A17+A8+A23+N32 -> 0 | AJ10: =(AB10*1000)+(AH10*100)+(AF10*10)-AI10+0.1 -> 4020.1 | AK10: =AJ10 -> 4020.1
E11: =+'GRUPOS PRE JUVENIL'!E8 -> CLUB ESTUDIANTES CK | F11: =IF(AND(G11<>"",I11<>""),IF(G11=I11,"E",IF(G11>I11,"G","P")),"") | H11: - | J11: =IF(AND(I11<>"",G11<>""),IF(I11=G11,"E",IF(I11>G11,"G","P")),"") | K11: =+'GRUPOS PRE JUVENIL'!G9 -> SAETA REDEC
P12: =" 2) " & VLOOKUP(2,$Z$10:$AI$19,2,0) -> 2) GENERACION TOLIMA | Q12: =VLOOKUP(2,$Z$10:$AI$19,3,0) -> 4 | R12: =+SUM(S12:U13) -> 3 | S12: =VLOOKUP(2,$Z$10:$AI$19,4,0) -> 1 | T12: =VLOOKUP(2,$Z$10:$AI$19,5,0) -> 1 | U12: =VLOOKUP(2,$Z$10:$AI$19,6,0) -> 1 | V12: =VLOOKUP(2,$Z$10:$AI$19,7,0) -> 3 | W12: =VLOOKUP(2,$Z$10:$AI$19,8,0) -> 4 | X12: =VLOOKUP(2,$Z$10:$AH$19,9,0) -> -1 | Y12: =VLOOKUP(2,$Z$10:$AI$19,10,0) -> 0 | Z12: =RANK(AJ12,$AJ$10:$AJ$19,0) -> 3 | AA12: =+'GRUPOS PRE JUVENIL'!E8 -> CLUB ESTUDIANTES CK | AB12: =(AC12*3)+AD12 -> 0 | AC12: =COUNTIF(Q45:T45,"G") -> 0 | AD12: =COUNTIF(Q45:T45,"E") -> 0 | AE12: =COUNTIF(Q45:T45,"P") -> 3 | AF12: =+G11+I17+G26+I29 -> 1 | AG12: =+I11+G17+I26+G29 -> 5 | AH12: =AF12-AG12 -> -4 | AI12: =+A11+A26+N17+N29 -> 0 | AJ12: =(AB12*1000)+(AH12*100)+(AF12*10)-AI12+0.2 -> -389.8 | AK12: =AJ12 -> -389.8
E14: =+'GRUPOS PRE JUVENIL'!E9 -> GENERACION TOLIMA | F14: =IF(AND(G14<>"",I14<>""),IF(G14=I14,"E",IF(G14>I14,"G","P")),"") | H14: - | J14: =IF(AND(I14<>"",G14<>""),IF(I14=G14,"E",IF(I14>G14,"G","P")),"") | K14: =+'GRUPOS PRE JUVENIL'!G7 -> IVÁN VÉLEZ PROFESIONALES PALMIRA | P14: =" 3) " & VLOOKUP(3,$Z$10:$AI$19,2,0) -> 3) CLUB ESTUDIANTES CK | Q14: =VLOOKUP(3,$Z$10:$AI$19,3,0) -> 0 | R14: =+SUM(S14:U15) -> 3 | S14: =VLOOKUP(3,$Z$10:$AI$19,4,0) -> 0 | T14: =VLOOKUP(3,$Z$10:$AI$19,5,0) -> 0 | U14: =VLOOKUP(3,$Z$10:$AI$19,6,0) -> 3 | V14: =VLOOKUP(3,$Z$10:$AI$19,7,0) -> 1 | W14: =VLOOKUP(3,$Z$10:$AI$19,8,0) -> 5 | X14: =VLOOKUP(3,$Z$10:$AI$19,9,0) -> -4 | Y14: =VLOOKUP(3,$Z$10:$AI$19,10,0) -> 0 | Z14: =RANK(AJ14,$AJ$10:$AJ$19,0) -> 2 | AA14: =+'GRUPOS PRE JUVENIL'!E9 -> GENERACION TOLIMA | AB14: =(AC14*3)+AD14 -> 4 | AC14: =COUNTIF(Q46:T46,"G") -> 1 | AD14: =COUNTIF(Q46:T46,"E") -> 1 | AE14: =COUNTIF(Q46:T46,"P") -> 1 | AF14: =+G14+G20+I23+G29 -> 3 | AG14: =+I20+I14+G23+I29 -> 4 | AH14: =AF14-AG14 -> -1 | AI14: =+A14+A20+N23+A29 -> 0 | AJ14: =(AB14*1000)+(AH14*100)+(AF14*10)-AI14+0.3 -> 3930.3 | AK14: =+X14 -> -4
B17: 42813 | C17: 07:00. a.m. | E17: =+'GRUPOS PRE JUVENIL'!E7 -> ATHETIC MELGAR | F17: =IF(AND(G17<>"",I17<>""),IF(G17=I17,"E",IF(G17>I17,"G","P")),"") -> G | G17: 1 | H17: - | I17: 0 | J17: =IF(AND(I17<>"",G17<>""),IF(I17=G17,"E",IF(I17>G17,"G","P")),"") -> P | K17: =+'GRUPOS PRE JUVENIL'!E8 -> CLUB ESTUDIANTES CK | M17: CANCHA 1 A
B20: 42813 | C20: 08:40. a.m. | E20: =+'GRUPOS PRE JUVENIL'!E9 -> GENERACION TOLIMA | F20: =IF(AND(G20<>"",I20<>""),IF(G20=I20,"E",IF(G20>I20,"G","P")),"") -> P | G20: 0 | H20: - | I20: 2 | J20: =IF(AND(I20<>"",G20<>""),IF(I20=G20,"E",IF(I20>G20,"G","P")),"") -> G | K20: =+'GRUPOS PRE JUVENIL'!G9 -> SAETA REDEC | M20: CANCHA 1 A
W22: =IF(AJ8=1,IF(P21="","",P21),IF(SUM(Q10:Q19)>0,VLOOKUP(1,Z10:AA19,2,0),"")) -> ATHETIC MELGAR
B23: 42813 | C23: 01:20. p.m. | E23: =+'GRUPOS PRE JUVENIL'!E7 -> ATHETIC MELGAR | F23: =IF(AND(G23<>"",I23<>""),IF(G23=I23,"E",IF(G23>I23,"G","P")),"") -> E | G23: 1 | H23: - | I23: 1 | J23: =IF(AND(I23<>"",G23<>""),IF(I23=G23,"E",IF(I23>G23,"G","P")),"") -> E | K23: =+'GRUPOS PRE JUVENIL'!E9 -> GENERACION TOLIMA | M23: CANCHA 1 A | W23: =IF(AJ8=1,IF(P24="","",P24),IF(SUM(Q10:Q19)>0,VLOOKUP(2,Z10:AA19,2,0),"")) -> GENERACION TOLIMA
W24: =IF(AJ9=1,IF(P25="","",P25),IF(SUM(Q10:Q15)>0,VLOOKUP(3,Z10:AA15,2,0),"")) -> CLUB ESTUDIANTES CK
B26: 42812 | C26: 07:00. a.m. | E26: =+'GRUPOS PRE JUVENIL'!E8 -> CLUB ESTUDIANTES CK | F26: =IF(AND(G26<>"",I26<>""),IF(G26=I26,"E",IF(G26>I26,"G","P")),"") -> P | G26: 0 | H26: - | I26: 2 | J26: =IF(AND(I26<>"",G26<>""),IF(I26=G26,"E",IF(I26>G26,"G","P")),"") -> G | K26: =+'GRUPOS PRE JUVENIL'!G8 -> UNION TOLIMENSE | M26: CANCHA 1 B
B29: 42812 | C29: 03:00. p.m. | E29: =+'GRUPOS PRE JUVENIL'!E9 -> GENERACION TOLIMA | F29: =IF(AND(G29<>"",I29<>""),IF(G29=I29,"E",IF(G29>I29,"G","P")),"") -> G | G29: 2 | H29: - | I29: 1 | J29: =IF(AND(I29<>"",G29<>""),IF(I29=G29,"E",IF(I29>G29,"G","P")),"") -> P | K29: =+'GRUPOS PRE JUVENIL'!E8 -> CLUB ESTUDIANTES CK | M29: CANCHA 1 C
J31: =IF(AG8=1,"Indique el primero y segundo equipos clasificados de la serie:","") | L31: =IF(AG8=1,"Primero:","")
B32: 42812 | C32: 03:00. p.m. | E32: =+'GRUPOS PRE JUVENIL'!G7 -> IVÁN VÉLEZ PROFESIONALES PALMIRA | F32: =IF(AND(G32<>"",I32<>""),IF(G32=I32,"E",IF(G32>I32,"G","P")),"") -> G | G32: 1 | H32: - | I32: 0 | J32: =IF(AND(I32<>"",G32<>""),IF(I32=G32,"E",IF(I32>G32,"G","P")),"") -> P | K32: =+'GRUPOS PRE JUVENIL'!E7 -> ATHETIC MELGAR | M32: CANCHA 1 B
P44: =+'GRUPOS PRE JUVENIL'!E7 -> ATHETIC MELGAR | Q44: =+F8 | R44: =+F17 -> G | S44: =+F23 -> E | T44: =+J32 -> P
P45: =+'GRUPOS PRE JUVENIL'!E8 -> CLUB ESTUDIANTES CK | Q45: =+F11 | R45: =+J17 -> P | S45: =+F26 -> P | T45: =+J29 -> P
P46: =+'GRUPOS PRE JUVENIL'!E9 -> GENERACION TOLIMA | Q46: =+F14 | R46: =+F20 -> P | S46: =+J23 -> E | T46: =+F29 -> G

Sheet GRUPO B
A1: IV Campeonato Nacional de Futbol
A2: “COPA FUTURO TALENTO”
B3: =+'GRUPOS PRE JUVENIL'!D3 -> NACIDOS 2016 2017 | F3: =+'GRUPOS PRE JUVENIL'!D4 -> NOV 30 1 Y 2 DICIEMBRE 2024
B4: =+'GRUPOS PRE JUVENIL'!G6 -> GRUPO B | P4: POSICIONES | AJ4: =COUNT(G8,I8,G11,I11,G14,I14,G17,I17,G20,I20,G35,I35,G23,I23,G26,I26,G29,I29,G32,I32) -> 12
B6: PARTIDOS | P6: GRUPO B | Q6: Pts. | R6: PJ | S6: Gan. | T6: Emp. | U6: Per. | V6: GF | W6: GC | X6: Dif. | Y6: Tj | AC6: win | AD6: empate | AE6: perdido | AJ6: =IF(AJ4=12,IF(INDEX(Z8:AK17,MATCH(2,Z8:Z15,0),11)=INDEX(Z8:AK15,MATCH(1,Z8:Z15,0),11),1,0),0) -> 0
A7: Tj | N7: Tj
E8: =+'GRUPO A'!E8:E9 -> ATHETIC MELGAR | F8: =IF(AND(G8<>"",I8<>""),IF(G8=I8,"E",IF(G8>I8,"G","P")),"") | H8: - | J8: =IF(AND(I8<>"",G8<>""),IF(I8=G8,"E",IF(I8>G8,"G","P")),"") | K8: =+'GRUPO A'!K8:K9 -> UNION TOLIMENSE | P8: =" 1) " & VLOOKUP(1,$Z$8:$AI$17,2,0) -> 1) IVÁN VÉLEZ PROFESIONALES PALMIRA | Q8: =VLOOKUP(1,$Z$8:$AI$17,3,0) -> 9 | R8: =+SUM(S8:U9) -> 3 | S8: =VLOOKUP(1,$Z$8:$AI$17,4,0) -> 3 | T8: =VLOOKUP(1,$Z$8:$AI$17,5,0) -> 0 | U8: =VLOOKUP(1,$Z$8:$AI$17,6,0) -> 0 | V8: =VLOOKUP(1,$Z$8:$AI$17,7,0) -> 8 | W8: =VLOOKUP(1,$Z$8:$AI$17,8,0) -> 0 | X8: =VLOOKUP(1,$Z$8:$AH$17,9,0) -> 8 | Y8: =VLOOKUP(1,$Z$8:$AI$17,10,0) -> 0 | Z8: =RANK(AJ8,$AJ$8:$AJ$17,0) -> 1 | AA8: =+'GRUPOS PRE JUVENIL'!G7 -> IVÁN VÉLEZ PROFESIONALES PALMIRA | AB8: =(AC8*3)+AD8 -> 9 | AC8: =COUNTIF(Q42:T42,"G") -> 3 | AD8: =COUNTIF(Q42:T42,"E") -> 0 | AE8: =COUNTIF(Q42:T42,"P") -> 0 | AF8: =+I14+G17+G32+G23 -> 8 | AG8: =+G14+I17+I32+I23 -> 0 | AH8: =AF8-AG8 -> 8 | AI8: =+N14+A17+A32+A23 -> 0 | AJ8: =(AB8*1000)+(AH8*100)+(AF8*10)-AI8+0.1 -> 9880.1 | AK8: =AJ8 -> 9880.1
P10: =" 2) " & VLOOKUP(2,$Z$8:$AI$17,2,0) -> 2) SAETA REDEC | Q10: =VLOOKUP(2,$Z$8:$AI$17,3,0) -> 4 | R10: =+SUM(S10:U11) -> 3 | S10: =VLOOKUP(2,$Z$8:$AI$17,4,0) -> 1 | T10: =VLOOKUP(2,$Z$8:$AI$17,5,0) -> 1 | U10: =VLOOKUP(2,$Z$8:$AI$17,6,0) -> 1 | V10: =VLOOKUP(2,$Z$8:$AI$17,7,0) -> 3 | W10: =VLOOKUP(2,$Z$8:$AI$17,8,0) -> 4 | X10: =VLOOKUP(2,$Z$8:$AH$17,9,0) -> -1 | Y10: =VLOOKUP(2,$Z$8:$AI$17,10,0) -> 0 | Z10: =RANK(AJ10,$AJ$8:$AJ$17,0) -> 3 | AA10: =+'GRUPOS PRE JUVENIL'!G8 -> UNION TOLIMENSE | AB10: =(AC10*3)+AD10 -> 4 | AC10: =COUNTIF(Q43:T43,"G") -> 1 | AD10: =COUNTIF(Q43:T43,"E") -> 1 | AE10: =COUNTIF(Q43:T43,"P") -> 1 | AF10: =+I8+I17+I26+G29 -> 3 | AG10: =+G8+G17+G26+I29 -> 5 | AH10: =AF10-AG10 -> -2 | AI10: =+N8+A29+N17+N26 -> 0 | AJ10: =(AB10*1000)+(AH10*100)+(AF10*10)-AI10+0.2 -> 3830.2 | AK10: =AJ10 -> 3830.2
E11: =+'GRUPO A'!E11:E12 -> CLUB ESTUDIANTES CK | F11: =IF(AND(G11<>"",I11<>""),IF(G11=I11,"E",IF(G11>I11,"G","P")),"") | H11: - | J11: =IF(AND(I11<>"",G11<>""),IF(I11=G11,"E",IF(I11>G11,"G","P")),"") | K11: =+'GRUPO A'!K11:K12 -> SAETA REDEC
P12: =" 3) " & VLOOKUP(3,$Z$8:$AI$17,2,0) -> 3) UNION TOLIMENSE | Q12: =VLOOKUP(3,$Z$8:$AI$17,3,0) -> 4 | R12: =+SUM(S12:U13) -> 3 | S12: =VLOOKUP(3,$Z$8:$AI$17,4,0) -> 1 | T12: =VLOOKUP(3,$Z$8:$AI$17,5,0) -> 1 | U12: =VLOOKUP(3,$Z$8:$AI$17,6,0) -> 1 | V12: =VLOOKUP(3,$Z$8:$AI$17,7,0) -> 3 | W12: =VLOOKUP(3,$Z$8:$AI$17,8,0) -> 5 | X12: =VLOOKUP(3,$Z$8:$AI$17,9,0) -> -2 | Y12: =VLOOKUP(3,$Z$8:$AI$17,10,0) -> 0 | Z12: =RANK(AJ12,$AJ$8:$AJ$17,0) -> 2 | AA12: =+'GRUPOS PRE JUVENIL'!G9 -> SAETA REDEC | AB12: =(AC12*3)+AD12 -> 4 | AC12: =COUNTIF(Q44:T44,"G") -> 1 | AD12: =COUNTIF(Q44:T44,"E") -> 1 | AE12: =COUNTIF(Q44:T44,"P") -> 1 | AF12: =+I11+I20+I23+I29 -> 3 | AG12: =+G20+G11+G23+G29 -> 4 | AH12: =AF12-AG12 -> -1 | AI12: =+N11+N20+N23+N29 -> 0 | AJ12: =(AB12*1000)+(AH12*100)+(AF12*10)-AI12+0.3 -> 3930.3 | AK12: =+X12 -> -2
E14: =+'GRUPO A'!E14:E15 -> GENERACION TOLIMA | F14: =IF(AND(G14<>"",I14<>""),IF(G14=I14,"E",IF(G14>I14,"G","P")),"") | H14: - | J14: =IF(AND(I14<>"",G14<>""),IF(I14=G14,"E",IF(I14>G14,"G","P")),"") | K14: =+'GRUPO A'!K14:K15 -> IVÁN VÉLEZ PROFESIONALES PALMIRA
B17: 42813 | C17: 01:20. p.m. | E17: =+'GRUPOS PRE JUVENIL'!G7 -> IVÁN VÉLEZ PROFESIONALES PALMIRA | F17: =IF(AND(G17<>"",I17<>""),IF(G17=I17,"E",IF(G17>I17,"G","P")),"") -> G | G17: 4 | H17: - | I17: 0 | J17: =IF(AND(I17<>"",G17<>""),IF(I17=G17,"E",IF(I17>G17,"G","P")),"") -> P | K17: =+'GRUPOS PRE JUVENIL'!G8 -> UNION TOLIMENSE | M17: CANCHA 1 C
B20: 42813 | C20: =+'GRUPO A'!C20:C21 -> 08:40. a.m. | E20: =+'GRUPO A'!E20:E21 -> GENERACION TOLIMA | F20: =IF(AND(G20<>"",I20<>""),IF(G20=I20,"E",IF(G20>I20,"G","P")),"") -> P | G20: 0 | H20: - | I20: 2 | J20: =IF(AND(I20<>"",G20<>""),IF(I20=G20,"E",IF(I20>G20,"G","P")),"") -> G | K20: =+'GRUPOS PRE JUVENIL'!G9 -> SAETA REDEC | M20: =+'GRUPO A'!M20:M21 -> CANCHA 1 A | W20: =IF(AJ6=1,IF(P19="","",P19),IF(SUM(Q8:Q13)>0,VLOOKUP(1,Z8:AA17,2,0),"")) -> IVÁN VÉLEZ PROFESIONALES PALMIRA
W21: =IF(AJ6=1,IF(P22="","",P22),IF(SUM(Q8:Q13)>0,VLOOKUP(2,Z8:AA17,2,0),"")) -> SAETA REDEC
W22: =IF(AJ7=1,IF(P23="","",P23),IF(SUM(Q8:Q13)>0,VLOOKUP(3,Z8:AA17,2,0),"")) -> UNION TOLIMENSE
B23: 42812 | C23: 08:40. p.m. | E23: =+'GRUPOS PRE JUVENIL'!G7 -> IVÁN VÉLEZ PROFESIONALES PALMIRA | F23: =IF(AND(G23<>"",I23<>""),IF(G23=I23,"E",IF(G23>I23,"G","P")),"") -> G | G23: 3 | H23: - | I23: 0 | J23: =IF(AND(I23<>"",G23<>""),IF(I23=G23,"E",IF(I23>G23,"G","P")),"") -> P | K23: =+'GRUPOS PRE JUVENIL'!G9 -> SAETA REDEC | M23: CANCHA 1 B | W23: =IF(AJ6=1,IF(P24="","",P24),IF(SUM(Q8:Q13)>0,VLOOKUP(4,Z8:AK17,2,0),"")) -> #N/A
B26: =+'GRUPO A'!B26:B27 -> 42812 | C26: =+'GRUPO A'!C26:C27 -> 07:00. a.m. | E26: =+'GRUPO A'!E26:E27 -> CLUB ESTUDIANTES CK | F26: =IF(AND(G26<>"",I26<>""),IF(G26=I26,"E",IF(G26>I26,"G","P")),"") -> P | G26: 0 | H26: - | I26: 2 | J26: =IF(AND(I26<>"",G26<>""),IF(I26=G26,"E",IF(I26>G26,"G","P")),"") -> G | K26: =+'GRUPO A'!K26:K27 -> UNION TOLIMENSE | M26: =+'GRUPO A'!M26:M27 -> CANCHA 1 B
B29: 42812 | C29: 03:00. p.m. | E29: =+'GRUPOS PRE JUVENIL'!G8 -> UNION TOLIMENSE | F29: =IF(AND(G29<>"",I29<>""),IF(G29=I29,"E",IF(G29>I29,"G","P")),"") -> E | G29: 1 | H29: - | I29: 1 | J29: =IF(AND(I29<>"",G29<>""),IF(I29=G29,"E",IF(I29>G29,"G","P")),"") -> E | K29: =+'GRUPOS PRE JUVENIL'!G9 -> SAETA REDEC | M29: CANCHA 1 A
J31: =IF(AG6=1,"Indique el primero y segundo equipos clasificados de la serie:","") | L31: =IF(AG6=1,"Primero:","")
B32: =+'GRUPO A'!B32:B33 -> 42812 | C32: =+'GRUPO A'!C32:C33 -> 03:00. p.m. | E32: =+'GRUPO A'!E32:E33 -> IVÁN VÉLEZ PROFESIONALES PALMIRA | F32: =IF(AND(G32<>"",I32<>""),IF(G32=I32,"E",IF(G32>I32,"G","P")),"") -> G | G32: 1 | H32: - | I32: 0 | J32: =IF(AND(I32<>"",G32<>""),IF(I32=G32,"E",IF(I32>G32,"G","P")),"") -> P | K32: =+'GRUPO A'!K32:K33 -> ATHETIC MELGAR | M32: =+'GRUPO A'!M32:M33 -> CANCHA 1 B
P42: =+'GRUPOS PRE JUVENIL'!G7 -> IVÁN VÉLEZ PROFESIONALES PALMIRA | Q42: =+J14 | R42: =+F17 -> G | S42: =+F23 -> G | T42: =+F32 -> G
P43: =+'GRUPOS PRE JUVENIL'!G8 -> UNION TOLIMENSE | Q43: =+J8 | R43: =+J17 -> P | S43: =+J26 -> G | T43: =+F29 -> E
P44: =+'GRUPOS PRE JUVENIL'!G9 -> SAETA REDEC | Q44: =+J11 | R44: =+J20 -> G | S44: =+J23 -> P | T44: =+J29 -> E

Sheet GRUPO C
A1: =+'[1]GRUPOS INFANTIL'!C1 -> XVCampeonato Nacional de Fútbol
A2: “COPA FUTURO TALENTO”
B3: =+'[1]GRUPOS INFANTIL'!C3 -> JUVENIL | F3: =+'[1]GRUPOS INFANTIL'!C4 -> 2002 2003
B4: =+'[1]GRUPOS INFANTIL'!D6 -> GRUPO A
B6: PARTIDOS | P6: POSICIONES | AJ6: =COUNT(G8,I8,G11,I11,G14,I14,G17,I17,G20,I20,G23,I23,G26,I26,G29,I29,G32,I32,G35,I35) -> 12
A7: Tj | N7: Tj
F8: =IF(AND(G8<>"",I8<>""),IF(G8=I8,"E",IF(G8>I8,"G","P")),"") | H8: - | J8: =IF(AND(I8<>"",G8<>""),IF(I8=G8,"E",IF(I8>G8,"G","P")),"") | Q8: Pts. | R8: PJ | S8: Gan. | T8: Emp. | U8: Per. | V8: GF | W8: GC | X8: Dif. | Y8: Tj | AF8: GF | AG8: GC | AH8: DG | AJ8: =IF(AJ6=12,IF(INDEX(Z22:AK29,MATCH(2,Z21:Z29,0),11)=INDEX(Z22:AK29,MATCH(1,Z21:Z29,0),11),1,0),0) -> 0
P10: =" 1) " & VLOOKUP(1,$Z$10:$AI$17,2,0) -> 1) ATHLETIC SPORT | Q10: =VLOOKUP(1,$Z$10:$AI$17,3,0) -> 7 | R10: =+SUM(S10:U11) -> 3 | S10: =VLOOKUP(1,$Z$10:$AI$17,4,0) -> 2 | T10: =VLOOKUP(1,$Z$10:$AI$17,5,0) -> 1 | U10: =VLOOKUP(1,$Z$10:$AI$17,6,0) -> 0 | V10: =VLOOKUP(1,$Z$10:$AI$17,7,0) -> 10 | W10: =VLOOKUP(1,$Z$10:$AI$17,8,0) -> 1 | X10: =VLOOKUP(1,$Z$10:$AH$17,9,0) -> 9 | Y10: =VLOOKUP(1,$Z$10:$AI$17,10,0) -> 0 | Z10: =RANK(AJ10,$AJ$10:$AJ$17,0) -> 4 | AA10: =+'GRUPOS PRE JUVENIL'!I7 -> CD INDEPENDIENTE | AB10: =(AC10*3)+AD10 -> 1 | AC10: =COUNTIF(Q58:T58,"G")+AC19 -> 0 | AD10: =COUNTIF(Q58:T58,"E")+AD19 -> 1 | AE10: =COUNTIF(Q58:T58,"P")+AE19 -> 2 | AF10: =+G8+G20+G26+G35+AF19 -> 3 | AG10: =+I8+I20+I26+I35+AG19 -> 10 | AH10: =AF10-AG10 -> -7 | AI10: =+A8+A20+A26+A35+AI19 -> 0 | AJ10: =(AB10*1000)+(AH10*100)+(AF10*10)-AI10+0.1 -> 330.1 | AK10: =AJ10+X10 -> 339.1
F11: =IF(AND(G11<>"",I11<>""),IF(G11=I11,"E",IF(G11>I11,"G","P")),"") | H11: - | J11: =IF(AND(I11<>"",G11<>""),IF(I11=G11,"E",IF(I11>G11,"G","P")),"")
P12: =" 2) " & VLOOKUP(2,$Z$10:$AI$17,2,0) -> 2) ATHETIC CLUB MUNICIPAL | Q12: =VLOOKUP(2,$Z$10:$AI$17,3,0) -> 7 | R12: =+SUM(S12:U13) -> 3 | S12: =VLOOKUP(2,$Z$10:$AI$17,4,0) -> 2 | T12: =VLOOKUP(2,$Z$10:$AI$17,5,0) -> 1 | U12: =VLOOKUP(2,$Z$10:$AI$17,6,0) -> 0 | V12: =VLOOKUP(2,$Z$10:$AI$17,7,0) -> 5 | W12: =VLOOKUP(2,$Z$10:$AI$17,8,0) -> 1 | X12: =VLOOKUP(2,$Z$10:$AH$17,9,0) -> 4 | Y12: =VLOOKUP(2,$Z$10:$AI$17,10,0) -> 0 | Z12: =RANK(AJ12,$AJ$10:$AJ$17,0) -> 1 | AA12: =+'GRUPOS PRE JUVENIL'!I8 -> ATHLETIC SPORT | AB12: =(AC12*3)+AD12 -> 7 | AC12: =COUNTIF(Q59:T59,"G")+AC20 -> 2 | AD12: =COUNTIF(Q59:T59,"E")+AD20 -> 1 | AE12: =COUNTIF(Q59:T59,"P")+AE20 -> 0 | AF12: =+G11+I20+G29+G32+AF20 -> 10 | AG12: =+I11+I29+G20+I32+AG20 -> 1 | AH12: =AF12-AG12 -> 9 | AI12: =+A29+A11+N20+A32+AI20 -> 0 | AJ12: =(AB12*1000)+(AH12*100)+(AF12*10)-AI12+0.2 -> 8000.2 | AK12: =AJ12+X12 -> 8004.2
F14: =IF(AND(G14<>"",I14<>""),IF(G14=I14,"E",IF(G14>I14,"G","P")),"") | H14: - | J14: =IF(AND(I14<>"",G14<>""),IF(I14=G14,"E",IF(I14>G14,"G","P")),"") | P14: =" 3) " & VLOOKUP(3,$Z$10:$AI$17,2,0) -> 3) ACADEMIA REAL | Q14: =VLOOKUP(3,$Z$10:$AI$17,3,0) -> 1 | R14: =+SUM(S14:U15) -> 3 | S14: =VLOOKUP(3,$Z$10:$AI$17,4,0) -> 0 | T14: =VLOOKUP(3,$Z$10:$AI$17,5,0) -> 1 | U14: =VLOOKUP(3,$Z$10:$AI$17,6,0) -> 2 | V14: =VLOOKUP(3,$Z$10:$AI$17,7,0) -> 3 | W14: =VLOOKUP(3,$Z$10:$AI$17,8,0) -> 9 | X14: =VLOOKUP(3,$Z$10:$AI$17,9,0) -> -6 | Y14: =VLOOKUP(3,$Z$10:$AI$17,10,0) -> 0 | Z14: =RANK(AJ14,$AJ$10:$AJ$17,0) -> 2 | AA14: =+'GRUPOS PRE JUVENIL'!I9 -> ATHETIC CLUB MUNICIPAL | AB14: =(AC14*3)+AD14 -> 7 | AC14: =COUNTIF(Q60:T60,"G")+AC21 -> 2 | AD14: =COUNTIF(Q60:T60,"E")+AD21 -> 1 | AE14: =COUNTIF(Q60:T60,"P")+AE21 -> 0 | AF14: =+G14+I26+G23+I32+AF21 -> 5 | AG14: =+G26+I14+I23+G32+AG21 -> 1 | AH14: =AF14-AG14 -> 4 | AI14: =+A14+A23+N26+N32+AI21 -> 0 | AJ14: =(AB14*1000)+(AH14*100)+(AF14*10)-AI14+0.3 -> 7450.3 | AK14: =+X14 -> -6
P16: =" 4) " & VLOOKUP(4,$Z$10:$AI$17,2,0) -> 4) CD INDEPENDIENTE | Q16: =VLOOKUP(4,$Z$10:$AI$17,3,0) -> 1 | R16: =+SUM(S16:U17) -> 3 | S16: =VLOOKUP(4,$Z$10:$AI$17,4,0) -> 0 | T16: =VLOOKUP(4,$Z$10:$AI$17,5,0) -> 1 | U16: =VLOOKUP(4,$Z$10:$AI$17,6,0) -> 2 | V16: =VLOOKUP(4,$Z$10:$AI$17,7,0) -> 3 | W16: =VLOOKUP(4,$Z$10:$AI$17,8,0) -> 10 | X16: =VLOOKUP(4,$Z$10:$AI$17,9,0) -> -7 | Y16: =VLOOKUP(4,$Z$10:$AI$17,10,0) -> 0 | Z16: =RANK(AJ16,$AJ$10:$AJ$17,0) -> 3 | AA16: =+'GRUPOS PRE JUVENIL'!I10 -> ACADEMIA REAL | AB16: =(AC16*3)+AD16 -> 1 | AC16: =COUNTIF(Q61:T61,"G")+AC22 -> 0 | AD16: =COUNTIF(Q61:T61,"E")+AD22 -> 1 | AE16: =COUNTIF(Q61:T61,"P")+AE22 -> 2 | AF16: =+G17+I29+I23+I35+AF22 -> 3 | AG16: =+G29+G23+G35+AG22 -> 9 | AH16: =AF16-AG16 -> -6 | AI16: =+A17+N23+N29+N35+AI22 -> 0 | AJ16: =(AB16*1000)+(AH16*100)+(AF16*10)-AI16+0.4 -> 430.4 | AK16: =+X16 -> -7
F17: =IF(AND(G17<>"",I17<>""),IF(G17=I17,"E",IF(G17>I17,"G","P")),"") | H17: - | J17: =IF(AND(I17<>"",G17<>""),IF(I17=G17,"E",IF(I17>G17,"G","P")),"")
Z19: =+'[1]GRUPO B'!Z10 -> 4 | AA19: =+'[1]GRUPO B'!AA10 -> CANUTO F.C. | AB19: =+'[1]GRUPO B'!AB10 -> 0 | AC19: =+'[1]GRUPO B'!AC10 -> 0 | AD19: =+'[1]GRUPO B'!AD10 -> 0 | AE19: =+'[1]GRUPO B'!AE10 -> 0 | AF19: =+'[1]GRUPO B'!AF10 -> 0 | AG19: =+'[1]GRUPO B'!AG10 -> 0 | ... AK19: =+'[1]GRUPO B'!AK10 -> 0.1
B20: 4 | E20: =+'GRUPOS PRE JUVENIL'!I7 -> CD INDEPENDIENTE | F20: =IF(AND(G20<>"",I20<>""),IF(G20=I20,"E",IF(G20>I20,"G","P")),"") -> P | G20: 0 | H20: - | I20: 5 | J20: =IF(AND(I20<>"",G20<>""),IF(I20=G20,"E",IF(I20>G20,"G","P")),"") -> G | K20: =+'GRUPOS PRE JUVENIL'!I8 -> ATHLETIC SPORT | M20: CANCHA 2 | Z20: =+'[1]GRUPO B'!Z12 -> 3 | AA20: =+'[1]GRUPO B'!AA12 -> HUITACA FUTBOL CLUB CHIA | AB20: =+'[1]GRUPO B'!AB12 -> 0 | AC20: =+'[1]GRUPO B'!AC12 -> 0 | AD20: =+'[1]GRUPO B'!AD12 -> 0 | AE20: =+'[1]GRUPO B'!AE12 -> 0 | AF20: =+'[1]GRUPO B'!AF12 -> 0 | AG20: =+'[1]GRUPO B'!AG12 -> 0 | ... AK20: =+'[1]GRUPO B'!AK12 -> 0.2
Z21: =+'[1]GRUPO B'!Z14 -> 2 | AA21: =+'[1]GRUPO B'!AA14 -> CLUB PROMOTOR DEPORTIVO SCORPION | AB21: =+'[1]GRUPO B'!AB14 -> 0 | AC21: =+'[1]GRUPO B'!AC14 -> 0 | AD21: =+'[1]GRUPO B'!AD14 -> 0 | AE21: =+'[1]GRUPO B'!AE14 -> 0 | AF21: =+'[1]GRUPO B'!AF14 -> 0 | AG21: =+'[1]GRUPO B'!AG14 -> 0 | ... AK21: =+'[1]GRUPO B'!AK14 -> 0
Z22: =+'[1]GRUPO B'!Z16 -> 1 | AA22: =+'[1]GRUPO B'!AA16 -> #REF! | AB22: =+'[1]GRUPO B'!AB16 -> 0 | AC22: =+'[1]GRUPO B'!AC16 -> 0 | AD22: =+'[1]GRUPO B'!AD16 -> 0 | AE22: =+'[1]GRUPO B'!AE16 -> 0 | AF22: =+'[1]GRUPO B'!AF16 -> 0 | AG22: =+'[1]GRUPO B'!AG16 -> 0 | ... AK22: =+'[1]GRUPO B'!AK16 -> 0
B23: 3 | E23: =+'GRUPOS PRE JUVENIL'!I9 -> ATHETIC CLUB MUNICIPAL | F23: =IF(AND(G23<>"",I23<>""),IF(G23=I23,"E",IF(G23>I23,"G","P")),"") -> G | G23: 2 | H23: - | I23: 0 | J23: =IF(AND(I23<>"",G23<>""),IF(I23=G23,"E",IF(I23>G23,"G","P")),"") -> P | K23: =+'GRUPOS PRE JUVENIL'!I10 -> ACADEMIA REAL | M23: LAS VEGAS
B26: 1 | E26: =+'GRUPOS PRE JUVENIL'!I7 -> CD INDEPENDIENTE | F26: =IF(AND(G26<>"",I26<>""),IF(G26=I26,"E",IF(G26>I26,"G","P")),"") -> P | G26: 1 | H26: - | I26: 3 | J26: =IF(AND(I26<>"",G26<>""),IF(I26=G26,"E",IF(I26>G26,"G","P")),"") -> G | K26: =+'GRUPOS PRE JUVENIL'!I9 -> ATHETIC CLUB MUNICIPAL | M26: LAS VEGAS
B29: 2 | E29: =+'GRUPOS PRE JUVENIL'!I8 -> ATHLETIC SPORT | F29: =IF(AND(G29<>"",I29<>""),IF(G29=I29,"E",IF(G29>I29,"G","P")),"") -> G | G29: 5 | H29: - | I29: 1 | J29: =IF(AND(I29<>"",G29<>""),IF(I29=G29,"E",IF(I29>G29,"G","P")),"") -> P | K29: =+'GRUPOS PRE JUVENIL'!I10 -> ACADEMIA REAL | M29: LAS VEGAS
B32: 5 | E32: =+'GRUPOS PRE JUVENIL'!I8 -> ATHLETIC SPORT | F32: =IF(AND(G32<>"",I32<>""),IF(G32=I32,"E",IF(G32>I32,"G","P")),"") -> E | G32: 0 | H32: - | I32: 0 | J32: =IF(AND(I32<>"",G32<>""),IF(I32=G32,"E",IF(I32>G32,"G","P")),"") -> E | K32: =+'GRUPOS PRE JUVENIL'!I9 -> ATHETIC CLUB MUNICIPAL | M32: CANCHA 2
W34: =IF(AJ8=1,IF(P33="","",P33),IF(SUM(Q10:Q17)>0,VLOOKUP(1,Z10:AA17,2,0),"")) -> ATHLETIC SPORT
B35: 6 | E35: =+'GRUPOS PRE JUVENIL'!I7 -> CD INDEPENDIENTE | F35: =IF(AND(G35<>"",I35<>""),IF(G35=I35,"E",IF(G35>I35,"G","P")),"") -> E | G35: 2 | H35: - | I35: 2 | J35: =IF(AND(I35<>"",G35<>""),IF(I35=G35,"E",IF(I35>G35,"G","P")),"") -> E | K35: =+'GRUPOS PRE JUVENIL'!I10 -> ACADEMIA REAL | M35: CANCHA 1 | W35: =IF(AJ8=1,IF(P36="","",P36),IF(SUM(Q10:Q17)>0,VLOOKUP(2,Z10:AA17,2,0),"")) -> ATHETIC CLUB MUNICIPAL
J43: =IF(AG20=1,"Indique el primero y segundo equipos clasificados de la serie:","") | L43: =IF(AG20=1,"Primero:","")
J46: =IF(AG20=1,"(Debido a la paridad de los resultados, no pueden deducirse de forma automática.)","") | L46: =IF(AG20=1,"Segundo:","")
P58: =+'[1]GRUPOS INFANTIL'!D7 -> EMPRENDER F. C. | Q58: =+F8 | R58: =+F20 -> P | S58: =+F26 -> P | T58: =+F35 -> E
P59: =+'[1]GRUPOS INFANTIL'!D8 -> LA VILLA F. C. | Q59: =+F11 | R59: =+J20 -> G | S59: =+F29 -> G | T59: =+F32 -> E
P60: =+'[1]GRUPOS INFANTIL'!D9 -> CLUB ANGELES | Q60: =+F14 | R60: =+F23 -> G | S60: =+J26 -> G | T60: =+J32 -> E
P61: =+'[1]GRUPOS INFANTIL'!D10 -> CLUB DEPORTIVO LIBERTAD | Q61: =+F17 | R61: =+J23 -> P | S61: =+J29 -> P | T61: =+J35 -> E

Sheet CALENDARIO  (2)
A1: =+'GRUPOS PRE JUVENIL'!D1 -> XVIII Torneo Nacional de Fútbol Infantil
A2: =+'GRUPOS PRE JUVENIL'!D2 -> “COPA SOCCER MELGAR"
A3: =+'GRUPOS PRE JUVENIL'!D3 -> NACIDOS 2016 2017
A4: =+'GRUPOS PRE JUVENIL'!D4 -> NOV 30 1 Y 2 DICIEMBRE 2024
A5: CALENDARIO OFICIAL
B6: PARTIDOS fecha 1 y 2 | L6: =+'GRUPO A'!P8 -> GRUPO A | M6: =+'GRUPO A'!Q8 -> Pts. | N6: =+'GRUPO A'!R8 -> PJ | O6: =+'GRUPO A'!S8 -> Gan. | P6: =+'GRUPO A'!T8 -> Emp. | Q6: =+'GRUPO A'!U8 -> Per. | R6: =+'GRUPO A'!V8 -> GF | S6: =+'GRUPO A'!W8 -> GC | ... U6: =+'GRUPO A'!Y8 -> Tj
B7: CANCHA | C7: HORA | D7: EQUIPO | E7: MARCADOR | G7: EQUIPO | H7: GRUPO | I7: CATEGORIA | L7: =+'GRUPO A'!P10 -> 1) ATHETIC MELGAR | M7: =+'GRUPO A'!Q10 -> 4 | N7: =+'GRUPO A'!R10 -> 3 | O7: =+'GRUPO A'!S10 -> 1 | P7: =+'GRUPO A'!T10 -> 1 | Q7: =+'GRUPO A'!U10 -> 1 | R7: =+'GRUPO A'!V10 -> 2 | S7: =+'GRUPO A'!W10 -> 2 | ... U7: =+'GRUPO A'!Y10 -> 0
A8: 45626 | B8: CASETABLA SINTETICO NO GUAYOS | C8: 0.36805556 | D8: =+'GRUPO A'!E20 -> GENERACION TOLIMA | E8: =+'GRUPO A'!G20 -> 0 | F8: =+'GRUPO A'!I20 -> 2 | G8: =+'GRUPO A'!K20 -> SAETA REDEC | H8: INTERGRUPO | I8: =+$A$3 -> NACIDOS 2016 2017 | L8: =+'GRUPO A'!P12 -> 2) GENERACION TOLIMA | M8: =+'GRUPO A'!Q12 -> 4 | N8: =+'GRUPO A'!R12 -> 3 | O8: =+'GRUPO A'!S12 -> 1 | P8: =+'GRUPO A'!T12 -> 1 | Q8: =+'GRUPO A'!U12 -> 1 | R8: =+'GRUPO A'!V12 -> 3 | S8: =+'GRUPO A'!W12 -> 4 | ... U8: =+'GRUPO A'!Y12 -> 0
A9: 45626 | B9: CASETABLA SINTETICO NO GUAYOS | C9: 0.41666667 | D9: =+'GRUPO A'!E26 -> CLUB ESTUDIANTES CK | E9: =+'GRUPO A'!G26 -> 0 | F9: =+'GRUPO A'!I26 -> 2 | G9: =+'GRUPO A'!K26 -> UNION TOLIMENSE | H9: INTERGRUPO | I9: =+$A$3 -> NACIDOS 2016 2017 | L9: =+'GRUPO A'!P14 -> 3) CLUB ESTUDIANTES CK | M9: =+'GRUPO A'!Q14 -> 0 | N9: =+'GRUPO A'!R14 -> 3 | O9: =+'GRUPO A'!S14 -> 0 | P9: =+'GRUPO A'!T14 -> 0 | Q9: =+'GRUPO A'!U14 -> 3 | R9: =+'GRUPO A'!V14 -> 1 | S9: =+'GRUPO A'!W14 -> 5 | ... U9: =+'GRUPO A'!Y14 -> 0
A10: 45626 | B10: CASETABLA SINTETICO NO GUAYOS | C10: 0.45833333 | D10: =+'GRUPO A'!E32 -> IVÁN VÉLEZ PROFESIONALES PALMIRA | E10: =+'GRUPO A'!G32 -> 1 | F10: =+'GRUPO A'!I32 -> 0 | G10: =+'GRUPO A'!K32 -> ATHETIC MELGAR | H10: INTERGRUPO | I10: =+$A$3 -> NACIDOS 2016 2017
A11: 45626 | B11: CASETABLA SINTETICO NO GUAYOS | C11: 0.54861111 | D11: =+'GRUPO C'!E26 -> CD INDEPENDIENTE | E11: =+'GRUPO C'!G26 -> 1 | F11: =+'GRUPO C'!I26 -> 3 | G11: =+'GRUPO C'!K26 -> ATHETIC CLUB MUNICIPAL | H11: GRUPO C | I11: =+$A$3 -> NACIDOS 2016 2017 | L11: =+'GRUPO B'!P6 -> GRUPO B | M11: =+'GRUPO B'!Q6 -> Pts. | N11: =+'GRUPO B'!R6 -> PJ | O11: =+'GRUPO B'!S6 -> Gan. | P11: =+'GRUPO B'!T6 -> Emp. | Q11: =+'GRUPO B'!U6 -> Per. | R11: =+'GRUPO B'!V6 -> GF | S11: =+'GRUPO B'!W6 -> GC | ... U11: =+'GRUPO B'!Y6 -> Tj
A12: 45626 | B12: CASETABLA SINTETICO NO GUAYOS | C12: 0.59027778 | D12: =+'GRUPO C'!E29 -> ATHLETIC SPORT | E12: =+'GRUPO C'!G29 -> 5 | F12: =+'GRUPO C'!I29 -> 1 | G12: =+'GRUPO C'!K29 -> ACADEMIA REAL | H12: GRUPO C | I12: =+$A$3 -> NACIDOS 2016 2017 | L12: =+'GRUPO B'!P8 -> 1) IVÁN VÉLEZ PROFESIONALES PALMIRA | M12: =+'GRUPO B'!Q8 -> 9 | N12: =+'GRUPO B'!R8 -> 3 | O12: =+'GRUPO B'!S8 -> 3 | P12: =+'GRUPO B'!T8 -> 0 | Q12: =+'GRUPO B'!U8 -> 0 | R12: =+'GRUPO B'!V8 -> 8 | S12: =+'GRUPO B'!W8 -> 0 | ... U12: =+'GRUPO B'!Y8 -> 0
A13: 45626 | B13: CASETABLA SINTETICO NO GUAYOS | C13: 0.63888889 | D13: =+'GRUPO B'!E29 -> UNION TOLIMENSE | E13: =+'GRUPO B'!G29 -> 1 | F13: =+'GRUPO B'!I29 -> 1 | G13: =+'GRUPO B'!K29 -> SAETA REDEC | H13: =+'GRUPO B'!B4 -> GRUPO B | I13: =+$A$3 -> NACIDOS 2016 2017 | L13: =+'GRUPO B'!P10 -> 2) SAETA REDEC | M13: =+'GRUPO B'!Q10 -> 4 | N13: =+'GRUPO B'!R10 -> 3 | O13: =+'GRUPO B'!S10 -> 1 | P13: =+'GRUPO B'!T10 -> 1 | Q13: =+'GRUPO B'!U10 -> 1 | R13: =+'GRUPO B'!V10 -> 3 | S13: =+'GRUPO B'!W10 -> 4 | ... U13: =+'GRUPO B'!Y10 -> 0
A14: 45626 | B14: CASETABLA SINTETICO NO GUAYOS | C14: 0.68055556 | D14: =+'GRUPO A'!E23 -> ATHETIC MELGAR | E14: =+'GRUPO A'!G23 -> 1 | F14: =+'GRUPO A'!I23 -> 1 | G14: =+'GRUPO A'!K23 -> GENERACION TOLIMA | H14: =+H25 -> GRUPO A | I14: =+$A$3 -> NACIDOS 2016 2017 | L14: =+'GRUPO B'!P12 -> 3) UNION TOLIMENSE | M14: =+'GRUPO B'!Q12 -> 4 | N14: =+'GRUPO B'!R12 -> 3 | O14: =+'GRUPO B'!S12 -> 1 | P14: =+'GRUPO B'!T12 -> 1 | Q14: =+'GRUPO B'!U12 -> 1 | R14: =+'GRUPO B'!V12 -> 3 | S14: =+'GRUPO B'!W12 -> 5 | ... U14: =+'GRUPO B'!Y12 -> 0
B16: PARTIDOS FECHA 2 y 3 | L16: =+'GRUPOS PRE JUVENIL'!I6 -> GRUPO C | M16: =+'GRUPO C'!Q8 -> Pts. | N16: =+'GRUPO C'!R8 -> PJ | O16: =+'GRUPO C'!S8 -> Gan. | P16: =+'GRUPO C'!T8 -> Emp. | Q16: =+'GRUPO C'!U8 -> Per. | R16: =+'GRUPO C'!V8 -> GF | S16: =+'GRUPO C'!W8 -> GC | T16: =+'GRUPO C'!X8 -> Dif. | U16: =+'GRUPO C'!Y8 -> Tj
B17: CANCHA | C17: HORA | D17: EQUIPO | E17: MARCADOR | G17: EQUIPO | H17: GRUPO | I17: CATEGORIA | L17: =+'GRUPO C'!P10 -> 1) ATHLETIC SPORT | M17: =+'GRUPO C'!Q10 -> 7 | N17: =+'GRUPO C'!R10 -> 3 | O17: =+'GRUPO C'!S10 -> 2 | P17: =+'GRUPO C'!T10 -> 1 | Q17: =+'GRUPO C'!U10 -> 0 | R17: =+'GRUPO C'!V10 -> 10 | S17: =+'GRUPO C'!W10 -> 1 | ... U17: =+'GRUPO C'!Y10 -> 0
A18: 45627 | B18: CASETABLA SINTETICO NO GUAYOS | C18: 0.33333333 | D18: =+'GRUPO C'!E23 -> ATHETIC CLUB MUNICIPAL | E18: =+'GRUPO C'!G23 -> 2 | F18: =+'GRUPO C'!I23 -> 0 | G18: =+'GRUPO C'!K23 -> ACADEMIA REAL | H18: GRUPO C | I18: =+$A$3 -> NACIDOS 2016 2017 | L18: =+'GRUPO C'!P12 -> 2) ATHETIC CLUB MUNICIPAL | M18: =+'GRUPO C'!Q12 -> 7 | N18: =+'GRUPO C'!R12 -> 3 | O18: =+'GRUPO C'!S12 -> 2 | P18: =+'GRUPO C'!T12 -> 1 | Q18: =+'GRUPO C'!U12 -> 0 | R18: =+'GRUPO C'!V12 -> 5 | S18: =+'GRUPO C'!W12 -> 1 | ... U18: =+'GRUPO C'!Y12 -> 0
A19: 45627 | B19: CASETABLA SINTETICO NO GUAYOS | C19: 0.375 | D19: =+'GRUPO C'!E20 -> CD INDEPENDIENTE | E19: =+'GRUPO C'!G20 -> 0 | F19: =+'GRUPO C'!I20 -> 5 | G19: =+'GRUPO C'!K20 -> ATHLETIC SPORT | H19: GRUPO C | I19: =+$A$3 -> NACIDOS 2016 2017 | L19: =+'GRUPO C'!P14 -> 3) ACADEMIA REAL | M19: =+'GRUPO C'!Q14 -> 1 | N19: =+'GRUPO C'!R14 -> 3 | O19: =+'GRUPO C'!S14 -> 0 | P19: =+'GRUPO C'!T14 -> 1 | Q19: =+'GRUPO C'!U14 -> 2 | R19: =+'GRUPO C'!V14 -> 3 | S19: =+'GRUPO C'!W14 -> 9 | ... U19: =+'GRUPO C'!Y14 -> 0
A20: 45627 | B20: CASETABLA SINTETICO NO GUAYOS | C20: 0.42361111 | D20: =+'GRUPO B'!E17 -> IVÁN VÉLEZ PROFESIONALES PALMIRA | E20: =+'GRUPO B'!G17 -> 4 | F20: =+'GRUPO B'!I17 -> 0 | G20: =+'GRUPO B'!K17 -> UNION TOLIMENSE | H20: =+'GRUPO B'!B4 -> GRUPO B | I20: =+$A$3 -> NACIDOS 2016 2017 | L20: =+'GRUPO C'!P16 -> 4) CD INDEPENDIENTE | M20: =+'GRUPO C'!Q16 -> 1 | N20: =+'GRUPO C'!R16 -> 3 | O20: =+'GRUPO C'!S16 -> 0 | P20: =+'GRUPO C'!T16 -> 1 | Q20: =+'GRUPO C'!U16 -> 2 | R20: =+'GRUPO C'!V16 -> 3 | S20: =+'GRUPO C'!W16 -> 10 | ... U20: =+'GRUPO C'!Y16 -> 0
A21: 45627 | B21: CASETABLA SINTETICO NO GUAYOS | C21: 0.46527778 | D21: =+'GRUPO A'!E29 -> GENERACION TOLIMA | E21: =+'GRUPO A'!G29 -> 2 | F21: =+'GRUPO A'!I29 -> 1 | G21: =+'GRUPO A'!K29 -> CLUB ESTUDIANTES CK | H21: =+'GRUPO A'!B4 -> GRUPO A | I21: =+$A$3 -> NACIDOS 2016 2017
A22: 45627 | B22: CASETABLA SINTETICO NO GUAYOS | C22: 0.54861111 | D22: =+'GRUPO C'!E35 -> CD INDEPENDIENTE | E22: =+'GRUPO C'!G35 -> 2 | F22: =+'GRUPO C'!I35 -> 2 | G22: =+'GRUPO C'!K35 -> ACADEMIA REAL | H22: GRUPO C | I22: =+$A$3 -> NACIDOS 2016 2017 | K22: RECLASIFICACIÒN | AA22: 44423 | AB22: CANCHA 1 | AC22: 0.35069444 | AD22: =+'GRUPO A'!E8 -> ATHETIC MELGAR | AE22: =+'GRUPO A'!G8 -> 0 | AF22: =+'GRUPO A'!I8 -> 0 | AG22: =+'GRUPO A'!K8 -> UNION TOLIMENSE | AH22: INTERGRUPO | AI22: =+$A$4 -> NOV 30 1 Y 2 DICIEMBRE 2024
A23: 45627 | B23: CASETABLA SINTETICO NO GUAYOS | C23: 0.59722222 | D23: =+'GRUPO C'!E32 -> ATHLETIC SPORT | E23: =+'GRUPO C'!G32 -> 0 | F23: =+'GRUPO C'!I32 -> 0 | G23: =+'GRUPO C'!K32 -> ATHETIC CLUB MUNICIPAL | H23: GRUPO C | I23: =+$A$3 -> NACIDOS 2016 2017 | K23: LUGAR | L23: EQUIPO | M23: Pts | N23: PJ | O23: Gan | P23: Emp | Q23: Per | R23: GF | S23: GC | T23: Dif | U23: Tj | AA23: 44423 | AB23: CANCHA 1 | AC23: 0.40972222 | AD23: =+'GRUPO A'!E11 -> CLUB ESTUDIANTES CK | AE23: =+'GRUPO A'!G11 -> 0 | AF23: =+'GRUPO A'!I11 -> 0 | AG23: =+'GRUPO A'!K11 -> SAETA REDEC | AH23: INTERGRUPO | AI23: =+$A$4 -> NOV 30 1 Y 2 DICIEMBRE 2024
A24: 45627 | B24: CASETABLA SINTETICO NO GUAYOS | C24: 0.64583333 | D24: =+'GRUPO B'!E23 -> IVÁN VÉLEZ PROFESIONALES PALMIRA | E24: =+'GRUPO B'!G23 -> 3 | F24: =+'GRUPO B'!I23 -> 0 | G24: =+'GRUPO B'!K23 -> SAETA REDEC | H24: =+H20 -> GRUPO B | I24: =+$A$3 -> NACIDOS 2016 2017 | K24: 1 | L24: ='GRUPO B'!P8 -> 1) IVÁN VÉLEZ PROFESIONALES PALMIRA | M24: ='GRUPO B'!Q8 -> 9 | N24: ='GRUPO B'!R8 -> 3 | O24: ='GRUPO B'!S8 -> 3 | P24: ='GRUPO B'!T8 -> 0 | Q24: ='GRUPO B'!U8 -> 0 | R24: ='GRUPO B'!V8 -> 8 | S24: ='GRUPO B'!W8 -> 0 | ... U24: ='GRUPO B'!Y8 -> 0 | AA24: 44423 | AB24: CANCHA 1 | AC24: 0.45486111 | AD24: =+'GRUPO A'!E14 -> GENERACION TOLIMA | AE24: =+'GRUPO A'!G14 -> 0 | AF24: =+'GRUPO A'!I14 -> 0 | AG24: =+'GRUPO A'!K14 -> IVÁN VÉLEZ PROFESIONALES PALMIRA | AH24: INTERGRUPO | AI24: =+$A$4 -> NOV 30 1 Y 2 DICIEMBRE 2024
A25: 45627 | B25: CASETABLA SINTETICO NO GUAYOS | C25: 0.69444444 | D25: =+'GRUPO A'!E17 -> ATHETIC MELGAR | E25: =+'GRUPO A'!G17 -> 1 | F25: =+'GRUPO A'!I17 -> 0 | G25: =+'GRUPO A'!K17 -> CLUB ESTUDIANTES CK | H25: =+'GRUPO A'!B4 -> GRUPO A | I25: =+$A$3 -> NACIDOS 2016 2017 | K25: 2 | L25: ='GRUPO C'!P10 -> 1) ATHLETIC SPORT | M25: ='GRUPO C'!Q10 -> 7 | N25: ='GRUPO C'!R10 -> 3 | O25: ='GRUPO C'!S10 -> 2 | P25: ='GRUPO C'!T10 -> 1 | Q25: ='GRUPO C'!U10 -> 0 | R25: ='GRUPO C'!V10 -> 10 | S25: ='GRUPO C'!W10 -> 1 | ... U25: ='GRUPO C'!Y10 -> 0
K26: 3 | L26: ='GRUPO A'!P10 -> 1) ATHETIC MELGAR | M26: ='GRUPO A'!Q10 -> 4 | N26: ='GRUPO A'!R10 -> 3 | O26: ='GRUPO A'!S10 -> 1 | P26: ='GRUPO A'!T10 -> 1 | Q26: ='GRUPO A'!U10 -> 1 | R26: ='GRUPO A'!V10 -> 2 | S26: ='GRUPO A'!W10 -> 2 | ... U26: ='GRUPO A'!Y10 -> 0
B27: SEMIFINAL | K27: 4 | L27: ='GRUPO C'!P12 -> 2) ATHETIC CLUB MUNICIPAL | M27: ='GRUPO C'!Q12 -> 7 | N27: ='GRUPO C'!R12 -> 3 | O27: ='GRUPO C'!S12 -> 2 | P27: ='GRUPO C'!T12 -> 1 | Q27: ='GRUPO C'!U12 -> 0 | R27: ='GRUPO C'!V12 -> 5 | S27: ='GRUPO C'!W12 -> 1 | ... U27: ='GRUPO C'!Y12 -> 0
B28: CANCHA | C28: HORA | D28: EQUIPO | E28: MARCADOR | G28: EQUIPO | H28: GRUPO | I28: CATEGORÍA | K28: 5 | L28: ='GRUPO A'!P12 -> 2) GENERACION TOLIMA | M28: ='GRUPO A'!Q12 -> 4 | N28: ='GRUPO A'!R12 -> 3 | O28: ='GRUPO A'!S12 -> 1 | P28: ='GRUPO A'!T12 -> 1 | Q28: ='GRUPO A'!U12 -> 1 | R28: ='GRUPO A'!V12 -> 3 | S28: ='GRUPO A'!W12 -> 4 | ... U28: ='GRUPO A'!Y12 -> 0
A29: 45628 | B29: CASETABLA SINTETICO NO GUAYOS | C29: 0.3125 | D29: PRIMERO GRUPO A | E29: 0 | F29: 0 | G29: PRIMERO GRUPO C | H29: SEMIFINAL COPA ORO LLAVE A | I29: =+$A$3 -> NACIDOS 2016 2017 | K29: 6 | L29: ='GRUPO B'!P10 -> 2) SAETA REDEC | M29: ='GRUPO B'!Q10 -> 4 | N29: ='GRUPO B'!R10 -> 3 | O29: ='GRUPO B'!S10 -> 1 | P29: ='GRUPO B'!T10 -> 1 | Q29: ='GRUPO B'!U10 -> 1 | R29: ='GRUPO B'!V10 -> 3 | S29: ='GRUPO B'!W10 -> 4 | ... U29: ='GRUPO B'!Y10 -> 0
A30: 45628 | B30: CASETABLA SINTETICO NO GUAYOS | C30: 0.36111111 | D30: PRIMERO GRUPO B | E30: 0 | F30: 0 | G30: CUARTO TABLA RECLASIFICACION | H30: SEMIFINAL COPA ORO LLAVE B | I30: =+$A$3 -> NACIDOS 2016 2017 | K30: 7 | L30: ='GRUPO B'!P12 -> 3) UNION TOLIMENSE | M30: ='GRUPO B'!Q12 -> 4 | N30: ='GRUPO B'!R12 -> 3 | O30: ='GRUPO B'!S12 -> 1 | P30: ='GRUPO B'!T12 -> 1 | Q30: ='GRUPO B'!U12 -> 1 | R30: ='GRUPO B'!V12 -> 3 | S30: ='GRUPO B'!W12 -> 5 | ... U30: ='GRUPO B'!Y12 -> 0
A31: 45628 | B31: CASETABLA SINTETICO NO GUAYOS | C31: 0.40972222 | D31: QUINTO TABLA RECLASIFICACIÒN | E31: 0 | F31: 0 | G31: SEXTO TABLA RECLASIFICACIÒN | H31: FINAL COPA PLATA | I31: =+$A$3 -> NACIDOS 2016 2017 | K31: 8 | L31: ='GRUPO C'!P14 -> 3) ACADEMIA REAL | M31: ='GRUPO C'!Q14 -> 1 | N31: ='GRUPO C'!R14 -> 3 | O31: ='GRUPO C'!S14 -> 0 | P31: ='GRUPO C'!T14 -> 1 | Q31: ='GRUPO C'!U14 -> 2 | R31: ='GRUPO C'!V14 -> 3 | S31: ='GRUPO C'!W14 -> 9 | ... U31: ='GRUPO C'!Y14 -> 0
A32: 45628 | B32: CASETABLA SINTETICO NO GUAYOS | C32: 0.45486111 | D32: SEPTIMO TABLA RECLASIFICACIÒN | E32: 0 | F32: 0 | G32: OCTAVO TABLA RECLASIFICACIÒN | H32: TERCER LUGAR COPA PLATA | I32: =+$A$3 -> NACIDOS 2016 2017 | K32: 9 | L32: ='GRUPO C'!P16 -> 4) CD INDEPENDIENTE | M32: ='GRUPO C'!Q16 -> 1 | N32: ='GRUPO C'!R16 -> 3 | O32: ='GRUPO C'!S16 -> 0 | P32: ='GRUPO C'!T16 -> 1 | Q32: ='GRUPO C'!U16 -> 2 | R32: ='GRUPO C'!V16 -> 3 | S32: ='GRUPO C'!W16 -> 10 | ... U32: ='GRUPO C'!Y16 -> 0
A33: 45628 | B33: CASETABLA SINTETICO NO GUAYOS | C33: 0.50694444 | D33: NOVENO TABLA RECLASIFICACIÒN | E33: 0 | F33: 0 | G33: DECIMO TABLA RECLASIFICACIÒN | H33: FINAL COPA BRONCE | I33: =+$A$3 -> NACIDOS 2016 2017 | K33: 10 | L33: ='GRUPO A'!P14 -> 3) CLUB ESTUDIANTES CK | M33: ='GRUPO A'!Q14 -> 0 | N33: ='GRUPO A'!R14 -> 3 | O33: ='GRUPO A'!S14 -> 0 | P33: ='GRUPO A'!T14 -> 0 | Q33: ='GRUPO A'!U14 -> 3 | R33: ='GRUPO A'!V14 -> 1 | S33: ='GRUPO A'!W14 -> 5 | ... U33: ='GRUPO A'!Y14 -> 0
B35: FINAL
B36: CANCHA | C36: HORA | D36: EQUIPO | E36: MARCADOR | G36: EQUIPO | H36: GRUPO | I36: CATEGORÍA
A37: 45628 | B37: CASETABLA SINTETICO NO GUAYOS | C37: 0.5625 | D37: PERDEDOR LLAVE A | E37: =+'[2]GRUPO A'!G56 -> 0 | F37: =+'[2]GRUPO A'!I56 -> 0 | G37: PERDEDOR LLAVE B | H37: TERCER LUGAR COPA ORO | I37: =+$A$3 -> NACIDOS 2016 2017
A38: 45628 | B38: CASETABLA SINTETICO NO GUAYOS | C38: 0.60763889 | D38: GANADOR LLAVE A | E38: =+'[2]GRUPO A'!G53 -> 0 | F38: =+'[2]GRUPO A'!I53 -> 0 | G38: GANADOR LLAVE B | H38: FINAL COPA ORO | I38: =+$A$3 -> NACIDOS 2016 2017
C43: juzgamiento | D43: =22*100000 -> 2200000
C44: luz estadio | D44: =9*120000 -> 1080000
C45: logistica personal | D45: =3*160000 -> 480000
C46: alimentacion logistica | D46: =12*36000 -> 432000
...

Sheet IMPRIMIR (A-B) 1-2
A1: =+'GRUPOS PRE JUVENIL'!B1:L1 -> #VALUE!
A2: “COPA FUTURO TALENTO”
D3: =+'GRUPOS PRE JUVENIL'!C6 -> 0
D4: =+'GRUPOS PRE JUVENIL'!C7 -> 0
D5: =+'GRUPOS PRE JUVENIL'!C8 -> 0
D6: =+'GRUPOS PRE JUVENIL'!C9 -> 0
D7: =+'GRUPOS PRE JUVENIL'!C10 -> 0
D8: =+'GRUPOS PRE JUVENIL'!C11 -> 0
B10: =+'GRUPOS PRE JUVENIL'!D3 -> NACIDOS 2016 2017
B11: =+'GRUPOS PRE JUVENIL'!D4 -> NOV 30 1 Y 2 DICIEMBRE 2024
A12: =+#REF! -> #REF!
A14: PARTIDOS fecha 1- fecha 2
P15: º
A16: =+#REF! -> #REF! | B16: =+#REF! -> #REF! | C16: =+#REF! -> #REF! | E16: =IF(AND(F16<>"",H16<>""),IF(F16=H16,"E",IF(F16>H16,"G","P")),"") -> #REF! | F16: 1 | G16: - | H16: =+#REF! -> #REF! | I16: =IF(AND(H16<>"",F16<>""),IF(H16=F16,"E",IF(H16>F16,"G","P")),"") -> #REF! | J16: =+#REF! -> #REF! | M16: =+#REF! -> #REF!
A19: =+#REF! -> #REF! | B19: =+#REF! -> #REF! | C19: =+#REF! -> #REF! | E19: =IF(AND(F19<>"",H19<>""),IF(F19=H19,"E",IF(F19>H19,"G","P")),"") -> #REF! | F19: =+#REF! -> #REF! | G19: - | H19: =+#REF! -> #REF! | I19: =IF(AND(H19<>"",F19<>""),IF(H19=F19,"E",IF(H19>F19,"G","P")),"") -> #REF! | J19: =+#REF! -> #REF! | M19: =+#REF! -> #REF!
A21: =+#REF! -> #REF! | B21: =+#REF! -> #REF! | C21: =+#REF! -> #REF! | E21: =IF(AND(F21<>"",H21<>""),IF(F21=H21,"E",IF(F21>H21,"G","P")),"") -> E | F21: 0 | G21: - | H21: 0 | I21: =IF(AND(H21<>"",F21<>""),IF(H21=F21,"E",IF(H21>F21,"G","P")),"") -> E | J21: =+#REF! -> #REF! | M21: =+#REF! -> #REF!
A23: =+#REF! -> #REF! | B23: =+#REF! -> #REF! | C23: =+#REF! -> #REF! | E23: =IF(AND(F23<>"",H23<>""),IF(F23=H23,"E",IF(F23>H23,"G","P")),"") -> #REF! | F23: =+#REF! -> #REF! | G23: - | H23: =+#REF! -> #REF! | I23: =IF(AND(H23<>"",F23<>""),IF(H23=F23,"E",IF(H23>F23,"G","P")),"") -> #REF! | J23: =+#REF! -> #REF! | M23: =+#REF! -> #REF!
A25: =+#REF! -> #REF! | B25: =+#REF! -> #REF! | C25: =+#REF! -> #REF! | E25: =IF(AND(F25<>"",H25<>""),IF(F25=H25,"E",IF(F25>H25,"G","P")),"") -> #REF! | F25: =+#REF! -> #REF! | G25: - | H25: =+#REF! -> #REF! | I25: =IF(AND(H25<>"",F25<>""),IF(H25=F25,"E",IF(H25>F25,"G","P")),"") -> #REF! | J25: =+#REF! -> #REF! | M25: =+#REF! -> #REF!
D28: =+'GRUPOS PRE JUVENIL'!E6 -> GRUPO A
D29: =+'GRUPOS PRE JUVENIL'!E7 -> ATHETIC MELGAR
D30: =+'GRUPOS PRE JUVENIL'!E8 -> CLUB ESTUDIANTES CK
D31: =+'GRUPOS PRE JUVENIL'!E9 -> GENERACION TOLIMA
D32: =+'GRUPOS PRE JUVENIL'!#REF! -> #REF!
D33: =+'GRUPOS PRE JUVENIL'!#REF! -> #REF!
A35: =+'GRUPOS PRE JUVENIL'!E6 -> GRUPO A
A37: PARTIDOS fecha 1- fecha 2
A39: =+'GRUPO A'!B14 -> 0 | B39: =+#REF! -> #REF! | C39: =+'GRUPO A'!E14 -> GENERACION TOLIMA | E39: =IF(AND(F39<>"",H39<>""),IF(F39=H39,"E",IF(F39>H39,"G","P")),"") -> E | F39: =+'GRUPO A'!G14 -> 0 | G39: - | H39: =+'GRUPO A'!I14 -> 0 | I39: =IF(AND(H39<>"",F39<>""),IF(H39=F39,"E",IF(H39>F39,"G","P")),"") -> E | J39: =+'GRUPO A'!K14 -> IVÁN VÉLEZ PROFESIONALES PALMIRA | M39: =+'GRUPO A'!M14 -> 0
A41: =+'GRUPO A'!B8 -> 0 | B41: =+'GRUPO A'!C8 -> 0 | C41: =+'GRUPO A'!E8 -> ATHETIC MELGAR | E41: =IF(AND(F41<>"",H41<>""),IF(F41=H41,"E",IF(F41>H41,"G","P")),"") -> E | F41: =+'GRUPO A'!G8 -> 0 | G41: - | H41: =+'GRUPO A'!I8 -> 0 | I41: =IF(AND(H41<>"",F41<>""),IF(H41=F41,"E",IF(H41>F41,"G","P")),"") -> E | J41: =+'GRUPO A'!K8 -> UNION TOLIMENSE | M41: =+'GRUPO A'!M8 -> 0
A43: =+'GRUPO A'!B11 -> 0 | B43: =+'GRUPO A'!C11 -> 0 | C43: =+'GRUPO A'!E11 -> CLUB ESTUDIANTES CK | E43: =IF(AND(F43<>"",H43<>""),IF(F43=H43,"E",IF(F43>H43,"G","P")),"") -> E | F43: =+'GRUPO A'!G11 -> 0 | G43: - | H43: =+'GRUPO A'!I11 -> 0 | I43: =IF(AND(H43<>"",F43<>""),IF(H43=F43,"E",IF(H43>F43,"G","P")),"") -> E | J43: =+'GRUPO A'!K11 -> SAETA REDEC | M43: =+'GRUPO A'!M11 -> 0
A45: =+'GRUPO A'!B17 -> 42813 | B45: =+'GRUPO A'!C20 -> 08:40. a.m. | C45: =+'GRUPO A'!E20 -> GENERACION TOLIMA | E45: =IF(AND(F45<>"",H45<>""),IF(F45=H45,"E",IF(F45>H45,"G","P")),"") -> P | F45: =+'GRUPO A'!G20 -> 0 | G45: - | H45: =+'GRUPO A'!I20 -> 2 | I45: =IF(AND(H45<>"",F45<>""),IF(H45=F45,"E",IF(H45>F45,"G","P")),"") -> G | J45: =+'GRUPO A'!K20 -> SAETA REDEC | M45: =+'GRUPO A'!M20 -> CANCHA 1 A
A47: =+'GRUPO A'!B26 -> 42812 | B47: =+'GRUPO A'!C26 -> 07:00. a.m. | C47: =+'GRUPO A'!E17 -> ATHETIC MELGAR | E47: =IF(AND(F47<>"",H47<>""),IF(F47=H47,"E",IF(F47>H47,"G","P")),"") -> G | F47: =+'GRUPO A'!G17 -> 1 | G47: - | H47: =+'GRUPO A'!I17 -> 0 | I47: =IF(AND(H47<>"",F47<>""),IF(H47=F47,"E",IF(H47>F47,"G","P")),"") -> P | J47: =+'GRUPO A'!K17 -> CLUB ESTUDIANTES CK | M47: =+'GRUPO A'!M17 -> CANCHA 1 A
A49: NOTA: LA ORGANIZACIÓN DEL TORNEO NO SE HACE RESPONSABLE DE ACCIDENTES O PERDIDA DE ELEMENTOS DURANTE EL TRANSCURSO DEL TORNEO. Les recordamos traer el seguro de salud de los deportistas. Tarjeta de identidad Original, Registro Civil.
A54: Sede Administrativa Cra 13 No 6-43 Barrio La Florida
A55: Celular 310 241 33 76 Fijo 2 450 593
A56: soccermelgar@outlook.com
A57: Melgar - Tolima

Sheet IMPRIMIR (C-D) 1-2.
A1: =+'IMPRIMIR (A-B) 1-2'!A1:M1 -> #VALUE!
A2: “COPA FUTURO TALENTO”
D3: =+'GRUPOS PRE JUVENIL'!G6 -> GRUPO B
D4: =+'GRUPOS PRE JUVENIL'!G7 -> IVÁN VÉLEZ PROFESIONALES PALMIRA
D5: =+'GRUPOS PRE JUVENIL'!G8 -> UNION TOLIMENSE
D6: =+'GRUPOS PRE JUVENIL'!G9 -> SAETA REDEC
D7: =+'GRUPOS PRE JUVENIL'!I10 -> ACADEMIA REAL
D8: =+'GRUPOS PRE JUVENIL'!I11 -> 0
B10: =+'GRUPOS PRE JUVENIL'!D3 -> NACIDOS 2016 2017
B11: =+'GRUPOS PRE JUVENIL'!D4 -> NOV 30 1 Y 2 DICIEMBRE 2024
A12: =+'GRUPOS PRE JUVENIL'!G6 -> GRUPO B
A14: PARTIDOS fecha 1- fecha 2
A16: =+'GRUPO B'!B8 -> 0 | B16: =+'GRUPO B'!C8 -> 0 | C16: =+'GRUPO B'!E8 -> ATHETIC MELGAR | E16: =IF(AND(F16<>"",H16<>""),IF(F16=H16,"E",IF(F16>H16,"G","P")),"") -> E | F16: =+'GRUPO B'!G8 -> 0 | G16: - | H16: =+'GRUPO B'!I8 -> 0 | I16: =IF(AND(H16<>"",F16<>""),IF(H16=F16,"E",IF(H16>F16,"G","P")),"") -> E | J16: =+'GRUPO B'!K8 -> UNION TOLIMENSE | M16: =+'GRUPO B'!M8 -> 0
A19: =+'GRUPO B'!B11 -> 0 | B19: =+'GRUPO B'!C11 -> 0 | C19: =+'GRUPO B'!E11 -> CLUB ESTUDIANTES CK | E19: =IF(AND(F19<>"",H19<>""),IF(F19=H19,"E",IF(F19>H19,"G","P")),"") -> E | F19: =+'GRUPO B'!G11 -> 0 | G19: - | H19: =+'GRUPO B'!I11 -> 0 | I19: =IF(AND(H19<>"",F19<>""),IF(H19=F19,"E",IF(H19>F19,"G","P")),"") -> E | J19: =+'GRUPO B'!K11 -> SAETA REDEC | M19: =+'GRUPO B'!M11 -> 0
A21: =+'GRUPO B'!B14 -> 0 | B21: =+'GRUPO B'!C14 -> 0 | C21: =+'GRUPO B'!E14 -> GENERACION TOLIMA | E21: =IF(AND(F21<>"",H21<>""),IF(F21=H21,"E",IF(F21>H21,"G","P")),"") -> E | F21: =+'GRUPO B'!G14 -> 0 | G21: - | H21: =+'GRUPO B'!I14 -> 0 | I21: =IF(AND(H21<>"",F21<>""),IF(H21=F21,"E",IF(H21>F21,"G","P")),"") -> E | J21: =+'GRUPO B'!K14 -> IVÁN VÉLEZ PROFESIONALES PALMIRA | M21: =+'GRUPO B'!M14 -> 0
A23: =+'GRUPO B'!B17 -> 42813 | B23: =+'GRUPO B'!C17 -> 01:20. p.m. | C23: =+'GRUPO B'!E17 -> IVÁN VÉLEZ PROFESIONALES PALMIRA | E23: =IF(AND(F23<>"",H23<>""),IF(F23=H23,"E",IF(F23>H23,"G","P")),"") -> G | F23: =+'GRUPO B'!G17 -> 4 | G23: - | H23: =+'GRUPO B'!I17 -> 0 | I23: =IF(AND(H23<>"",F23<>""),IF(H23=F23,"E",IF(H23>F23,"G","P")),"") -> P | J23: =+'GRUPO B'!K17 -> UNION TOLIMENSE | M23: =+'GRUPO B'!M17 -> CANCHA 1 C
A25: =+'GRUPO B'!B20 -> 42813 | B25: =+'GRUPO B'!C20 -> 08:40. a.m. | C25: =+'GRUPO B'!E20 -> GENERACION TOLIMA | E25: =IF(AND(F25<>"",H25<>""),IF(F25=H25,"E",IF(F25>H25,"G","P")),"") -> P | F25: =+'GRUPO B'!G20 -> 0 | G25: - | H25: =+'GRUPO B'!I20 -> 2 | I25: =IF(AND(H25<>"",F25<>""),IF(H25=F25,"E",IF(H25>F25,"G","P")),"") -> G | J25: =+'GRUPO B'!K20 -> SAETA REDEC | M25: =+'GRUPO B'!M20 -> CANCHA 1 A
D28: =+'GRUPOS PRE JUVENIL'!K6 -> 0
D29: =+'GRUPOS PRE JUVENIL'!K7 -> 0
D30: =+'GRUPOS PRE JUVENIL'!K8 -> 0
D31: =+'GRUPOS PRE JUVENIL'!#REF! -> #REF!
D32: =+'GRUPOS PRE JUVENIL'!K10 -> 0
D33: =+'GRUPOS PRE JUVENIL'!K11 -> 0
A35: =+'GRUPOS PRE JUVENIL'!K6 -> 0
A37: PARTIDOS fecha 1- fecha 2
A39: =+#REF! -> #REF! | B39: =+#REF! -> #REF! | C39: =+#REF! -> #REF! | E39: =IF(AND(F39<>"",H39<>""),IF(F39=H39,"E",IF(F39>H39,"G","P")),"") -> #REF! | F39: =+#REF! -> #REF! | G39: - | H39: =+#REF! -> #REF! | I39: =IF(AND(H39<>"",F39<>""),IF(H39=F39,"E",IF(H39>F39,"G","P")),"") -> #REF! | J39: =+#REF! -> #REF! | M39: =+#REF! -> #REF!
A42: =+#REF! -> #REF! | B42: =+#REF! -> #REF! | C42: =+#REF! -> #REF! | E42: =IF(AND(F42<>"",H42<>""),IF(F42=H42,"E",IF(F42>H42,"G","P")),"") -> #REF! | F42: =+#REF! -> #REF! | G42: - | H42: =+#REF! -> #REF! | I42: =IF(AND(H42<>"",F42<>""),IF(H42=F42,"E",IF(H42>F42,"G","P")),"") -> #REF! | J42: =+#REF! -> #REF! | M42: =+#REF! -> #REF!
A44: =+#REF! -> #REF! | B44: =+#REF! -> #REF! | C44: =+#REF! -> #REF! | E44: =IF(AND(F44<>"",H44<>""),IF(F44=H44,"E",IF(F44>H44,"G","P")),"") -> #REF! | F44: =+#REF! -> #REF! | G44: - | H44: =+#REF! -> #REF! | I44: =IF(AND(H44<>"",F44<>""),IF(H44=F44,"E",IF(H44>F44,"G","P")),"") -> #REF! | J44: =+#REF! -> #REF! | M44: =+#REF! -> #REF!
A46: =+#REF! -> #REF! | B46: =+#REF! -> #REF! | C46: =+#REF! -> #REF! | E46: =IF(AND(F46<>"",H46<>""),IF(F46=H46,"E",IF(F46>H46,"G","P")),"") -> #REF! | F46: =+#REF! -> #REF! | G46: - | H46: =+#REF! -> #REF! | I46: =IF(AND(H46<>"",F46<>""),IF(H46=F46,"E",IF(H46>F46,"G","P")),"") -> #REF! | J46: =+#REF! -> #REF! | M46: =+#REF! -> #REF!
A48: =+#REF! -> #REF! | B48: =+#REF! -> #REF! | C48: =+#REF! -> #REF! | E48: =IF(AND(F48<>"",H48<>""),IF(F48=H48,"E",IF(F48>H48,"G","P")),"") -> #REF! | F48: =+#REF! -> #REF! | G48: - | H48: =+#REF! -> #REF! | I48: =IF(AND(H48<>"",F48<>""),IF(H48=F48,"E",IF(H48>F48,"G","P")),"") -> #REF! | J48: =+#REF! -> #REF! | M48: =+#REF! -> #REF!
A50: NOTA: LA ORGANIZACIÓN DEL TORNEO NO SE HACE RESPONSABLE DE ACCIDENTES O PERDIDA DE ELEMENTOS DURANTE EL TRANSCURSO DEL TORNEO. Les recordamos traer el seguro de salud de los deportistas. Tarjeta de identidad Original, Registro Civil.
A55: Sede Administrativa Cra 13 No 6-43 Barrio La Florida
A56: Celular 310 241 33 76 Fijo 2 450 593
A57: soccermelgar@outlook.com
A58: Melgar - Tolima

Sheet IMPRIMIR (A-B) 3-4
A1: =+'IMPRIMIR (A-B) 1-2'!A1:M1 -> #VALUE!
A2: “COPA FUTURO TALENTO”
D3: =+'GRUPOS PRE JUVENIL'!C6 -> 0
D4: =+'GRUPOS PRE JUVENIL'!C7 -> 0
D5: =+'GRUPOS PRE JUVENIL'!C8 -> 0
D6: =+'GRUPOS PRE JUVENIL'!C9 -> 0
D7: =+'GRUPOS PRE JUVENIL'!C10 -> 0
D8: =+'GRUPOS PRE JUVENIL'!C11 -> 0
B10: =+'GRUPOS PRE JUVENIL'!D3 -> NACIDOS 2016 2017
B11: =+'GRUPOS PRE JUVENIL'!D4 -> NOV 30 1 Y 2 DICIEMBRE 2024
A12: =+'GRUPOS PRE JUVENIL'!C6 -> 0
A14: PARTIDOS fecha 3- fecha 4
A16: =+#REF! -> #REF! | B16: =+#REF! -> #REF! | C16: =+#REF! -> #REF! | E16: =IF(AND(F16<>"",H16<>""),IF(F16=H16,"E",IF(F16>H16,"G","P")),"") -> #REF! | F16: =+#REF! -> #REF! | G16: - | H16: =+#REF! -> #REF! | I16: =IF(AND(H16<>"",F16<>""),IF(H16=F16,"E",IF(H16>F16,"G","P")),"") -> #REF! | J16: =+#REF! -> #REF! | M16: =+#REF! -> #REF!
A19: =+#REF! -> #REF! | B19: =+#REF! -> #REF! | C19: =+#REF! -> #REF! | E19: =IF(AND(F19<>"",H19<>""),IF(F19=H19,"E",IF(F19>H19,"G","P")),"") -> #REF! | F19: =+#REF! -> #REF! | G19: - | H19: =+#REF! -> #REF! | I19: =IF(AND(H19<>"",F19<>""),IF(H19=F19,"E",IF(H19>F19,"G","P")),"") -> #REF! | J19: =+#REF! -> #REF! | M19: =+#REF! -> #REF!
A21: =+#REF! -> #REF! | B21: =+#REF! -> #REF! | C21: =+#REF! -> #REF! | E21: =IF(AND(F21<>"",H21<>""),IF(F21=H21,"E",IF(F21>H21,"G","P")),"") -> #REF! | F21: =+#REF! -> #REF! | G21: - | H21: =+#REF! -> #REF! | I21: =IF(AND(H21<>"",F21<>""),IF(H21=F21,"E",IF(H21>F21,"G","P")),"") -> #REF! | J21: =+#REF! -> #REF! | M21: =+#REF! -> #REF!
A23: =+#REF! -> #REF! | B23: =+#REF! -> #REF! | C23: =+#REF! -> #REF! | E23: =IF(AND(F23<>"",H23<>""),IF(F23=H23,"E",IF(F23>H23,"G","P")),"") -> #REF! | F23: =+#REF! -> #REF! | G23: - | H23: =+#REF! -> #REF! | I23: =IF(AND(H23<>"",F23<>""),IF(H23=F23,"E",IF(H23>F23,"G","P")),"") -> #REF! | J23: =+#REF! -> #REF! | M23: =+#REF! -> #REF!
A25: =+#REF! -> #REF! | B25: =+#REF! -> #REF! | C25: =+#REF! -> #REF! | E25: =IF(AND(F25<>"",H25<>""),IF(F25=H25,"E",IF(F25>H25,"G","P")),"") -> #REF! | F25: =+#REF! -> #REF! | G25: - | H25: =+#REF! -> #REF! | I25: =IF(AND(H25<>"",F25<>""),IF(H25=F25,"E",IF(H25>F25,"G","P")),"") -> #REF! | J25: =+#REF! -> #REF! | M25: =+#REF! -> #REF!
D28: =+'GRUPOS PRE JUVENIL'!E6 -> GRUPO A
D29: =+'GRUPOS PRE JUVENIL'!E7 -> ATHETIC MELGAR
D30: =+'GRUPOS PRE JUVENIL'!E8 -> CLUB ESTUDIANTES CK
D31: =+'GRUPOS PRE JUVENIL'!E9 -> GENERACION TOLIMA
D32: =+'GRUPOS PRE JUVENIL'!#REF! -> #REF!
D33: =+'GRUPOS PRE JUVENIL'!#REF! -> #REF!
A36: =+'GRUPOS PRE JUVENIL'!E6 -> GRUPO A
A38: PARTIDOS fecha 3- fecha 4
A40: =+'GRUPO A'!B26 -> 42812 | B40: =+'GRUPO A'!C26 -> 07:00. a.m. | C40: =+'GRUPO A'!E26 -> CLUB ESTUDIANTES CK | E40: =IF(AND(F40<>"",H40<>""),IF(F40=H40,"E",IF(F40>H40,"G","P")),"") -> P | F40: =+'GRUPO A'!G26 -> 0 | G40: - | H40: =+'GRUPO A'!I26 -> 2 | I40: =IF(AND(H40<>"",F40<>""),IF(H40=F40,"E",IF(H40>F40,"G","P")),"") -> G | J40: =+'GRUPO A'!K26 -> UNION TOLIMENSE | M40: =+'GRUPO A'!M26 -> CANCHA 1 B
A43: =+'GRUPO A'!B23 -> 42813 | B43: =+'GRUPO A'!C23 -> 01:20. p.m. | C43: =+'GRUPO A'!E23 -> ATHETIC MELGAR | E43: =IF(AND(F43<>"",H43<>""),IF(F43=H43,"E",IF(F43>H43,"G","P")),"") -> E | F43: =+'GRUPO A'!G23 -> 1 | G43: - | H43: =+'GRUPO A'!I23 -> 1 | I43: =IF(AND(H43<>"",F43<>""),IF(H43=F43,"E",IF(H43>F43,"G","P")),"") -> E | J43: =+'GRUPO A'!K23 -> GENERACION TOLIMA | M43: =+'GRUPO A'!M23 -> CANCHA 1 A
A45: =+'GRUPO A'!B35 -> 0 | B45: =+'GRUPO A'!C35 -> 0 | C45: =+'GRUPO A'!E35 -> 0 | E45: =IF(AND(F45<>"",H45<>""),IF(F45=H45,"E",IF(F45>H45,"G","P")),"") -> E | F45: =+'GRUPO A'!G35 -> 0 | G45: - | H45: =+'GRUPO A'!I35 -> 0 | I45: =IF(AND(H45<>"",F45<>""),IF(H45=F45,"E",IF(H45>F45,"G","P")),"") -> E | J45: =+'GRUPO A'!K35 -> 0 | M45: =+'GRUPO A'!M35 -> 0
A47: =+'GRUPO A'!B32 -> 42812 | B47: =+'GRUPO A'!C32 -> 03:00. p.m. | C47: =+'GRUPO A'!E32 -> IVÁN VÉLEZ PROFESIONALES PALMIRA | E47: =IF(AND(F47<>"",H47<>""),IF(F47=H47,"E",IF(F47>H47,"G","P")),"") -> G | F47: =+'GRUPO A'!G32 -> 1 | G47: - | H47: =+'GRUPO A'!I32 -> 0 | I47: =IF(AND(H47<>"",F47<>""),IF(H47=F47,"E",IF(H47>F47,"G","P")),"") -> P | J47: =+'GRUPO A'!K32 -> ATHETIC MELGAR | M47: =+'GRUPO A'!M32 -> CANCHA 1 B
A49: =+'GRUPO A'!B29 -> 42812 | B49: =+'GRUPO A'!C29 -> 03:00. p.m. | C49: =+'GRUPO A'!E29 -> GENERACION TOLIMA | E49: =IF(AND(F49<>"",H49<>""),IF(F49=H49,"E",IF(F49>H49,"G","P")),"") -> G | F49: =+'GRUPO A'!G29 -> 2 | G49: - | H49: =+'GRUPO A'!I29 -> 1 | I49: =IF(AND(H49<>"",F49<>""),IF(H49=F49,"E",IF(H49>F49,"G","P")),"") -> P | J49: =+'GRUPO A'!K29 -> CLUB ESTUDIANTES CK | M49: =+'GRUPO A'!M29 -> CANCHA 1 C
A51: NOTA: LA ORGANIZACIÓN DEL TORNEO NO SE HACE RESPONSABLE DE ACCIDENTES O PERDIDA DE ELEMENTOS DURANTE EL TRANSCURSO DEL TORNEO. Les recordamos traer el seguro de salud de los deportistas. Tarjeta de identidad Original, Registro Civil.
A56: Sede Administrativa Cra 13 No 6-43 Barrio La Florida
A57: Celular 310 241 33 76 Fijo 2 450 593
A58: soccermelgar@outlook.com
A59: Melgar - Tolima

Sheet IMPRIMIR (C-D)3-4.
A1: =+'GRUPOS PRE JUVENIL'!B1:L1 -> #VALUE!
A2: “COPA FUTURO TALENTO”
D3: =+'GRUPOS PRE JUVENIL'!G6 -> GRUPO B
D4: =+'GRUPOS PRE JUVENIL'!G7 -> IVÁN VÉLEZ PROFESIONALES PALMIRA
D5: =+'GRUPOS PRE JUVENIL'!G8 -> UNION TOLIMENSE
D6: =+'GRUPOS PRE JUVENIL'!G9 -> SAETA REDEC
D7: =+'GRUPOS PRE JUVENIL'!I10 -> ACADEMIA REAL
D8: =+'GRUPOS PRE JUVENIL'!I11 -> 0
B10: =+'GRUPOS PRE JUVENIL'!D3 -> NACIDOS 2016 2017
B11: =+'GRUPOS PRE JUVENIL'!D4 -> NOV 30 1 Y 2 DICIEMBRE 2024
A12: =+'GRUPOS PRE JUVENIL'!G6 -> GRUPO B
A14: PARTIDOS fecha 3- fecha 4
P15: º
A16: =+'GRUPO B'!B35 -> 0 | B16: =+'GRUPO B'!C35 -> 0 | C16: =+'GRUPO B'!E35 -> 0 | E16: =IF(AND(F16<>"",H16<>""),IF(F16=H16,"E",IF(F16>H16,"G","P")),"") -> E | F16: =+'GRUPO B'!G35 -> 0 | G16: - | H16: =+'GRUPO B'!I35 -> 0 | I16: =IF(AND(H16<>"",F16<>""),IF(H16=F16,"E",IF(H16>F16,"G","P")),"") -> E | J16: =+'GRUPO B'!K35 -> 0 | M16: =+'GRUPO B'!M35 -> 0
A19: =+'GRUPO B'!B23 -> 42812 | B19: =+'GRUPO B'!C23 -> 08:40. p.m. | C19: =+'GRUPO B'!E23 -> IVÁN VÉLEZ PROFESIONALES PALMIRA | E19: =IF(AND(F19<>"",H19<>""),IF(F19=H19,"E",IF(F19>H19,"G","P")),"") -> G | F19: =+'GRUPO B'!G23 -> 3 | G19: - | H19: =+'GRUPO B'!I23 -> 0 | I19: =IF(AND(H19<>"",F19<>""),IF(H19=F19,"E",IF(H19>F19,"G","P")),"") -> P | J19: =+'GRUPO B'!K23 -> SAETA REDEC | M19: =+'GRUPO B'!M23 -> CANCHA 1 B
A21: =+'GRUPO B'!B26 -> 42812 | B21: =+'GRUPO B'!C26 -> 07:00. a.m. | C21: =+'GRUPO B'!E26 -> CLUB ESTUDIANTES CK | E21: =IF(AND(F21<>"",H21<>""),IF(F21=H21,"E",IF(F21>H21,"G","P")),"") -> P | F21: =+'GRUPO B'!G26 -> 0 | G21: - | H21: =+'GRUPO B'!I26 -> 2 | I21: =IF(AND(H21<>"",F21<>""),IF(H21=F21,"E",IF(H21>F21,"G","P")),"") -> G | J21: =+'GRUPO B'!K26 -> UNION TOLIMENSE | M21: =+'GRUPO B'!M26 -> CANCHA 1 B
A23: =+'GRUPO B'!B29 -> 42812 | B23: =+'GRUPO B'!C29 -> 03:00. p.m. | C23: =+'GRUPO B'!E29 -> UNION TOLIMENSE | E23: =IF(AND(F23<>"",H23<>""),IF(F23=H23,"E",IF(F23>H23,"G","P")),"") -> E | F23: =+'GRUPO B'!G29 -> 1 | G23: - | H23: =+'GRUPO B'!I29 -> 1 | I23: =IF(AND(H23<>"",F23<>""),IF(H23=F23,"E",IF(H23>F23,"G","P")),"") -> E | J23: =+'GRUPO B'!K29 -> SAETA REDEC | M23: =+'GRUPO B'!M29 -> CANCHA 1 A
A25: =+'GRUPO B'!B32 -> 42812 | B25: =+'GRUPO B'!C32 -> 03:00. p.m. | C25: =+'GRUPO B'!E32 -> IVÁN VÉLEZ PROFESIONALES PALMIRA | E25: =IF(AND(F25<>"",H25<>""),IF(F25=H25,"E",IF(F25>H25,"G","P")),"") -> G | F25: =+'GRUPO B'!G32 -> 1 | G25: - | H25: =+'GRUPO B'!I32 -> 0 | I25: =IF(AND(H25<>"",F25<>""),IF(H25=F25,"E",IF(H25>F25,"G","P")),"") -> P | J25: =+'GRUPO B'!K32 -> ATHETIC MELGAR | M25: =+'GRUPO B'!M32 -> CANCHA 1 B
D28: =+'GRUPOS PRE JUVENIL'!K6 -> 0
D29: =+'GRUPOS PRE JUVENIL'!K7 -> 0
D30: =+'GRUPOS PRE JUVENIL'!K8 -> 0
D31: =+'GRUPOS PRE JUVENIL'!#REF! -> #REF!
D32: =+'GRUPOS PRE JUVENIL'!K10 -> 0
D33: =+'GRUPOS PRE JUVENIL'!K11 -> 0
A35: =+'GRUPOS PRE JUVENIL'!K6 -> 0
A38: =+#REF! -> #REF! | B38: =+#REF! -> #REF! | C38: =+#REF! -> #REF! | E38: =IF(AND(F38<>"",H38<>""),IF(F38=H38,"E",IF(F38>H38,"G","P")),"") -> #REF! | F38: =+#REF! -> #REF! | G38: - | H38: =+#REF! -> #REF! | I38: =IF(AND(H38<>"",F38<>""),IF(H38=F38,"E",IF(H38>F38,"G","P")),"") -> #REF! | J38: =+#REF! -> #REF! | M38: =+#REF! -> #REF!
A40: =+#REF! -> #REF! | B40: =+#REF! -> #REF! | C40: =+#REF! -> #REF! | E40: =IF(AND(F40<>"",H40<>""),IF(F40=H40,"E",IF(F40>H40,"G","P")),"") -> #REF! | F40: =+#REF! -> #REF! | G40: - | H40: =+#REF! -> #REF! | I40: =IF(AND(H40<>"",F40<>""),IF(H40=F40,"E",IF(H40>F40,"G","P")),"") -> #REF! | J40: =+#REF! -> #REF! | M40: =+#REF! -> #REF!
A42: =+#REF! -> #REF! | B42: =+#REF! -> #REF! | C42: =+#REF! -> #REF! | E42: =IF(AND(F42<>"",H42<>""),IF(F42=H42,"E",IF(F42>H42,"G","P")),"") -> #REF! | F42: =+#REF! -> #REF! | G42: - | H42: =+#REF! -> #REF! | I42: =IF(AND(H42<>"",F42<>""),IF(H42=F42,"E",IF(H42>F42,"G","P")),"") -> #REF! | J42: =+#REF! -> #REF! | M42: =+#REF! -> #REF!
A44: =+#REF! -> #REF! | B44: =+#REF! -> #REF! | C44: =+#REF! -> #REF! | E44: =IF(AND(F44<>"",H44<>""),IF(F44=H44,"E",IF(F44>H44,"G","P")),"") -> #REF! | F44: =+#REF! -> #REF! | G44: - | H44: =+#REF! -> #REF! | I44: =IF(AND(H44<>"",F44<>""),IF(H44=F44,"E",IF(H44>F44,"G","P")),"") -> #REF! | J44: =+#REF! -> #REF! | M44: =+#REF! -> #REF!
A46: =+#REF! -> #REF! | B46: =+#REF! -> #REF! | C46: =+#REF! -> #REF! | E46: =IF(AND(F46<>"",H46<>""),IF(F46=H46,"E",IF(F46>H46,"G","P")),"") -> #REF! | F46: =+#REF! -> #REF! | G46: - | H46: =+#REF! -> #REF! | I46: =IF(AND(H46<>"",F46<>""),IF(H46=F46,"E",IF(H46>F46,"G","P")),"") -> #REF! | J46: =+#REF! -> #REF! | M46: =+#REF! -> #REF!
A48: NOTA: LA ORGANIZACIÓN DEL TORNEO NO SE HACE RESPONSABLE DE ACCIDENTES O PERDIDA DE ELEMENTOS DURANTE EL TRANSCURSO DEL TORNEO. Les recordamos traer el seguro de salud de los deportistas. Tarjeta de identidad Original, Registro Civil.
A53: Sede Administrativa Cra 13 No 6-43 Barrio La Florida
A54: Celular 310 241 33 76 Fijo 2 450 593
A55: soccermelgar@outlook.com
A56: Melgar - Tolima

Sheet IMPRIMIR 6
A1: Campeonato Nacional de Futbol
A2: “COPA FUTURO TALENTO”
A3: DEFINICIÓN DEL TORNEO
B4: Observación: Si el partido se define por penales, éstos deben sumarse al resultado.
B5: SEMIFINALES | Q5: Ganador
B7: =+#REF! -> #REF! | C7: =+#REF! -> #REF! | D7: =+#REF! -> #REF! | E7: =+#REF! -> #REF! | G7: =IF(AND(I7<>"",K7<>""),IF(I7=K7,"E",IF(I7>K7,"G","P")),"") -> #REF! | I7: =+#REF! -> #REF! | J7: - | K7: =+#REF! -> #REF! | L7: =IF(AND(K7<>"",I7<>""),IF(K7=I7,"E",IF(K7>I7,"G","P")),"") -> #REF! | M7: =+#REF! -> #REF! | O7: =+#REF! -> #REF! | Q7: =IF(OR(G7="E",G7=""),"",IF(G7="G",E7,M7)) -> #REF! | S7: =IF(OR(G7="E",G7=""),"",IF(G7="P",E7,M7)) -> #REF!
B10: =+#REF! -> #REF! | C10: =+#REF! -> #REF! | D10: =+#REF! -> #REF! | E10: =+#REF! -> #REF! | G10: =IF(AND(I10<>"",K10<>""),IF(I10=K10,"E",IF(I10>K10,"G","P")),"") -> #REF! | I10: =+#REF! -> #REF! | J10: - | K10: =+#REF! -> #REF! | L10: =IF(AND(K10<>"",I10<>""),IF(K10=I10,"E",IF(K10>I10,"G","P")),"") -> #REF! | M10: =+#REF! -> #REF! | O10: =+#REF! -> #REF! | Q10: =IF(OR(G10="E",G10=""),"",IF(G10="G",E10,M10)) -> #REF! | S10: =IF(OR(G10="E",G10=""),"",IF(G10="P",E10,M10)) -> #REF!
C14: =+'GRUPOS PRE JUVENIL'!D3 -> NACIDOS 2016 2017 | J14: =+'GRUPOS PRE JUVENIL'!D4 -> NOV 30 1 Y 2 DICIEMBRE 2024

Sheet IMPRIMIR 7
A1: Campeonato Nacional de Futbol
A2: “COPA FUTURO TALENTO”
A3: FINAL DEL TORNEO
B4: Observación: Si el partido se define por penales, éstos deben sumarse al resultado.
B5: Partido por el TERCER PUESTO | Q5: TERCER PUESTO
Q6: =IF(OR(G7="E",G7=""),"",IF(G7="G",H7,M7)) -> #REF!
B7: =+#REF! -> #REF! | D7: =+#REF! -> #REF! | G7: =IF(AND(I7<>"",K7<>""),IF(I7=K7,"E",IF(I7>K7,"G","P")),"") -> #REF! | H7: =+#REF! -> #REF! | I7: =+#REF! -> #REF! | J7: - | K7: =+#REF! -> #REF! | L7: =IF(AND(K7<>"",I7<>""),IF(K7=I7,"E",IF(K7>I7,"G","P")),"") -> #REF! | M7: =+#REF! -> #REF! | O7: =+#REF! -> #REF!
B11: FINAL DEL CAMPEONATO | Q11: SEGUNDO PUESTO
Q12: =IF(OR(G13="E",G13=""),"",IF(G13="P",H13,M13)) -> #REF!
B13: =+#REF! -> #REF! | D13: =+#REF! -> #REF! | G13: =IF(AND(I13<>"",K13<>""),IF(I13=K13,"E",IF(I13>K13,"G","P")),"") -> #REF! | H13: =+#REF! -> #REF! | I13: =+#REF! -> #REF! | J13: - | K13: =+#REF! -> #REF! | L13: =IF(AND(K13<>"",I13<>""),IF(K13=I13,"E",IF(K13>I13,"G","P")),"") -> #REF! | M13: =+#REF! -> #REF! | O13: =+#REF! -> #REF!
B17: CAMPEÓN “COPA FUTURO TALENTO”
B19: =IF(OR(G13="E",G13=""),"",IF(G13="G",H13,M13)) -> #REF!
C22: =+'GRUPOS PRE JUVENIL'!D3 -> NACIDOS 2016 2017 | O22: =+'GRUPOS PRE JUVENIL'!D4 -> NOV 30 1 Y 2 DICIEMBRE 2024

Sheet Hoja1
B1: =+'GRUPOS PRE JUVENIL'!D1 -> XVIII Torneo Nacional de Fútbol Infantil
B2: =+'GRUPOS PRE JUVENIL'!D2 -> “COPA SOCCER MELGAR"
B3: =+'GRUPOS PRE JUVENIL'!D3 -> NACIDOS 2016 2017
B4: =+'GRUPOS PRE JUVENIL'!D4 -> NOV 30 1 Y 2 DICIEMBRE 2024
B5: FASE GRUPOS
F7: GRUPO A | H7: GRUPO B
F8: 1 | H8: 4
F9: 2 | H9: 5
F10: 3 | H10: 6
D12: INTERGRUPOS
D14: # 1 GRUPO A | G14: vs | H14: # 5 GRUPO B
D16: # 2 GRUPO A | G16: vs | H16: # 6 GRUPO B
D18: # 3 GRUPO A | G18: vs | H18: # 4 GRUPO B
D20: # 1 GRUPO A | G20: vs | H20: # 4 GRUPO B
D22: # 2 GRUPO A | G22: vs | H22: # 5 GRUPO B
D24: # 3 GRUPO A | G24: vs | H24: # 6 GRUPO B
B26: El partido intergrupo garantiza jugar como minimo 4 partidos a todos los equipos participantes.
B28: SEMIFINAL
B29: Pasan a la ronda semifinal, el LOS DOS PRIMEROS DE CADA GRUPO, se jugara el lunes festivo en la mañana
B32: LLAVE A | C32: 1RO DEL GRUPO A | G32: vs | H32: 2DO DEL GRUPO B
B34: LLAVE B | C34: 1RO DEL GRUPO B | G34: vs | H34: 2DO DEL GRUPO A
D36: 3 Y 4 LUGAR
D38: PERDEDOR LLAVE A | G38: vs | H38: PERDEDOR LLAVE B
D40: FINAL
D42: GANADOR LLAVE A | G42: vs | H42: GANADOR LLAVE B

Sheet fixture 3 dias 6 equipos 
