Workbook

Sheet GRUPOS INFANTIL
C1: XVIII Torneo Nacional de Fútbol Infantil
C2: “COPA SOCCER MELGAR”
C3: NACIDOS 2008 2009
C4: NOV 30 1 Y 2 DICIEMBRE 2024
D7: GRUPO A | H7: GRUPO B
D8: H&C.SPORT | H8: ALIANZA TOLIMENSE
D9: TALENTO TOLIMENSE | H9: CLUB DEPORTIVO SANPAY
D10: A10 ACADEMY | H10: CLUB DEPORTIVO EL DIAMANTE
D11: LE MAX TEAM | F11: 2024 | H11: REAL BOGOTÁ

Sheet GRUPO A
A1: =+'GRUPOS INFANTIL'!C1 -> XVIII Torneo Nacional de Fútbol Infantil
A2: “COPA FUTURO TALENTO”
B3: =+'GRUPOS INFANTIL'!C3 -> NACIDOS 2008 2009 | F3: =+'GRUPOS INFANTIL'!C4 -> NOV 30 1 Y 2 DICIEMBRE 2024
B4: =+'GRUPOS INFANTIL'!D7 -> GRUPO A
B6: PARTIDOS | P6: POSICIONES | AJ6: =COUNT(G8,I8,G11,I11,G14,I14,G17,I17,G20,I20,G23,I23,G26,I26,G29,I29,G32,I32,G35,I35) -> 12
A7: Tj | N7: Tj
F8: =IF(AND(G8<>"",I8<>""),IF(G8=I8,"E",IF(G8>I8,"G","P")),"") | H8: - | J8: =IF(AND(I8<>"",G8<>""),IF(I8=G8,"E",IF(I8>G8,"G","P")),"") | Q8: Pts. | R8: PJ | S8: Gan. | T8: Emp. | U8: Per. | V8: GF | W8: GC | X8: Dif. | Y8: Tj | AJ8: =IF(AJ6=12,IF(INDEX(Z22:AK29,MATCH(2,Z22:Z29,0),11)=INDEX(Z22:AK29,MATCH(1,Z22:Z29,0),11),1,0),0) -> #N/A
P10: =" 1) " & VLOOKUP(1,$Z$10:$AI$17,2,0) -> 1) A10 ACADEMY | Q10: =VLOOKUP(1,$Z$10:$AI$17,3,0) -> 9 | R10: =+SUM(S10:U11) -> 3 | S10: =VLOOKUP(1,$Z$10:$AI$17,4,0) -> 3 | T10: =VLOOKUP(1,$Z$10:$AI$17,5,0) -> 0 | U10: =VLOOKUP(1,$Z$10:$AI$17,6,0) -> 0 | V10: =VLOOKUP(1,$Z$10:$AI$17,7,0) -> 7 | W10: =VLOOKUP(1,$Z$10:$AI$17,8,0) -> 1 | X10: =VLOOKUP(1,$Z$10:$AH$17,9,0) -> 6 | Y10: =VLOOKUP(1,$Z$10:$AI$17,10,0) -> 0 | Z10: =RANK(AJ10,$AJ$10:$AJ$17,0) -> 2 | AA10: =+'GRUPOS INFANTIL'!D8 -> H&C.SPORT | AB10: =(AC10*3)+AD10 -> 6 | AC10: =COUNTIF(Q58:T58,"G") -> 2 | AD10: =COUNTIF(Q58:T58,"E") -> 0 | AE10: =COUNTIF(Q58:T58,"P") -> 1 | AF10: =+G8+G20+G26+G35 -> 10 | AG10: =+I8+I20+I26+I35 -> 5 | AH10: =AF10-AG10 -> 5 | AI10: =+A8+A20+A26+A35 -> 0 | AJ10: =(AB10*1000)+(AH10*100)+(AF10*10)-AI10+0.1 -> 6600.1 | AK10: =AJ10+X10 -> 6606.1
F11: =IF(AND(G11<>"",I11<>""),IF(G11=I11,"E",IF(G11>I11,"G","P")),"") | H11: - | J11: =IF(AND(I11<>"",G11<>""),IF(I11=G11,"E",IF(I11>G11,"G","P")),"")
P12: =" 2) " & VLOOKUP(2,$Z$10:$AI$17,2,0) -> 2) H&C.SPORT | Q12: =VLOOKUP(2,$Z$10:$AI$17,3,0) -> 6 | R12: =+SUM(S12:U13) -> 3 | S12: =VLOOKUP(2,$Z$10:$AI$17,4,0) -> 2 | T12: =VLOOKUP(2,$Z$10:$AI$17,5,0) -> 0 | U12: =VLOOKUP(2,$Z$10:$AI$17,6,0) -> 1 | V12: =VLOOKUP(2,$Z$10:$AI$17,7,0) -> 10 | W12: =VLOOKUP(2,$Z$10:$AI$17,8,0) -> 5 | X12: =VLOOKUP(2,$Z$10:$AH$17,9,0) -> 5 | Y12: =VLOOKUP(2,$Z$10:$AI$17,10,0) -> 0 | Z12: =RANK(AJ12,$AJ$10:$AJ$17,0) -> 4 | AA12: =+'GRUPOS INFANTIL'!D9 -> TALENTO TOLIMENSE | AB12: =(AC12*3)+AD12 -> 0 | AC12: =COUNTIF(Q59:T59,"G") -> 0 | AD12: =COUNTIF(Q59:T59,"E") -> 0 | AE12: =COUNTIF(Q59:T59,"P") -> 3 | AF12: =+G11+I20+G29+G32 -> 1 | AG12: =+I11+I29+G20+I32 -> 9 | AH12: =AF12-AG12 -> -8 | AI12: =+A29+A11+N20+A32 -> 0 | AJ12: =(AB12*1000)+(AH12*100)+(AF12*10)-AI12+0.2 -> -789.8 | AK12: =AJ12+X12 -> -784.8
F14: =IF(AND(G14<>"",I14<>""),IF(G14=I14,"E",IF(G14>I14,"G","P")),"") | H14: - | J14: =IF(AND(I14<>"",G14<>""),IF(I14=G14,"E",IF(I14>G14,"G","P")),"") | P14: =" 3) " & VLOOKUP(3,$Z$10:$AI$17,2,0) -> 3) LE MAX TEAM | Q14: =VLOOKUP(3,$Z$10:$AI$17,3,0) -> 3 | R14: =+SUM(S14:U15) -> 3 | S14: =VLOOKUP(3,$Z$10:$AI$17,4,0) -> 1 | T14: =VLOOKUP(3,$Z$10:$AI$17,5,0) -> 0 | U14: =VLOOKUP(3,$Z$10:$AI$17,6,0) -> 2 | V14: =VLOOKUP(3,$Z$10:$AI$17,7,0) -> 3 | W14: =VLOOKUP(3,$Z$10:$AI$17,8,0) -> 6 | X14: =VLOOKUP(3,$Z$10:$AI$17,9,0) -> -3 | Y14: =VLOOKUP(3,$Z$10:$AI$17,10,0) -> 0 | Z14: =RANK(AJ14,$AJ$10:$AJ$17,0) -> 1 | AA14: =+'GRUPOS INFANTIL'!D10 -> A10 ACADEMY | AB14: =(AC14*3)+AD14 -> 9 | AC14: =COUNTIF(Q60:T60,"G") -> 3 | AD14: =COUNTIF(Q60:T60,"E") -> 0 | AE14: =COUNTIF(Q60:T60,"P") -> 0 | AF14: =+G14+I26+G23+I32 -> 7 | AG14: =+G26+I14+I23+G32 -> 1 | AH14: =AF14-AG14 -> 6 | AI14: =+A14+A23+N26+N32 -> 0 | AJ14: =(AB14*1000)+(AH14*100)+(AF14*10)-AI14+0.3 -> 9670.3 | AK14: =+X14 -> -3
P16: =" 4) " & VLOOKUP(4,$Z$10:$AI$17,2,0) -> 4) TALENTO TOLIMENSE | Q16: =VLOOKUP(4,$Z$10:$AI$17,3,0) -> 0 | R16: =+SUM(S16:U17) -> 3 | S16: =VLOOKUP(4,$Z$10:$AI$17,4,0) -> 0 | T16: =VLOOKUP(4,$Z$10:$AI$17,5,0) -> 0 | U16: =VLOOKUP(4,$Z$10:$AI$17,6,0) -> 3 | V16: =VLOOKUP(4,$Z$10:$AI$17,7,0) -> 1 | W16: =VLOOKUP(4,$Z$10:$AI$17,8,0) -> 9 | X16: =VLOOKUP(4,$Z$10:$AI$17,9,0) -> -8 | Y16: =VLOOKUP(4,$Z$10:$AI$17,10,0) -> 0 | Z16: =RANK(AJ16,$AJ$10:$AJ$17,0) -> 3 | AA16: =+'GRUPOS INFANTIL'!D11 -> LE MAX TEAM | AB16: =(AC16*3)+AD16 -> 3 | AC16: =COUNTIF(Q61:T61,"G") -> 1 | AD16: =COUNTIF(Q61:T61,"E") -> 0 | AE16: =COUNTIF(Q61:T61,"P") -> 2 | AF16: =+G17+I29+I23+I35 -> 3 | AG16: =+I17+G29+G23+G35 -> 6 | AH16: =AF16-AG16 -> -3 | AI16: =+A17+N23+N29+N35 -> 0 | AJ16: =(AB16*1000)+(AH16*100)+(AF16*10)-AI16+0.4 -> 2730.4 | AK16: =+X16 -> -8
F17: =IF(AND(G17<>"",I17<>""),IF(G17=I17,"E",IF(G17>I17,"G","P")),"") | H17: - | J17: =IF(AND(I17<>"",G17<>""),IF(I17=G17,"E",IF(I17>G17,"G","P")),"")
B20: 42812 | C20: 07:15. a.m. | E20: =+'GRUPOS INFANTIL'!D8 -> H&C.SPORT | F20: =IF(AND(G20<>"",I20<>""),IF(G20=I20,"E",IF(G20>I20,"G","P")),"") -> G | G20: 5 | H20: - | I20: 0 | J20: =IF(AND(I20<>"",G20<>""),IF(I20=G20,"E",IF(I20>G20,"G","P")),"") -> P | K20: =+'GRUPOS INFANTIL'!D9 -> TALENTO TOLIMENSE | M20: CANCHA 2
B23: 42812 | C23: 08:20. a.m. | E23: =+'GRUPOS INFANTIL'!D10 -> A10 ACADEMY | F23: =IF(AND(G23<>"",I23<>""),IF(G23=I23,"E",IF(G23>I23,"G","P")),"") -> G | G23: 1 | H23: - | I23: 0 | J23: =IF(AND(I23<>"",G23<>""),IF(I23=G23,"E",IF(I23>G23,"G","P")),"") -> P | K23: =+'GRUPOS INFANTIL'!D11 -> LE MAX TEAM | M23: LAS VEGAS
B26: 42812 | C26: 03:00. p.m. | E26: =+'GRUPOS INFANTIL'!D8 -> H&C.SPORT | F26: =IF(AND(G26<>"",I26<>""),IF(G26=I26,"E",IF(G26>I26,"G","P")),"") -> P | G26: 0 | H26: - | I26: 4 | J26: =IF(AND(I26<>"",G26<>""),IF(I26=G26,"E",IF(I26>G26,"G","P")),"") -> G | K26: =+'GRUPOS INFANTIL'!D10 -> A10 ACADEMY | M26: LAS VEGAS
B29: 42812 | C29: 04:00. p.m. | E29: =+'GRUPOS INFANTIL'!D9 -> TALENTO TOLIMENSE | F29: =IF(AND(G29<>"",I29<>""),IF(G29=I29,"E",IF(G29>I29,"G","P")),"") -> P | G29: 0 | H29: - | I29: 2 | J29: =IF(AND(I29<>"",G29<>""),IF(I29=G29,"E",IF(I29>G29,"G","P")),"") -> G | K29: =+'GRUPOS INFANTIL'!D11 -> LE MAX TEAM | M29: LAS VEGAS
B32: 42813 | C32: 01:15. p.m. | E32: =+'GRUPOS INFANTIL'!D9 -> TALENTO TOLIMENSE | F32: =IF(AND(G32<>"",I32<>""),IF(G32=I32,"E",IF(G32>I32,"G","P")),"") -> P | G32: 1 | H32: - | I32: 2 | J32: =IF(AND(I32<>"",G32<>""),IF(I32=G32,"E",IF(I32>G32,"G","P")),"") -> G | K32: =+'GRUPOS INFANTIL'!D10 -> A10 ACADEMY | M32: CANCHA 2
W34: =IF(AJ8=1,IF(P33="","",P33),IF(SUM(Q10:Q17)>0,VLOOKUP(1,Z10:AA17,2,0),"")) -> #N/A
B35: 42813 | C35: 02:30. p.m. | E35: =+'GRUPOS INFANTIL'!D8 -> H&C.SPORT | F35: =IF(AND(G35<>"",I35<>""),IF(G35=I35,"E",IF(G35>I35,"G","P")),"") -> G | G35: 5 | H35: - | I35: 1 | J35: =IF(AND(I35<>"",G35<>""),IF(I35=G35,"E",IF(I35>G35,"G","P")),"") -> P | K35: =+'GRUPOS INFANTIL'!D11 -> LE MAX TEAM | M35: CANCHA 1 | W35: =IF(AJ8=1,IF(P36="","",P36),IF(SUM(Q10:Q17)>0,VLOOKUP(2,Z10:AA17,2,0),"")) -> #N/A
J43: =IF(AG20=1,"Indique el primero y segundo equipos clasificados de la serie:","") | L43: =IF(AG20=1,"Primero:","")
J46: =IF(AG20=1,"(Debido a la paridad de los resultados, no pueden deducirse de forma automática.)","") | L46: =IF(AG20=1,"Segundo:","")
P58: =+'GRUPOS INFANTIL'!D8 -> H&C.SPORT | Q58: =+F8 | R58: =+F20 -> G | S58: =+F26 -> P | T58: =+F35 -> G
P59: =+'GRUPOS INFANTIL'!D9 -> TALENTO TOLIMENSE | Q59: =+F11 | R59: =+J20 -> P | S59: =+F29 -> P | T59: =+F32 -> P
P60: =+'GRUPOS INFANTIL'!D10 -> A10 ACADEMY | Q60: =+F14 | R60: =+F23 -> G | S60: =+J26 -> G | T60: =+J32 -> G
P61: =+'GRUPOS INFANTIL'!D11 -> LE MAX TEAM | Q61: =+F17 | R61: =+J23 -> P | S61: =+J29 -> G | T61: =+J35 -> P

Sheet GRUPO B
A1: =+'GRUPOS INFANTIL'!C1 -> XVIII Torneo Nacional de Fútbol Infantil
A2: “COPA FUTURO TALENTO”
B3: =+'GRUPOS INFANTIL'!C3 -> NACIDOS 2008 2009 | F3: =+'GRUPOS INFANTIL'!C4 -> NOV 30 1 Y 2 DICIEMBRE 2024
B4: =+'GRUPOS INFANTIL'!H7 -> GRUPO B
B6: PARTIDOS | P6: POSICIONES | AJ6: =COUNT(G8,I8,G11,I11,G14,I14,G17,I17,G20,I20,G23,I23,G26,I26,G29,I29,G32,I32,G35,I35) -> 12
A7: Tj | N7: Tj
F8: =IF(AND(G8<>"",I8<>""),IF(G8=I8,"E",IF(G8>I8,"G","P")),"") | H8: - | J8: =IF(AND(I8<>"",G8<>""),IF(I8=G8,"E",IF(I8>G8,"G","P")),"") | Q8: Pts. | R8: PJ | S8: Gan. | T8: Emp. | U8: Per. | V8: GF | W8: GC | X8: Dif. | Y8: Tj | AJ8: =IF(AJ6=12,IF(INDEX(Z10:AK17,MATCH(2,Z10:Z17,0),11)=INDEX(Z10:AK17,MATCH(1,Z10:Z17,0),11),1,0),0) -> 0
P10: =" 1) " & VLOOKUP(1,$Z$10:$AI$17,2,0) -> 1) CLUB DEPORTIVO EL DIAMANTE | Q10: =VLOOKUP(1,$Z$10:$AI$17,3,0) -> 6 | R10: =+SUM(S10:U11) -> 3 | S10: =VLOOKUP(1,$Z$10:$AI$17,4,0) -> 2 | T10: =VLOOKUP(1,$Z$10:$AI$17,5,0) -> 0 | U10: =VLOOKUP(1,$Z$10:$AI$17,6,0) -> 1 | V10: =VLOOKUP(1,$Z$10:$AI$17,7,0) -> 7 | W10: =VLOOKUP(1,$Z$10:$AI$17,8,0) -> 3 | X10: =VLOOKUP(1,$Z$10:$AH$17,9,0) -> 4 | Y10: =VLOOKUP(1,$Z$10:$AI$17,10,0) -> 0 | Z10: =RANK(AJ10,$AJ$10:$AJ$17,0) -> 3 | AA10: =+'GRUPOS INFANTIL'!H8 -> ALIANZA TOLIMENSE | AB10: =(AC10*3)+AD10 -> 6 | AC10: =COUNTIF(Q58:T58,"G") -> 2 | AD10: =COUNTIF(Q58:T58,"E") -> 0 | AE10: =COUNTIF(Q58:T58,"P") -> 1 | AF10: =+I8+G20+G26+G32 -> 5 | AG10: =+I20+I26+I32+G8 -> 3 | AH10: =AF10-AG10 -> 2 | AI10: =+A20+A26+A32+N8 -> 0 | AJ10: =(AB10*1000)+(AH10*100)+(AF10*10)-AI10+0.1 -> 6250.1 | AK10: =AJ10+X10 -> 6254.1
F11: =IF(AND(G11<>"",I11<>""),IF(G11=I11,"E",IF(G11>I11,"G","P")),"") | H11: - | J11: =IF(AND(I11<>"",G11<>""),IF(I11=G11,"E",IF(I11>G11,"G","P")),"")
P12: =" 2) " & VLOOKUP(2,$Z$10:$AI$17,2,0) -> 2) CLUB DEPORTIVO SANPAY | Q12: =VLOOKUP(2,$Z$10:$AI$17,3,0) -> 6 | R12: =+SUM(S12:U13) -> 3 | S12: =VLOOKUP(2,$Z$10:$AI$17,4,0) -> 2 | T12: =VLOOKUP(2,$Z$10:$AI$17,5,0) -> 0 | U12: =VLOOKUP(2,$Z$10:$AI$17,6,0) -> 1 | V12: =VLOOKUP(2,$Z$10:$AI$17,7,0) -> 5 | W12: =VLOOKUP(2,$Z$10:$AI$17,8,0) -> 2 | X12: =VLOOKUP(2,$Z$10:$AH$17,9,0) -> 3 | Y12: =VLOOKUP(2,$Z$10:$AI$17,10,0) -> 0 | Z12: =RANK(AJ12,$AJ$10:$AJ$17,0) -> 2 | AA12: =+'GRUPOS INFANTIL'!H9 -> CLUB DEPORTIVO SANPAY | AB12: =(AC12*3)+AD12 -> 6 | AC12: =COUNTIF(Q59:T59,"G") -> 2 | AD12: =COUNTIF(Q59:T59,"E") -> 0 | AE12: =COUNTIF(Q59:T59,"P") -> 1 | AF12: =+I20+G29+G35+I11 -> 5 | AG12: =+G20+I29+I35+G11 -> 2 | AH12: =AF12-AG12 -> 3 | AI12: =+N20+A29+A35+N11 -> 0 | AJ12: =(AB12*1000)+(AH12*100)+(AF12*10)-AI12+0.2 -> 6350.2 | AK12: =AJ12+X12 -> 6353.2
F14: =IF(AND(G14<>"",I14<>""),IF(G14=I14,"E",IF(G14>I14,"G","P")),"") | H14: - | J14: =IF(AND(I14<>"",G14<>""),IF(I14=G14,"E",IF(I14>G14,"G","P")),"") | P14: =" 3) " & VLOOKUP(3,$Z$10:$AI$17,2,0) -> 3) ALIANZA TOLIMENSE | Q14: =VLOOKUP(3,$Z$10:$AI$17,3,0) -> 6 | R14: =+SUM(S14:U15) -> 3 | S14: =VLOOKUP(3,$Z$10:$AI$17,4,0) -> 2 | T14: =VLOOKUP(3,$Z$10:$AI$17,5,0) -> 0 | U14: =VLOOKUP(3,$Z$10:$AI$17,6,0) -> 1 | V14: =VLOOKUP(3,$Z$10:$AI$17,7,0) -> 5 | W14: =VLOOKUP(3,$Z$10:$AI$17,8,0) -> 3 | X14: =VLOOKUP(3,$Z$10:$AI$17,9,0) -> 2 | Y14: =VLOOKUP(3,$Z$10:$AI$17,10,0) -> 0 | Z14: =RANK(AJ14,$AJ$10:$AJ$17,0) -> 1 | AA14: =+'GRUPOS INFANTIL'!H10 -> CLUB DEPORTIVO EL DIAMANTE | AB14: =(AC14*3)+AD14 -> 6 | AC14: =COUNTIF(Q60:T60,"G") -> 2 | AD14: =COUNTIF(Q60:T60,"E") -> 0 | AE14: =COUNTIF(Q60:T60,"P") -> 1 | AF14: =+G23+I26+I35+I14 -> 7 | AG14: =+I23+G26+G35+G14 -> 3 | AH14: =AF14-AG14 -> 4 | AI14: =+A23+N26+N35+N14 -> 0 | AJ14: =(AB14*1000)+(AH14*100)+(AF14*10)-AI14+0.3 -> 6470.3 | AK14: =+X14 -> 2
P16: =" 4) " & VLOOKUP(4,$Z$10:$AI$17,2,0) -> 4) REAL BOGOTÁ | Q16: =VLOOKUP(4,$Z$10:$AI$17,3,0) -> 0 | R16: =+SUM(S16:U17) -> 3 | S16: =VLOOKUP(4,$Z$10:$AI$17,4,0) -> 0 | T16: =VLOOKUP(4,$Z$10:$AI$17,5,0) -> 0 | U16: =VLOOKUP(4,$Z$10:$AI$17,6,0) -> 3 | V16: =VLOOKUP(4,$Z$10:$AI$17,7,0) -> 2 | W16: =VLOOKUP(4,$Z$10:$AI$17,8,0) -> 11 | X16: =VLOOKUP(4,$Z$10:$AI$17,9,0) -> -9 | Y16: =VLOOKUP(4,$Z$10:$AI$17,10,0) -> 0 | Z16: =RANK(AJ16,$AJ$10:$AJ$17,0) -> 4 | AA16: =+'GRUPOS INFANTIL'!H11 -> REAL BOGOTÁ | AB16: =(AC16*3)+AD16 -> 0 | AC16: =COUNTIF(Q61:T61,"G") -> 0 | AD16: =COUNTIF(Q61:T61,"E") -> 0 | AE16: =COUNTIF(Q61:T61,"P") -> 3 | AF16: =+I23+I29+I32+I17 -> 2 | AG16: =+G23+G29+G32+G17 -> 11 | AH16: =AF16-AG16 -> -9 | AI16: =+N23+N29+N32+N17 -> 0 | AJ16: =(AB16*1000)+(AH16*100)+(AF16*10)-AI16+0.4 -> -879.6 | AK16: =+X16 -> -9
F17: =IF(AND(G17<>"",I17<>""),IF(G17=I17,"E",IF(G17>I17,"G","P")),"") | H17: - | J17: =IF(AND(I17<>"",G17<>""),IF(I17=G17,"E",IF(I17>G17,"G","P")),"")
B20: 42812 | C20: 12:00. m.d. | E20: =+'GRUPOS INFANTIL'!H8 -> ALIANZA TOLIMENSE | F20: =IF(AND(G20<>"",I20<>""),IF(G20=I20,"E",IF(G20>I20,"G","P")),"") -> G | G20: 2 | H20: - | I20: 0 | J20: =IF(AND(I20<>"",G20<>""),IF(I20=G20,"E",IF(I20>G20,"G","P")),"") -> P | K20: =+'GRUPOS INFANTIL'!H9 -> CLUB DEPORTIVO SANPAY | M20: CANCHA 2
B23: 42812 | C23: 01:10. p.m. | E23: =+'GRUPOS INFANTIL'!H10 -> CLUB DEPORTIVO EL DIAMANTE | F23: =IF(AND(G23<>"",I23<>""),IF(G23=I23,"E",IF(G23>I23,"G","P")),"") -> G | G23: 5 | H23: - | I23: 1 | J23: =IF(AND(I23<>"",G23<>""),IF(I23=G23,"E",IF(I23>G23,"G","P")),"") -> P | K23: =+'GRUPOS INFANTIL'!H11 -> REAL BOGOTÁ | M23: CANCHA 2
B26: 42813 | C26: 09:50. a.m. | E26: =+'GRUPOS INFANTIL'!H8 -> ALIANZA TOLIMENSE | F26: =IF(AND(G26<>"",I26<>""),IF(G26=I26,"E",IF(G26>I26,"G","P")),"") -> P | G26: 1 | H26: - | I26: 2 | J26: =IF(AND(I26<>"",G26<>""),IF(I26=G26,"E",IF(I26>G26,"G","P")),"") -> G | K26: =+'GRUPOS INFANTIL'!H10 -> CLUB DEPORTIVO EL DIAMANTE | M26: CANCHA 1
B29: 42813 | C29: 10:50. a.m. | E29: =+'GRUPOS INFANTIL'!H9 -> CLUB DEPORTIVO SANPAY | F29: =IF(AND(G29<>"",I29<>""),IF(G29=I29,"E",IF(G29>I29,"G","P")),"") -> G | G29: 4 | H29: - | I29: 0 | J29: =IF(AND(I29<>"",G29<>""),IF(I29=G29,"E",IF(I29>G29,"G","P")),"") -> P | K29: =+'GRUPOS INFANTIL'!H11 -> REAL BOGOTÁ | M29: CANCHA 1
B32: 42813 | C32: 04:30. p.m. | E32: =+'GRUPOS INFANTIL'!H8 -> ALIANZA TOLIMENSE | F32: =IF(AND(G32<>"",I32<>""),IF(G32=I32,"E",IF(G32>I32,"G","P")),"") -> G | G32: 2 | H32: - | I32: 1 | J32: =IF(AND(I32<>"",G32<>""),IF(I32=G32,"E",IF(I32>G32,"G","P")),"") -> P | K32: =+'GRUPOS INFANTIL'!H11 -> REAL BOGOTÁ | M32: CANCHA 1
W34: =IF(AJ8=1,IF(P33="","",P33),IF(SUM(Q10:Q17)>0,VLOOKUP(1,Z10:AA17,2,0),"")) -> CLUB DEPORTIVO EL DIAMANTE
B35: 42813 | C35: 03:25. p.m. | E35: =+'GRUPOS INFANTIL'!H9 -> CLUB DEPORTIVO SANPAY | F35: =IF(AND(G35<>"",I35<>""),IF(G35=I35,"E",IF(G35>I35,"G","P")),"") -> G | G35: 1 | H35: - | I35: 0 | J35: =IF(AND(I35<>"",G35<>""),IF(I35=G35,"E",IF(I35>G35,"G","P")),"") -> P | K35: =+'GRUPOS INFANTIL'!H10 -> CLUB DEPORTIVO EL DIAMANTE | M35: CANCHA 2 | W35: =IF(AJ8=1,IF(P36="","",P36),IF(SUM(Q10:Q17)>0,VLOOKUP(2,Z10:AA17,2,0),"")) -> CLUB DEPORTIVO SANPAY
J43: =IF(AG8=1,"Indique el primero y segundo equipos clasificados de la serie:","") | L43: =IF(AG8=1,"Primero:","")
J46: =IF(AG8=1,"(Debido a la paridad de los resultados, no pueden deducirse de forma automática.)","") | L46: =IF(AG8=1,"Segundo:","")
P58: =+'GRUPOS INFANTIL'!H8 -> ALIANZA TOLIMENSE | Q58: =+F20 -> G | R58: =+J8 | S58: =+F26 -> P | T58: =+F32 -> G
P59: =+'GRUPOS INFANTIL'!H9 -> CLUB DEPORTIVO SANPAY | Q59: =+J20 -> P | R59: =+J11 | S59: =+F29 -> G | T59: =+F35 -> G
P60: =+'GRUPOS INFANTIL'!H10 -> CLUB DEPORTIVO EL DIAMANTE | Q60: =+F23 -> G | R60: =+J14 | S60: =+J26 -> G | T60: =+J35 -> P
P61: =+'GRUPOS INFANTIL'!H11 -> REAL BOGOTÁ | Q61: =+J23 -> P | R61: =+J17 | S61: =+J29 -> P | T61: =+J32 -> P

Sheet CUARTOS DE FINAL.
H1: Campeonato Nacional de Futbol
B2: CUARTOS DE FINAL | H2: “COPA FUTURO TALENTO”
B3: Observación: Si el partido se define por penales, éstos deben sumarse al resultado.
B4: PARTIDOS | P4: Ganador
B6: 42596 | C6: LLAVE A | D6: 03:00. p.m. | F6: =IF(AND(H6<>"",J6<>""),IF(H6=J6,"E",IF(H6>J6,"G","P")),"") -> P | G6: =+'GRUPO A'!$W$34 -> #N/A | H6: 1 | I6: - | J6: 2 | K6: =IF(AND(J6<>"",H6<>""),IF(J6=H6,"E",IF(J6>H6,"G","P")),"") -> G | L6: =+#REF! -> #REF! | N6: PALMARA | P6: =IF(OR(F6="E",F6=""),"",IF(F6="G",G6,L6)) -> #REF!
B9: 42596 | C9: LLAVE B | D9: 04:20. p.m. | F9: =IF(AND(H9<>"",J9<>""),IF(H9=J9,"E",IF(H9>J9,"G","P")),"") -> G | G9: =+'GRUPO B'!$W$34 -> CLUB DEPORTIVO EL DIAMANTE | H9: 2 | I9: - | J9: 1 | K9: =IF(AND(J9<>"",H9<>""),IF(J9=H9,"E",IF(J9>H9,"G","P")),"") -> P | L9: =+#REF! -> #REF! | N9: CANCHA 2 | P9: =IF(OR(F9="E",F9=""),"",IF(F9="G",G9,L9)) -> CLUB DEPORTIVO EL DIAMANTE
B12: 42596 | C12: LLAVE C | D12: 03:00. p.m. | F12: =IF(AND(H12<>"",J12<>""),IF(H12=J12,"E",IF(H12>J12,"G","P")),"") -> P | G12: =+#REF! -> #REF! | H12: 1 | I12: - | J12: 2 | K12: =IF(AND(J12<>"",H12<>""),IF(J12=H12,"E",IF(J12>H12,"G","P")),"") -> G | L12: =+'GRUPO A'!$W$35 -> #N/A | N12: CANCHA 2 | P12: =IF(OR(F12="E",F12=""),"",IF(F12="G",G12,L12)) -> #N/A
B15: 42596 | C15: LLAVE D | D15: 04:20. p.m. | F15: =IF(AND(H15<>"",J15<>""),IF(H15=J15,"E",IF(H15>J15,"G","P")),"") -> G | G15: =+#REF! -> #REF! | H15: 2 | I15: - | J15: 1 | K15: =IF(AND(J15<>"",H15<>""),IF(J15=H15,"E",IF(J15>H15,"G","P")),"") -> P | L15: =+'GRUPO B'!W35 -> CLUB DEPORTIVO SANPAY | N15: PALMARA | P15: =IF(OR(F15="E",F15=""),"",IF(F15="G",G15,L15)) -> #REF!
B18: =+'GRUPOS INFANTIL'!C3 -> NACIDOS 2008 2009
B21: =+'GRUPOS INFANTIL'!C4 -> NOV 30 1 Y 2 DICIEMBRE 2024

Sheet IMPRIMIR
A1: Campeonato Nacional de Futbol
A2: “COPA FUTURO TALENTO”
B4: =+'GRUPOS INFANTIL'!D7 -> GRUPO A | D4: =+'GRUPOS INFANTIL'!H7 -> GRUPO B | G4: =+'GRUPOS INFANTIL'!F7 -> 0 | N4: =+'GRUPOS INFANTIL'!#REF! -> #REF!
B5: =+'GRUPOS INFANTIL'!D8 -> H&C.SPORT | D5: =+'GRUPOS INFANTIL'!H8 -> ALIANZA TOLIMENSE | G5: =+'GRUPOS INFANTIL'!F8 -> 0 | N5: =+'GRUPOS INFANTIL'!#REF! -> #REF!
B6: =+'GRUPOS INFANTIL'!D9 -> TALENTO TOLIMENSE | D6: =+'GRUPOS INFANTIL'!H9 -> CLUB DEPORTIVO SANPAY | G6: =+'GRUPOS INFANTIL'!F9 -> 0 | N6: =+'GRUPOS INFANTIL'!#REF! -> #REF!
B7: =+'GRUPOS INFANTIL'!D10 -> A10 ACADEMY | D7: =+'GRUPOS INFANTIL'!H10 -> CLUB DEPORTIVO EL DIAMANTE | G7: =+'GRUPOS INFANTIL'!F10 -> 0 | N7: =+'GRUPOS INFANTIL'!#REF! -> #REF!
B8: =+'GRUPOS INFANTIL'!D11 -> LE MAX TEAM | D8: =+'GRUPOS INFANTIL'!H11 -> REAL BOGOTÁ | G8: =+'GRUPOS INFANTIL'!#REF! -> #REF! | N8: =+'GRUPOS INFANTIL'!#REF! -> #REF!
B10: =+'GRUPOS INFANTIL'!C3 -> NACIDOS 2008 2009 | N10: =+'GRUPOS INFANTIL'!F11 -> 2024
B11: =+'GRUPOS INFANTIL'!C4 -> NOV 30 1 Y 2 DICIEMBRE 2024
A12: =+'GRUPO A'!B4 -> GRUPO A
A14: PARTIDOS fecha 1
A16: =+'GRUPO A'!B20 -> 42812 | B16: =+'GRUPO A'!C20 -> 07:15. a.m. | D16: =+'GRUPO A'!E20 -> H&C.SPORT | F16: =IF(AND(G16<>"",I16<>""),IF(G16=I16,"E",IF(G16>I16,"G","P")),"") | H16: - | J16: =IF(AND(I16<>"",G16<>""),IF(I16=G16,"E",IF(I16>G16,"G","P")),"") | K16: =+'GRUPO A'!K20 -> TALENTO TOLIMENSE | O16: =+'GRUPO A'!M20 -> CANCHA 2
A18: =+'GRUPO A'!B23 -> 42812 | B18: =+'GRUPO A'!C23 -> 08:20. a.m. | D18: =+'GRUPO A'!E23 -> A10 ACADEMY | F18: =IF(AND(G18<>"",I18<>""),IF(G18=I18,"E",IF(G18>I18,"G","P")),"") | H18: - | J18: =IF(AND(I18<>"",G18<>""),IF(I18=G18,"E",IF(I18>G18,"G","P")),"") | K18: =+'GRUPO A'!K23 -> LE MAX TEAM | O18: =+'GRUPO A'!M23 -> LAS VEGAS
A20: =+'GRUPO B'!B4 -> GRUPO B
A22: PARTIDOS fecha 1
A24: =+'GRUPO B'!B20 -> 42812 | B24: =+'GRUPO B'!C20 -> 12:00. m.d. | D24: =+'GRUPO B'!E20 -> ALIANZA TOLIMENSE | F24: =IF(AND(G24<>"",I24<>""),IF(G24=I24,"E",IF(G24>I24,"G","P")),"") | H24: - | J24: =IF(AND(I24<>"",G24<>""),IF(I24=G24,"E",IF(I24>G24,"G","P")),"") | K24: =+'GRUPO B'!K20 -> CLUB DEPORTIVO SANPAY | O24: =+'GRUPO B'!M20 -> CANCHA 2
A26: =+'GRUPO B'!B23 -> 42812 | B26: =+'GRUPO B'!C23 -> 01:10. p.m. | D26: =+'GRUPO B'!E23 -> CLUB DEPORTIVO EL DIAMANTE | F26: =IF(AND(G26<>"",I26<>""),IF(G26=I26,"E",IF(G26>I26,"G","P")),"") | H26: - | J26: =IF(AND(I26<>"",G26<>""),IF(I26=G26,"E",IF(I26>G26,"G","P")),"") | K26: =+'GRUPO B'!K23 -> REAL BOGOTÁ | O26: =+'GRUPO B'!M23 -> CANCHA 2
A27: =+#REF! -> #REF!
A29: PARTIDOS fecha 1
A31: =+#REF! -> #REF! | B31: =+#REF! -> #REF! | D31: =+#REF! -> #REF! | F31: =IF(AND(G31<>"",I31<>""),IF(G31=I31,"E",IF(G31>I31,"G","P")),"") | H31: - | J31: =IF(AND(I31<>"",G31<>""),IF(I31=G31,"E",IF(I31>G31,"G","P")),"") | K31: =+#REF! -> #REF! | O31: =+#REF! -> #REF!
A33: =+#REF! -> #REF! | B33: =+#REF! -> #REF! | D33: =+#REF! -> #REF! | F33: =IF(AND(G33<>"",I33<>""),IF(G33=I33,"E",IF(G33>I33,"G","P")),"") | H33: - | J33: =IF(AND(I33<>"",G33<>""),IF(I33=G33,"E",IF(I33>G33,"G","P")),"") | K33: =+#REF! -> #REF! | O33: =+#REF! -> #REF!
A34: =+#REF! -> #REF!
A36: PARTIDOS fecha 1
A38: =+#REF! -> #REF! | B38: =+#REF! -> #REF! | D38: =+#REF! -> #REF! | F38: =IF(AND(G38<>"",I38<>""),IF(G38=I38,"E",IF(G38>I38,"G","P")),"") | H38: - | J38: =IF(AND(I38<>"",G38<>""),IF(I38=G38,"E",IF(I38>G38,"G","P")),"") | K38: =+#REF! -> #REF! | O38: =+#REF! -> #REF!
A40: =+#REF! -> #REF! | B40: =+#REF! -> #REF! | D40: =+#REF! -> #REF! | F40: =IF(AND(G40<>"",I40<>""),IF(G40=I40,"E",IF(G40>I40,"G","P")),"") | H40: - | J40: =IF(AND(I40<>"",G40<>""),IF(I40=G40,"E",IF(I40>G40,"G","P")),"") | K40: =+#REF! -> #REF! | O40: =+#REF! -> #REF!
A41: NOTA: LA ORGANIZACIÓN DEL TORNEO NO SE HACE RESPONSABLE DE ACCIDENTES O PERDIDA DE ELEMENTOS DURANTE EL TRANSCURSO DEL TORNEO. Les recordamos traer el seguro de salud de los deportistas. Tarjeta de identidad Original, Registro Civil.
A46: Sede Administrativa Cra 13 No 6-43 Barrio La Florida
A47: Celular 310 241 33 76 Fijo 2 450 593
A48: soccermelgar@outlook.com
A49: Melgar - Tolima

Sheet IMPRIMIR 2
A1: Campeonato Nacional de Futbol
A2: “COPA FUTURO TALENTO”
B4: =+'GRUPOS INFANTIL'!D7 -> GRUPO A | D4: =+'GRUPOS INFANTIL'!H7 -> GRUPO B | G4: =+'GRUPOS INFANTIL'!F7 -> 0 | N4: =+'GRUPOS INFANTIL'!#REF! -> #REF!
B5: =+'GRUPOS INFANTIL'!D8 -> H&C.SPORT | D5: =+'GRUPOS INFANTIL'!H8 -> ALIANZA TOLIMENSE | G5: =+'GRUPOS INFANTIL'!F8 -> 0 | N5: =+'GRUPOS INFANTIL'!#REF! -> #REF!
B6: =+'GRUPOS INFANTIL'!D9 -> TALENTO TOLIMENSE | D6: =+'GRUPOS INFANTIL'!H9 -> CLUB DEPORTIVO SANPAY | G6: =+'GRUPOS INFANTIL'!F9 -> 0 | N6: =+'GRUPOS INFANTIL'!#REF! -> #REF!
B7: =+'GRUPOS INFANTIL'!D10 -> A10 ACADEMY | D7: =+'GRUPOS INFANTIL'!H10 -> CLUB DEPORTIVO EL DIAMANTE | G7: =+'GRUPOS INFANTIL'!F10 -> 0 | N7: =+'GRUPOS INFANTIL'!#REF! -> #REF!
B8: =+'GRUPOS INFANTIL'!D11 -> LE MAX TEAM | D8: =+'GRUPOS INFANTIL'!H11 -> REAL BOGOTÁ | G8: =+'GRUPOS INFANTIL'!#REF! -> #REF! | N8: =+'GRUPOS INFANTIL'!#REF! -> #REF!
B10: =+'GRUPOS INFANTIL'!C3 -> NACIDOS 2008 2009 | N10: =+'GRUPOS INFANTIL'!F11 -> 2024
B11: =+'GRUPOS INFANTIL'!C4 -> NOV 30 1 Y 2 DICIEMBRE 2024
A12: =+'GRUPO A'!B4 -> GRUPO A
A14: PARTIDOS fecha 2
A16: =+'GRUPO A'!B26 -> 42812 | B16: =+'GRUPO A'!C26 -> 03:00. p.m. | D16: =+'GRUPO A'!E26 -> H&C.SPORT | F16: =IF(AND(G16<>"",I16<>""),IF(G16=I16,"E",IF(G16>I16,"G","P")),"") | H16: - | J16: =IF(AND(I16<>"",G16<>""),IF(I16=G16,"E",IF(I16>G16,"G","P")),"") | K16: =+'GRUPO A'!K26 -> A10 ACADEMY | O16: =+'GRUPO A'!M26 -> LAS VEGAS
A18: =+'GRUPO A'!B29 -> 42812 | B18: =+'GRUPO A'!C29 -> 04:00. p.m. | D18: =+'GRUPO A'!E29 -> TALENTO TOLIMENSE | F18: =IF(AND(G18<>"",I18<>""),IF(G18=I18,"E",IF(G18>I18,"G","P")),"") | H18: - | J18: =IF(AND(I18<>"",G18<>""),IF(I18=G18,"E",IF(I18>G18,"G","P")),"") | K18: =+'GRUPO A'!K29 -> LE MAX TEAM | O18: =+'GRUPO A'!M29 -> LAS VEGAS
A20: =+'GRUPO B'!B4 -> GRUPO B
A22: PARTIDOS fecha 2
A24: =+'GRUPO B'!B26 -> 42813 | B24: =+'GRUPO B'!C26 -> 09:50. a.m. | D24: =+'GRUPO B'!E26 -> ALIANZA TOLIMENSE | F24: =IF(AND(G24<>"",I24<>""),IF(G24=I24,"E",IF(G24>I24,"G","P")),"") | H24: - | J24: =IF(AND(I24<>"",G24<>""),IF(I24=G24,"E",IF(I24>G24,"G","P")),"") | K24: =+'GRUPO B'!K26 -> CLUB DEPORTIVO EL DIAMANTE | O24: =+'GRUPO B'!M26 -> CANCHA 1
A26: =+'GRUPO B'!B29 -> 42813 | B26: =+'GRUPO B'!C29 -> 10:50. a.m. | D26: =+'GRUPO B'!E29 -> CLUB DEPORTIVO SANPAY | F26: =IF(AND(G26<>"",I26<>""),IF(G26=I26,"E",IF(G26>I26,"G","P")),"") | H26: - | J26: =IF(AND(I26<>"",G26<>""),IF(I26=G26,"E",IF(I26>G26,"G","P")),"") | K26: =+'GRUPO B'!K29 -> REAL BOGOTÁ | O26: =+'GRUPO B'!M29 -> CANCHA 1
A27: =+#REF! -> #REF!
A29: PARTIDOS fecha 2
A31: =+#REF! -> #REF! | B31: =+#REF! -> #REF! | D31: =+#REF! -> #REF! | F31: =IF(AND(G31<>"",I31<>""),IF(G31=I31,"E",IF(G31>I31,"G","P")),"") | H31: - | J31: =IF(AND(I31<>"",G31<>""),IF(I31=G31,"E",IF(I31>G31,"G","P")),"") | K31: =+#REF! -> #REF! | O31: =+#REF! -> #REF!
A33: =+#REF! -> #REF! | B33: =+#REF! -> #REF! | D33: =+#REF! -> #REF! | F33: =IF(AND(G33<>"",I33<>""),IF(G33=I33,"E",IF(G33>I33,"G","P")),"") | H33: - | J33: =IF(AND(I33<>"",G33<>""),IF(I33=G33,"E",IF(I33>G33,"G","P")),"") | K33: =+#REF! -> #REF! | O33: =+#REF! -> #REF!
A34: =+#REF! -> #REF!
A36: PARTIDOS fecha 2
A38: =+#REF! -> #REF! | B38: =+#REF! -> #REF! | D38: =+#REF! -> #REF! | F38: =IF(AND(G38<>"",I38<>""),IF(G38=I38,"E",IF(G38>I38,"G","P")),"") | H38: - | J38: =IF(AND(I38<>"",G38<>""),IF(I38=G38,"E",IF(I38>G38,"G","P")),"") | K38: =+#REF! -> #REF! | O38: =+#REF! -> #REF!
A40: =+#REF! -> #REF! | B40: =+#REF! -> #REF! | D40: =+#REF! -> #REF! | F40: =IF(AND(G40<>"",I40<>""),IF(G40=I40,"E",IF(G40>I40,"G","P")),"") | H40: - | J40: =IF(AND(I40<>"",G40<>""),IF(I40=G40,"E",IF(I40>G40,"G","P")),"") | K40: =+#REF! -> #REF! | O40: =+#REF! -> #REF!
A41: NOTA: LA ORGANIZACIÓN DEL TORNEO NO SE HACE RESPONSABLE DE ACCIDENTES O PERDIDA DE ELEMENTOS DURANTE EL TRANSCURSO DEL TORNEO. Les recordamos traer el seguro de salud de los deportistas. Tarjeta de identidad Original, Registro Civil.
A46: Sede Administrativa Cra 13 No 6-43 Barrio La Florida
A47: Celular 310 241 33 76 Fijo 2 450 593
A48: soccermelgar@outlook.com
A49: Melgar - Tolima

Sheet IMPRIMIR 3
B1: Campeonato Nacional de Futbol
B2: “COPA FUTURO TALENTO”
G3: =+'GRUPOS INFANTIL'!C3 -> NACIDOS 2008 2009
G4: =+'GRUPOS INFANTIL'!C4 -> NOV 30 1 Y 2 DICIEMBRE 2024
B6: =+'GRUPOS INFANTIL'!D7 -> GRUPO A | D6: =+'GRUPO A'!Q20:Q21 -> #VALUE! | E6: =+'GRUPO A'!R20:R21 -> #VALUE! | F6: =+'GRUPO A'!S20:S21 -> #VALUE! | G6: =+'GRUPO A'!T20:T21 -> #VALUE! | H6: =+'GRUPO A'!U20:U21 -> #VALUE! | I6: =+'GRUPO A'!V20:V21 -> #VALUE! | J6: =+'GRUPO A'!W20:W21 -> #VALUE! | K6: =+'GRUPO A'!X20:X21 -> #VALUE! | L6: =+'GRUPO A'!Y20:Y21 -> #VALUE!
B8: =+'GRUPO A'!P22:P23 -> #VALUE! | D8: =+'GRUPO A'!Q22:Q23 -> #VALUE! | E8: =+'GRUPO A'!R22:R23 -> #VALUE! | F8: =+'GRUPO A'!S22:S23 -> #VALUE! | G8: =+'GRUPO A'!T22:T23 -> #VALUE! | H8: =+'GRUPO A'!U22:U23 -> #VALUE! | I8: =+'GRUPO A'!V22:V23 -> #VALUE! | J8: =+'GRUPO A'!W22:W23 -> #VALUE! | K8: =+'GRUPO A'!X22:X23 -> #VALUE! | L8: =+'GRUPO A'!Y22:Y23 -> #VALUE!
B10: =+'GRUPO A'!P24:P25 -> #VALUE! | D10: =+'GRUPO A'!Q24:Q25 -> #VALUE! | E10: =+'GRUPO A'!R24:R25 -> #VALUE! | F10: =+'GRUPO A'!S24:S25 -> #VALUE! | G10: =+'GRUPO A'!T24:T25 -> #VALUE! | H10: =+'GRUPO A'!U24:U25 -> #VALUE! | I10: =+'GRUPO A'!V24:V25 -> #VALUE! | J10: =+'GRUPO A'!W24:W25 -> #VALUE! | K10: =+'GRUPO A'!X24:X25 -> #VALUE! | L10: =+'GRUPO A'!Y24:Y25 -> #VALUE!
B12: =+'GRUPO A'!P26:P27 -> #VALUE! | D12: =+'GRUPO A'!Q26:Q27 -> #VALUE! | E12: =+'GRUPO A'!R26:R27 -> #VALUE! | F12: =+'GRUPO A'!S26:S27 -> #VALUE! | G12: =+'GRUPO A'!T26:T27 -> #VALUE! | H12: =+'GRUPO A'!U26:U27 -> #VALUE! | I12: =+'GRUPO A'!V26:V27 -> #VALUE! | J12: =+'GRUPO A'!W26:W27 -> #VALUE! | K12: =+'GRUPO A'!X26:X27 -> #VALUE! | L12: =+'GRUPO A'!Y26:Y27 -> #VALUE!
B14: =+'GRUPO A'!P28:P29 -> #VALUE! | D14: =+'GRUPO A'!Q28:Q29 -> #VALUE! | E14: =+'GRUPO A'!R28:R29 -> #VALUE! | F14: =+'GRUPO A'!S28:S29 -> #VALUE! | G14: =+'GRUPO A'!T28:T29 -> #VALUE! | H14: =+'GRUPO A'!U28:U29 -> #VALUE! | I14: =+'GRUPO A'!V28:V29 -> #VALUE! | J14: =+'GRUPO A'!W28:W29 -> #VALUE! | K14: =+'GRUPO A'!X28:X29 -> #VALUE! | L14: =+'GRUPO A'!Y28:Y29 -> #VALUE!
A17: PARTIDOS fecha 3 ULTIMA
A19: =+'GRUPO A'!B32 -> 42813 | B19: =+'GRUPO A'!C32 -> 01:15. p.m. | C19: =+'GRUPO A'!E32 -> TALENTO TOLIMENSE | E19: - | G19: =+'GRUPO A'!K32 -> A10 ACADEMY | K19: =+'GRUPO A'!M32 -> CANCHA 2
A21: =+'GRUPO A'!B35 -> 42813 | B21: =+'GRUPO A'!C35 -> 02:30. p.m. | C21: =+'GRUPO A'!E35 -> H&C.SPORT | E21: - | G21: =+'GRUPO A'!K35 -> LE MAX TEAM | K21: =+'GRUPO A'!M35 -> CANCHA 1
B23: =+'GRUPOS INFANTIL'!H7 -> GRUPO B | D23: =+'GRUPO B'!Q8 -> Pts. | E23: =+'GRUPO B'!R8 -> PJ | F23: =+'GRUPO B'!S8 -> Gan. | G23: =+'GRUPO B'!T8 -> Emp. | H23: =+'GRUPO B'!U8 -> Per. | I23: =+'GRUPO B'!V8 -> GF | J23: =+'GRUPO B'!W8 -> GC | K23: =+'GRUPO B'!X8 -> Dif. | L23: =+'GRUPO B'!Y8 -> Tj
B25: =+'GRUPO B'!P10 -> 1) CLUB DEPORTIVO EL DIAMANTE | D25: =+'GRUPO B'!Q10 -> 6 | E25: =+'GRUPO B'!R10 -> 3 | F25: =+'GRUPO B'!S10 -> 2 | G25: =+'GRUPO B'!T10 -> 0 | H25: =+'GRUPO B'!U10 -> 1 | I25: =+'GRUPO B'!V10 -> 7 | J25: =+'GRUPO B'!W10 -> 3 | K25: =+'GRUPO B'!X10 -> 4 | L25: =+'GRUPO B'!Y10 -> 0
B27: =+'GRUPO B'!P12 -> 2) CLUB DEPORTIVO SANPAY | D27: =+'GRUPO B'!Q12 -> 6 | E27: =+'GRUPO B'!R12 -> 3 | F27: =+'GRUPO B'!S12 -> 2 | G27: =+'GRUPO B'!T12 -> 0 | H27: =+'GRUPO B'!U12 -> 1 | I27: =+'GRUPO B'!V12 -> 5 | J27: =+'GRUPO B'!W12 -> 2 | K27: =+'GRUPO B'!X12 -> 3 | L27: =+'GRUPO B'!Y12 -> 0
B29: =+'GRUPO B'!P14 -> 3) ALIANZA TOLIMENSE | D29: =+'GRUPO B'!Q14 -> 6 | E29: =+'GRUPO B'!R14 -> 3 | F29: =+'GRUPO B'!S14 -> 2 | G29: =+'GRUPO B'!T14 -> 0 | H29: =+'GRUPO B'!U14 -> 1 | I29: =+'GRUPO B'!V14 -> 5 | J29: =+'GRUPO B'!W14 -> 3 | K29: =+'GRUPO B'!X14 -> 2 | L29: =+'GRUPO B'!Y14 -> 0
B31: =+'GRUPO B'!P16 -> 4) REAL BOGOTÁ | D31: =+'GRUPO B'!Q16 -> 0 | E31: =+'GRUPO B'!R16 -> 3 | F31: =+'GRUPO B'!S16 -> 0 | G31: =+'GRUPO B'!T16 -> 0 | H31: =+'GRUPO B'!U16 -> 3 | I31: =+'GRUPO B'!V16 -> 2 | J31: =+'GRUPO B'!W16 -> 11 | K31: =+'GRUPO B'!X16 -> -9 | L31: =+'GRUPO B'!Y16 -> 0
A34: PARTIDOS fecha 3 ULTIMA
A36: =+'GRUPO B'!B32 -> 42813 | B36: =+'GRUPO B'!C32 -> 04:30. p.m. | C36: =+'GRUPO B'!E32 -> ALIANZA TOLIMENSE | E36: - | G36: =+'GRUPO B'!K32 -> REAL BOGOTÁ | K36: =+'GRUPO B'!M32 -> CANCHA 1
A38: =+'GRUPO B'!B35 -> 42813 | B38: =+'GRUPO B'!C32 -> 04:30. p.m. | C38: =+'GRUPO B'!E35 -> CLUB DEPORTIVO SANPAY | E38: - | G38: =+'GRUPO B'!K35 -> CLUB DEPORTIVO EL DIAMANTE | K38: =+'GRUPO B'!M35 -> CANCHA 2
B41: =+'GRUPOS INFANTIL'!F7 -> 0 | D41: =+'GRUPO B'!Q8 -> Pts. | E41: =+'GRUPO B'!R8 -> PJ | F41: =+'GRUPO B'!S8 -> Gan. | G41: =+'GRUPO B'!T8 -> Emp. | H41: =+'GRUPO B'!U8 -> Per. | I41: =+'GRUPO B'!V8 -> GF | J41: =+'GRUPO B'!W8 -> GC | K41: =+'GRUPO B'!X8 -> Dif. | L41: =+'GRUPO B'!Y8 -> Tj
B43: =+'GRUPO B'!P10 -> 1) CLUB DEPORTIVO EL DIAMANTE | D43: =+'GRUPO B'!Q10 -> 6 | E43: =+'GRUPO B'!R10 -> 3 | F43: =+'GRUPO B'!S10 -> 2 | G43: =+'GRUPO B'!T10 -> 0 | H43: =+'GRUPO B'!U10 -> 1 | I43: =+'GRUPO B'!V10 -> 7 | J43: =+'GRUPO B'!W10 -> 3 | K43: =+'GRUPO B'!X10 -> 4 | L43: =+'GRUPO B'!Y10 -> 0
B45: =+'GRUPO B'!P12 -> 2) CLUB DEPORTIVO SANPAY | D45: =+'GRUPO B'!Q12 -> 6 | E45: =+'GRUPO B'!R12 -> 3 | F45: =+'GRUPO B'!S12 -> 2 | G45: =+'GRUPO B'!T12 -> 0 | H45: =+'GRUPO B'!U12 -> 1 | I45: =+'GRUPO B'!V12 -> 5 | J45: =+'GRUPO B'!W12 -> 2 | K45: =+'GRUPO B'!X12 -> 3 | L45: =+'GRUPO B'!Y12 -> 0
B47: =+'GRUPO B'!P14 -> 3) ALIANZA TOLIMENSE | D47: =+'GRUPO B'!Q14 -> 6 | E47: =+'GRUPO B'!R14 -> 3 | F47: =+'GRUPO B'!S14 -> 2 | G47: =+'GRUPO B'!T14 -> 0 | H47: =+'GRUPO B'!U14 -> 1 | I47: =+'GRUPO B'!V14 -> 5 | J47: =+'GRUPO B'!W14 -> 3 | K47: =+'GRUPO B'!X14 -> 2 | L47: =+'GRUPO B'!Y14 -> 0
B49: =+'GRUPO B'!P16 -> 4) REAL BOGOTÁ | D49: =+'GRUPO B'!Q16 -> 0 | E49: =+'GRUPO B'!R16 -> 3 | F49: =+'GRUPO B'!S16 -> 0 | G49: =+'GRUPO B'!T16 -> 0 | H49: =+'GRUPO B'!U16 -> 3 | I49: =+'GRUPO B'!V16 -> 2 | J49: =+'GRUPO B'!W16 -> 11 | K49: =+'GRUPO B'!X16 -> -9 | L49: =+'GRUPO B'!Y16 -> 0
A52: PARTIDOS fecha 3 ULTIMA
A54: =+#REF! -> #REF! | B54: =+#REF! -> #REF! | C54: =+#REF! -> #REF! | E54: - | G54: =+#REF! -> #REF! | K54: =+#REF! -> #REF!
A56: =+#REF! -> #REF! | B56: =+#REF! -> #REF! | C56: =+#REF! -> #REF! | E56: - | G56: =+#REF! -> #REF! | K56: =+#REF! -> #REF!
B59: =+'GRUPOS INFANTIL'!#REF! -> #REF! | D59: =+#REF! -> #REF! | E59: =+#REF! -> #REF! | F59: =+#REF! -> #REF! | G59: =+#REF! -> #REF! | H59: =+#REF! -> #REF! | I59: =+#REF! -> #REF! | J59: =+#REF! -> #REF! | K59: =+#REF! -> #REF! | L59: =+#REF! -> #REF!
B61: =+#REF! -> #REF! | D61: =+#REF! -> #REF! | E61: =+#REF! -> #REF! | F61: =+#REF! -> #REF! | G61: =+#REF! -> #REF! | H61: =+#REF! -> #REF! | I61: =+#REF! -> #REF! | J61: =+#REF! -> #REF! | K61: =+#REF! -> #REF! | L61: =+#REF! -> #REF!
B63: =+#REF! -> #REF! | D63: =+#REF! -> #REF! | E63: =+#REF! -> #REF! | F63: =+#REF! -> #REF! | G63: =+#REF! -> #REF! | H63: =+#REF! -> #REF! | I63: =+#REF! -> #REF! | J63: =+#REF! -> #REF! | K63: =+#REF! -> #REF! | L63: =+#REF! -> #REF!
B65: =+#REF! -> #REF! | D65: =+#REF! -> #REF! | E65: =+#REF! -> #REF! | F65: =+#REF! -> #REF! | G65: =+#REF! -> #REF! | H65: =+#REF! -> #REF! | I65: =+#REF! -> #REF! | J65: =+#REF! -> #REF! | K65: =+#REF! -> #REF! | L65: =+#REF! -> #REF!
B67: =+#REF! -> #REF! | D67: =+#REF! -> #REF! | E67: =+#REF! -> #REF! | F67: =+#REF! -> #REF! | G67: =+#REF! -> #REF! | H67: =+#REF! -> #REF! | I67: =+#REF! -> #REF! | J67: =+#REF! -> #REF! | K67: =+#REF! -> #REF! | L67: =+#REF! -> #REF!
A70: PARTIDOS fecha 3 ULTIMA
A72: =+#REF! -> #REF! | B72: =+#REF! -> #REF! | C72: =+#REF! -> #REF! | E72: - | G72: =+#REF! -> #REF! | K72: =+#REF! -> #REF!
A74: =+#REF! -> #REF! | B74: =+#REF! -> #REF! | C74: =+#REF! -> #REF! | E74: - | G74: =+#REF! -> #REF! | K74: =+#REF! -> #REF!
A75: La organización no se hace responsable de las posibles lesiones ocasionadas dentro y fuera del campo de juego, accidentes o perdidas de elementos durante el transcurso del torneo.
A78: Sede Administrativa Cra 13 No 6-43 Barrio La Florida
A79: Celular 310 241 33 76 Fijo 2 450 593
A80: soccermelgar@outlook.com
...

Sheet IMPRIMIR 3 (2)
B1: Campeonato Nacional de Futbol
B2: “COPA FUTURO TALENTO”
G3: =+'GRUPOS INFANTIL'!C3 -> NACIDOS 2008 2009
G4: =+'GRUPOS INFANTIL'!C4 -> NOV 30 1 Y 2 DICIEMBRE 2024
B6: =+'GRUPOS INFANTIL'!D7 -> GRUPO A | D6: =+'GRUPO A'!Q20:Q21 -> #VALUE! | E6: =+'GRUPO A'!R20:R21 -> #VALUE! | F6: =+'GRUPO A'!S20:S21 -> #VALUE! | G6: =+'GRUPO A'!T20:T21 -> #VALUE! | H6: =+'GRUPO A'!U20:U21 -> #VALUE! | I6: =+'GRUPO A'!V20:V21 -> #VALUE! | J6: =+'GRUPO A'!W20:W21 -> #VALUE! | K6: =+'GRUPO A'!X20:X21 -> #VALUE! | L6: =+'GRUPO A'!Y20:Y21 -> #VALUE!
B8: =+'GRUPO A'!P22:P23 -> #VALUE! | D8: =+'GRUPO A'!Q22:Q23 -> #VALUE! | E8: =+'GRUPO A'!R22:R23 -> #VALUE! | F8: =+'GRUPO A'!S22:S23 -> #VALUE! | G8: =+'GRUPO A'!T22:T23 -> #VALUE! | H8: =+'GRUPO A'!U22:U23 -> #VALUE! | I8: =+'GRUPO A'!V22:V23 -> #VALUE! | J8: =+'GRUPO A'!W22:W23 -> #VALUE! | K8: =+'GRUPO A'!X22:X23 -> #VALUE! | L8: =+'GRUPO A'!Y22:Y23 -> #VALUE!
B10: =+'GRUPO A'!P24:P25 -> #VALUE! | D10: =+'GRUPO A'!Q24:Q25 -> #VALUE! | E10: =+'GRUPO A'!R24:R25 -> #VALUE! | F10: =+'GRUPO A'!S24:S25 -> #VALUE! | G10: =+'GRUPO A'!T24:T25 -> #VALUE! | H10: =+'GRUPO A'!U24:U25 -> #VALUE! | I10: =+'GRUPO A'!V24:V25 -> #VALUE! | J10: =+'GRUPO A'!W24:W25 -> #VALUE! | K10: =+'GRUPO A'!X24:X25 -> #VALUE! | L10: =+'GRUPO A'!Y24:Y25 -> #VALUE!
B12: =+'GRUPO A'!P26:P27 -> #VALUE! | D12: =+'GRUPO A'!Q26:Q27 -> #VALUE! | E12: =+'GRUPO A'!R26:R27 -> #VALUE! | F12: =+'GRUPO A'!S26:S27 -> #VALUE! | G12: =+'GRUPO A'!T26:T27 -> #VALUE! | H12: =+'GRUPO A'!U26:U27 -> #VALUE! | I12: =+'GRUPO A'!V26:V27 -> #VALUE! | J12: =+'GRUPO A'!W26:W27 -> #VALUE! | K12: =+'GRUPO A'!X26:X27 -> #VALUE! | L12: =+'GRUPO A'!Y26:Y27 -> #VALUE!
B14: =+'GRUPO A'!P28:P29 -> #VALUE! | D14: =+'GRUPO A'!Q28:Q29 -> #VALUE! | E14: =+'GRUPO A'!R28:R29 -> #VALUE! | F14: =+'GRUPO A'!S28:S29 -> #VALUE! | G14: =+'GRUPO A'!T28:T29 -> #VALUE! | H14: =+'GRUPO A'!U28:U29 -> #VALUE! | I14: =+'GRUPO A'!V28:V29 -> #VALUE! | J14: =+'GRUPO A'!W28:W29 -> #VALUE! | K14: =+'GRUPO A'!X28:X29 -> #VALUE! | L14: =+'GRUPO A'!Y28:Y29 -> #VALUE!
A17: PARTIDOS fecha 3 ULTIMA
A19: =+'GRUPO A'!B32 -> 42813 | B19: =+'GRUPO A'!C32 -> 01:15. p.m. | C19: =+'GRUPO A'!E32 -> TALENTO TOLIMENSE | E19: - | G19: =+'GRUPO A'!K32 -> A10 ACADEMY | K19: =+'GRUPO A'!M32 -> CANCHA 2
A21: =+'GRUPO A'!B35 -> 42813 | B21: =+'GRUPO A'!C35 -> 02:30. p.m. | C21: =+'GRUPO A'!E35 -> H&C.SPORT | E21: - | G21: =+'GRUPO A'!K35 -> LE MAX TEAM | K21: =+'GRUPO A'!M35 -> CANCHA 1
B23: =+'GRUPOS INFANTIL'!H7 -> GRUPO B | D23: =+'GRUPO B'!Q8 -> Pts. | E23: =+'GRUPO B'!R8 -> PJ | F23: =+'GRUPO B'!S8 -> Gan. | G23: =+'GRUPO B'!T8 -> Emp. | H23: =+'GRUPO B'!U8 -> Per. | I23: =+'GRUPO B'!V8 -> GF | J23: =+'GRUPO B'!W8 -> GC | K23: =+'GRUPO B'!X8 -> Dif. | L23: =+'GRUPO B'!Y8 -> Tj
B25: =+'GRUPO B'!P10 -> 1) CLUB DEPORTIVO EL DIAMANTE | D25: =+'GRUPO B'!Q10 -> 6 | E25: =+'GRUPO B'!R10 -> 3 | F25: =+'GRUPO B'!S10 -> 2 | G25: =+'GRUPO B'!T10 -> 0 | H25: =+'GRUPO B'!U10 -> 1 | I25: =+'GRUPO B'!V10 -> 7 | J25: =+'GRUPO B'!W10 -> 3 | K25: =+'GRUPO B'!X10 -> 4 | L25: =+'GRUPO B'!Y10 -> 0
B27: =+'GRUPO B'!P12 -> 2) CLUB DEPORTIVO SANPAY | D27: =+'GRUPO B'!Q12 -> 6 | E27: =+'GRUPO B'!R12 -> 3 | F27: =+'GRUPO B'!S12 -> 2 | G27: =+'GRUPO B'!T12 -> 0 | H27: =+'GRUPO B'!U12 -> 1 | I27: =+'GRUPO B'!V12 -> 5 | J27: =+'GRUPO B'!W12 -> 2 | K27: =+'GRUPO B'!X12 -> 3 | L27: =+'GRUPO B'!Y12 -> 0
B29: =+'GRUPO B'!P14 -> 3) ALIANZA TOLIMENSE | D29: =+'GRUPO B'!Q14 -> 6 | E29: =+'GRUPO B'!R14 -> 3 | F29: =+'GRUPO B'!S14 -> 2 | G29: =+'GRUPO B'!T14 -> 0 | H29: =+'GRUPO B'!U14 -> 1 | I29: =+'GRUPO B'!V14 -> 5 | J29: =+'GRUPO B'!W14 -> 3 | K29: =+'GRUPO B'!X14 -> 2 | L29: =+'GRUPO B'!Y14 -> 0
B31: =+'GRUPO B'!P16 -> 4) REAL BOGOTÁ | D31: =+'GRUPO B'!Q16 -> 0 | E31: =+'GRUPO B'!R16 -> 3 | F31: =+'GRUPO B'!S16 -> 0 | G31: =+'GRUPO B'!T16 -> 0 | H31: =+'GRUPO B'!U16 -> 3 | I31: =+'GRUPO B'!V16 -> 2 | J31: =+'GRUPO B'!W16 -> 11 | K31: =+'GRUPO B'!X16 -> -9 | L31: =+'GRUPO B'!Y16 -> 0
A34: PARTIDOS fecha 3 ULTIMA
A36: =+'GRUPO B'!B32 -> 42813 | B36: =+'GRUPO B'!C32 -> 04:30. p.m. | C36: =+'GRUPO B'!E32 -> ALIANZA TOLIMENSE | E36: - | G36: =+'GRUPO B'!K32 -> REAL BOGOTÁ | K36: =+'GRUPO B'!M32 -> CANCHA 1
A38: =+'GRUPO B'!B35 -> 42813 | B38: =+'GRUPO B'!C32 -> 04:30. p.m. | C38: =+'GRUPO B'!E35 -> CLUB DEPORTIVO SANPAY | E38: - | G38: =+'GRUPO B'!K35 -> CLUB DEPORTIVO EL DIAMANTE | K38: =+'GRUPO B'!M35 -> CANCHA 2
B41: =+'GRUPOS INFANTIL'!F7 -> 0 | D41: =+'GRUPO B'!Q8 -> Pts. | E41: =+'GRUPO B'!R8 -> PJ | F41: =+'GRUPO B'!S8 -> Gan. | G41: =+'GRUPO B'!T8 -> Emp. | H41: =+'GRUPO B'!U8 -> Per. | I41: =+'GRUPO B'!V8 -> GF | J41: =+'GRUPO B'!W8 -> GC | K41: =+'GRUPO B'!X8 -> Dif. | L41: =+'GRUPO B'!Y8 -> Tj
B43: =+'GRUPO B'!P10 -> 1) CLUB DEPORTIVO EL DIAMANTE | D43: =+'GRUPO B'!Q10 -> 6 | E43: =+'GRUPO B'!R10 -> 3 | F43: =+'GRUPO B'!S10 -> 2 | G43: =+'GRUPO B'!T10 -> 0 | H43: =+'GRUPO B'!U10 -> 1 | I43: =+'GRUPO B'!V10 -> 7 | J43: =+'GRUPO B'!W10 -> 3 | K43: =+'GRUPO B'!X10 -> 4 | L43: =+'GRUPO B'!Y10 -> 0
B45: =+'GRUPO B'!P12 -> 2) CLUB DEPORTIVO SANPAY | D45: =+'GRUPO B'!Q12 -> 6 | E45: =+'GRUPO B'!R12 -> 3 | F45: =+'GRUPO B'!S12 -> 2 | G45: =+'GRUPO B'!T12 -> 0 | H45: =+'GRUPO B'!U12 -> 1 | I45: =+'GRUPO B'!V12 -> 5 | J45: =+'GRUPO B'!W12 -> 2 | K45: =+'GRUPO B'!X12 -> 3 | L45: =+'GRUPO B'!Y12 -> 0
B47: =+'GRUPO B'!P14 -> 3) ALIANZA TOLIMENSE | D47: =+'GRUPO B'!Q14 -> 6 | E47: =+'GRUPO B'!R14 -> 3 | F47: =+'GRUPO B'!S14 -> 2 | G47: =+'GRUPO B'!T14 -> 0 | H47: =+'GRUPO B'!U14 -> 1 | I47: =+'GRUPO B'!V14 -> 5 | J47: =+'GRUPO B'!W14 -> 3 | K47: =+'GRUPO B'!X14 -> 2 | L47: =+'GRUPO B'!Y14 -> 0
B49: =+'GRUPO B'!P16 -> 4) REAL BOGOTÁ | D49: =+'GRUPO B'!Q16 -> 0 | E49: =+'GRUPO B'!R16 -> 3 | F49: =+'GRUPO B'!S16 -> 0 | G49: =+'GRUPO B'!T16 -> 0 | H49: =+'GRUPO B'!U16 -> 3 | I49: =+'GRUPO B'!V16 -> 2 | J49: =+'GRUPO B'!W16 -> 11 | K49: =+'GRUPO B'!X16 -> -9 | L49: =+'GRUPO B'!Y16 -> 0
A52: PARTIDOS fecha 3 ULTIMA
A54: =+#REF! -> #REF! | B54: =+#REF! -> #REF! | C54: =+#REF! -> #REF! | E54: - | G54: =+#REF! -> #REF! | K54: =+#REF! -> #REF!
A56: =+#REF! -> #REF! | B56: =+#REF! -> #REF! | C56: =+#REF! -> #REF! | E56: - | G56: =+#REF! -> #REF! | K56: =+#REF! -> #REF!
B59: =+'GRUPOS INFANTIL'!#REF! -> #REF! | D59: =+#REF! -> #REF! | E59: =+#REF! -> #REF! | F59: =+#REF! -> #REF! | G59: =+#REF! -> #REF! | H59: =+#REF! -> #REF! | I59: =+#REF! -> #REF! | J59: =+#REF! -> #REF! | K59: =+#REF! -> #REF! | L59: =+#REF! -> #REF!
B61: =+#REF! -> #REF! | D61: =+#REF! -> #REF! | E61: =+#REF! -> #REF! | F61: =+#REF! -> #REF! | G61: =+#REF! -> #REF! | H61: =+#REF! -> #REF! | I61: =+#REF! -> #REF! | J61: =+#REF! -> #REF! | K61: =+#REF! -> #REF! | L61: =+#REF! -> #REF!
B63: =+#REF! -> #REF! | D63: =+#REF! -> #REF! | E63: =+#REF! -> #REF! | F63: =+#REF! -> #REF! | G63: =+#REF! -> #REF! | H63: =+#REF! -> #REF! | I63: =+#REF! -> #REF! | J63: =+#REF! -> #REF! | K63: =+#REF! -> #REF! | L63: =+#REF! -> #REF!
B65: =+#REF! -> #REF! | D65: =+#REF! -> #REF! | E65: =+#REF! -> #REF! | F65: =+#REF! -> #REF! | G65: =+#REF! -> #REF! | H65: =+#REF! -> #REF! | I65: =+#REF! -> #REF! | J65: =+#REF! -> #REF! | K65: =+#REF! -> #REF! | L65: =+#REF! -> #REF!
B67: =+#REF! -> #REF! | D67: =+#REF! -> #REF! | E67: =+#REF! -> #REF! | F67: =+#REF! -> #REF! | G67: =+#REF! -> #REF! | H67: =+#REF! -> #REF! | I67: =+#REF! -> #REF! | J67: =+#REF! -> #REF! | K67: =+#REF! -> #REF! | L67: =+#REF! -> #REF!
A70: PARTIDOS fecha 3 ULTIMA
A72: =+#REF! -> #REF! | B72: =+#REF! -> #REF! | C72: =+#REF! -> #REF! | E72: - | G72: =+#REF! -> #REF! | K72: =+#REF! -> #REF!
A74: =+#REF! -> #REF! | B74: =+#REF! -> #REF! | C74: =+#REF! -> #REF! | E74: - | G74: =+#REF! -> #REF! | K74: =+#REF! -> #REF!
A75: La organización no se hace responsable de las posibles lesiones ocasionadas dentro y fuera del campo de juego, accidentes o perdidas de elementos durante el transcurso del torneo.
A78: Sede Administrativa Cra 13 No 6-43 Barrio La Florida
A79: Celular 310 241 33 76 Fijo 2 450 593
A80: soccermelgar@outlook.com
...

Sheet CUARTOS DE FINAL
H1: Campeonato Nacional de Futbol
B2: CUARTOS DE FINAL | H2: “COPA FUTURO TALENTO”
B3: Observación: Si el partido se define por penales, éstos deben sumarse al resultado.
B4: PARTIDOS | P4: Ganador
B6: =+'CUARTOS DE FINAL.'!B6:B7 -> 42596 | C6: =+'CUARTOS DE FINAL.'!C6:C7 -> LLAVE A | D6: =+'CUARTOS DE FINAL.'!D6:D7 -> 03:00. p.m. | F6: =IF(AND(H6<>"",J6<>""),IF(H6=J6,"E",IF(H6>J6,"G","P")),"") -> E | G6: =+'CUARTOS DE FINAL.'!G6:G7 -> #N/A | H6: . | I6: - | J6: . | K6: =IF(AND(J6<>"",H6<>""),IF(J6=H6,"E",IF(J6>H6,"G","P")),"") -> E | L6: =+'CUARTOS DE FINAL.'!L6:L7 -> #REF! | N6: =+'CUARTOS DE FINAL.'!N6:N7 -> PALMARA | P6: =IF(OR(F6="E",F6=""),"",IF(F6="G",G6,L6))
B9: =+'CUARTOS DE FINAL.'!B9:B10 -> 42596 | C9: =+'CUARTOS DE FINAL.'!C9:C10 -> LLAVE B | D9: =+'CUARTOS DE FINAL.'!D9:D10 -> 04:20. p.m. | F9: =IF(AND(H9<>"",J9<>""),IF(H9=J9,"E",IF(H9>J9,"G","P")),"") -> E | G9: =+'CUARTOS DE FINAL.'!G9:G10 -> CLUB DEPORTIVO EL DIAMANTE | H9: . | I9: - | J9: . | K9: =IF(AND(J9<>"",H9<>""),IF(J9=H9,"E",IF(J9>H9,"G","P")),"") -> E | L9: =+'CUARTOS DE FINAL.'!L9:L10 -> #REF! | N9: =+'CUARTOS DE FINAL.'!N9:N10 -> CANCHA 2 | P9: =IF(OR(F9="E",F9=""),"",IF(F9="G",G9,L9))
B12: =+'CUARTOS DE FINAL.'!B12:B13 -> 42596 | C12: =+'CUARTOS DE FINAL.'!C12:C13 -> LLAVE C | D12: =+'CUARTOS DE FINAL.'!D12:D13 -> 03:00. p.m. | F12: =IF(AND(H12<>"",J12<>""),IF(H12=J12,"E",IF(H12>J12,"G","P")),"") -> E | G12: =+'CUARTOS DE FINAL.'!G12:G13 -> #REF! | H12: . | I12: - | J12: . | K12: =IF(AND(J12<>"",H12<>""),IF(J12=H12,"E",IF(J12>H12,"G","P")),"") -> E | L12: =+'CUARTOS DE FINAL.'!L12:L13 -> #N/A | N12: =+'CUARTOS DE FINAL.'!N12:N13 -> CANCHA 2 | P12: =IF(OR(F12="E",F12=""),"",IF(F12="G",G12,L12))
B15: =+'CUARTOS DE FINAL.'!B15:B16 -> 42596 | C15: =+'CUARTOS DE FINAL.'!C15:C16 -> LLAVE D | D15: =+'CUARTOS DE FINAL.'!D15:D16 -> 04:20. p.m. | F15: =IF(AND(H15<>"",J15<>""),IF(H15=J15,"E",IF(H15>J15,"G","P")),"") -> E | G15: =+'CUARTOS DE FINAL.'!G15:G16 -> #REF! | H15: . | I15: - | J15: . | K15: =IF(AND(J15<>"",H15<>""),IF(J15=H15,"E",IF(J15>H15,"G","P")),"") -> E | L15: =+'CUARTOS DE FINAL.'!L15:L16 -> CLUB DEPORTIVO SANPAY | N15: =+'CUARTOS DE FINAL.'!N15:N16 -> PALMARA | P15: =IF(OR(F15="E",F15=""),"",IF(F15="G",G15,L15))
B18: BABY FUTBOL
B21: Nacidos Año 2005-2006

Sheet IMPRIMIR 4
A1: Campeonato Nacional de Futbol
A2: “COPA FUTURO TALENTO”
A3: DEFINICIÓN DEL TORNEO
B4: Observación: Si el partido se define por penales, éstos deben sumarse al resultado.
B5: SEMIFINALES | Q5: Ganador
B7: =+#REF! -> #REF! | C7: =+#REF! -> #REF! | D7: =+#REF! -> #REF! | E7: =+#REF! -> #REF! | G7: =IF(AND(I7<>"",K7<>""),IF(I7=K7,"E",IF(I7>K7,"G","P")),"") -> #REF! | I7: =+#REF! -> #REF! | J7: - | K7: =+#REF! -> #REF! | L7: =IF(AND(K7<>"",I7<>""),IF(K7=I7,"E",IF(K7>I7,"G","P")),"") -> #REF! | M7: =+#REF! -> #REF! | O7: =+#REF! -> #REF! | Q7: =IF(OR(G7="E",G7=""),"",IF(G7="G",E7,M7)) -> #REF! | S7: =IF(OR(G7="E",G7=""),"",IF(G7="P",E7,M7)) -> #REF!
B10: =+#REF! -> #REF! | C10: =+#REF! -> #REF! | D10: =+#REF! -> #REF! | E10: =+#REF! -> #REF! | G10: =IF(AND(I10<>"",K10<>""),IF(I10=K10,"E",IF(I10>K10,"G","P")),"") -> #REF! | I10: =+#REF! -> #REF! | J10: - | K10: =+#REF! -> #REF! | L10: =IF(AND(K10<>"",I10<>""),IF(K10=I10,"E",IF(K10>I10,"G","P")),"") -> #REF! | M10: =+#REF! -> #REF! | O10: =+#REF! -> #REF! | Q10: =IF(OR(G10="E",G10=""),"",IF(G10="G",E10,M10)) -> #REF! | S10: =IF(OR(G10="E",G10=""),"",IF(G10="P",E10,M10)) -> #REF!
C14: =+'GRUPOS INFANTIL'!C3 -> NACIDOS 2008 2009 | J14: =+'GRUPOS INFANTIL'!C4 -> NOV 30 1 Y 2 DICIEMBRE 2024

Sheet IMPRIMIR 5
A1: Campeonato Nacional de Futbol
A2: “COPA FUTURO TALENTO”
A3: FINAL DEL TORNEO
B4: Observación: Si el partido se define por penales, éstos deben sumarse al resultado.
B5: Partido por el TERCER PUESTO | Q5: TERCER PUESTO
Q6: =IF(OR(G7="E",G7=""),"",IF(G7="G",H7,M7)) -> #REF!
B7: =+#REF! -> #REF! | D7: =+#REF! -> #REF! | G7: =IF(AND(I7<>"",K7<>""),IF(I7=K7,"E",IF(I7>K7,"G","P")),"") -> #REF! | H7: =+#REF! -> #REF! | I7: =+#REF! -> #REF! | J7: - | K7: =+#REF! -> #REF! | L7: =IF(AND(K7<>"",I7<>""),IF(K7=I7,"E",IF(K7>I7,"G","P")),"") -> #REF! | M7: =+#REF! -> #REF! | O7: =+#REF! -> #REF!
B11: FINAL DEL CAMPEONATO | Q11: SEGUNDO PUESTO
Q12: =IF(OR(G13="E",G13=""),"",IF(G13="P",H13,M13)) -> #REF!
B13: =+#REF! -> #REF! | D13: =+#REF! -> #REF! | G13: =IF(AND(I13<>"",K13<>""),IF(I13=K13,"E",IF(I13>K13,"G","P")),"") -> #REF! | H13: =+#REF! -> #REF! | I13: =+#REF! -> #REF! | J13: - | K13: =+#REF! -> #REF! | L13: =IF(AND(K13<>"",I13<>""),IF(K13=I13,"E",IF(K13>I13,"G","P")),"") -> #REF! | M13: =+#REF! -> #REF! | O13: =+#REF! -> #REF!
B17: CAMPEÓN “COPA FUTURO TALENTO”
B19: =IF(OR(G13="E",G13=""),"",IF(G13="G",H13,M13)) -> #REF!
C22: =+'GRUPOS INFANTIL'!C3 -> NACIDOS 2008 2009 | O22: =+'GRUPOS INFANTIL'!C4 -> NOV 30 1 Y 2 DICIEMBRE 2024

Sheet Hoja1
C1: IV Campeonato Nacional de Futbol
C2: “COPA FUTURO TALENTO”
C4: FASE GRUPOS
C6: GRUPO A | E6: GRUPO B | G6: GRUPO C | I6: GRUPO D
C7: 1 | E7: 5 | G7: 9 | I7: 13
C8: 2 | E8: 6 | G8: 10 | I8: 14
C9: 3 | E9: 7 | G9: 11 | I9: 15
C10: 4 | E10: 8 | G10: 12 | I10: 16
B12: CUARTOS DE FINAL
B14: LLAVE A | C14: PRIMERO DEL GRUPO A | F14: vs | G14: SEGUNDO DEL GRUPO C
B16: LLAVE B | C16: PRIMERO DEL GRUPO B | F16: vs | G16: SEGUNDO DEL GRUPO D
B18: LLAVE C | C18: PRIMERO DEL GRUPO C | F18: vs | G18: SEGUNDO DEL GRUPO A
B20: LLAVE D | C20: PRIMERO DEL GRUPO D | F20: vs | G20: SEGUNDO DEL GRUPO B
B22: SEMIFINAL
B24: LLAVE 1 | C24: GANADOR LLAVE A | F24: vs | G24: GANADOR LLAVE B
B26: LLAVE 2 | C26: GANADOR LLAVE C | F26: vs | G26: GANADOR LLAVE D
C28: TERCER Y CUARTO LUGAR
C30: PERDEDOR LLAVE 1 | F30: vs | G30: PERDEDOR LLAVE 2
C32: FINAL
C34: GANADOR LLAVE 1 | F34: vs | G34: GANADOR LLAVE 2

Sheet Hoja2 (2)
A1: =+'GRUPOS INFANTIL'!C1:H1 -> #VALUE!
A2: =+'GRUPOS INFANTIL'!C2:H2 -> #VALUE!
A3: =+'GRUPOS INFANTIL'!C3 -> NACIDOS 2008 2009
A4: =+'GRUPOS INFANTIL'!C4 -> NOV 30 1 Y 2 DICIEMBRE 2024
A5: CALENDARIO OFICIAL
B6: =+IMPRIMIR!A14 -> PARTIDOS fecha 1 | J6: =+'GRUPO A'!B4 -> GRUPO A | K6: =+'GRUPO A'!Q20 -> 0 | L6: =+'GRUPO A'!R20 -> 0 | M6: =+'GRUPO A'!S20 -> 0 | N6: =+'GRUPO A'!T20 -> 0 | O6: =+'GRUPO A'!U20 -> 0 | P6: =+'GRUPO A'!V20 -> 0 | Q6: =+'GRUPO A'!W20 -> 0 | R6: =+'GRUPO A'!X20 -> 0 | S6: =+'GRUPO A'!Y20 -> 0
B7: CANCHA | C7: HORA | D7: EQUIPO | E7: MARCADOR | G7: EQUIPO | H7: GRUPO | J7: =+'GRUPO A'!P22 -> 0 | K7: =+'GRUPO A'!Q22 -> 0 | L7: =+'GRUPO A'!R22 -> 0 | M7: =+'GRUPO A'!S22 -> 0 | N7: =+'GRUPO A'!T22 -> 0 | O7: =+'GRUPO A'!U22 -> 0 | P7: =+'GRUPO A'!V22 -> 0 | Q7: =+'GRUPO A'!W22 -> 0 | ... S7: =+'GRUPO A'!Y22 -> 0
A8: =+'GRUPO A'!B20 -> 42812 | B8: =+'GRUPO A'!M20 -> CANCHA 2 | C8: =+'GRUPO A'!C20 -> 07:15. a.m. | D8: =+'GRUPO A'!E20 -> H&C.SPORT | E8: =+'GRUPO A'!G20 -> 5 | F8: =+'GRUPO A'!I20 -> 0 | G8: =+'GRUPO A'!K20 -> TALENTO TOLIMENSE | H8: =+'GRUPO A'!B4 -> GRUPO A | J8: =+'GRUPO A'!P24 -> 0 | K8: =+'GRUPO A'!Q24 -> 0 | L8: =+'GRUPO A'!R24 -> 0 | M8: =+'GRUPO A'!S24 -> 0 | N8: =+'GRUPO A'!T24 -> 0 | O8: =+'GRUPO A'!U24 -> 0 | P8: =+'GRUPO A'!V24 -> 0 | Q8: =+'GRUPO A'!W24 -> 0 | ... S8: =+'GRUPO A'!Y24 -> 0
B9: =+'GRUPO A'!M23 -> LAS VEGAS | C9: =+'GRUPO A'!C23 -> 08:20. a.m. | D9: =+'GRUPO A'!E23 -> A10 ACADEMY | E9: =+'GRUPO A'!G23 -> 1 | F9: =+'GRUPO A'!I23 -> 0 | G9: =+'GRUPO A'!K23 -> LE MAX TEAM | H9: =+'GRUPO A'!B4 -> GRUPO A | J9: =+'GRUPO A'!P26 -> 0 | K9: =+'GRUPO A'!Q26 -> 0 | L9: =+'GRUPO A'!R26 -> 0 | M9: =+'GRUPO A'!S26 -> 0 | N9: =+'GRUPO A'!T26 -> 0 | O9: =+'GRUPO A'!U26 -> 0 | P9: =+'GRUPO A'!V26 -> 0 | Q9: =+'GRUPO A'!W26 -> 0 | ... S9: =+'GRUPO A'!Y26 -> 0
B10: =+'GRUPO B'!M20 -> CANCHA 2 | C10: =+'GRUPO B'!C20 -> 12:00. m.d. | D10: =+'GRUPO B'!E20 -> ALIANZA TOLIMENSE | E10: =+'GRUPO B'!G20 -> 2 | F10: =+'GRUPO B'!I20 -> 0 | G10: =+'GRUPO B'!K20 -> CLUB DEPORTIVO SANPAY | H10: =+'GRUPO B'!B4 -> GRUPO B | J10: =+'GRUPO A'!P28 -> 0 | K10: =+'GRUPO A'!Q28 -> 0 | L10: =+'GRUPO A'!R28 -> 0 | M10: =+'GRUPO A'!S28 -> 0 | N10: =+'GRUPO A'!T28 -> 0 | O10: =+'GRUPO A'!U28 -> 0 | P10: =+'GRUPO A'!V28 -> 0 | Q10: =+'GRUPO A'!W28 -> 0 | ... S10: =+'GRUPO A'!Y28 -> 0
B11: =+'GRUPO B'!M23 -> CANCHA 2 | C11: =+'GRUPO B'!C23 -> 01:10. p.m. | D11: =+'GRUPO B'!E23 -> CLUB DEPORTIVO EL DIAMANTE | E11: =+'GRUPO B'!G23 -> 5 | F11: =+'GRUPO B'!I23 -> 1 | G11: =+'GRUPO B'!K23 -> REAL BOGOTÁ | H11: =+'GRUPO B'!B4 -> GRUPO B
B12: =+#REF! -> #REF! | C12: =+#REF! -> #REF! | D12: =+#REF! -> #REF! | E12: =+#REF! -> #REF! | F12: =+#REF! -> #REF! | G12: =+#REF! -> #REF! | H12: =+#REF! -> #REF! | J12: =+'GRUPO B'!B4 -> GRUPO B | K12: =+'GRUPO B'!Q8 -> Pts. | L12: =+'GRUPO B'!R8 -> PJ | M12: =+'GRUPO B'!S8 -> Gan. | N12: =+'GRUPO B'!T8 -> Emp. | O12: =+'GRUPO B'!U8 -> Per. | P12: =+'GRUPO B'!V8 -> GF | Q12: =+'GRUPO B'!W8 -> GC | R12: =+'GRUPO B'!X8 -> Dif. | S12: =+'GRUPO B'!Y8 -> Tj
B13: =+#REF! -> #REF! | C13: =+#REF! -> #REF! | D13: =+#REF! -> #REF! | E13: =+#REF! -> #REF! | F13: =+#REF! -> #REF! | G13: =+#REF! -> #REF! | H13: =+#REF! -> #REF! | J13: =+'GRUPO B'!P10 -> 1) CLUB DEPORTIVO EL DIAMANTE | K13: =+'GRUPO B'!Q10 -> 6 | L13: =+'GRUPO B'!R10 -> 3 | M13: =+'GRUPO B'!S10 -> 2 | N13: =+'GRUPO B'!T10 -> 0 | O13: =+'GRUPO B'!U10 -> 1 | P13: =+'GRUPO B'!V10 -> 7 | Q13: =+'GRUPO B'!W10 -> 3 | ... S13: =+'GRUPO B'!Y10 -> 0
B14: =+#REF! -> #REF! | C14: =+#REF! -> #REF! | D14: =+#REF! -> #REF! | E14: =+#REF! -> #REF! | F14: =+#REF! -> #REF! | G14: =+#REF! -> #REF! | H14: =+#REF! -> #REF! | J14: =+'GRUPO B'!P12 -> 2) CLUB DEPORTIVO SANPAY | K14: =+'GRUPO B'!Q12 -> 6 | L14: =+'GRUPO B'!R12 -> 3 | M14: =+'GRUPO B'!S12 -> 2 | N14: =+'GRUPO B'!T12 -> 0 | O14: =+'GRUPO B'!U12 -> 1 | P14: =+'GRUPO B'!V12 -> 5 | Q14: =+'GRUPO B'!W12 -> 2 | ... S14: =+'GRUPO B'!Y12 -> 0
B15: =+#REF! -> #REF! | C15: =+#REF! -> #REF! | D15: =+#REF! -> #REF! | E15: =+#REF! -> #REF! | F15: =+#REF! -> #REF! | G15: =+#REF! -> #REF! | H15: =+#REF! -> #REF! | J15: =+'GRUPO B'!P14 -> 3) ALIANZA TOLIMENSE | K15: =+'GRUPO B'!Q14 -> 6 | L15: =+'GRUPO B'!R14 -> 3 | M15: =+'GRUPO B'!S14 -> 2 | N15: =+'GRUPO B'!T14 -> 0 | O15: =+'GRUPO B'!U14 -> 1 | P15: =+'GRUPO B'!V14 -> 5 | Q15: =+'GRUPO B'!W14 -> 3 | ... S15: =+'GRUPO B'!Y14 -> 0
B17: =+'IMPRIMIR 2'!A14 -> PARTIDOS fecha 2 | J17: =+'GRUPO B'!P16 -> 4) REAL BOGOTÁ | K17: =+'GRUPO B'!Q16 -> 0 | L17: =+'GRUPO B'!R16 -> 3 | M17: =+'GRUPO B'!S16 -> 0 | N17: =+'GRUPO B'!T16 -> 0 | O17: =+'GRUPO B'!U16 -> 3 | P17: =+'GRUPO B'!V16 -> 2 | Q17: =+'GRUPO B'!W16 -> 11 | ... S17: =+'GRUPO B'!Y16 -> 0
B18: CANCHA | C18: HORA | D18: EQUIPO | E18: MARCADOR | G18: EQUIPO | H18: GRUPO
A19: =+'GRUPO A'!B26 -> 42812 | B19: =+'GRUPO A'!M26 -> LAS VEGAS | C19: =+'GRUPO A'!C26 -> 03:00. p.m. | D19: =+'GRUPO A'!E26 -> H&C.SPORT | E19: =+'GRUPO A'!G26 -> 0 | F19: =+'GRUPO A'!I26 -> 4 | G19: =+'GRUPO A'!K26 -> A10 ACADEMY | H19: =+'GRUPO A'!B4 -> GRUPO A | J19: =+#REF! -> #REF! | K19: =+#REF! -> #REF! | L19: =+#REF! -> #REF! | M19: =+#REF! -> #REF! | N19: =+#REF! -> #REF! | O19: =+#REF! -> #REF! | P19: =+#REF! -> #REF! | Q19: =+#REF! -> #REF! | ... S19: =+#REF! -> #REF!
B20: =+'GRUPO A'!M29 -> LAS VEGAS | C20: =+'GRUPO A'!C29 -> 04:00. p.m. | D20: =+'GRUPO A'!E29 -> TALENTO TOLIMENSE | E20: =+'GRUPO A'!G29 -> 0 | F20: =+'GRUPO A'!I29 -> 2 | G20: =+'GRUPO A'!K29 -> LE MAX TEAM | H20: =+'GRUPO A'!B4 -> GRUPO A | J20: =+#REF! -> #REF! | K20: =+#REF! -> #REF! | L20: =+#REF! -> #REF! | M20: =+#REF! -> #REF! | N20: =+#REF! -> #REF! | O20: =+#REF! -> #REF! | P20: =+#REF! -> #REF! | Q20: =+#REF! -> #REF! | ... S20: =+#REF! -> #REF!
B21: =+'GRUPO B'!M26 -> CANCHA 1 | C21: =+'GRUPO B'!C26 -> 09:50. a.m. | D21: =+'GRUPO B'!E26 -> ALIANZA TOLIMENSE | E21: =+'GRUPO B'!G26 -> 1 | F21: =+'GRUPO B'!I26 -> 2 | G21: =+'GRUPO B'!K26 -> CLUB DEPORTIVO EL DIAMANTE | H21: =+'GRUPO B'!B4 -> GRUPO B | J21: =+#REF! -> #REF! | K21: =+#REF! -> #REF! | L21: =+#REF! -> #REF! | M21: =+#REF! -> #REF! | N21: =+#REF! -> #REF! | O21: =+#REF! -> #REF! | P21: =+#REF! -> #REF! | Q21: =+#REF! -> #REF! | ... S21: =+#REF! -> #REF!
B22: =+'GRUPO B'!M29 -> CANCHA 1 | C22: =+'GRUPO B'!C29 -> 10:50. a.m. | D22: =+'GRUPO B'!E29 -> CLUB DEPORTIVO SANPAY | E22: =+'GRUPO B'!G29 -> 4 | F22: =+'GRUPO B'!I29 -> 0 | G22: =+'GRUPO B'!K29 -> REAL BOGOTÁ | H22: =+'GRUPO B'!B4 -> GRUPO B | J22: =+#REF! -> #REF! | K22: =+#REF! -> #REF! | L22: =+#REF! -> #REF! | M22: =+#REF! -> #REF! | N22: =+#REF! -> #REF! | O22: =+#REF! -> #REF! | P22: =+#REF! -> #REF! | Q22: =+#REF! -> #REF! | ... S22: =+#REF! -> #REF!
B23: =+#REF! -> #REF! | C23: =+#REF! -> #REF! | D23: =+#REF! -> #REF! | E23: =+#REF! -> #REF! | F23: =+#REF! -> #REF! | G23: =+#REF! -> #REF! | H23: =+#REF! -> #REF! | J23: =+#REF! -> #REF! | K23: =+#REF! -> #REF! | L23: =+#REF! -> #REF! | M23: =+#REF! -> #REF! | N23: =+#REF! -> #REF! | O23: =+#REF! -> #REF! | P23: =+#REF! -> #REF! | Q23: =+#REF! -> #REF! | ... S23: =+#REF! -> #REF!
B24: =+#REF! -> #REF! | C24: =+#REF! -> #REF! | D24: =+#REF! -> #REF! | E24: =+#REF! -> #REF! | F24: =+#REF! -> #REF! | G24: =+#REF! -> #REF! | H24: =+#REF! -> #REF!
B25: =+#REF! -> #REF! | C25: =+#REF! -> #REF! | D25: =+#REF! -> #REF! | E25: =+#REF! -> #REF! | F25: =+#REF! -> #REF! | G25: =+#REF! -> #REF! | H25: =+#REF! -> #REF! | J25: =+#REF! -> #REF! | K25: =+#REF! -> #REF! | L25: =+#REF! -> #REF! | M25: =+#REF! -> #REF! | N25: =+#REF! -> #REF! | O25: =+#REF! -> #REF! | P25: =+#REF! -> #REF! | Q25: =+#REF! -> #REF! | ... S25: =+#REF! -> #REF!
B26: =+#REF! -> #REF! | C26: =+#REF! -> #REF! | D26: =+#REF! -> #REF! | E26: =+#REF! -> #REF! | F26: =+#REF! -> #REF! | G26: =+#REF! -> #REF! | H26: =+#REF! -> #REF! | J26: =+#REF! -> #REF! | K26: =+#REF! -> #REF! | L26: =+#REF! -> #REF! | M26: =+#REF! -> #REF! | N26: =+#REF! -> #REF! | O26: =+#REF! -> #REF! | P26: =+#REF! -> #REF! | Q26: =+#REF! -> #REF! | ... S26: =+#REF! -> #REF!
B28: =+'IMPRIMIR 3'!A17 -> PARTIDOS fecha 3 ULTIMA | J28: =+#REF! -> #REF! | K28: =+#REF! -> #REF! | L28: =+#REF! -> #REF! | M28: =+#REF! -> #REF! | N28: =+#REF! -> #REF! | O28: =+#REF! -> #REF! | P28: =+#REF! -> #REF! | Q28: =+#REF! -> #REF! | ... S28: =+#REF! -> #REF!
B29: CANCHA | C29: HORA | D29: EQUIPO | E29: MARCADOR | G29: EQUIPO | H29: GRUPO | J29: =+#REF! -> #REF! | K29: =+#REF! -> #REF! | L29: =+#REF! -> #REF! | M29: =+#REF! -> #REF! | N29: =+#REF! -> #REF! | O29: =+#REF! -> #REF! | P29: =+#REF! -> #REF! | Q29: =+#REF! -> #REF! | ... S29: =+#REF! -> #REF!
A30: =+'GRUPO A'!B32 -> 42813 | B30: =+'GRUPO A'!M32 -> CANCHA 2 | C30: =+'GRUPO A'!C32 -> 01:15. p.m. | D30: =+'GRUPO A'!E32 -> TALENTO TOLIMENSE | E30: =+'GRUPO A'!G32 -> 1 | F30: =+'GRUPO A'!I32 -> 2 | G30: =+'GRUPO A'!K32 -> A10 ACADEMY | H30: =+'GRUPO A'!B4 -> GRUPO A | J30: =+#REF! -> #REF! | K30: =+#REF! -> #REF! | L30: =+#REF! -> #REF! | M30: =+#REF! -> #REF! | N30: =+#REF! -> #REF! | O30: =+#REF! -> #REF! | P30: =+#REF! -> #REF! | Q30: =+#REF! -> #REF! | ... S30: =+#REF! -> #REF!
B31: =+'GRUPO A'!M35 -> CANCHA 1 | C31: =+'GRUPO A'!C35 -> 02:30. p.m. | D31: =+'GRUPO A'!E35 -> H&C.SPORT | E31: =+'GRUPO A'!G35 -> 5 | F31: =+'GRUPO A'!I35 -> 1 | G31: =+'GRUPO A'!K35 -> LE MAX TEAM | H31: =+'GRUPO A'!B4 -> GRUPO A
B32: =+'GRUPO B'!M32 -> CANCHA 1 | C32: =+'GRUPO B'!C32 -> 04:30. p.m. | D32: =+'GRUPO B'!E32 -> ALIANZA TOLIMENSE | E32: =+'GRUPO B'!G32 -> 2 | F32: =+'GRUPO B'!I32 -> 1 | G32: =+'GRUPO B'!K32 -> REAL BOGOTÁ | H32: =+'GRUPO B'!B4 -> GRUPO B
B33: =+'GRUPO B'!M35 -> CANCHA 2 | C33: =+'GRUPO B'!C35 -> 03:25. p.m. | D33: =+'GRUPO B'!E35 -> CLUB DEPORTIVO SANPAY | E33: =+'GRUPO B'!G35 -> 1 | F33: =+'GRUPO B'!I35 -> 0 | G33: =+'GRUPO B'!K35 -> CLUB DEPORTIVO EL DIAMANTE | H33: =+'GRUPO B'!B4 -> GRUPO B
B34: =+#REF! -> #REF! | C34: =+#REF! -> #REF! | D34: =+#REF! -> #REF! | E34: =+#REF! -> #REF! | F34: =+#REF! -> #REF! | G34: =+#REF! -> #REF! | H34: =+#REF! -> #REF!
B35: =+#REF! -> #REF! | C35: =+#REF! -> #REF! | D35: =+#REF! -> #REF! | E35: =+#REF! -> #REF! | F35: =+#REF! -> #REF! | G35: =+#REF! -> #REF! | H35: =+#REF! -> #REF!
B36: =+#REF! -> #REF! | C36: =+#REF! -> #REF! | D36: =+#REF! -> #REF! | E36: =+#REF! -> #REF! | F36: =+#REF! -> #REF! | G36: =+#REF! -> #REF! | H36: =+#REF! -> #REF!
B37: =+#REF! -> #REF! | C37: =+#REF! -> #REF! | D37: =+#REF! -> #REF! | E37: =+#REF! -> #REF! | F37: =+#REF! -> #REF! | G37: =+#REF! -> #REF! | H37: =+#REF! -> #REF!
B39: =+#REF! -> #REF!
B40: CANCHA | C40: HORA | D40: EQUIPO | E40: MARCADOR | G40: EQUIPO | H40: LLAVE
A41: =+'CUARTOS DE FINAL.'!B9 -> 42596 | B41: =+'CUARTOS DE FINAL.'!N6 -> PALMARA | C41: =+'CUARTOS DE FINAL.'!D6 -> 03:00. p.m. | D41: =+'CUARTOS DE FINAL.'!G6 -> #N/A | E41: =+'CUARTOS DE FINAL.'!H6 -> 1 | F41: =+'CUARTOS DE FINAL.'!J6 -> 2 | G41: =+'CUARTOS DE FINAL.'!L6 -> #REF! | H41: =+'CUARTOS DE FINAL.'!C6 -> LLAVE A
B42: =+'CUARTOS DE FINAL.'!N9 -> CANCHA 2 | C42: =+'CUARTOS DE FINAL.'!D9 -> 04:20. p.m. | D42: =+'CUARTOS DE FINAL.'!G9 -> CLUB DEPORTIVO EL DIAMANTE | E42: =+'CUARTOS DE FINAL.'!H9 -> 2 | F42: =+'CUARTOS DE FINAL.'!J9 -> 1 | G42: =+'CUARTOS DE FINAL.'!L9 -> #REF! | H42: =+'CUARTOS DE FINAL.'!C9 -> LLAVE B
B43: =+'CUARTOS DE FINAL.'!N12 -> CANCHA 2 | C43: =+'CUARTOS DE FINAL.'!D12 -> 03:00. p.m. | D43: =+'CUARTOS DE FINAL.'!G12 -> #REF! | E43: =+'CUARTOS DE FINAL.'!H12 -> 1 | F43: =+'CUARTOS DE FINAL.'!J12 -> 2 | G43: =+'CUARTOS DE FINAL.'!L12 -> #N/A | H43: =+'CUARTOS DE FINAL.'!C12 -> LLAVE C
...

Sheet Hoja2 (3)
A1: =+'GRUPOS INFANTIL'!C1:H1 -> #VALUE!
A2: =+'GRUPOS INFANTIL'!C2:H2 -> #VALUE!
A3: =+'GRUPOS INFANTIL'!C3 -> NACIDOS 2008 2009
A4: =+'GRUPOS INFANTIL'!C4 -> NOV 30 1 Y 2 DICIEMBRE 2024
A5: CALENDARIO OFICIAL
B6: =+IMPRIMIR!A14 -> PARTIDOS fecha 1 | J6: =+'GRUPO A'!B4 -> GRUPO A | K6: =+'GRUPO A'!Q20 -> 0 | L6: =+'GRUPO A'!R20 -> 0 | M6: =+'GRUPO A'!S20 -> 0 | N6: =+'GRUPO A'!T20 -> 0 | O6: =+'GRUPO A'!U20 -> 0 | P6: =+'GRUPO A'!V20 -> 0 | Q6: =+'GRUPO A'!W20 -> 0 | R6: =+'GRUPO A'!X20 -> 0 | S6: =+'GRUPO A'!Y20 -> 0
B7: CANCHA | C7: HORA | D7: EQUIPO | E7: MARCADOR | G7: EQUIPO | H7: GRUPO | J7: =+'GRUPO A'!P22 -> 0 | K7: =+'GRUPO A'!Q22 -> 0 | L7: =+'GRUPO A'!R22 -> 0 | M7: =+'GRUPO A'!S22 -> 0 | N7: =+'GRUPO A'!T22 -> 0 | O7: =+'GRUPO A'!U22 -> 0 | P7: =+'GRUPO A'!V22 -> 0 | Q7: =+'GRUPO A'!W22 -> 0 | ... S7: =+'GRUPO A'!Y22 -> 0
A8: =+'GRUPO A'!B20 -> 42812 | B8: =+'GRUPO A'!M20 -> CANCHA 2 | C8: =+'GRUPO A'!C20 -> 07:15. a.m. | D8: =+'GRUPO A'!E20 -> H&C.SPORT | E8: =+'GRUPO A'!G20 -> 5 | F8: =+'GRUPO A'!I20 -> 0 | G8: =+'GRUPO A'!K20 -> TALENTO TOLIMENSE | H8: =+'GRUPO A'!B4 -> GRUPO A | J8: =+'GRUPO A'!P24 -> 0 | K8: =+'GRUPO A'!Q24 -> 0 | L8: =+'GRUPO A'!R24 -> 0 | M8: =+'GRUPO A'!S24 -> 0 | N8: =+'GRUPO A'!T24 -> 0 | O8: =+'GRUPO A'!U24 -> 0 | P8: =+'GRUPO A'!V24 -> 0 | Q8: =+'GRUPO A'!W24 -> 0 | ... S8: =+'GRUPO A'!Y24 -> 0
