Workbook

Sheet GRUPOS INFANTIL
B1: XVIII Festival Nacional de Fútbol Infantil
B2: “COPA SOCCER MELGAR”
B3: NACIDOS 2014 2015
B4: SEPTIEMBRE 28 Y 29 DEL 2024
B6: GRUPO A | D6: GRUPO B | F6: GRUPO C | H6: GRUPO D
B7: AJAX AIMARA | D7: ESCUELA DEPORTIVA FÚTBOL RAQUIRA | F7: BLUEMARTIN F.C . | H7: ACADEMIA IGUARAN F. C.
B8: CLUB DEPORTIVO OS FUTSAL | D8: TEMPLO DEL FÚTBOL | F8: EIFD TESOROS SPORTS | H8: COLEGIO NEIL ARMSTRONG
B9: ESCUELA DE FORMACION DEPORTIVA MARACANA | D9: CLUB CAMPESTRE IBAGUE | F9: CENTAUROS DEL ARIARI | H9: CORDOBA Y CERRANO F. C.
B10: CLUB LOS PAPETICOS | H10: GRAMA F. C. | J10: 2023

Sheet GRUPO A
A1: =+'GRUPOS INFANTIL'!B1 -> XVIII Festival Nacional de Fútbol Infantil
A2: “COPA FUTURO TALENTO”
B3: =+'GRUPOS INFANTIL'!B3 -> NACIDOS 2014 2015 | F3: =+'GRUPOS INFANTIL'!B4 -> SEPTIEMBRE 28 Y 29 DEL 2024
B4: =+'GRUPOS INFANTIL'!B6 -> GRUPO A
B6: PARTIDOS | P6: POSICIONES | AJ6: =COUNT(G8,I8,G11,I11,G14,I14,G17,I17,G20,I20,G23,I23,G26,I26,G29,I29,G32,I32,G35,I35) -> 12
A7: Tj | N7: Tj
F8: =IF(AND(G8<>"",I8<>""),IF(G8=I8,"E",IF(G8>I8,"G","P")),"") | H8: - | J8: =IF(AND(I8<>"",G8<>""),IF(I8=G8,"E",IF(I8>G8,"G","P")),"") | Q8: Pts. | R8: PJ | S8: Gan. | T8: Emp. | U8: Per. | V8: GF | W8: GC | X8: Dif. | Y8: Tj | AJ8: =IF(AJ6=12,IF(INDEX(Z22:AK29,MATCH(2,Z22:Z29,0),11)=INDEX(Z22:AK29,MATCH(1,Z22:Z29,0),11),1,0),0) -> #N/A
P10: =" 1) " & VLOOKUP(1,$Z$10:$AI$17,2,0) -> 1) CLUB LOS PAPETICOS | Q10: =VLOOKUP(1,$Z$10:$AI$17,3,0) -> 7 | R10: =+SUM(S10:U11) -> 3 | S10: =VLOOKUP(1,$Z$10:$AI$17,4,0) -> 2 | T10: =VLOOKUP(1,$Z$10:$AI$17,5,0) -> 1 | U10: =VLOOKUP(1,$Z$10:$AI$17,6,0) -> 0 | V10: =VLOOKUP(1,$Z$10:$AI$17,7,0) -> 20 | W10: =VLOOKUP(1,$Z$10:$AI$17,8,0) -> 7 | X10: =VLOOKUP(1,$Z$10:$AH$17,9,0) -> 13 | Y10: =VLOOKUP(1,$Z$10:$AI$17,10,0) -> 0 | Z10: =RANK(AJ10,$AJ$10:$AJ$17,0) -> 3 | AA10: =+'GRUPOS INFANTIL'!B7 -> AJAX AIMARA | AB10: =(AC10*3)+AD10 -> 3 | AC10: =COUNTIF(Q58:T58,"G") -> 1 | AD10: =COUNTIF(Q58:T58,"E") -> 0 | AE10: =COUNTIF(Q58:T58,"P") -> 2 | AF10: =+G8+G20+G26+G35 -> 13 | AG10: =+I8+I20+I26+I35 -> 9 | AH10: =AF10-AG10 -> 4 | AI10: =+A8+A20+A26+A35 -> 0 | AJ10: =(AB10*1000)+(AH10*10)+(AF10*10)-AI10+0.1 -> 3170.1 | AK10: =AJ10+X10 -> 3183.1
F11: =IF(AND(G11<>"",I11<>""),IF(G11=I11,"E",IF(G11>I11,"G","P")),"") | H11: - | J11: =IF(AND(I11<>"",G11<>""),IF(I11=G11,"E",IF(I11>G11,"G","P")),"")
P12: =" 2) " & VLOOKUP(2,$Z$10:$AI$17,2,0) -> 2) ESCUELA DE FORMACION DEPORTIVA MARACANA | Q12: =VLOOKUP(2,$Z$10:$AI$17,3,0) -> 7 | R12: =+SUM(S12:U13) -> 3 | S12: =VLOOKUP(2,$Z$10:$AI$17,4,0) -> 2 | T12: =VLOOKUP(2,$Z$10:$AI$17,5,0) -> 1 | U12: =VLOOKUP(2,$Z$10:$AI$17,6,0) -> 0 | V12: =VLOOKUP(2,$Z$10:$AI$17,7,0) -> 13 | W12: =VLOOKUP(2,$Z$10:$AI$17,8,0) -> 4 | X12: =VLOOKUP(2,$Z$10:$AH$17,9,0) -> 9 | Y12: =VLOOKUP(2,$Z$10:$AI$17,10,0) -> 0 | Z12: =RANK(AJ12,$AJ$10:$AJ$17,0) -> 4 | AA12: =+'GRUPOS INFANTIL'!B8 -> CLUB DEPORTIVO OS FUTSAL | AB12: =(AC12*3)+AD12 -> 0 | AC12: =COUNTIF(Q59:T59,"G") -> 0 | AD12: =COUNTIF(Q59:T59,"E") -> 0 | AE12: =COUNTIF(Q59:T59,"P") -> 3 | AF12: =+G11+I20+G29+G32 -> 2 | AG12: =+I11+I29+G20+I32 -> 28 | AH12: =AF12-AG12 -> -26 | AI12: =+A29+A11+N20+A32 -> 0 | AJ12: =(AB12*1000)+(AH12*100)+(AF12*10)-AI12+0.2 -> -2579.8 | AK12: =AJ12+X12 -> -2570.8
F14: =IF(AND(G14<>"",I14<>""),IF(G14=I14,"E",IF(G14>I14,"G","P")),"") | H14: - | J14: =IF(AND(I14<>"",G14<>""),IF(I14=G14,"E",IF(I14>G14,"G","P")),"") | P14: =" 3) " & VLOOKUP(3,$Z$10:$AI$17,2,0) -> 3) AJAX AIMARA | Q14: =VLOOKUP(3,$Z$10:$AI$17,3,0) -> 3 | R14: =+SUM(S14:U15) -> 3 | S14: =VLOOKUP(3,$Z$10:$AI$17,4,0) -> 1 | T14: =VLOOKUP(3,$Z$10:$AI$17,5,0) -> 0 | U14: =VLOOKUP(3,$Z$10:$AI$17,6,0) -> 2 | V14: =VLOOKUP(3,$Z$10:$AI$17,7,0) -> 13 | W14: =VLOOKUP(3,$Z$10:$AI$17,8,0) -> 9 | X14: =VLOOKUP(3,$Z$10:$AI$17,9,0) -> 4 | Y14: =VLOOKUP(3,$Z$10:$AI$17,10,0) -> 0 | Z14: =RANK(AJ14,$AJ$10:$AJ$17,0) -> 2 | AA14: =+'GRUPOS INFANTIL'!B9 -> ESCUELA DE FORMACION DEPORTIVA MARACANA | AB14: =(AC14*3)+AD14 -> 7 | AC14: =COUNTIF(Q60:T60,"G") -> 2 | AD14: =COUNTIF(Q60:T60,"E") -> 1 | AE14: =COUNTIF(Q60:T60,"P") -> 0 | AF14: =+G14+I26+G23+I32 -> 13 | AG14: =+G26+I14+I23+G32 -> 4 | AH14: =AF14-AG14 -> 9 | AI14: =+A14+A23+N26+N32 -> 0 | AJ14: =(AB14*1000)+(AH14*100)+(AF14*10)-AI14+0.3 -> 8030.3 | AK14: =+X14 -> 4
P16: =" 4) " & VLOOKUP(4,$Z$10:$AI$17,2,0) -> 4) CLUB DEPORTIVO OS FUTSAL | Q16: =VLOOKUP(4,$Z$10:$AI$17,3,0) -> 0 | R16: =+SUM(S16:U17) -> 3 | S16: =VLOOKUP(4,$Z$10:$AI$17,4,0) -> 0 | T16: =VLOOKUP(4,$Z$10:$AI$17,5,0) -> 0 | U16: =VLOOKUP(4,$Z$10:$AI$17,6,0) -> 3 | V16: =VLOOKUP(4,$Z$10:$AI$17,7,0) -> 2 | W16: =VLOOKUP(4,$Z$10:$AI$17,8,0) -> 28 | X16: =VLOOKUP(4,$Z$10:$AI$17,9,0) -> -26 | Y16: =VLOOKUP(4,$Z$10:$AI$17,10,0) -> 0 | Z16: =RANK(AJ16,$AJ$10:$AJ$17,0) -> 1 | AA16: =+'GRUPOS INFANTIL'!B10 -> CLUB LOS PAPETICOS | AB16: =(AC16*3)+AD16 -> 7 | AC16: =COUNTIF(Q61:T61,"G") -> 2 | AD16: =COUNTIF(Q61:T61,"E") -> 1 | AE16: =COUNTIF(Q61:T61,"P") -> 0 | AF16: =+G17+I29+I23+I35 -> 20 | AG16: =+I17+G29+G23+G35 -> 7 | AH16: =AF16-AG16 -> 13 | AI16: =+A17+N23+N29+N35 -> 0 | AJ16: =(AB16*1000)+(AH16*100)+(AF16*10)-AI16+0.4 -> 8500.4 | AK16: =+X16 -> -26
F17: =IF(AND(G17<>"",I17<>""),IF(G17=I17,"E",IF(G17>I17,"G","P")),"") | H17: - | J17: =IF(AND(I17<>"",G17<>""),IF(I17=G17,"E",IF(I17>G17,"G","P")),"")
B20: 42812 | C20: 07:15. a.m. | E20: =+'GRUPOS INFANTIL'!B7 -> AJAX AIMARA | F20: =IF(AND(G20<>"",I20<>""),IF(G20=I20,"E",IF(G20>I20,"G","P")),"") -> G | G20: 10 | H20: - | I20: 0 | J20: =IF(AND(I20<>"",G20<>""),IF(I20=G20,"E",IF(I20>G20,"G","P")),"") -> P | K20: =+'GRUPOS INFANTIL'!B8 -> CLUB DEPORTIVO OS FUTSAL | M20: CANCHA 2
B23: 42812 | C23: 08:20. a.m. | E23: =+'GRUPOS INFANTIL'!B9 -> ESCUELA DE FORMACION DEPORTIVA MARACANA | F23: =IF(AND(G23<>"",I23<>""),IF(G23=I23,"E",IF(G23>I23,"G","P")),"") -> E | G23: 3 | H23: - | I23: 3 | J23: =IF(AND(I23<>"",G23<>""),IF(I23=G23,"E",IF(I23>G23,"G","P")),"") -> E | K23: =+'GRUPOS INFANTIL'!B10 -> CLUB LOS PAPETICOS | M23: LAS VEGAS
B26: 42812 | C26: 03:00. p.m. | E26: =+'GRUPOS INFANTIL'!B7 -> AJAX AIMARA | F26: =IF(AND(G26<>"",I26<>""),IF(G26=I26,"E",IF(G26>I26,"G","P")),"") -> P | G26: 1 | H26: - | I26: 2 | J26: =IF(AND(I26<>"",G26<>""),IF(I26=G26,"E",IF(I26>G26,"G","P")),"") -> G | K26: =+'GRUPOS INFANTIL'!B9 -> ESCUELA DE FORMACION DEPORTIVA MARACANA | M26: LAS VEGAS
B29: 42812 | C29: 04:00. p.m. | E29: =+'GRUPOS INFANTIL'!B8 -> CLUB DEPORTIVO OS FUTSAL | F29: =IF(AND(G29<>"",I29<>""),IF(G29=I29,"E",IF(G29>I29,"G","P")),"") -> P | G29: 2 | H29: - | I29: 10 | J29: =IF(AND(I29<>"",G29<>""),IF(I29=G29,"E",IF(I29>G29,"G","P")),"") -> G | K29: =+'GRUPOS INFANTIL'!B10 -> CLUB LOS PAPETICOS | M29: LAS VEGAS
B32: 42813 | C32: 01:15. p.m. | E32: =+'GRUPOS INFANTIL'!B8 -> CLUB DEPORTIVO OS FUTSAL | F32: =IF(AND(G32<>"",I32<>""),IF(G32=I32,"E",IF(G32>I32,"G","P")),"") -> P | G32: 0 | H32: - | I32: 8 | J32: =IF(AND(I32<>"",G32<>""),IF(I32=G32,"E",IF(I32>G32,"G","P")),"") -> G | K32: =+'GRUPOS INFANTIL'!B9 -> ESCUELA DE FORMACION DEPORTIVA MARACANA | M32: CANCHA 2
W34: =IF(AJ8=1,IF(P33="","",P33),IF(SUM(Q10:Q17)>0,VLOOKUP(1,Z10:AA17,2,0),"")) -> #N/A
B35: 42813 | C35: 02:30. p.m. | E35: =+'GRUPOS INFANTIL'!B7 -> AJAX AIMARA | F35: =IF(AND(G35<>"",I35<>""),IF(G35=I35,"E",IF(G35>I35,"G","P")),"") -> P | G35: 2 | H35: - | I35: 7 | J35: =IF(AND(I35<>"",G35<>""),IF(I35=G35,"E",IF(I35>G35,"G","P")),"") -> G | K35: =+'GRUPOS INFANTIL'!B10 -> CLUB LOS PAPETICOS | M35: CANCHA 1 | W35: =IF(AJ8=1,IF(P36="","",P36),IF(SUM(Q10:Q17)>0,VLOOKUP(2,Z10:AA17,2,0),"")) -> #N/A
J43: =IF(AG20=1,"Indique el primero y segundo equipos clasificados de la serie:","") | L43: =IF(AG20=1,"Primero:","")
J46: =IF(AG20=1,"(Debido a la paridad de los resultados, no pueden deducirse de forma automática.)","") | L46: =IF(AG20=1,"Segundo:","")
P58: =+'GRUPOS INFANTIL'!B7 -> AJAX AIMARA | Q58: =+F8 | R58: =+F20 -> G | S58: =+F26 -> P | T58: =+F35 -> P
P59: =+'GRUPOS INFANTIL'!B8 -> CLUB DEPORTIVO OS FUTSAL | Q59: =+F11 | R59: =+J20 -> P | S59: =+F29 -> P | T59: =+F32 -> P
P60: =+'GRUPOS INFANTIL'!B9 -> ESCUELA DE FORMACION DEPORTIVA MARACANA | Q60: =+F14 | R60: =+F23 -> E | S60: =+J26 -> G | T60: =+J32 -> G
P61: =+'GRUPOS INFANTIL'!B10 -> CLUB LOS PAPETICOS | Q61: =+F17 | R61: =+J23 -> E | S61: =+J29 -> G | T61: =+J35 -> G

Sheet GRUPO B
A1: =+'GRUPOS INFANTIL'!B1 -> XVIII Festival Nacional de Fútbol Infantil
A2: “COPA FUTURO TALENTO”
B3: =+'GRUPOS INFANTIL'!B3 -> NACIDOS 2014 2015 | F3: =+'GRUPOS INFANTIL'!B4 -> SEPTIEMBRE 28 Y 29 DEL 2024
B4: =+'GRUPOS INFANTIL'!D6 -> GRUPO B
B6: PARTIDOS | P6: POSICIONES | AJ6: =COUNT(G8,I8,G11,I11,G14,I14,G17,I17,G20,I20,G23,I23,G26,I26,G29,I29,G32,I32,G35,I35) -> 12
A7: Tj | N7: Tj
F8: =IF(AND(G8<>"",I8<>""),IF(G8=I8,"E",IF(G8>I8,"G","P")),"") | H8: - | J8: =IF(AND(I8<>"",G8<>""),IF(I8=G8,"E",IF(I8>G8,"G","P")),"") | Q8: Pts. | R8: PJ | S8: Gan. | T8: Emp. | U8: Per. | V8: GF | W8: GC | X8: Dif. | Y8: Tj | AJ8: =IF(AJ6=12,IF(INDEX(Z10:AK17,MATCH(2,Z10:Z17,0),11)=INDEX(Z10:AK17,MATCH(1,Z10:Z17,0),11),1,0),0) -> 0
P10: =" 1) " & VLOOKUP(1,$Z$10:$AI$17,2,0) -> 1) TEMPLO DEL FÚTBOL | Q10: =VLOOKUP(1,$Z$10:$AI$17,3,0) -> 7 | R10: =+SUM(S10:U11) -> 3 | S10: =VLOOKUP(1,$Z$10:$AI$17,4,0) -> 2 | T10: =VLOOKUP(1,$Z$10:$AI$17,5,0) -> 1 | U10: =VLOOKUP(1,$Z$10:$AI$17,6,0) -> 0 | V10: =VLOOKUP(1,$Z$10:$AI$17,7,0) -> 9 | W10: =VLOOKUP(1,$Z$10:$AI$17,8,0) -> 1 | X10: =VLOOKUP(1,$Z$10:$AH$17,9,0) -> 8 | Y10: =VLOOKUP(1,$Z$10:$AI$17,10,0) -> 0 | Z10: =RANK(AJ10,$AJ$10:$AJ$17,0) -> 3 | AA10: =+'GRUPOS INFANTIL'!D7 -> ESCUELA DEPORTIVA FÚTBOL RAQUIRA | AB10: =(AC10*3)+AD10 -> 0 | AC10: =COUNTIF(Q58:T58,"G") -> 0 | AD10: =COUNTIF(Q58:T58,"E") -> 0 | AE10: =COUNTIF(Q58:T58,"P") -> 3 | AF10: =+I8+G20+G26+G32 -> 2 | AG10: =+I20+I26+I32+G8 -> 10 | AH10: =AF10-AG10 -> -8 | AI10: =+A20+A26+A32+N8 -> 0 | AJ10: =(AB10*1000)+(AH10*100)+(AF10*10)-AI10+0.1 -> -779.9 | AK10: =AJ10+X10 -> -771.9
F11: =IF(AND(G11<>"",I11<>""),IF(G11=I11,"E",IF(G11>I11,"G","P")),"") | H11: - | J11: =IF(AND(I11<>"",G11<>""),IF(I11=G11,"E",IF(I11>G11,"G","P")),"")
P12: =" 2) " & VLOOKUP(2,$Z$10:$AI$17,2,0) -> 2) CLUB CAMPESTRE IBAGUE | Q12: =VLOOKUP(2,$Z$10:$AI$17,3,0) -> 7 | R12: =+SUM(S12:U13) -> 3 | S12: =VLOOKUP(2,$Z$10:$AI$17,4,0) -> 2 | T12: =VLOOKUP(2,$Z$10:$AI$17,5,0) -> 1 | U12: =VLOOKUP(2,$Z$10:$AI$17,6,0) -> 0 | V12: =VLOOKUP(2,$Z$10:$AI$17,7,0) -> 9 | W12: =VLOOKUP(2,$Z$10:$AI$17,8,0) -> 3 | X12: =VLOOKUP(2,$Z$10:$AH$17,9,0) -> 6 | Y12: =VLOOKUP(2,$Z$10:$AI$17,10,0) -> 0 | Z12: =RANK(AJ12,$AJ$10:$AJ$17,0) -> 1 | AA12: =+'GRUPOS INFANTIL'!D8 -> TEMPLO DEL FÚTBOL | AB12: =(AC12*3)+AD12 -> 7 | AC12: =COUNTIF(Q59:T59,"G") -> 2 | AD12: =COUNTIF(Q59:T59,"E") -> 1 | AE12: =COUNTIF(Q59:T59,"P") -> 0 | AF12: =+I20+G29+G35+I11 -> 9 | AG12: =+G20+I29+I35+G11 -> 1 | AH12: =AF12-AG12 -> 8 | AI12: =+N20+A29+A35+N11 -> 0 | AJ12: =(AB12*1000)+(AH12*100)+(AF12*10)-AI12+0.2 -> 7890.2 | AK12: =AJ12+X12 -> 7896.2
F14: =IF(AND(G14<>"",I14<>""),IF(G14=I14,"E",IF(G14>I14,"G","P")),"") | H14: - | J14: =IF(AND(I14<>"",G14<>""),IF(I14=G14,"E",IF(I14>G14,"G","P")),"") | P14: =" 3) " & VLOOKUP(3,$Z$10:$AI$17,2,0) -> 3) ESCUELA DEPORTIVA FÚTBOL RAQUIRA | Q14: =VLOOKUP(3,$Z$10:$AI$17,3,0) -> 0 | R14: =+SUM(S14:U15) -> 3 | S14: =VLOOKUP(3,$Z$10:$AI$17,4,0) -> 0 | T14: =VLOOKUP(3,$Z$10:$AI$17,5,0) -> 0 | U14: =VLOOKUP(3,$Z$10:$AI$17,6,0) -> 3 | V14: =VLOOKUP(3,$Z$10:$AI$17,7,0) -> 2 | W14: =VLOOKUP(3,$Z$10:$AI$17,8,0) -> 10 | X14: =VLOOKUP(3,$Z$10:$AI$17,9,0) -> -8 | Y14: =VLOOKUP(3,$Z$10:$AI$17,10,0) -> 0 | Z14: =RANK(AJ14,$AJ$10:$AJ$17,0) -> 2 | AA14: =+'GRUPOS INFANTIL'!D9 -> CLUB CAMPESTRE IBAGUE | AB14: =(AC14*3)+AD14 -> 7 | AC14: =COUNTIF(Q60:T60,"G") -> 2 | AD14: =COUNTIF(Q60:T60,"E") -> 1 | AE14: =COUNTIF(Q60:T60,"P") -> 0 | AF14: =+G23+I26+I35+I14 -> 9 | AG14: =+I23+G26+G35+G14 -> 3 | AH14: =AF14-AG14 -> 6 | AI14: =+A23+N26+N35+N14 -> 0 | AJ14: =(AB14*1000)+(AH14*100)+(AF14*10)-AI14+0.3 -> 7690.3 | AK14: =+X14 -> -8
F17: =IF(AND(G17<>"",I17<>""),IF(G17=I17,"E",IF(G17>I17,"G","P")),"") | H17: - | J17: =IF(AND(I17<>"",G17<>""),IF(I17=G17,"E",IF(I17>G17,"G","P")),"")
B20: 42812 | C20: 12:00. m.d. | E20: =+'GRUPOS INFANTIL'!D7 -> ESCUELA DEPORTIVA FÚTBOL RAQUIRA | F20: =IF(AND(G20<>"",I20<>""),IF(G20=I20,"E",IF(G20>I20,"G","P")),"") -> P | G20: 0 | H20: - | I20: 3 | J20: =IF(AND(I20<>"",G20<>""),IF(I20=G20,"E",IF(I20>G20,"G","P")),"") -> G | K20: =+'GRUPOS INFANTIL'!D8 -> TEMPLO DEL FÚTBOL | M20: CANCHA 2
B23: 42812 | C23: 01:10. p.m. | E23: =+'GRUPOS INFANTIL'!D9 -> CLUB CAMPESTRE IBAGUE | F23: =IF(AND(G23<>"",I23<>""),IF(G23=I23,"E",IF(G23>I23,"G","P")),"") -> G | G23: 3 | H23: - | I23: 1 | J23: =IF(AND(I23<>"",G23<>""),IF(I23=G23,"E",IF(I23>G23,"G","P")),"") -> P | K23: =+'GRUPOS INFANTIL'!F9 -> CENTAUROS DEL ARIARI | M23: CANCHA 2
B26: 42813 | C26: 09:50. a.m. | E26: =+'GRUPOS INFANTIL'!D7 -> ESCUELA DEPORTIVA FÚTBOL RAQUIRA | F26: =IF(AND(G26<>"",I26<>""),IF(G26=I26,"E",IF(G26>I26,"G","P")),"") -> P | G26: 2 | H26: - | I26: 6 | J26: =IF(AND(I26<>"",G26<>""),IF(I26=G26,"E",IF(I26>G26,"G","P")),"") -> G | K26: =+'GRUPOS INFANTIL'!D9 -> CLUB CAMPESTRE IBAGUE | M26: CANCHA 1
B29: 42813 | C29: 10:50. a.m. | E29: =+'GRUPOS INFANTIL'!D8 -> TEMPLO DEL FÚTBOL | F29: =IF(AND(G29<>"",I29<>""),IF(G29=I29,"E",IF(G29>I29,"G","P")),"") -> G | G29: 6 | H29: - | I29: 1 | J29: =IF(AND(I29<>"",G29<>""),IF(I29=G29,"E",IF(I29>G29,"G","P")),"") -> P | K29: =+'GRUPOS INFANTIL'!F8 -> EIFD TESOROS SPORTS | M29: CANCHA 1
B32: 42813 | C32: 04:30. p.m. | E32: =+'GRUPOS INFANTIL'!D7 -> ESCUELA DEPORTIVA FÚTBOL RAQUIRA | F32: =IF(AND(G32<>"",I32<>""),IF(G32=I32,"E",IF(G32>I32,"G","P")),"") -> P | G32: 0 | H32: - | I32: 1 | J32: =IF(AND(I32<>"",G32<>""),IF(I32=G32,"E",IF(I32>G32,"G","P")),"") -> G | K32: =+'GRUPOS INFANTIL'!F7 -> BLUEMARTIN F.C . | M32: CANCHA 1
W34: =IF(AJ8=1,IF(P33="","",P33),IF(SUM(Q10:Q17)>0,VLOOKUP(1,Z10:AA17,2,0),"")) -> TEMPLO DEL FÚTBOL
B35: 42813 | C35: 03:25. p.m. | E35: =+'GRUPOS INFANTIL'!D8 -> TEMPLO DEL FÚTBOL | F35: =IF(AND(G35<>"",I35<>""),IF(G35=I35,"E",IF(G35>I35,"G","P")),"") -> E | G35: 0 | H35: - | I35: 0 | J35: =IF(AND(I35<>"",G35<>""),IF(I35=G35,"E",IF(I35>G35,"G","P")),"") -> E | K35: =+'GRUPOS INFANTIL'!D9 -> CLUB CAMPESTRE IBAGUE | M35: CANCHA 2 | W35: =IF(AJ8=1,IF(P36="","",P36),IF(SUM(Q10:Q17)>0,VLOOKUP(2,Z10:AA17,2,0),"")) -> CLUB CAMPESTRE IBAGUE
J43: =IF(AG8=1,"Indique el primero y segundo equipos clasificados de la serie:","") | L43: =IF(AG8=1,"Primero:","")
J46: =IF(AG8=1,"(Debido a la paridad de los resultados, no pueden deducirse de forma automática.)","") | L46: =IF(AG8=1,"Segundo:","")
P58: =+'GRUPOS INFANTIL'!D7 -> ESCUELA DEPORTIVA FÚTBOL RAQUIRA | Q58: =+F20 -> P | R58: =+J8 | S58: =+F26 -> P | T58: =+F32 -> P
P59: =+'GRUPOS INFANTIL'!D8 -> TEMPLO DEL FÚTBOL | Q59: =+J20 -> G | R59: =+J11 | S59: =+F29 -> G | T59: =+F35 -> E
P60: =+'GRUPOS INFANTIL'!D9 -> CLUB CAMPESTRE IBAGUE | Q60: =+F23 -> G | R60: =+J14 | S60: =+J26 -> G | T60: =+J35 -> E
P61: =+'GRUPOS INFANTIL'!D10 -> 0 | Q61: =+J23 -> P | R61: =+J17 | S61: =+J29 -> P | T61: =+J32 -> G

Sheet CUARTOS DE FINAL.
H1: Campeonato Nacional de Futbol
B2: CUARTOS DE FINAL | H2: “COPA FUTURO TALENTO”
B3: Observación: Si el partido se define por penales, éstos deben sumarse al resultado.
B4: PARTIDOS | P4: Ganador
B6: 42596 | C6: LLAVE A | D6: 03:00. p.m. | F6: =IF(AND(H6<>"",J6<>""),IF(H6=J6,"E",IF(H6>J6,"G","P")),"") -> P | G6: =+'GRUPO A'!$W$34 -> #N/A | H6: 1 | I6: - | J6: 2 | K6: =IF(AND(J6<>"",H6<>""),IF(J6=H6,"E",IF(J6>H6,"G","P")),"") -> G | L6: =+#REF! -> #REF! | N6: PALMARA | P6: =IF(OR(F6="E",F6=""),"",IF(F6="G",G6,L6)) -> #REF!
B9: 42596 | C9: LLAVE B | D9: 04:20. p.m. | F9: =IF(AND(H9<>"",J9<>""),IF(H9=J9,"E",IF(H9>J9,"G","P")),"") -> G | G9: =+'GRUPO B'!$W$34 -> TEMPLO DEL FÚTBOL | H9: 2 | I9: - | J9: 1 | K9: =IF(AND(J9<>"",H9<>""),IF(J9=H9,"E",IF(J9>H9,"G","P")),"") -> P | L9: =+#REF! -> #REF! | N9: CANCHA 2 | P9: =IF(OR(F9="E",F9=""),"",IF(F9="G",G9,L9)) -> TEMPLO DEL FÚTBOL
B12: 42596 | C12: LLAVE C | D12: 03:00. p.m. | F12: =IF(AND(H12<>"",J12<>""),IF(H12=J12,"E",IF(H12>J12,"G","P")),"") -> P | G12: =+#REF! -> #REF! | H12: 1 | I12: - | J12: 2 | K12: =IF(AND(J12<>"",H12<>""),IF(J12=H12,"E",IF(J12>H12,"G","P")),"") -> G | L12: =+'GRUPO A'!$W$35 -> #N/A | N12: CANCHA 2 | P12: =IF(OR(F12="E",F12=""),"",IF(F12="G",G12,L12)) -> #N/A
B15: 42596 | C15: LLAVE D | D15: 04:20. p.m. | F15: =IF(AND(H15<>"",J15<>""),IF(H15=J15,"E",IF(H15>J15,"G","P")),"") -> G | G15: =+#REF! -> #REF! | H15: 2 | I15: - | J15: 1 | K15: =IF(AND(J15<>"",H15<>""),IF(J15=H15,"E",IF(J15>H15,"G","P")),"") -> P | L15: =+'GRUPO B'!W35 -> CLUB CAMPESTRE IBAGUE | N15: PALMARA | P15: =IF(OR(F15="E",F15=""),"",IF(F15="G",G15,L15)) -> #REF!
B18: =+'GRUPOS INFANTIL'!B3 -> NACIDOS 2014 2015
B21: =+'GRUPOS INFANTIL'!B4 -> SEPTIEMBRE 28 Y 29 DEL 2024

Sheet GRUPO C
A1: =+'GRUPOS INFANTIL'!B1 -> XVIII Festival Nacional de Fútbol Infantil
A2: “COPA FUTURO TALENTO”
B3: =+'GRUPOS INFANTIL'!B3 -> NACIDOS 2014 2015 | F3: =+'GRUPOS INFANTIL'!B4 -> SEPTIEMBRE 28 Y 29 DEL 2024
B4: =+'GRUPOS INFANTIL'!F6 -> GRUPO C
B6: PARTIDOS | P6: POSICIONES | AJ6: =COUNT(G8,I8,G11,I11,G14,I14,G17,I17,G20,I20,G23,I23,G26,I26,G29,I29,G32,I32,G35,I35) -> 12
A7: Tj | N7: Tj
F8: =IF(AND(G8<>"",I8<>""),IF(G8=I8,"E",IF(G8>I8,"G","P")),"") | H8: - | J8: =IF(AND(I8<>"",G8<>""),IF(I8=G8,"E",IF(I8>G8,"G","P")),"") | Q8: Pts. | R8: PJ | S8: Gan. | T8: Emp. | U8: Per. | V8: GF | W8: GC | X8: Dif. | Y8: Tj | AJ8: =IF(AJ6=12,IF(INDEX(Z22:AK29,MATCH(2,Z22:Z29,0),11)=INDEX(Z22:AK29,MATCH(1,Z22:Z29,0),11),1,0),0) -> #N/A
P10: =" 1) " & VLOOKUP(1,$Z$10:$AI$17,2,0) -> 1) BLUEMARTIN F.C . | Q10: =VLOOKUP(1,$Z$10:$AI$17,3,0) -> 9 | R10: =+SUM(S10:U11) -> 3 | S10: =VLOOKUP(1,$Z$10:$AI$17,4,0) -> 3 | T10: =VLOOKUP(1,$Z$10:$AI$17,5,0) -> 0 | U10: =VLOOKUP(1,$Z$10:$AI$17,6,0) -> 0 | V10: =VLOOKUP(1,$Z$10:$AI$17,7,0) -> 5 | W10: =VLOOKUP(1,$Z$10:$AI$17,8,0) -> 0 | X10: =VLOOKUP(1,$Z$10:$AH$17,9,0) -> 5 | Y10: =VLOOKUP(1,$Z$10:$AI$17,10,0) -> 0 | Z10: =RANK(AJ10,$AJ$10:$AJ$17,0) -> 1 | AA10: =+'GRUPOS INFANTIL'!F7 -> BLUEMARTIN F.C . | AB10: =(AC10*3)+AD10 -> 9 | AC10: =COUNTIF(Q58:T58,"G") -> 3 | AD10: =COUNTIF(Q58:T58,"E") -> 0 | AE10: =COUNTIF(Q58:T58,"P") -> 0 | AF10: =+G8+G20+G26+I35 -> 5 | AG10: =+I8+I20+I26+G35 -> 0 | AH10: =AF10-AG10 -> 5 | AI10: =+A8+A20+A26+A35 -> 0 | AJ10: =(AB10*1000)+(AH10*100)+(AF10*10)-AI10+0.1 -> 9550.1 | AK10: =AJ10+X10 -> 9555.1
F11: =IF(AND(G11<>"",I11<>""),IF(G11=I11,"E",IF(G11>I11,"G","P")),"") | H11: - | J11: =IF(AND(I11<>"",G11<>""),IF(I11=G11,"E",IF(I11>G11,"G","P")),"")
P12: =" 2) " & VLOOKUP(2,$Z$10:$AI$17,2,0) -> 2) CENTAUROS DEL ARIARI | Q12: =VLOOKUP(2,$Z$10:$AI$17,3,0) -> 3 | R12: =+SUM(S12:U13) -> 3 | S12: =VLOOKUP(2,$Z$10:$AI$17,4,0) -> 1 | T12: =VLOOKUP(2,$Z$10:$AI$17,5,0) -> 0 | U12: =VLOOKUP(2,$Z$10:$AI$17,6,0) -> 2 | V12: =VLOOKUP(2,$Z$10:$AI$17,7,0) -> 5 | W12: =VLOOKUP(2,$Z$10:$AI$17,8,0) -> 5 | X12: =VLOOKUP(2,$Z$10:$AH$17,9,0) -> 0 | Y12: =VLOOKUP(2,$Z$10:$AI$17,10,0) -> 0 | Z12: =RANK(AJ12,$AJ$10:$AJ$17,0) -> 3 | AA12: =+'GRUPOS INFANTIL'!F8 -> EIFD TESOROS SPORTS | AB12: =(AC12*3)+AD12 -> 0 | AC12: =COUNTIF(Q59:T59,"G") -> 0 | AD12: =COUNTIF(Q59:T59,"E") -> 0 | AE12: =COUNTIF(Q59:T59,"P") -> 3 | AF12: =+G11+I20+I29+G32 -> 3 | AG12: =+I11+G29+G20+I32 -> 12 | AH12: =AF12-AG12 -> -9 | AI12: =+A29+A11+N20+A32 -> 0 | AJ12: =(AB12*1000)+(AH12*100)+(AF12*10)-AI12+0.2 -> -869.8 | AK12: =AJ12+X12 -> -869.8
F14: =IF(AND(G14<>"",I14<>""),IF(G14=I14,"E",IF(G14>I14,"G","P")),"") | H14: - | J14: =IF(AND(I14<>"",G14<>""),IF(I14=G14,"E",IF(I14>G14,"G","P")),"") | P14: =" 3) " & VLOOKUP(3,$Z$10:$AI$17,2,0) -> 3) EIFD TESOROS SPORTS | Q14: =VLOOKUP(3,$Z$10:$AI$17,3,0) -> 0 | R14: =+SUM(S14:U15) -> 3 | S14: =VLOOKUP(3,$Z$10:$AI$17,4,0) -> 0 | T14: =VLOOKUP(3,$Z$10:$AI$17,5,0) -> 0 | U14: =VLOOKUP(3,$Z$10:$AI$17,6,0) -> 3 | V14: =VLOOKUP(3,$Z$10:$AI$17,7,0) -> 3 | W14: =VLOOKUP(3,$Z$10:$AI$17,8,0) -> 12 | X14: =VLOOKUP(3,$Z$10:$AI$17,9,0) -> -9 | Y14: =VLOOKUP(3,$Z$10:$AI$17,10,0) -> 0 | Z14: =RANK(AJ14,$AJ$10:$AJ$17,0) -> 2 | AA14: =+'GRUPOS INFANTIL'!F9 -> CENTAUROS DEL ARIARI | AB14: =(AC14*3)+AD14 -> 3 | AC14: =COUNTIF(Q60:T60,"G") -> 1 | AD14: =COUNTIF(Q60:T60,"E") -> 0 | AE14: =COUNTIF(Q60:T60,"P") -> 2 | AF14: =+G14+I26+I23+I32 -> 5 | AG14: =+G26+I14+I23+G32 -> 5 | AH14: =AF14-AG14 -> 0 | AI14: =+A14+A23+N26+N32 -> 0 | AJ14: =(AB14*1000)+(AH14*100)+(AF14*10)-AI14+0.3 -> 3050.3 | AK14: =+X14 -> -9
F17: =IF(AND(G17<>"",I17<>""),IF(G17=I17,"E",IF(G17>I17,"G","P")),"") | H17: - | J17: =IF(AND(I17<>"",G17<>""),IF(I17=G17,"E",IF(I17>G17,"G","P")),"")
B20: 42812 | C20: 07:15. a.m. | E20: =+'GRUPOS INFANTIL'!F7 -> BLUEMARTIN F.C . | F20: =IF(AND(G20<>"",I20<>""),IF(G20=I20,"E",IF(G20>I20,"G","P")),"") -> G | G20: 2 | H20: - | I20: 0 | J20: =IF(AND(I20<>"",G20<>""),IF(I20=G20,"E",IF(I20>G20,"G","P")),"") -> P | K20: =+'GRUPOS INFANTIL'!F8 -> EIFD TESOROS SPORTS | M20: CANCHA 2
B23: 42812 | C23: 08:20. a.m. | E23: =+'GRUPO B'!E23:E24 -> CLUB CAMPESTRE IBAGUE | F23: =IF(AND(G23<>"",I23<>""),IF(G23=I23,"E",IF(G23>I23,"G","P")),"") -> G | G23: 3 | H23: - | I23: 1 | J23: =IF(AND(I23<>"",G23<>""),IF(I23=G23,"E",IF(I23>G23,"G","P")),"") -> P | K23: =+'GRUPOS INFANTIL'!F9 -> CENTAUROS DEL ARIARI | M23: LAS VEGAS
B26: 42812 | C26: 03:00. p.m. | E26: =+'GRUPOS INFANTIL'!F7 -> BLUEMARTIN F.C . | F26: =IF(AND(G26<>"",I26<>""),IF(G26=I26,"E",IF(G26>I26,"G","P")),"") -> G | G26: 2 | H26: - | I26: 0 | J26: =IF(AND(I26<>"",G26<>""),IF(I26=G26,"E",IF(I26>G26,"G","P")),"") -> P | K26: =+'GRUPOS INFANTIL'!F9 -> CENTAUROS DEL ARIARI | M26: LAS VEGAS
B29: 42812 | C29: 04:00. p.m. | E29: =+'GRUPO B'!E29:E30 -> TEMPLO DEL FÚTBOL | F29: =IF(AND(G29<>"",I29<>""),IF(G29=I29,"E",IF(G29>I29,"G","P")),"") -> G | G29: 6 | H29: - | I29: 1 | J29: =IF(AND(I29<>"",G29<>""),IF(I29=G29,"E",IF(I29>G29,"G","P")),"") -> P | K29: =+'GRUPOS INFANTIL'!F8 -> EIFD TESOROS SPORTS | M29: LAS VEGAS
B32: 42813 | C32: 01:15. p.m. | E32: =+'GRUPOS INFANTIL'!F8 -> EIFD TESOROS SPORTS | F32: =IF(AND(G32<>"",I32<>""),IF(G32=I32,"E",IF(G32>I32,"G","P")),"") -> P | G32: 2 | H32: - | I32: 4 | J32: =IF(AND(I32<>"",G32<>""),IF(I32=G32,"E",IF(I32>G32,"G","P")),"") -> G | K32: =+'GRUPOS INFANTIL'!F9 -> CENTAUROS DEL ARIARI | M32: CANCHA 2
W34: =IF(AJ8=1,IF(P33="","",P33),IF(SUM(Q10:Q17)>0,VLOOKUP(1,Z10:AA17,2,0),"")) -> #N/A
B35: 42813 | C35: 02:30. p.m. | E35: =+'GRUPO B'!E32 -> ESCUELA DEPORTIVA FÚTBOL RAQUIRA | F35: =IF(AND(G35<>"",I35<>""),IF(G35=I35,"E",IF(G35>I35,"G","P")),"") -> P | G35: 0 | H35: - | I35: 1 | J35: =IF(AND(I35<>"",G35<>""),IF(I35=G35,"E",IF(I35>G35,"G","P")),"") -> G | K35: =+'GRUPOS INFANTIL'!F7 -> BLUEMARTIN F.C . | M35: CANCHA 1 | W35: =IF(AJ8=1,IF(P36="","",P36),IF(SUM(Q10:Q17)>0,VLOOKUP(2,Z10:AA17,2,0),"")) -> #N/A
J43: =IF(AG20=1,"Indique el primero y segundo equipos clasificados de la serie:","") | L43: =IF(AG20=1,"Primero:","")
J46: =IF(AG20=1,"(Debido a la paridad de los resultados, no pueden deducirse de forma automática.)","") | L46: =IF(AG20=1,"Segundo:","")
P58: =+'GRUPOS INFANTIL'!F7 -> BLUEMARTIN F.C . | Q58: =+F8 | R58: =+F20 -> G | S58: =+F26 -> G | T58: =+J35 -> G
P59: =+'GRUPOS INFANTIL'!F8 -> EIFD TESOROS SPORTS | Q59: =+F11 | R59: =+J20 -> P | S59: =+J29 -> P | T59: =+F32 -> P
P60: =+'GRUPOS INFANTIL'!F9 -> CENTAUROS DEL ARIARI | Q60: =+F14 | R60: =+J23 -> P | S60: =+J26 -> P | T60: =+J32 -> G
P61: =+'GRUPOS INFANTIL'!F10 -> 0 | Q61: =+F17 | R61: =+J23 -> P | S61: =+J29 -> P | T61: =+J35 -> G

Sheet GRUPO D
A1: =+'GRUPOS INFANTIL'!B1 -> XVIII Festival Nacional de Fútbol Infantil
A2: “COPA FUTURO TALENTO”
B3: =+'GRUPOS INFANTIL'!B3 -> NACIDOS 2014 2015 | F3: =+'GRUPOS INFANTIL'!B4 -> SEPTIEMBRE 28 Y 29 DEL 2024
B4: =+'GRUPOS INFANTIL'!H6 -> GRUPO D
B6: PARTIDOS | P6: POSICIONES | AJ6: =COUNT(G8,I8,G11,I11,G14,I14,G17,I17,G20,I20,G23,I23,G26,I26,G29,I29,G32,I32,G35,I35) -> 12
A7: Tj | N7: Tj
F8: =IF(AND(G8<>"",I8<>""),IF(G8=I8,"E",IF(G8>I8,"G","P")),"") | H8: - | J8: =IF(AND(I8<>"",G8<>""),IF(I8=G8,"E",IF(I8>G8,"G","P")),"") | Q8: Pts. | R8: PJ | S8: Gan. | T8: Emp. | U8: Per. | V8: GF | W8: GC | X8: Dif. | Y8: Tj | AJ8: =IF(AJ6=12,IF(INDEX(Z22:AK29,MATCH(2,Z22:Z29,0),11)=INDEX(Z22:AK29,MATCH(1,Z22:Z29,0),11),1,0),0) -> #N/A
P10: =" 1) " & VLOOKUP(1,$Z$10:$AI$17,2,0) -> 1) ACADEMIA IGUARAN F. C. | Q10: =VLOOKUP(1,$Z$10:$AI$17,3,0) -> 9 | R10: =+SUM(S10:U11) -> 3 | S10: =VLOOKUP(1,$Z$10:$AI$17,4,0) -> 3 | T10: =VLOOKUP(1,$Z$10:$AI$17,5,0) -> 0 | U10: =VLOOKUP(1,$Z$10:$AI$17,6,0) -> 0 | V10: =VLOOKUP(1,$Z$10:$AI$17,7,0) -> 15 | W10: =VLOOKUP(1,$Z$10:$AI$17,8,0) -> 3 | X10: =VLOOKUP(1,$Z$10:$AH$17,9,0) -> 12 | Y10: =VLOOKUP(1,$Z$10:$AI$17,10,0) -> 0 | Z10: =RANK(AJ10,$AJ$10:$AJ$17,0) -> 1 | AA10: =+'GRUPOS INFANTIL'!H7 -> ACADEMIA IGUARAN F. C. | AB10: =(AC10*3)+AD10 -> 9 | AC10: =COUNTIF(Q58:T58,"G") -> 3 | AD10: =COUNTIF(Q58:T58,"E") -> 0 | AE10: =COUNTIF(Q58:T58,"P") -> 0 | AF10: =+G8+G20+G26+G35 -> 15 | AG10: =+I8+I20+I26+I35 -> 3 | AH10: =AF10-AG10 -> 12 | AI10: =+A8+A20+A26+A35 -> 0 | AJ10: =(AB10*1000)+(AH10*100)+(AF10*10)-AI10+0.1 -> 10350.1 | AK10: =AJ10+X10 -> 10362.1
F11: =IF(AND(G11<>"",I11<>""),IF(G11=I11,"E",IF(G11>I11,"G","P")),"") | H11: - | J11: =IF(AND(I11<>"",G11<>""),IF(I11=G11,"E",IF(I11>G11,"G","P")),"")
P12: =" 2) " & VLOOKUP(2,$Z$10:$AI$17,2,0) -> 2) GRAMA F. C. | Q12: =VLOOKUP(2,$Z$10:$AI$17,3,0) -> 4 | R12: =+SUM(S12:U13) -> 3 | S12: =VLOOKUP(2,$Z$10:$AI$17,4,0) -> 1 | T12: =VLOOKUP(2,$Z$10:$AI$17,5,0) -> 1 | U12: =VLOOKUP(2,$Z$10:$AI$17,6,0) -> 1 | V12: =VLOOKUP(2,$Z$10:$AI$17,7,0) -> 13 | W12: =VLOOKUP(2,$Z$10:$AI$17,8,0) -> 9 | X12: =VLOOKUP(2,$Z$10:$AH$17,9,0) -> 4 | Y12: =VLOOKUP(2,$Z$10:$AI$17,10,0) -> 0 | Z12: =RANK(AJ12,$AJ$10:$AJ$17,0) -> 4 | AA12: =+'GRUPOS INFANTIL'!H8 -> COLEGIO NEIL ARMSTRONG | AB12: =(AC12*3)+AD12 -> 0 | AC12: =COUNTIF(Q59:T59,"G") -> 0 | AD12: =COUNTIF(Q59:T59,"E") -> 0 | AE12: =COUNTIF(Q59:T59,"P") -> 3 | AF12: =+G11+I20+G29+G32 -> 5 | AG12: =+I11+I29+G20+I32 -> 16 | AH12: =AF12-AG12 -> -11 | AI12: =+A29+A11+N20+A32 -> 0 | AJ12: =(AB12*1000)+(AH12*100)+(AF12*10)-AI12+0.2 -> -1049.8 | AK12: =AJ12+X12 -> -1045.8
F14: =IF(AND(G14<>"",I14<>""),IF(G14=I14,"E",IF(G14>I14,"G","P")),"") | H14: - | J14: =IF(AND(I14<>"",G14<>""),IF(I14=G14,"E",IF(I14>G14,"G","P")),"") | P14: =" 3) " & VLOOKUP(3,$Z$10:$AI$17,2,0) -> 3) CORDOBA Y CERRANO F. C. | Q14: =VLOOKUP(3,$Z$10:$AI$17,3,0) -> 4 | R14: =+SUM(S14:U15) -> 3 | S14: =VLOOKUP(3,$Z$10:$AI$17,4,0) -> 1 | T14: =VLOOKUP(3,$Z$10:$AI$17,5,0) -> 1 | U14: =VLOOKUP(3,$Z$10:$AI$17,6,0) -> 1 | V14: =VLOOKUP(3,$Z$10:$AI$17,7,0) -> 8 | W14: =VLOOKUP(3,$Z$10:$AI$17,8,0) -> 13 | X14: =VLOOKUP(3,$Z$10:$AI$17,9,0) -> -5 | Y14: =VLOOKUP(3,$Z$10:$AI$17,10,0) -> 0 | Z14: =RANK(AJ14,$AJ$10:$AJ$17,0) -> 3 | AA14: =+'GRUPOS INFANTIL'!H9 -> CORDOBA Y CERRANO F. C. | AB14: =(AC14*3)+AD14 -> 4 | AC14: =COUNTIF(Q60:T60,"G") -> 1 | AD14: =COUNTIF(Q60:T60,"E") -> 1 | AE14: =COUNTIF(Q60:T60,"P") -> 1 | AF14: =+G14+I26+G23+I32 -> 8 | AG14: =+G26+I14+I23+G32 -> 13 | AH14: =AF14-AG14 -> -5 | AI14: =+A14+A23+N26+N32 -> 0 | AJ14: =(AB14*1000)+(AH14*100)+(AF14*10)-AI14+0.3 -> 3580.3 | AK14: =+X14 -> -5
P16: =" 4) " & VLOOKUP(4,$Z$10:$AI$17,2,0) -> 4) COLEGIO NEIL ARMSTRONG | Q16: =VLOOKUP(4,$Z$10:$AI$17,3,0) -> 0 | R16: =+SUM(S16:U17) -> 3 | S16: =VLOOKUP(4,$Z$10:$AI$17,4,0) -> 0 | T16: =VLOOKUP(4,$Z$10:$AI$17,5,0) -> 0 | U16: =VLOOKUP(4,$Z$10:$AI$17,6,0) -> 3 | V16: =VLOOKUP(4,$Z$10:$AI$17,7,0) -> 5 | W16: =VLOOKUP(4,$Z$10:$AI$17,8,0) -> 16 | X16: =VLOOKUP(4,$Z$10:$AI$17,9,0) -> -11 | Y16: =VLOOKUP(4,$Z$10:$AI$17,10,0) -> 0 | Z16: =RANK(AJ16,$AJ$10:$AJ$17,0) -> 2 | AA16: =+'GRUPOS INFANTIL'!H10 -> GRAMA F. C. | AB16: =(AC16*3)+AD16 -> 4 | AC16: =COUNTIF(Q61:T61,"G") -> 1 | AD16: =COUNTIF(Q61:T61,"E") -> 1 | AE16: =COUNTIF(Q61:T61,"P") -> 1 | AF16: =+G17+I29+I23+I35 -> 13 | AG16: =+I17+G29+G23+G35 -> 9 | AH16: =AF16-AG16 -> 4 | AI16: =+A17+N23+N29+N35 -> 0 | AJ16: =(AB16*1000)+(AH16*100)+(AF16*10)-AI16+0.4 -> 4530.4 | AK16: =+X16 -> -11
F17: =IF(AND(G17<>"",I17<>""),IF(G17=I17,"E",IF(G17>I17,"G","P")),"") | H17: - | J17: =IF(AND(I17<>"",G17<>""),IF(I17=G17,"E",IF(I17>G17,"G","P")),"")
B20: 42812 | C20: 07:15. a.m. | E20: =+'GRUPOS INFANTIL'!H7 -> ACADEMIA IGUARAN F. C. | F20: =IF(AND(G20<>"",I20<>""),IF(G20=I20,"E",IF(G20>I20,"G","P")),"") -> G | G20: 4 | H20: - | I20: 2 | J20: =IF(AND(I20<>"",G20<>""),IF(I20=G20,"E",IF(I20>G20,"G","P")),"") -> P | K20: =+'GRUPOS INFANTIL'!H8 -> COLEGIO NEIL ARMSTRONG | M20: CANCHA 2
B23: 42812 | C23: 08:20. a.m. | E23: =+'GRUPOS INFANTIL'!H9 -> CORDOBA Y CERRANO F. C. | F23: =IF(AND(G23<>"",I23<>""),IF(G23=I23,"E",IF(G23>I23,"G","P")),"") -> E | G23: 4 | H23: - | I23: 4 | J23: =IF(AND(I23<>"",G23<>""),IF(I23=G23,"E",IF(I23>G23,"G","P")),"") -> E | K23: =+'GRUPOS INFANTIL'!H10 -> GRAMA F. C. | M23: LAS VEGAS
B26: 42812 | C26: 03:00. p.m. | E26: =+'GRUPOS INFANTIL'!H7 -> ACADEMIA IGUARAN F. C. | F26: =IF(AND(G26<>"",I26<>""),IF(G26=I26,"E",IF(G26>I26,"G","P")),"") -> G | G26: 8 | H26: - | I26: 0 | J26: =IF(AND(I26<>"",G26<>""),IF(I26=G26,"E",IF(I26>G26,"G","P")),"") -> P | K26: =+'GRUPOS INFANTIL'!H9 -> CORDOBA Y CERRANO F. C. | M26: LAS VEGAS
B29: 42812 | C29: 04:00. p.m. | E29: =+'GRUPOS INFANTIL'!H8 -> COLEGIO NEIL ARMSTRONG | F29: =IF(AND(G29<>"",I29<>""),IF(G29=I29,"E",IF(G29>I29,"G","P")),"") -> P | G29: 2 | H29: - | I29: 8 | J29: =IF(AND(I29<>"",G29<>""),IF(I29=G29,"E",IF(I29>G29,"G","P")),"") -> G | K29: =+'GRUPOS INFANTIL'!H10 -> GRAMA F. C. | M29: LAS VEGAS
B32: 42813 | C32: 01:15. p.m. | E32: =+'GRUPOS INFANTIL'!H8 -> COLEGIO NEIL ARMSTRONG | F32: =IF(AND(G32<>"",I32<>""),IF(G32=I32,"E",IF(G32>I32,"G","P")),"") -> P | G32: 1 | H32: - | I32: 4 | J32: =IF(AND(I32<>"",G32<>""),IF(I32=G32,"E",IF(I32>G32,"G","P")),"") -> G | K32: =+'GRUPOS INFANTIL'!H9 -> CORDOBA Y CERRANO F. C. | M32: CANCHA 2
W34: =IF(AJ8=1,IF(P33="","",P33),IF(SUM(Q10:Q17)>0,VLOOKUP(1,Z10:AA17,2,0),"")) -> #N/A
B35: 42813 | C35: 02:30. p.m. | E35: =+'GRUPOS INFANTIL'!H7 -> ACADEMIA IGUARAN F. C. | F35: =IF(AND(G35<>"",I35<>""),IF(G35=I35,"E",IF(G35>I35,"G","P")),"") -> G | G35: 3 | H35: - | I35: 1 | J35: =IF(AND(I35<>"",G35<>""),IF(I35=G35,"E",IF(I35>G35,"G","P")),"") -> P | K35: =+'GRUPOS INFANTIL'!H10 -> GRAMA F. C. | M35: CANCHA 1 | W35: =IF(AJ8=1,IF(P36="","",P36),IF(SUM(Q10:Q17)>0,VLOOKUP(2,Z10:AA17,2,0),"")) -> #N/A
J43: =IF(AG20=1,"Indique el primero y segundo equipos clasificados de la serie:","") | L43: =IF(AG20=1,"Primero:","")
J46: =IF(AG20=1,"(Debido a la paridad de los resultados, no pueden deducirse de forma automática.)","") | L46: =IF(AG20=1,"Segundo:","")
P58: =+'GRUPOS INFANTIL'!H7 -> ACADEMIA IGUARAN F. C. | Q58: =+F8 | R58: =+F20 -> G | S58: =+F26 -> G | T58: =+F35 -> G
P59: =+'GRUPOS INFANTIL'!H8 -> COLEGIO NEIL ARMSTRONG | Q59: =+F11 | R59: =+J20 -> P | S59: =+F29 -> P | T59: =+F32 -> P
P60: =+'GRUPOS INFANTIL'!H9 -> CORDOBA Y CERRANO F. C. | Q60: =+F14 | R60: =+F23 -> E | S60: =+J26 -> P | T60: =+J32 -> G
P61: =+'GRUPOS INFANTIL'!H10 -> GRAMA F. C. | Q61: =+F17 | R61: =+J23 -> E | S61: =+J29 -> G | T61: =+J35 -> P

Sheet IMPRIMIR HOJA
A1: =+'GRUPOS INFANTIL'!B1 -> XVIII Festival Nacional de Fútbol Infantil
A2: =+'GRUPOS INFANTIL'!B2 -> “COPA SOCCER MELGAR”
A3: =+'GRUPOS INFANTIL'!B3 -> NACIDOS 2014 2015
A4: =+'GRUPOS INFANTIL'!B4 -> SEPTIEMBRE 28 Y 29 DEL 2024
A6: CALENDARIO OFICIAL
B7: PARTIDOS FECHA 1 | K7: =+'GRUPO A'!B4 -> GRUPO A | L7: =+'GRUPO A'!Q8 -> Pts. | M7: =+'GRUPO A'!R8 -> PJ | N7: =+'GRUPO A'!S8 -> Gan. | O7: =+'GRUPO A'!T8 -> Emp. | P7: =+'GRUPO A'!U8 -> Per. | Q7: =+'GRUPO A'!V8 -> GF | R7: =+'GRUPO A'!W8 -> GC | S7: =+'GRUPO A'!X8 -> Dif. | T7: =+'GRUPO A'!Y8 -> Tj
B8: CANCHA | C8: HORA | D8: EQUIPO | E8: MARCADOR | G8: EQUIPO | H8: GRUPO | I8: CATEGORIA | K8: =+'GRUPO A'!P10 -> 1) CLUB LOS PAPETICOS | L8: =+'GRUPO A'!Q10 -> 7 | M8: =+'GRUPO A'!R10 -> 3 | N8: =+'GRUPO A'!S10 -> 2 | O8: =+'GRUPO A'!T10 -> 1 | P8: =+'GRUPO A'!U10 -> 0 | Q8: =+'GRUPO A'!V10 -> 20 | R8: =+'GRUPO A'!W10 -> 7 | ... T8: =+'GRUPO A'!Y10 -> 0
A9: 45563 | B9: CANCHA 1 A CLUB POLICIA | C9: 0.40972222 | D9: =+'GRUPO C'!E20 -> BLUEMARTIN F.C . | E9: =+'GRUPO C'!G20 -> 2 | F9: =+'GRUPO C'!I20 -> 0 | G9: =+'GRUPO C'!K20 -> EIFD TESOROS SPORTS | H9: =+'GRUPO C'!B4 -> GRUPO C | I9: =+$A$3 -> NACIDOS 2014 2015 | K9: =+'GRUPO A'!P12 -> 2) ESCUELA DE FORMACION DEPORTIVA MARACANA | L9: =+'GRUPO A'!Q12 -> 7 | M9: =+'GRUPO A'!R14 -> 3 | N9: =+'GRUPO A'!S12 -> 2 | O9: =+'GRUPO A'!T12 -> 1 | P9: =+'GRUPO A'!U12 -> 0 | Q9: =+'GRUPO A'!V12 -> 13 | R9: =+'GRUPO A'!W12 -> 4 | S9: =+'GRUPO A'!X12 -> 9 | T9: =+'GRUPO A'!Y12 -> 0
A10: 45563 | B10: CANCHA 1 B CLUB POLICIA | C10: 0.40972222 | D10: =+'GRUPO B'!E23 -> CLUB CAMPESTRE IBAGUE | E10: =+'GRUPO B'!G23 -> 3 | F10: =+'GRUPO B'!I23 -> 1 | G10: =+'GRUPO B'!K23 -> CENTAUROS DEL ARIARI | H10: INTERGRUPO | I10: =+$A$3 -> NACIDOS 2014 2015 | K10: =+'GRUPO A'!P14 -> 3) AJAX AIMARA | L10: =+'GRUPO A'!Q14 -> 3 | M10: =+'GRUPO A'!R14 -> 3 | N10: =+'GRUPO A'!S14 -> 1 | O10: =+'GRUPO A'!T14 -> 0 | P10: =+'GRUPO A'!U14 -> 2 | Q10: =+'GRUPO A'!V14 -> 13 | R10: =+'GRUPO A'!W14 -> 9 | ... T10: =+'GRUPO A'!Y14 -> 0
A11: 45563 | B11: CANCHA 1 B CLUB POLICIA | C11: 0.45833333 | D11: =+'GRUPO B'!E20 -> ESCUELA DEPORTIVA FÚTBOL RAQUIRA | E11: =+'GRUPO B'!G20 -> 0 | F11: =+'GRUPO B'!I20 -> 3 | G11: =+'GRUPO B'!K20 -> TEMPLO DEL FÚTBOL | H11: =+'GRUPO B'!B4 -> GRUPO B | I11: =+$A$3 -> NACIDOS 2014 2015 | K11: =+'GRUPO A'!P16 -> 4) CLUB DEPORTIVO OS FUTSAL | L11: =+'GRUPO A'!Q16 -> 0 | M11: =+'GRUPO A'!R16 -> 3 | N11: =+'GRUPO A'!S16 -> 0 | O11: =+'GRUPO A'!T16 -> 0 | P11: =+'GRUPO A'!U16 -> 3 | Q11: =+'GRUPO A'!V16 -> 2 | R11: =+'GRUPO A'!W16 -> 28 | ... T11: =+'GRUPO A'!Y16 -> 0
A12: 45563 | B12: ESTADIO MUNICIPAL CANCHA 1 A (SINTETICO) | C12: 0.5 | D12: =+'GRUPO A'!E26 -> AJAX AIMARA | E12: =+'GRUPO A'!G26 -> 1 | F12: =+'GRUPO A'!I26 -> 2 | G12: =+'GRUPO A'!K26 -> ESCUELA DE FORMACION DEPORTIVA MARACANA | H12: =+'GRUPO A'!B4 -> GRUPO A | I12: =+$A$3 -> NACIDOS 2014 2015 | K12: =+'GRUPO B'!B4 -> GRUPO B | L12: =+'GRUPO B'!Q8 -> Pts. | M12: =+'GRUPO B'!R8 -> PJ | N12: =+'GRUPO B'!S8 -> Gan. | O12: =+'GRUPO B'!T8 -> Emp. | P12: =+'GRUPO B'!U8 -> Per. | Q12: =+'GRUPO B'!V8 -> GF | R12: =+'GRUPO B'!W8 -> GC | S12: =+'GRUPO B'!X8 -> Dif. | T12: =+'GRUPO B'!Y8 -> Tj
A13: 45563 | B13: ESTADIO MUNICIPAL CANCHA 1 B (SINTETICO) | C13: 0.5 | D13: =+'GRUPO D'!E26 -> ACADEMIA IGUARAN F. C. | E13: =+'GRUPO D'!G26 -> 8 | F13: =+'GRUPO D'!I26 -> 0 | G13: =+'GRUPO D'!K26 -> CORDOBA Y CERRANO F. C. | H13: =+'GRUPO D'!B4 -> GRUPO D | I13: =+$A$3 -> NACIDOS 2014 2015 | K13: =+'GRUPO B'!P10 -> 1) TEMPLO DEL FÚTBOL | L13: =+'GRUPO B'!Q10 -> 7 | M13: =+'GRUPO B'!R10 -> 3 | N13: =+'GRUPO B'!S10 -> 2 | O13: =+'GRUPO B'!T10 -> 1 | P13: =+'GRUPO B'!U10 -> 0 | Q13: =+'GRUPO B'!V10 -> 9 | R13: =+'GRUPO B'!W10 -> 1 | ... T13: =+'GRUPO B'!Y10 -> 0
A14: 45563 | B14: ESTADIO MUNICIPAL CANCHA 1 A (SINTETICO) | C14: 0.54861111 | D14: =+'GRUPO A'!E29 -> CLUB DEPORTIVO OS FUTSAL | E14: =+'GRUPO A'!G29 -> 2 | F14: =+'GRUPO A'!I29 -> 10 | G14: =+'GRUPO A'!K29 -> CLUB LOS PAPETICOS | H14: =+'GRUPO A'!B4 -> GRUPO A | I14: =+$A$3 -> NACIDOS 2014 2015 | K14: =+'GRUPO B'!P12 -> 2) CLUB CAMPESTRE IBAGUE | L14: =+'GRUPO B'!Q12 -> 7 | M14: =+'GRUPO B'!R12 -> 3 | N14: =+'GRUPO B'!S12 -> 2 | O14: =+'GRUPO B'!T12 -> 1 | P14: =+'GRUPO B'!U12 -> 0 | Q14: =+'GRUPO B'!V12 -> 9 | R14: =+'GRUPO B'!W12 -> 3 | ... T14: =+'GRUPO B'!Y12 -> 0
A15: 45563 | B15: ESTADIO MUNICIPAL CANCHA 1 B (SINTETICO) | C15: 0.54861111 | D15: =+'GRUPO D'!E29 -> COLEGIO NEIL ARMSTRONG | E15: =+'GRUPO D'!G29 -> 2 | F15: =+'GRUPO D'!I29 -> 8 | G15: =+'GRUPO D'!K29 -> GRAMA F. C. | H15: =+'GRUPO D'!B4 -> GRUPO D | I15: =+$A$3 -> NACIDOS 2014 2015 | K15: =+'GRUPO B'!P14 -> 3) ESCUELA DEPORTIVA FÚTBOL RAQUIRA | L15: =+'GRUPO B'!Q14 -> 0 | M15: =+'GRUPO B'!R14 -> 3 | N15: =+'GRUPO B'!S14 -> 0 | O15: =+'GRUPO B'!T14 -> 0 | P15: =+'GRUPO B'!U14 -> 3 | Q15: =+'GRUPO B'!V14 -> 2 | R15: =+'GRUPO B'!W14 -> 10 | ... T15: =+'GRUPO B'!Y14 -> 0
K16: =+'GRUPO C'!B4 -> GRUPO C | L16: =+'GRUPO C'!Q8 -> Pts. | M16: =+'GRUPO C'!R8 -> PJ | N16: =+'GRUPO C'!S8 -> Gan. | O16: =+'GRUPO C'!T8 -> Emp. | P16: =+'GRUPO C'!U8 -> Per. | Q16: =+'GRUPO C'!V8 -> GF | R16: =+'GRUPO C'!W8 -> GC | S16: =+'GRUPO C'!X8 -> Dif. | T16: =+'GRUPO C'!Y8 -> Tj | X16: LA CUARTA FECHA SE JUGARAN DOS TIEMPOS DE 18 MINUTOS CADA UNO
B17: =+'IMPRIMIR 2'!A14 -> PARTIDOS fecha 2 | K17: =+'GRUPO C'!P10 -> 1) BLUEMARTIN F.C . | L17: =+'GRUPO C'!Q10 -> 9 | M17: =+'GRUPO C'!R10 -> 3 | N17: =+'GRUPO C'!S10 -> 3 | O17: =+'GRUPO C'!T10 -> 0 | P17: =+'GRUPO C'!U10 -> 0 | Q17: =+'GRUPO C'!V10 -> 5 | R17: =+'GRUPO C'!W10 -> 0 | ... T17: =+'GRUPO C'!Y10 -> 0
B18: CANCHA | C18: HORA | D18: EQUIPO | E18: MARCADOR | G18: EQUIPO | H18: GRUPO | I18: =+I8 -> CATEGORIA | K18: =+'GRUPO C'!P12 -> 2) CENTAUROS DEL ARIARI | L18: =+'GRUPO C'!Q12 -> 3 | M18: =+'GRUPO C'!R12 -> 3 | N18: =+'GRUPO C'!S12 -> 1 | O18: =+'GRUPO C'!T12 -> 0 | P18: =+'GRUPO C'!U12 -> 2 | Q18: =+'GRUPO C'!V12 -> 5 | R18: =+'GRUPO C'!W12 -> 5 | ... T18: =+'GRUPO C'!Y12 -> 0 | X18: PRIMERO GRUPO A | Y18: vs | Z18: PRIMERO GRUPO C | AE18: 1.A | AF18: 2:00 p.m.
A19: 45563 | B19: CANCHA 1 A CLUB POLICIA | C19: 0.63541667 | D19: =+'GRUPO C'!E26 -> BLUEMARTIN F.C . | E19: =+'GRUPO C'!G26 -> 2 | F19: =+'GRUPO C'!I26 -> 0 | G19: =+'GRUPO C'!K26 -> CENTAUROS DEL ARIARI | H19: =+'GRUPO C'!B4 -> GRUPO C | I19: =+$A$3 -> NACIDOS 2014 2015 | K19: =+'GRUPO C'!P14 -> 3) EIFD TESOROS SPORTS | L19: =+'GRUPO C'!Q14 -> 0 | M19: =+'GRUPO C'!R14 -> 3 | N19: =+'GRUPO C'!S14 -> 0 | O19: =+'GRUPO C'!T14 -> 0 | P19: =+'GRUPO C'!U14 -> 3 | Q19: =+'GRUPO C'!V14 -> 3 | R19: =+'GRUPO C'!W14 -> 12 | ... T19: =+'GRUPO C'!Y14 -> 0 | X19: SEGUNDO PRUPO A | Y19: vs | Z19: SEGUNDO GRUPO C | AE19: 1.B | AF19: 2:00 p.m.
A20: 45563 | B20: CANCHA 1 B CLUB POLICIA | C20: 0.63541667 | D20: =+'GRUPO B'!E29 -> TEMPLO DEL FÚTBOL | E20: =+'GRUPO B'!G29 -> 6 | F20: =+'GRUPO B'!I29 -> 1 | G20: =+'GRUPO B'!K29 -> EIFD TESOROS SPORTS | H20: INTERGRUPO | I20: =+$A$3 -> NACIDOS 2014 2015 | K20: =+'GRUPO D'!B4 -> GRUPO D | L20: =+'GRUPO D'!Q8 -> Pts. | M20: =+'GRUPO D'!R8 -> PJ | N20: =+'GRUPO D'!S8 -> Gan. | O20: =+'GRUPO D'!T8 -> Emp. | P20: =+'GRUPO D'!U8 -> Per. | Q20: =+'GRUPO D'!V8 -> GF | R20: =+'GRUPO D'!W8 -> GC | S20: =+'GRUPO D'!X8 -> Dif. | T20: =+'GRUPO D'!Y8 -> Tj | X20: TERCERO GRUPO A | Y20: vs | Z20: TERCERO GRUPO C | AE20: 2.D | AF20: 2:00 p.m.
A21: 45563 | B21: ESTADIO MUNICIPAL CANCHA 1 A (SINTETICO) | C21: 0.75694444 | D21: =+'GRUPO D'!E23 -> CORDOBA Y CERRANO F. C. | E21: =+'GRUPO D'!G23 -> 4 | F21: =+'GRUPO D'!I23 -> 4 | G21: =+'GRUPO D'!K23 -> GRAMA F. C. | H21: =+'GRUPO D'!B4 -> GRUPO D | I21: =+$A$3 -> NACIDOS 2014 2015 | K21: =+'GRUPO D'!P10 -> 1) ACADEMIA IGUARAN F. C. | L21: =+'GRUPO D'!Q10 -> 9 | M21: =+'GRUPO D'!R10 -> 3 | N21: =+'GRUPO D'!S10 -> 3 | O21: =+'GRUPO D'!T10 -> 0 | P21: =+'GRUPO D'!U10 -> 0 | Q21: =+'GRUPO D'!V10 -> 15 | R21: =+'GRUPO D'!W10 -> 3 | ... T21: =+'GRUPO D'!Y10 -> 0 | X21: PRIMERO GRUPO B | Y21: vs | Z21: PRIMERO GRUPO D | AE21: 1.C | AF21: 2:20 p.m.
A22: 45563 | B22: ESTADIO MUNICIPAL CANCHA 1 B (SINTETICO) | C22: 0.75694444 | D22: =+'GRUPO A'!E20 -> AJAX AIMARA | E22: =+'GRUPO A'!G20 -> 10 | F22: =+'GRUPO A'!I20 -> 0 | G22: =+'GRUPO A'!K20 -> CLUB DEPORTIVO OS FUTSAL | H22: =+'GRUPO A'!B4 -> GRUPO A | I22: =+$A$3 -> NACIDOS 2014 2015 | K22: =+'GRUPO D'!P12 -> 2) GRAMA F. C. | L22: =+'GRUPO D'!Q12 -> 4 | M22: =+'GRUPO D'!R12 -> 3 | N22: =+'GRUPO D'!S12 -> 1 | O22: =+'GRUPO D'!T12 -> 1 | P22: =+'GRUPO D'!U12 -> 1 | Q22: =+'GRUPO D'!V12 -> 13 | R22: =+'GRUPO D'!W12 -> 9 | ... T22: =+'GRUPO D'!Y12 -> 0 | X22: SEGUNDO PRUPO B | Y22: vs | Z22: SEGUNDO GRUPO D | AE22: 1.D | AF22: 2:20 p.m.
A23: 45563 | B23: ESTADIO MUNICIPAL CANCHA 1 A (SINTETICO) | C23: 0.80555556 | D23: =+'GRUPO A'!E23 -> ESCUELA DE FORMACION DEPORTIVA MARACANA | E23: =+'GRUPO A'!G23 -> 3 | F23: =+'GRUPO A'!I23 -> 3 | G23: =+'GRUPO A'!K23 -> CLUB LOS PAPETICOS | H23: =+'GRUPO A'!B4 -> GRUPO A | I23: =+$A$3 -> NACIDOS 2014 2015 | K23: =+'GRUPO D'!P14 -> 3) CORDOBA Y CERRANO F. C. | L23: =+'GRUPO D'!Q14 -> 4 | M23: =+'GRUPO D'!R14 -> 3 | N23: =+'GRUPO D'!S14 -> 1 | O23: =+'GRUPO D'!T14 -> 1 | P23: =+'GRUPO D'!U14 -> 1 | Q23: =+'GRUPO D'!V14 -> 8 | R23: =+'GRUPO D'!W14 -> 13 | ... T23: =+'GRUPO D'!Y14 -> 0 | X23: TERCERO GRUPO B | Y23: vs | Z23: TERCERO GRUPO D | AE23: 1.A | AF23: 2:50 p.m.
A24: 45563 | B24: ESTADIO MUNICIPAL CANCHA 1 B (SINTETICO) | C24: 0.80555556 | D24: =+'GRUPO D'!E20 -> ACADEMIA IGUARAN F. C. | E24: =+'GRUPO D'!G20 -> 4 | F24: =+'GRUPO D'!I20 -> 2 | G24: =+'GRUPO D'!K20 -> COLEGIO NEIL ARMSTRONG | H24: =+'GRUPO D'!B4 -> GRUPO D | I24: =+$A$3 -> NACIDOS 2014 2015 | K24: =+'GRUPO D'!P16 -> 4) COLEGIO NEIL ARMSTRONG | L24: =+'GRUPO D'!Q16 -> 0 | M24: =+'GRUPO D'!R16 -> 3 | N24: =+'GRUPO D'!S16 -> 0 | O24: =+'GRUPO D'!T16 -> 0 | P24: =+'GRUPO D'!U16 -> 3 | Q24: =+'GRUPO D'!V16 -> 5 | R24: =+'GRUPO D'!W16 -> 16 | ... T24: =+'GRUPO D'!Y16 -> 0 | X24: PRIMERO GRUPO E | Y24: vs | Z24: PRIMERO GRUPO G | AE24: 1.B | AF24: 2:50 p.m.
A25: 45563 | B25: ESTADIO MUNICIPAL CANCHA 1 B (SINTETICO) | C25: 0.85416667 | D25: =+'GRUPO B'!E26 -> ESCUELA DEPORTIVA FÚTBOL RAQUIRA | E25: =+'GRUPO B'!G26 -> 2 | F25: =+'GRUPO B'!I26 -> 6 | G25: =+'GRUPO B'!K26 -> CLUB CAMPESTRE IBAGUE | H25: =+'GRUPO B'!B4 -> GRUPO B | I25: =+$A$3 -> NACIDOS 2014 2015 | X25: SEGUNDO PRUPO E | Y25: vs | Z25: SEGUNDO GRUPO G | AE25: 2.D | AF25: 2:50 p.m.
X26: TERCERO GRUPO E | Y26: vs | Z26: TERCERO GRUPO G | AE26: 1.C | AF26: 3:10 p.m.
B27: PARTIDOS FECHA 3 | X27: CUARTO GRUPO G | Y27: vs | Z27: CUARTO GRUPO H | AE27: 1.D | AF27: 3:10 p.m.
B28: CANCHA | C28: HORA | D28: EQUIPO | E28: MARCADOR | G28: EQUIPO | H28: GRUPO | I28: =+I18 -> CATEGORIA | X28: SEGUNDO PRUPO F | Y28: vs | Z28: SEGUNDO GRUPO H | AE28: 1.A | AF28: 3:40 p.m.
A29: 45564 | B29: CANCHA 1 A CLUB POLICIA | C29: 0.28472222 | D29: =+'GRUPO B'!E35 -> TEMPLO DEL FÚTBOL | E29: =+'GRUPO B'!G35 -> 0 | F29: =+'GRUPO B'!I35 -> 0 | G29: =+'GRUPO B'!K35 -> CLUB CAMPESTRE IBAGUE | H29: =+'GRUPO B'!B4 -> GRUPO B | I29: =+$A$3 -> NACIDOS 2014 2015 | X29: TERCERO GRUPO F | Y29: vs | Z29: TERCERO GRUPO H | AE29: 1.B | AF29: 3:40 p.m.
A30: 45564 | B30: CANCHA 1 B CLUB POLICIA | C30: 0.34027778 | D30: =+'GRUPO C'!E35 -> ESCUELA DEPORTIVA FÚTBOL RAQUIRA | E30: =+'GRUPO C'!G35 -> 0 | F30: =+'GRUPO C'!I35 -> 1 | G30: =+'GRUPO C'!K35 -> BLUEMARTIN F.C . | H30: INTERGRUPO | I30: =+$A$3 -> NACIDOS 2014 2015 | X30: PRIMERO GRUPO F | Y30: vs | Z30: PRIMERO GRUPO H | AE30: 2.D | AF30: 3:40 p.m.
A31: 45564 | B31: CANCHA 1 A CLUB POLICIA | C31: 0.38888889 | D31: =+'GRUPO C'!E32 -> EIFD TESOROS SPORTS | E31: =+'GRUPO C'!G32 -> 2 | F31: =+'GRUPO C'!I32 -> 4 | G31: =+'GRUPO C'!K32 -> CENTAUROS DEL ARIARI | H31: =+'GRUPO C'!B4 -> GRUPO C | I31: =+$A$3 -> NACIDOS 2014 2015
A32: 45564 | B32: ESTADIO MUNICIPAL CANCHA 1 A (SINTETICO) | C32: 0.38888889 | D32: =+'GRUPO D'!E32 -> COLEGIO NEIL ARMSTRONG | E32: =+'GRUPO D'!G32 -> 1 | F32: =+'GRUPO D'!I32 -> 4 | G32: =+'GRUPO D'!K32 -> CORDOBA Y CERRANO F. C. | H32: =+'GRUPO D'!B4 -> GRUPO D | I32: =+$A$3 -> NACIDOS 2014 2015
A33: 45564 | B33: ESTADIO MUNICIPAL CANCHA 1 B (SINTETICO) | C33: 0.38888889 | D33: =+'GRUPO A'!E35 -> AJAX AIMARA | E33: =+'GRUPO A'!G35 -> 2 | F33: =+'GRUPO A'!I35 -> 7 | G33: =+'GRUPO A'!K35 -> CLUB LOS PAPETICOS | H33: =+'GRUPO A'!B4 -> GRUPO A | I33: =+$A$3 -> NACIDOS 2014 2015 | W33: PRIMERO GRUPO A | X33: vs | Y33: PRIMERO GRUPO B | AE33: 3:05 p.m.
A34: 45564 | B34: ESTADIO MUNICIPAL CANCHA 1 A (SINTETICO) | C34: 0.4375 | D34: =+'GRUPO D'!E35 -> ACADEMIA IGUARAN F. C. | E34: =+'GRUPO D'!G35 -> 3 | F34: =+'GRUPO D'!I35 -> 1 | G34: =+'GRUPO D'!K35 -> GRAMA F. C. | H34: =+'GRUPO D'!B4 -> GRUPO D | I34: =+$A$3 -> NACIDOS 2014 2015 | W34: SEGUNDO PRUPO A | X34: vs | Y34: SEGUNDO GRUPO B | AE34: 3:05 p.m.
A35: 45564 | B35: ESTADIO MUNICIPAL CANCHA 1 B (SINTETICO) | C35: 0.4375 | D35: =+'GRUPO A'!E32 -> CLUB DEPORTIVO OS FUTSAL | E35: =+'GRUPO A'!G32 -> 0 | F35: =+'GRUPO A'!I32 -> 8 | G35: =+'GRUPO A'!K32 -> ESCUELA DE FORMACION DEPORTIVA MARACANA | H35: =+'GRUPO A'!B4 -> GRUPO A | I35: =+$A$3 -> NACIDOS 2014 2015 | W35: TERCERO GRUPO A | X35: vs | Y35: TERCERO GRUPO B | AE35: 2:15 p.m.
W36: CUARTO GRUPO A | X36: vs | Y36: CUARTO GRUPO B | AE36: 2:15 p.m.
B37: PARTIDOS FECHA 3
B38: CANCHA | C38: HORA | D38: EQUIPO | E38: MARCADOR | G38: EQUIPO | H38: GRUPO | I38: =+I28 -> CATEGORIA
A39: 45564 | B39: CANCHA 1 A CLUB POLICIA | C39: 0.56944444 | D39: =+K19 -> 3) EIFD TESOROS SPORTS | E39: =+'GRUPO A'!G39 -> 0 | F39: =+'GRUPO A'!I39 -> 0 | G39: =+K23 -> 3) CORDOBA Y CERRANO F. C. | H39: FINAL COPA BRONCE | I39: =+$A$3 -> NACIDOS 2014 2015
A40: 45564 | B40: CANCHA 1 B CLUB POLICIA | C40: 0.56944444 | D40: =+K24 -> 4) COLEGIO NEIL ARMSTRONG | E40: =+'GRUPO A'!G40 -> 0 | F40: =+'GRUPO A'!I40 -> 0 | G40: =+K22 -> 2) GRAMA F. C. | H40: FINAL COPA PLATA | I40: =+$A$3 -> NACIDOS 2014 2015
A41: 45564 | B41: CANCHA 1 B CLUB POLICIA | C41: 0.61805556 | D41: =+K11 -> 4) CLUB DEPORTIVO OS FUTSAL | E41: =+'GRUPO A'!G43 -> 0 | F41: =+'GRUPO A'!I43 -> 0 | G41: =+K18 -> 2) CENTAUROS DEL ARIARI | H41: FINAL COPA SOCCER MELGAR | I41: =+$A$3 -> NACIDOS 2014 2015
...

Sheet IMPRIMIR HOJA (2)
A1: =+'GRUPOS INFANTIL'!B1 -> XVIII Festival Nacional de Fútbol Infantil
A2: =+'GRUPOS INFANTIL'!B2 -> “COPA SOCCER MELGAR”
A3: =+'GRUPOS INFANTIL'!B3 -> NACIDOS 2014 2015
A4: =+'GRUPOS INFANTIL'!B4 -> SEPTIEMBRE 28 Y 29 DEL 2024
A6: CALENDARIO OFICIAL
B7: PARTIDOS FECHA 1 | K7: =+'GRUPO A'!B4 -> GRUPO A | L7: =+'GRUPO A'!Q8 -> Pts. | M7: =+'GRUPO A'!R8 -> PJ | N7: =+'GRUPO A'!S8 -> Gan. | O7: =+'GRUPO A'!T8 -> Emp. | P7: =+'GRUPO A'!U8 -> Per. | Q7: =+'GRUPO A'!V8 -> GF | R7: =+'GRUPO A'!W8 -> GC | S7: =+'GRUPO A'!X8 -> Dif. | T7: =+'GRUPO A'!Y8 -> Tj
B8: CANCHA | C8: HORA | D8: EQUIPO | E8: MARCADOR | G8: EQUIPO | H8: GRUPO | I8: CATEGORIA | K8: =+'GRUPO A'!P10 -> 1) CLUB LOS PAPETICOS | L8: =+'GRUPO A'!Q10 -> 7 | M8: =+'GRUPO A'!R10 -> 3 | N8: =+'GRUPO A'!S10 -> 2 | O8: =+'GRUPO A'!T10 -> 1 | P8: =+'GRUPO A'!U10 -> 0 | Q8: =+'GRUPO A'!V10 -> 20 | R8: =+'GRUPO A'!W10 -> 7 | ... T8: =+'GRUPO A'!Y10 -> 0
A9: 45563 | B9: CANCHA 1 A CLUB POLICIA | C9: 0.40972222 | D9: =+'GRUPO C'!E20 -> BLUEMARTIN F.C . | E9: =+'GRUPO C'!G20 -> 2 | F9: =+'GRUPO C'!I20 -> 0 | G9: =+'GRUPO C'!K20 -> EIFD TESOROS SPORTS | H9: =+'GRUPO C'!B4 -> GRUPO C | I9: =+$A$3 -> NACIDOS 2014 2015 | K9: =+'GRUPO A'!P12 -> 2) ESCUELA DE FORMACION DEPORTIVA MARACANA | L9: =+'GRUPO A'!Q12 -> 7 | M9: =+'GRUPO A'!R14 -> 3 | N9: =+'GRUPO A'!S12 -> 2 | O9: =+'GRUPO A'!T12 -> 1 | P9: =+'GRUPO A'!U12 -> 0 | Q9: =+'GRUPO A'!V12 -> 13 | R9: =+'GRUPO A'!W12 -> 4 | S9: =+'GRUPO A'!X12 -> 9 | T9: =+'GRUPO A'!Y12 -> 0
A10: 45563 | B10: CANCHA 1 B CLUB POLICIA | C10: 0.40972222 | D10: =+'GRUPO B'!E23 -> CLUB CAMPESTRE IBAGUE | E10: =+'GRUPO B'!G23 -> 3 | F10: =+'GRUPO B'!I23 -> 1 | G10: =+'GRUPO B'!K23 -> CENTAUROS DEL ARIARI | H10: INTERGRUPO | I10: =+$A$3 -> NACIDOS 2014 2015 | K10: =+'GRUPO A'!P14 -> 3) AJAX AIMARA | L10: =+'GRUPO A'!Q14 -> 3 | M10: =+'GRUPO A'!R14 -> 3 | N10: =+'GRUPO A'!S14 -> 1 | O10: =+'GRUPO A'!T14 -> 0 | P10: =+'GRUPO A'!U14 -> 2 | Q10: =+'GRUPO A'!V14 -> 13 | R10: =+'GRUPO A'!W14 -> 9 | ... T10: =+'GRUPO A'!Y14 -> 0
A11: 45563 | B11: CANCHA 1 B CLUB POLICIA | C11: 0.45833333 | D11: =+'GRUPO B'!E20 -> ESCUELA DEPORTIVA FÚTBOL RAQUIRA | E11: =+'GRUPO B'!G20 -> 0 | F11: =+'GRUPO B'!I20 -> 3 | G11: =+'GRUPO B'!K20 -> TEMPLO DEL FÚTBOL | H11: =+'GRUPO B'!B4 -> GRUPO B | I11: =+$A$3 -> NACIDOS 2014 2015 | K11: =+'GRUPO A'!P16 -> 4) CLUB DEPORTIVO OS FUTSAL | L11: =+'GRUPO A'!Q16 -> 0 | M11: =+'GRUPO A'!R16 -> 3 | N11: =+'GRUPO A'!S16 -> 0 | O11: =+'GRUPO A'!T16 -> 0 | P11: =+'GRUPO A'!U16 -> 3 | Q11: =+'GRUPO A'!V16 -> 2 | R11: =+'GRUPO A'!W16 -> 28 | ... T11: =+'GRUPO A'!Y16 -> 0
A12: 45563 | B12: ESTADIO MUNICIPAL CANCHA 1 A (SINTETICO) | C12: 0.5 | D12: =+'GRUPO A'!E26 -> AJAX AIMARA | E12: =+'GRUPO A'!G26 -> 1 | F12: =+'GRUPO A'!I26 -> 2 | G12: =+'GRUPO A'!K26 -> ESCUELA DE FORMACION DEPORTIVA MARACANA | H12: =+'GRUPO A'!B4 -> GRUPO A | I12: =+$A$3 -> NACIDOS 2014 2015 | K12: =+'GRUPO B'!B4 -> GRUPO B | L12: =+'GRUPO B'!Q8 -> Pts. | M12: =+'GRUPO B'!R8 -> PJ | N12: =+'GRUPO B'!S8 -> Gan. | O12: =+'GRUPO B'!T8 -> Emp. | P12: =+'GRUPO B'!U8 -> Per. | Q12: =+'GRUPO B'!V8 -> GF | R12: =+'GRUPO B'!W8 -> GC | S12: =+'GRUPO B'!X8 -> Dif. | T12: =+'GRUPO B'!Y8 -> Tj
A13: 45563 | B13: ESTADIO MUNICIPAL CANCHA 1 B (SINTETICO) | C13: 0.5 | D13: =+'GRUPO D'!E26 -> ACADEMIA IGUARAN F. C. | E13: =+'GRUPO D'!G26 -> 8 | F13: =+'GRUPO D'!I26 -> 0 | G13: =+'GRUPO D'!K26 -> CORDOBA Y CERRANO F. C. | H13: =+'GRUPO D'!B4 -> GRUPO D | I13: =+$A$3 -> NACIDOS 2014 2015 | K13: =+'GRUPO B'!P10 -> 1) TEMPLO DEL FÚTBOL | L13: =+'GRUPO B'!Q10 -> 7 | M13: =+'GRUPO B'!R10 -> 3 | N13: =+'GRUPO B'!S10 -> 2 | O13: =+'GRUPO B'!T10 -> 1 | P13: =+'GRUPO B'!U10 -> 0 | Q13: =+'GRUPO B'!V10 -> 9 | R13: =+'GRUPO B'!W10 -> 1 | ... T13: =+'GRUPO B'!Y10 -> 0
A14: 45563 | B14: ESTADIO MUNICIPAL CANCHA 1 A (SINTETICO) | C14: 0.54861111 | D14: =+'GRUPO A'!E29 -> CLUB DEPORTIVO OS FUTSAL | E14: =+'GRUPO A'!G29 -> 2 | F14: =+'GRUPO A'!I29 -> 10 | G14: =+'GRUPO A'!K29 -> CLUB LOS PAPETICOS | H14: =+'GRUPO A'!B4 -> GRUPO A | I14: =+$A$3 -> NACIDOS 2014 2015 | K14: =+'GRUPO B'!P12 -> 2) CLUB CAMPESTRE IBAGUE | L14: =+'GRUPO B'!Q12 -> 7 | M14: =+'GRUPO B'!R12 -> 3 | N14: =+'GRUPO B'!S12 -> 2 | O14: =+'GRUPO B'!T12 -> 1 | P14: =+'GRUPO B'!U12 -> 0 | Q14: =+'GRUPO B'!V12 -> 9 | R14: =+'GRUPO B'!W12 -> 3 | ... T14: =+'GRUPO B'!Y12 -> 0
A15: 45563 | B15: ESTADIO MUNICIPAL CANCHA 1 B (SINTETICO) | C15: 0.54861111 | D15: =+'GRUPO D'!E29 -> COLEGIO NEIL ARMSTRONG | E15: =+'GRUPO D'!G29 -> 2 | F15: =+'GRUPO D'!I29 -> 8 | G15: =+'GRUPO D'!K29 -> GRAMA F. C. | H15: =+'GRUPO D'!B4 -> GRUPO D | I15: =+$A$3 -> NACIDOS 2014 2015 | K15: =+'GRUPO B'!P14 -> 3) ESCUELA DEPORTIVA FÚTBOL RAQUIRA | L15: =+'GRUPO B'!Q14 -> 0 | M15: =+'GRUPO B'!R14 -> 3 | N15: =+'GRUPO B'!S14 -> 0 | O15: =+'GRUPO B'!T14 -> 0 | P15: =+'GRUPO B'!U14 -> 3 | Q15: =+'GRUPO B'!V14 -> 2 | R15: =+'GRUPO B'!W14 -> 10 | ... T15: =+'GRUPO B'!Y14 -> 0
K16: =+'GRUPO C'!B4 -> GRUPO C | L16: =+'GRUPO C'!Q8 -> Pts. | M16: =+'GRUPO C'!R8 -> PJ | N16: =+'GRUPO C'!S8 -> Gan. | O16: =+'GRUPO C'!T8 -> Emp. | P16: =+'GRUPO C'!U8 -> Per. | Q16: =+'GRUPO C'!V8 -> GF | R16: =+'GRUPO C'!W8 -> GC | S16: =+'GRUPO C'!X8 -> Dif. | T16: =+'GRUPO C'!Y8 -> Tj | X16: LA CUARTA FECHA SE JUGARAN DOS TIEMPOS DE 18 MINUTOS CADA UNO
B17: =+'IMPRIMIR 2'!A14 -> PARTIDOS fecha 2 | K17: =+'GRUPO C'!P10 -> 1) BLUEMARTIN F.C . | L17: =+'GRUPO C'!Q10 -> 9 | M17: =+'GRUPO C'!R10 -> 3 | N17: =+'GRUPO C'!S10 -> 3 | O17: =+'GRUPO C'!T10 -> 0 | P17: =+'GRUPO C'!U10 -> 0 | Q17: =+'GRUPO C'!V10 -> 5 | R17: =+'GRUPO C'!W10 -> 0 | ... T17: =+'GRUPO C'!Y10 -> 0
B18: CANCHA | C18: HORA | D18: EQUIPO | E18: MARCADOR | G18: EQUIPO | H18: GRUPO | I18: =+I8 -> CATEGORIA | K18: =+'GRUPO C'!P12 -> 2) CENTAUROS DEL ARIARI | L18: =+'GRUPO C'!Q12 -> 3 | M18: =+'GRUPO C'!R12 -> 3 | N18: =+'GRUPO C'!S12 -> 1 | O18: =+'GRUPO C'!T12 -> 0 | P18: =+'GRUPO C'!U12 -> 2 | Q18: =+'GRUPO C'!V12 -> 5 | R18: =+'GRUPO C'!W12 -> 5 | ... T18: =+'GRUPO C'!Y12 -> 0 | X18: PRIMERO GRUPO A | Y18: vs | Z18: PRIMERO GRUPO C | AE18: 1.A | AF18: 2:00 p.m.
A19: 45563 | B19: CANCHA 1 A CLUB POLICIA | C19: 0.63541667 | D19: =+'GRUPO C'!E26 -> BLUEMARTIN F.C . | E19: =+'GRUPO C'!G26 -> 2 | F19: =+'GRUPO C'!I26 -> 0 | G19: =+'GRUPO C'!K26 -> CENTAUROS DEL ARIARI | H19: =+'GRUPO C'!B4 -> GRUPO C | I19: =+$A$3 -> NACIDOS 2014 2015 | K19: =+'GRUPO C'!P14 -> 3) EIFD TESOROS SPORTS | L19: =+'GRUPO C'!Q14 -> 0 | M19: =+'GRUPO C'!R14 -> 3 | N19: =+'GRUPO C'!S14 -> 0 | O19: =+'GRUPO C'!T14 -> 0 | P19: =+'GRUPO C'!U14 -> 3 | Q19: =+'GRUPO C'!V14 -> 3 | R19: =+'GRUPO C'!W14 -> 12 | ... T19: =+'GRUPO C'!Y14 -> 0 | X19: SEGUNDO PRUPO A | Y19: vs | Z19: SEGUNDO GRUPO C | AE19: 1.B | AF19: 2:00 p.m.
A20: 45563 | B20: CANCHA 1 B CLUB POLICIA | C20: 0.63541667 | D20: =+'GRUPO B'!E29 -> TEMPLO DEL FÚTBOL | E20: =+'GRUPO B'!G29 -> 6 | F20: =+'GRUPO B'!I29 -> 1 | G20: =+'GRUPO B'!K29 -> EIFD TESOROS SPORTS | H20: INTERGRUPO | I20: =+$A$3 -> NACIDOS 2014 2015 | K20: =+'GRUPO D'!B4 -> GRUPO D | L20: =+'GRUPO D'!Q8 -> Pts. | M20: =+'GRUPO D'!R8 -> PJ | N20: =+'GRUPO D'!S8 -> Gan. | O20: =+'GRUPO D'!T8 -> Emp. | P20: =+'GRUPO D'!U8 -> Per. | Q20: =+'GRUPO D'!V8 -> GF | R20: =+'GRUPO D'!W8 -> GC | S20: =+'GRUPO D'!X8 -> Dif. | T20: =+'GRUPO D'!Y8 -> Tj | X20: TERCERO GRUPO A | Y20: vs | Z20: TERCERO GRUPO C | AE20: 2.D | AF20: 2:00 p.m.
A21: 45563 | B21: ESTADIO MUNICIPAL CANCHA 1 A (SINTETICO) | C21: 0.75694444 | D21: =+'GRUPO D'!E23 -> CORDOBA Y CERRANO F. C. | E21: =+'GRUPO D'!G23 -> 4 | F21: =+'GRUPO D'!I23 -> 4 | G21: =+'GRUPO D'!K23 -> GRAMA F. C. | H21: =+'GRUPO D'!B4 -> GRUPO D | I21: =+$A$3 -> NACIDOS 2014 2015 | K21: =+'GRUPO D'!P10 -> 1) ACADEMIA IGUARAN F. C. | L21: =+'GRUPO D'!Q10 -> 9 | M21: =+'GRUPO D'!R10 -> 3 | N21: =+'GRUPO D'!S10 -> 3 | O21: =+'GRUPO D'!T10 -> 0 | P21: =+'GRUPO D'!U10 -> 0 | Q21: =+'GRUPO D'!V10 -> 15 | R21: =+'GRUPO D'!W10 -> 3 | ... T21: =+'GRUPO D'!Y10 -> 0 | X21: PRIMERO GRUPO B | Y21: vs | Z21: PRIMERO GRUPO D | AE21: 1.C | AF21: 2:20 p.m.
A22: 45563 | B22: ESTADIO MUNICIPAL CANCHA 1 B (SINTETICO) | C22: 0.75694444 | D22: =+'GRUPO A'!E20 -> AJAX AIMARA | E22: =+'GRUPO A'!G20 -> 10 | F22: =+'GRUPO A'!I20 -> 0 | G22: =+'GRUPO A'!K20 -> CLUB DEPORTIVO OS FUTSAL | H22: =+'GRUPO A'!B4 -> GRUPO A | I22: =+$A$3 -> NACIDOS 2014 2015 | K22: =+'GRUPO D'!P12 -> 2) GRAMA F. C. | L22: =+'GRUPO D'!Q12 -> 4 | M22: =+'GRUPO D'!R12 -> 3 | N22: =+'GRUPO D'!S12 -> 1 | O22: =+'GRUPO D'!T12 -> 1 | P22: =+'GRUPO D'!U12 -> 1 | Q22: =+'GRUPO D'!V12 -> 13 | R22: =+'GRUPO D'!W12 -> 9 | ... T22: =+'GRUPO D'!Y12 -> 0 | X22: SEGUNDO PRUPO B | Y22: vs | Z22: SEGUNDO GRUPO D | AE22: 1.D | AF22: 2:20 p.m.
A23: 45563 | B23: ESTADIO MUNICIPAL CANCHA 1 A (SINTETICO) | C23: 0.80555556 | D23: =+'GRUPO A'!E23 -> ESCUELA DE FORMACION DEPORTIVA MARACANA | E23: =+'GRUPO A'!G23 -> 3 | F23: =+'GRUPO A'!I23 -> 3 | G23: =+'GRUPO A'!K23 -> CLUB LOS PAPETICOS | H23: =+'GRUPO A'!B4 -> GRUPO A | I23: =+$A$3 -> NACIDOS 2014 2015 | K23: =+'GRUPO D'!P14 -> 3) CORDOBA Y CERRANO F. C. | L23: =+'GRUPO D'!Q14 -> 4 | M23: =+'GRUPO D'!R14 -> 3 | N23: =+'GRUPO D'!S14 -> 1 | O23: =+'GRUPO D'!T14 -> 1 | P23: =+'GRUPO D'!U14 -> 1 | Q23: =+'GRUPO D'!V14 -> 8 | R23: =+'GRUPO D'!W14 -> 13 | ... T23: =+'GRUPO D'!Y14 -> 0 | X23: TERCERO GRUPO B | Y23: vs | Z23: TERCERO GRUPO D | AE23: 1.A | AF23: 2:50 p.m.
A24: 45563 | B24: ESTADIO MUNICIPAL CANCHA 1 B (SINTETICO) | C24: 0.80555556 | D24: =+'GRUPO D'!E20 -> ACADEMIA IGUARAN F. C. | E24: =+'GRUPO D'!G20 -> 4 | F24: =+'GRUPO D'!I20 -> 2 | G24: =+'GRUPO D'!K20 -> COLEGIO NEIL ARMSTRONG | H24: =+'GRUPO D'!B4 -> GRUPO D | I24: =+$A$3 -> NACIDOS 2014 2015 | K24: =+'GRUPO D'!P16 -> 4) COLEGIO NEIL ARMSTRONG | L24: =+'GRUPO D'!Q16 -> 0 | M24: =+'GRUPO D'!R16 -> 3 | N24: =+'GRUPO D'!S16 -> 0 | O24: =+'GRUPO D'!T16 -> 0 | P24: =+'GRUPO D'!U16 -> 3 | Q24: =+'GRUPO D'!V16 -> 5 | R24: =+'GRUPO D'!W16 -> 16 | ... T24: =+'GRUPO D'!Y16 -> 0 | X24: PRIMERO GRUPO E | Y24: vs | Z24: PRIMERO GRUPO G | AE24: 1.B | AF24: 2:50 p.m.
A25: 45563 | B25: ESTADIO MUNICIPAL CANCHA 1 B (SINTETICO) | C25: 0.85416667 | D25: =+'GRUPO B'!E26 -> ESCUELA DEPORTIVA FÚTBOL RAQUIRA | E25: =+'GRUPO B'!G26 -> 2 | F25: =+'GRUPO B'!I26 -> 6 | G25: =+'GRUPO B'!K26 -> CLUB CAMPESTRE IBAGUE | H25: =+'GRUPO B'!B4 -> GRUPO B | I25: =+$A$3 -> NACIDOS 2014 2015 | X25: SEGUNDO PRUPO E | Y25: vs | Z25: SEGUNDO GRUPO G | AE25: 2.D | AF25: 2:50 p.m.
X26: TERCERO GRUPO E | Y26: vs | Z26: TERCERO GRUPO G | AE26: 1.C | AF26: 3:10 p.m.
B27: PARTIDOS FECHA 3 | X27: CUARTO GRUPO G | Y27: vs | Z27: CUARTO GRUPO H | AE27: 1.D | AF27: 3:10 p.m.
B28: CANCHA | C28: HORA | D28: EQUIPO | E28: MARCADOR | G28: EQUIPO | H28: GRUPO | I28: =+I18 -> CATEGORIA | X28: SEGUNDO PRUPO F | Y28: vs | Z28: SEGUNDO GRUPO H | AE28: 1.A | AF28: 3:40 p.m.
A29: 45564 | B29: CANCHA 1 A CLUB POLICIA | C29: 0.28472222 | D29: =+'GRUPO B'!E35 -> TEMPLO DEL FÚTBOL | E29: =+'GRUPO B'!G35 -> 0 | F29: =+'GRUPO B'!I35 -> 0 | G29: =+'GRUPO B'!K35 -> CLUB CAMPESTRE IBAGUE | H29: =+'GRUPO B'!B4 -> GRUPO B | I29: =+$A$3 -> NACIDOS 2014 2015 | X29: TERCERO GRUPO F | Y29: vs | Z29: TERCERO GRUPO H | AE29: 1.B | AF29: 3:40 p.m.
A30: 45564 | B30: CANCHA 1 B CLUB POLICIA | C30: 0.34027778 | D30: =+'GRUPO C'!E35 -> ESCUELA DEPORTIVA FÚTBOL RAQUIRA | E30: =+'GRUPO C'!G35 -> 0 | F30: =+'GRUPO C'!I35 -> 1 | G30: =+'GRUPO C'!K35 -> BLUEMARTIN F.C . | H30: INTERGRUPO | I30: =+$A$3 -> NACIDOS 2014 2015 | X30: PRIMERO GRUPO F | Y30: vs | Z30: PRIMERO GRUPO H | AE30: 2.D | AF30: 3:40 p.m.
A31: 45564 | B31: CANCHA 1 A CLUB POLICIA | C31: 0.38888889 | D31: =+'GRUPO C'!E32 -> EIFD TESOROS SPORTS | E31: =+'GRUPO C'!G32 -> 2 | F31: =+'GRUPO C'!I32 -> 4 | G31: =+'GRUPO C'!K32 -> CENTAUROS DEL ARIARI | H31: =+'GRUPO C'!B4 -> GRUPO C | I31: =+$A$3 -> NACIDOS 2014 2015
A32: 45564 | B32: ESTADIO MUNICIPAL CANCHA 1 A (SINTETICO) | C32: 0.38888889 | D32: =+'GRUPO D'!E32 -> COLEGIO NEIL ARMSTRONG | E32: =+'GRUPO D'!G32 -> 1 | F32: =+'GRUPO D'!I32 -> 4 | G32: =+'GRUPO D'!K32 -> CORDOBA Y CERRANO F. C. | H32: =+'GRUPO D'!B4 -> GRUPO D | I32: =+$A$3 -> NACIDOS 2014 2015
A33: 45564 | B33: ESTADIO MUNICIPAL CANCHA 1 B (SINTETICO) | C33: 0.38888889 | D33: =+'GRUPO A'!E35 -> AJAX AIMARA | E33: =+'GRUPO A'!G35 -> 2 | F33: =+'GRUPO A'!I35 -> 7 | G33: =+'GRUPO A'!K35 -> CLUB LOS PAPETICOS | H33: =+'GRUPO A'!B4 -> GRUPO A | I33: =+$A$3 -> NACIDOS 2014 2015 | W33: PRIMERO GRUPO A | X33: vs | Y33: PRIMERO GRUPO B | AE33: 3:05 p.m.
A34: 45564 | B34: ESTADIO MUNICIPAL CANCHA 1 A (SINTETICO) | C34: 0.4375 | D34: =+'GRUPO D'!E35 -> ACADEMIA IGUARAN F. C. | E34: =+'GRUPO D'!G35 -> 3 | F34: =+'GRUPO D'!I35 -> 1 | G34: =+'GRUPO D'!K35 -> GRAMA F. C. | H34: =+'GRUPO D'!B4 -> GRUPO D | I34: =+$A$3 -> NACIDOS 2014 2015 | W34: SEGUNDO PRUPO A | X34: vs | Y34: SEGUNDO GRUPO B | AE34: 3:05 p.m.
A35: 45564 | B35: ESTADIO MUNICIPAL CANCHA 1 B (SINTETICO) | C35: 0.4375 | D35: =+'GRUPO A'!E32 -> CLUB DEPORTIVO OS FUTSAL | E35: =+'GRUPO A'!G32 -> 0 | F35: =+'GRUPO A'!I32 -> 8 | G35: =+'GRUPO A'!K32 -> ESCUELA DE FORMACION DEPORTIVA MARACANA | H35: =+'GRUPO A'!B4 -> GRUPO A | I35: =+$A$3 -> NACIDOS 2014 2015 | W35: TERCERO GRUPO A | X35: vs | Y35: TERCERO GRUPO B | AE35: 2:15 p.m.
W36: CUARTO GRUPO A | X36: vs | Y36: CUARTO GRUPO B | AE36: 2:15 p.m.
B37: PARTIDOS FECHA 3
B38: CANCHA | C38: HORA | D38: EQUIPO | E38: MARCADOR | G38: EQUIPO | H38: GRUPO | I38: =+I28 -> CATEGORIA
A39: 45564 | B39: CANCHA 1 A CLUB POLICIA | C39: 0.56944444 | D39: =+K19 -> 3) EIFD TESOROS SPORTS | E39: =+'GRUPO A'!G39 -> 0 | F39: =+'GRUPO A'!I39 -> 0 | G39: TERCERO GRUPO D | H39: FINAL COPA BRONCE | I39: =+$A$3 -> NACIDOS 2014 2015
A40: 45564 | B40: CANCHA 1 B CLUB POLICIA | C40: 0.56944444 | D40: =+K18 -> 2) CENTAUROS DEL ARIARI | E40: =+'GRUPO A'!G40 -> 0 | F40: =+'GRUPO A'!I40 -> 0 | G40: SEGUNDO GRUPO D | H40: FINAL COPA PLATA | I40: =+$A$3 -> NACIDOS 2014 2015
A41: 45564 | B41: CANCHA 1 B CLUB POLICIA | C41: 0.61805556 | D41: CUARTO GRUPO A | E41: =+'GRUPO A'!G43 -> 0 | F41: =+'GRUPO A'!I43 -> 0 | G41: CUARTO GRUPO D | H41: FINAL COPA SOCCER MELGAR | I41: =+$A$3 -> NACIDOS 2014 2015
...

Sheet DEFINICION
A1: =+'GRUPOS INFANTIL'!B1 -> XVIII Festival Nacional de Fútbol Infantil
A2: “COPA FUTURO TALENTO”
A3: =+'GRUPOS INFANTIL'!B3 -> NACIDOS 2014 2015
A4: =+'GRUPOS INFANTIL'!B4 -> SEPTIEMBRE 28 Y 29 DEL 2024
B5: SEMIFINALES
B6: Observación: Si el partido se define por penales, éstos deben sumarse al resultado.
B7: SEMIFINALES | S7: Ganador
