Workbook

Sheet PRE BABY GRUPOS
C1: XVIII Festival Nacional Fútbol Infantil
C2: “COPA SOCCER MELGAR”
C3: NACIDOS 2012 2013
C4: SEPTIEMBRE 28 Y 29 DEL 2024
E5: DICIEMBRE 18 AL 21 VERSIÓN UNO
C6: GRUPO A | E6: GRUPO B | G6: GRUPO C | I6: GRUPO D
C7: COLEGIO NEIL ARMSTRONG | E7: COLEGIO PRINCIPADO DE MONACO | G7: GRAMA F. C. | I7: CLUB CAMPESTRE IBAGUE DOS
C8: CLUB LOS PAPETICOS | E8: CLUB ARIEL ARMEL | G8: NOVATOS F. C. | I8: ESCUELA DEPORTIVA DE FÚTBOL RAQUIRA
C9: CLUB CAMPESTRE IBAGUE UNO | E9: CENTAUROS DEL ARIARI | G9: ESCUELA DE FORMACIÓN DEPORTIVA MARACANA | I9: CORDOBA Y SERRANO F. C.
I11: 2024

Sheet GRUPO A
A1: =+'PRE BABY GRUPOS'!C1 -> XVIII Festival Nacional Fútbol Infantil
A2: “COPA FUTURO TALENTO”
B3: =+'PRE BABY GRUPOS'!#REF! -> #REF! | F3: =+'PRE BABY GRUPOS'!C3 -> NACIDOS 2012 2013
B4: =+'PRE BABY GRUPOS'!C6 -> GRUPO A
B6: PARTIDOS | P6: POSICIONES | AJ6: =COUNT(G8,I8,G11,I11,G14,I14,G17,I17,G20,I20,G23,I23,G26,I26,G29,I29,G32,I32,G35,I35) -> 12
A7: Tj | N7: Tj
B8: 42966 | C8: 04:40. p.m. | E8: =+'PRE BABY GRUPOS'!C7 -> COLEGIO NEIL ARMSTRONG | F8: =IF(AND(G8<>"",I8<>""),IF(G8=I8,"E",IF(G8>I8,"G","P")),"") -> G | G8: 4 | H8: - | I8: 2 | J8: =IF(AND(I8<>"",G8<>""),IF(I8=G8,"E",IF(I8>G8,"G","P")),"") -> P | K8: =+'PRE BABY GRUPOS'!E7 -> COLEGIO PRINCIPADO DE MONACO | M8: CANCHA 1 C | Q8: Pts. | R8: PJ | S8: Gan. | T8: Emp. | U8: Per. | V8: GF | W8: GC | X8: Dif. | Y8: Tj | AJ8: =IF(AJ6=12,IF(INDEX(Z22:AK29,MATCH(2,Z22:Z29,0),11)=INDEX(Z22:AK29,MATCH(1,Z22:Z29,0),11),1,0),0) -> #N/A
P10: =" 1) " & VLOOKUP(1,$Z$10:$AI$17,2,0) -> 1) CLUB LOS PAPETICOS | Q10: =VLOOKUP(1,$Z$10:$AI$17,3,0) -> 7 | R10: =+SUM(S10:U11) -> 3 | S10: =VLOOKUP(1,$Z$10:$AI$17,4,0) -> 2 | T10: =VLOOKUP(1,$Z$10:$AI$17,5,0) -> 1 | U10: =VLOOKUP(1,$Z$10:$AI$17,6,0) -> 0 | V10: =VLOOKUP(1,$Z$10:$AI$17,7,0)-3 -> 10 | W10: =VLOOKUP(1,$Z$10:$AI$17,8,0) -> 5 | X10: =VLOOKUP(1,$Z$10:$AH$17,9,0) -> 8 | Y10: =VLOOKUP(1,$Z$10:$AI$17,10,0) -> 0 | Z10: =RANK(AJ10,$AJ$10:$AJ$17,0) -> 2 | AA10: =+'PRE BABY GRUPOS'!C7 -> COLEGIO NEIL ARMSTRONG | AB10: =(AC10*3)+AD10 -> 7 | AC10: =COUNTIF(Q58:T58,"G") -> 2 | AD10: =COUNTIF(Q58:T58,"E") -> 1 | AE10: =COUNTIF(Q58:T58,"P") -> 0 | AF10: =+G8+G20+G17+G29 -> 9 | AG10: =+I8+I20+I17+I29 -> 4 | AH10: =AF10-AG10 -> 5 | AI10: =+A8+A20+A29+A17 -> 0 | AJ10: =(AB10*1000)+(AH10*100)+(AF10*10)-AI10+0.1 -> 7590.1 | AK10: =AJ10+X10 -> 7598.1
B11: 42965 | C11: 11:55. a.m. | E11: =+'PRE BABY GRUPOS'!C8 -> CLUB LOS PAPETICOS | F11: =IF(AND(G11<>"",I11<>""),IF(G11=I11,"E",IF(G11>I11,"G","P")),"") -> G | G11: 3 | H11: - | I11: 2 | J11: =IF(AND(I11<>"",G11<>""),IF(I11=G11,"E",IF(I11>G11,"G","P")),"") -> P | K11: =+'PRE BABY GRUPOS'!E8 -> CLUB ARIEL ARMEL | M11: CANCHA 1 A
P12: =" 2) " & VLOOKUP(2,$Z$10:$AI$17,2,0) -> 2) COLEGIO NEIL ARMSTRONG | Q12: =VLOOKUP(2,$Z$10:$AI$17,3,0) -> 7 | R12: =+SUM(S12:U13) -> 3 | S12: =VLOOKUP(2,$Z$10:$AI$17,4,0) -> 2 | T12: =VLOOKUP(2,$Z$10:$AI$17,5,0) -> 1 | U12: =VLOOKUP(2,$Z$10:$AI$17,6,0) -> 0 | V12: =VLOOKUP(2,$Z$10:$AI$17,7,0) -> 9 | W12: =VLOOKUP(2,$Z$10:$AI$17,8,0) -> 4 | X12: =VLOOKUP(2,$Z$10:$AH$17,9,0) -> 5 | Y12: =VLOOKUP(2,$Z$10:$AI$17,10,0) -> 0 | Z12: =RANK(AJ12,$AJ$10:$AJ$17,0) -> 1 | AA12: =+'PRE BABY GRUPOS'!C8 -> CLUB LOS PAPETICOS | AB12: =(AC12*3)+AD12 -> 7 | AC12: =COUNTIF(Q59:T59,"G") -> 2 | AD12: =COUNTIF(Q59:T59,"E") -> 1 | AE12: =COUNTIF(Q59:T59,"P") -> 0 | AF12: =+G11+I17+G23+G32 -> 13 | AG12: =+I11+I23+G17+I32 -> 5 | AH12: =AF12-AG12 -> 8 | AI12: =+A23+A11+N17+A32 -> 0 | AJ12: =(AB12*1000)+(AH12*100)+(AF12*10)-AI12+0.2 -> 7930.2 | AK12: =AJ12+X12 -> 7935.2
B14: 42967 | C14: 02:55. p.m. | E14: =+'PRE BABY GRUPOS'!C9 -> CLUB CAMPESTRE IBAGUE UNO | F14: =IF(AND(G14<>"",I14<>""),IF(G14=I14,"E",IF(G14>I14,"G","P")),"") -> G | G14: 3 | H14: - | I14: 0 | J14: =IF(AND(I14<>"",G14<>""),IF(I14=G14,"E",IF(I14>G14,"G","P")),"") -> P | K14: =+'PRE BABY GRUPOS'!E9 -> CENTAUROS DEL ARIARI | M14: CANCHA 1 B | P14: =" 3) " & VLOOKUP(3,$Z$10:$AI$17,2,0) -> 3) CLUB CAMPESTRE IBAGUE UNO | Q14: =VLOOKUP(3,$Z$10:$AI$17,3,0) -> 3 | R14: =+SUM(S14:U15) -> 3 | S14: =VLOOKUP(3,$Z$10:$AI$17,4,0) -> 1 | T14: =VLOOKUP(3,$Z$10:$AI$17,5,0) -> 0 | U14: =VLOOKUP(3,$Z$10:$AI$17,6,0) -> 2 | V14: =VLOOKUP(3,$Z$10:$AI$17,7,0) -> 3 | W14: =VLOOKUP(3,$Z$10:$AI$17,8,0) -> 13 | X14: =VLOOKUP(3,$Z$10:$AI$17,9,0) -> -10 | Y14: =VLOOKUP(3,$Z$10:$AI$17,10,0) -> 0 | Z14: =RANK(AJ14,$AJ$10:$AJ$17,0) -> 3 | AA14: =+'PRE BABY GRUPOS'!C9 -> CLUB CAMPESTRE IBAGUE UNO | AB14: =(AC14*3)+AD14 -> 3 | AC14: =COUNTIF(Q60:T60,"G") -> 1 | AD14: =COUNTIF(Q60:T60,"E") -> 0 | AE14: =COUNTIF(Q60:T60,"P") -> 2 | AF14: =+G14+I29+G26+I32-3 -> 3 | AG14: =+G29+I14+I26+G32 -> 13 | AH14: =AF14-AG14 -> -10 | AI14: =+A14+A26+N29+N32 -> 0 | AJ14: =(AB14*1000)+(AH14*100)+(AF14*10)-AI14+0.3 -> 2030.3 | AK14: =+X14 -> -10
B17: 42967 | C17: 02:00. p.m. | E17: =+'PRE BABY GRUPOS'!C7 -> COLEGIO NEIL ARMSTRONG | F17: =IF(AND(G17<>"",I17<>""),IF(G17=I17,"E",IF(G17>I17,"G","P")),"") -> E | G17: 1 | H17: - | I17: 1 | J17: =IF(AND(I17<>"",G17<>""),IF(I17=G17,"E",IF(I17>G17,"G","P")),"") -> E | K17: =+'PRE BABY GRUPOS'!C8 -> CLUB LOS PAPETICOS | M17: CANCHA 1 A
B20: 42966 | C20: 11:45. a.m. | F20: =IF(AND(G20<>"",I20<>""),IF(G20=I20,"E",IF(G20>I20,"G","P")),"") | H20: - | J20: =IF(AND(I20<>"",G20<>""),IF(I20=G20,"E",IF(I20>G20,"G","P")),"") | M20: CANCHA 1 A
B23: 42966 | C23: 11:45. a.m. | F23: =IF(AND(G23<>"",I23<>""),IF(G23=I23,"E",IF(G23>I23,"G","P")),"") | H23: - | J23: =IF(AND(I23<>"",G23<>""),IF(I23=G23,"E",IF(I23>G23,"G","P")),"") | M23: CANCHA 1 B
B26: 42966 | C26: 12:40. p.m. | F26: =IF(AND(G26<>"",I26<>""),IF(G26=I26,"E",IF(G26>I26,"G","P")),"") | H26: - | J26: =IF(AND(I26<>"",G26<>""),IF(I26=G26,"E",IF(I26>G26,"G","P")),"") | M26: CANCHA 1 C
B29: 42965 | C29: 12:50. p.m. | E29: =+'PRE BABY GRUPOS'!C7 -> COLEGIO NEIL ARMSTRONG | F29: =IF(AND(G29<>"",I29<>""),IF(G29=I29,"E",IF(G29>I29,"G","P")),"") -> G | G29: 4 | H29: - | I29: 1 | J29: =IF(AND(I29<>"",G29<>""),IF(I29=G29,"E",IF(I29>G29,"G","P")),"") -> P | K29: =+'PRE BABY GRUPOS'!C9 -> CLUB CAMPESTRE IBAGUE UNO | M29: CANCHA 1 C
B32: 42967 | C32: 09:50. a.m. | E32: =+'PRE BABY GRUPOS'!C8 -> CLUB LOS PAPETICOS | F32: =IF(AND(G32<>"",I32<>""),IF(G32=I32,"E",IF(G32>I32,"G","P")),"") -> G | G32: 9 | H32: - | I32: 2 | J32: =IF(AND(I32<>"",G32<>""),IF(I32=G32,"E",IF(I32>G32,"G","P")),"") -> P | K32: =+'PRE BABY GRUPOS'!C9 -> CLUB CAMPESTRE IBAGUE UNO | M32: CANCHA 1 A
W34: =IF(AJ8=1,IF(P33="","",P33),IF(SUM(Q10:Q17)>0,VLOOKUP(1,Z10:AA17,2,0),"")) -> #N/A
W35: =IF(AJ8=1,IF(P36="","",P36),IF(SUM(Q22:Q29)>0,VLOOKUP(2,Z22:AA29,2,0),"")) -> #N/A
J43: =IF(AG20=1,"Indique el primero y segundo equipos clasificados de la serie:","") | L43: =IF(AG20=1,"Primero:","")
J46: =IF(AG20=1,"(Debido a la paridad de los resultados, no pueden deducirse de forma automática.)","") | L46: =IF(AG20=1,"Segundo:","")
P58: =+'PRE BABY GRUPOS'!C7 -> COLEGIO NEIL ARMSTRONG | Q58: =+F8 -> G | R58: =+F17 -> E | S58: =+F20 | T58: =+F29 -> G
P59: =+'PRE BABY GRUPOS'!C8 -> CLUB LOS PAPETICOS | Q59: =+F11 -> G | R59: =+J17 -> E | S59: =+F23 | T59: =+F32 -> G
P60: =+'PRE BABY GRUPOS'!C9 -> CLUB CAMPESTRE IBAGUE UNO | Q60: =+F14 -> G | R60: =+F26 | S60: =+J29 -> P | T60: =+J32 -> P

Sheet GRUPO B
A1: =+'PRE BABY GRUPOS'!C1 -> XVIII Festival Nacional Fútbol Infantil
A2: “COPA FUTURO TALENTO”
B3: =+'PRE BABY GRUPOS'!#REF! -> #REF! | F3: =+'PRE BABY GRUPOS'!C3 -> NACIDOS 2012 2013
B4: =+'PRE BABY GRUPOS'!E6 -> GRUPO B
B6: PARTIDOS | P6: POSICIONES | AJ6: =COUNT(G8,I8,G11,I11,G14,I14,G17,I17,G20,I20,G23,I23,G26,I26,G29,I29,G32,I32,G35,I35) -> 12
A7: Tj | N7: Tj
B8: =+'GRUPO A'!B8 -> 42966 | C8: =+'GRUPO A'!C8 -> 04:40. p.m. | E8: =+'GRUPO A'!E8:E9 -> COLEGIO NEIL ARMSTRONG | F8: =IF(AND(G8<>"",I8<>""),IF(G8=I8,"E",IF(G8>I8,"G","P")),"") -> G | G8: 4 | H8: - | I8: 2 | J8: =IF(AND(I8<>"",G8<>""),IF(I8=G8,"E",IF(I8>G8,"G","P")),"") -> P | K8: =+'GRUPO A'!K8:K9 -> COLEGIO PRINCIPADO DE MONACO | M8: =+'GRUPO A'!M8 -> CANCHA 1 C | Q8: Pts. | R8: PJ | S8: Gan. | T8: Emp. | U8: Per. | V8: GF | W8: GC | X8: Dif. | Y8: Tj | AJ8: =IF(AJ6=12,IF(INDEX(Z10:AK17,MATCH(2,Z10:Z17,0),11)=INDEX(Z10:AK17,MATCH(1,Z10:Z17,0),11),1,0),0) -> 0
P10: =" 1) " & VLOOKUP(1,$Z$10:$AI$17,2,0) -> 1) CLUB ARIEL ARMEL | Q10: =VLOOKUP(1,$Z$10:$AI$17,3,0) -> 4 | R10: =+SUM(S10:U11) -> 3 | S10: =VLOOKUP(1,$Z$10:$AI$17,4,0) -> 1 | T10: =VLOOKUP(1,$Z$10:$AI$17,5,0) -> 1 | U10: =VLOOKUP(1,$Z$10:$AI$17,6,0) -> 1 | V10: =VLOOKUP(1,$Z$10:$AI$17,7,0) -> 7 | W10: =VLOOKUP(1,$Z$10:$AI$17,8,0) -> 4 | X10: =VLOOKUP(1,$Z$10:$AH$17,9,0) -> 3 | Y10: =VLOOKUP(1,$Z$10:$AI$17,10,0) -> 0 | Z10: =RANK(AJ10,$AJ$10:$AJ$17,0) -> 3 | AA10: =+'PRE BABY GRUPOS'!E7 -> COLEGIO PRINCIPADO DE MONACO | AB10: =(AC10*3)+AD10 -> 1 | AC10: =COUNTIF(Q58:T58,"G") -> 0 | AD10: =COUNTIF(Q58:T58,"E") -> 1 | AE10: =COUNTIF(Q58:T58,"P") -> 2 | AF10: =+I8+G20+G29+G17 -> 7 | AG10: =+I17+I20+I29+G8 -> 12 | AH10: =AF10-AG10 -> -5 | AI10: =+A17+A20+A29+N8 -> 0 | AJ10: =(AB10*1000)+(AH10*100)+(AF10*10)-AI10+0.1 -> 570.1 | AK10: =AJ10+X10 -> 573.1
B11: =+'GRUPO A'!B11 -> 42965 | C11: =+'GRUPO A'!C11 -> 11:55. a.m. | E11: =+'GRUPO A'!E11:E12 -> CLUB LOS PAPETICOS | F11: =IF(AND(G11<>"",I11<>""),IF(G11=I11,"E",IF(G11>I11,"G","P")),"") -> G | G11: 3 | H11: - | I11: 2 | J11: =IF(AND(I11<>"",G11<>""),IF(I11=G11,"E",IF(I11>G11,"G","P")),"") -> P | K11: =+'GRUPO A'!K11:K12 -> CLUB ARIEL ARMEL | M11: =+'GRUPO A'!M11 -> CANCHA 1 A
P12: =" 2) " & VLOOKUP(2,$Z$10:$AI$17,2,0) -> 2) CENTAUROS DEL ARIARI | Q12: =VLOOKUP(2,$Z$10:$AI$17,3,0) -> 3 | R12: =+SUM(S12:U13) -> 3 | S12: =VLOOKUP(2,$Z$10:$AI$17,4,0) -> 1 | T12: =VLOOKUP(2,$Z$10:$AI$17,5,0) -> 0 | U12: =VLOOKUP(2,$Z$10:$AI$17,6,0) -> 2 | V12: =VLOOKUP(2,$Z$10:$AI$17,7,0) -> 4 | W12: =VLOOKUP(2,$Z$10:$AI$17,8,0) -> 5 | X12: =VLOOKUP(2,$Z$10:$AH$17,9,0) -> -1 | Y12: =VLOOKUP(2,$Z$10:$AI$17,10,0) -> 0 | Z12: =RANK(AJ12,$AJ$10:$AJ$17,0) -> 1 | AA12: =+'PRE BABY GRUPOS'!E8 -> CLUB ARIEL ARMEL | AB12: =(AC12*3)+AD12 -> 4 | AC12: =COUNTIF(Q59:T59,"G") -> 1 | AD12: =COUNTIF(Q59:T59,"E") -> 1 | AE12: =COUNTIF(Q59:T59,"P") -> 1 | AF12: =+G23+I17+G32+I11 -> 7 | AG12: =+G17+I23+I32+G11-3 -> 4 | AH12: =AF12-AG12 -> 3 | AI12: =+N17+A23+A32+N11 -> 0 | AJ12: =(AB12*1000)+(AH12*100)+(AF12*10)-AI12+0.2 -> 4370.2 | AK12: =AJ12+X12 -> 4369.2
B14: =+'GRUPO A'!B14 -> 42967 | C14: =+'GRUPO A'!C14 -> 02:55. p.m. | E14: =+'GRUPO A'!E14:E15 -> CLUB CAMPESTRE IBAGUE UNO | F14: =IF(AND(G14<>"",I14<>""),IF(G14=I14,"E",IF(G14>I14,"G","P")),"") -> G | G14: 3 | H14: - | I14: 0 | J14: =IF(AND(I14<>"",G14<>""),IF(I14=G14,"E",IF(I14>G14,"G","P")),"") -> P | K14: =+'GRUPO A'!K14:K15 -> CENTAUROS DEL ARIARI | M14: =+'GRUPO A'!M14 -> CANCHA 1 B | P14: =" 3) " & VLOOKUP(3,$Z$10:$AI$17,2,0) -> 3) COLEGIO PRINCIPADO DE MONACO | Q14: =VLOOKUP(3,$Z$10:$AI$17,3,0) -> 1 | R14: =+SUM(S14:U15) -> 3 | S14: =VLOOKUP(3,$Z$10:$AI$17,4,0) -> 0 | T14: =VLOOKUP(3,$Z$10:$AI$17,5,0) -> 1 | U14: =VLOOKUP(3,$Z$10:$AI$17,6,0) -> 2 | V14: =VLOOKUP(3,$Z$10:$AI$17,7,0) -> 7 | W14: =VLOOKUP(3,$Z$10:$AI$17,8,0) -> 12 | X14: =VLOOKUP(3,$Z$10:$AI$17,9,0) -> -5 | Y14: =VLOOKUP(3,$Z$10:$AI$17,10,0) -> 0 | Z14: =RANK(AJ14,$AJ$10:$AJ$17,0) -> 2 | AA14: =+'PRE BABY GRUPOS'!E9 -> CENTAUROS DEL ARIARI | AB14: =(AC14*3)+AD14 -> 3 | AC14: =COUNTIF(Q60:T60,"G") -> 1 | AD14: =COUNTIF(Q60:T60,"E") -> 0 | AE14: =COUNTIF(Q60:T60,"P") -> 2 | AF14: =+G26+I29+I32+I14 -> 4 | AG14: =+G29+I26+G32+G14 -> 5 | AH14: =AF14-AG14 -> -1 | AI14: =+A26+N29+N32+N14 -> 0 | AJ14: =(AB14*1000)+(AH14*100)+(AF14*10)-AI14+0.3 -> 2940.3 | AK14: =+X14 -> -5
B17: 42967 | C17: 03:50. p.m. | E17: =+'PRE BABY GRUPOS'!E7 -> COLEGIO PRINCIPADO DE MONACO | F17: =IF(AND(G17<>"",I17<>""),IF(G17=I17,"E",IF(G17>I17,"G","P")),"") -> E | G17: 4 | H17: - | I17: 4 | J17: =IF(AND(I17<>"",G17<>""),IF(I17=G17,"E",IF(I17>G17,"G","P")),"") -> E | K17: =+'PRE BABY GRUPOS'!E8 -> CLUB ARIEL ARMEL | M17: CANCHA 1 A
B20: 42966 | C20: 11:45. a.m. | F20: =IF(AND(G20<>"",I20<>""),IF(G20=I20,"E",IF(G20>I20,"G","P")),"") | H20: - | J20: =IF(AND(I20<>"",G20<>""),IF(I20=G20,"E",IF(I20>G20,"G","P")),"") | M20: CANCHA 1 C
B23: 42966 | C23: 04:40. a.m. | F23: =IF(AND(G23<>"",I23<>""),IF(G23=I23,"E",IF(G23>I23,"G","P")),"") | H23: - | J23: =IF(AND(I23<>"",G23<>""),IF(I23=G23,"E",IF(I23>G23,"G","P")),"") | M23: CANCHA 1 A
B26: 42966 | C26: 04:40. p.m. | F26: =IF(AND(G26<>"",I26<>""),IF(G26=I26,"E",IF(G26>I26,"G","P")),"") | H26: - | J26: =IF(AND(I26<>"",G26<>""),IF(I26=G26,"E",IF(I26>G26,"G","P")),"") | M26: CANCHA 1 B
B29: 42967 | C29: 10:50. a.m. | E29: =+'PRE BABY GRUPOS'!E7 -> COLEGIO PRINCIPADO DE MONACO | F29: =IF(AND(G29<>"",I29<>""),IF(G29=I29,"E",IF(G29>I29,"G","P")),"") -> P | G29: 1 | H29: - | I29: 4 | J29: =IF(AND(I29<>"",G29<>""),IF(I29=G29,"E",IF(I29>G29,"G","P")),"") -> G | K29: =+'PRE BABY GRUPOS'!E9 -> CENTAUROS DEL ARIARI | M29: CANCHA 1 A
B32: 42965 | C32: 04:30. p.m. | E32: =+'PRE BABY GRUPOS'!E8 -> CLUB ARIEL ARMEL | F32: =IF(AND(G32<>"",I32<>""),IF(G32=I32,"E",IF(G32>I32,"G","P")),"") -> G | G32: 1 | H32: - | I32: 0 | J32: =IF(AND(I32<>"",G32<>""),IF(I32=G32,"E",IF(I32>G32,"G","P")),"") -> P | K32: =+'PRE BABY GRUPOS'!E9 -> CENTAUROS DEL ARIARI | M32: CANCHA 1 A
W34: =IF(AJ8=1,IF(P33="","",P33),IF(SUM(Q10:Q17)>0,VLOOKUP(1,Z10:AA17,2,0),"")) -> CLUB ARIEL ARMEL
W35: =IF(AJ8=1,IF(P36="","",P36),IF(SUM(Q10:Q17)>0,VLOOKUP(2,Z10:AA17,2,0),"")) -> CENTAUROS DEL ARIARI
J43: =IF(AG8=1,"Indique el primero y segundo equipos clasificados de la serie:","") | L43: =IF(AG8=1,"Primero:","")
J46: =IF(AG8=1,"(Debido a la paridad de los resultados, no pueden deducirse de forma automática.)","") | L46: =IF(AG8=1,"Segundo:","")
P58: =+'PRE BABY GRUPOS'!E7 -> COLEGIO PRINCIPADO DE MONACO | Q58: =+J8 -> P | R58: =+F17 -> E | S58: =+F20 | T58: =+F29 -> P
P59: =+'PRE BABY GRUPOS'!E8 -> CLUB ARIEL ARMEL | Q59: =+J11 -> P | R59: =+J17 -> E | S59: =+F23 | T59: =+F32 -> G
P60: =+'PRE BABY GRUPOS'!E9 -> CENTAUROS DEL ARIARI | Q60: =+J14 -> P | R60: =+F26 | S60: =+J29 -> G | T60: =+J32 -> P

Sheet GRUPO C
A1: =+'PRE BABY GRUPOS'!C1 -> XVIII Festival Nacional Fútbol Infantil
A2: “COPA FUTURO TALENTO”
B3: =+'PRE BABY GRUPOS'!#REF! -> #REF! | F3: =+'PRE BABY GRUPOS'!C3 -> NACIDOS 2012 2013
B4: =+'PRE BABY GRUPOS'!G6 -> GRUPO C
B6: PARTIDOS | P6: POSICIONES | AJ6: =COUNT(G8,I8,G11,I11,G14,I14,G17,I17,G20,I20,G23,I23,G26,I26,G29,I29,G32,I32,G35,I35) -> 12
A7: Tj | N7: Tj
B8: 42967 | C8: 02:00. p.m. | E8: =+'PRE BABY GRUPOS'!G7 -> GRAMA F. C. | F8: =IF(AND(G8<>"",I8<>""),IF(G8=I8,"E",IF(G8>I8,"G","P")),"") -> P | G8: 1 | H8: - | I8: 4 | J8: =IF(AND(I8<>"",G8<>""),IF(I8=G8,"E",IF(I8>G8,"G","P")),"") -> G | K8: =+'PRE BABY GRUPOS'!I7 -> CLUB CAMPESTRE IBAGUE DOS | M8: CANCHA 1 C | Q8: Pts. | R8: PJ | S8: Gan. | T8: Emp. | U8: Per. | V8: GF | W8: GC | X8: Dif. | Y8: Tj | AJ8: =IF(AJ6=12,IF(INDEX(Z10:AK17,MATCH(2,Z10:Z17,0),11)=INDEX(Z10:AK17,MATCH(1,Z10:Z17,0),11),1,0),0) -> 0
P10: =" 1) " & VLOOKUP(1,$Z$10:$AI$17,2,0) -> 1) GRAMA F. C. | Q10: =VLOOKUP(1,$Z$10:$AI$17,3,0) -> 6 | R10: =+SUM(S10:U11) -> 3 | S10: =VLOOKUP(1,$Z$10:$AI$17,4,0) -> 2 | T10: =VLOOKUP(1,$Z$10:$AI$17,5,0) -> 0 | U10: =VLOOKUP(1,$Z$10:$AI$17,6,0) -> 1 | V10: =VLOOKUP(1,$Z$10:$AI$17,7,0) -> 8 | W10: =VLOOKUP(1,$Z$10:$AI$17,8,0) -> 6 | X10: =VLOOKUP(1,$Z$10:$AH$17,9,0) -> 2 | Y10: =VLOOKUP(1,$Z$10:$AI$17,10,0) -> 0 | Z10: =RANK(AJ10,$AJ$10:$AJ$17,0) -> 1 | AA10: =+'PRE BABY GRUPOS'!G7 -> GRAMA F. C. | AB10: =(AC10*3)+AD10 -> 6 | AC10: =COUNTIF(Q58:T58,"G") -> 2 | AD10: =COUNTIF(Q58:T58,"E") -> 0 | AE10: =COUNTIF(Q58:T58,"P") -> 1 | AF10: =+I17+G26+G29+G8 -> 8 | AG10: =+G17+I26+I29+I8 -> 6 | AH10: =AF10-AG10 -> 2 | AI10: =+N17+A26+A29+A8 -> 0 | AJ10: =(AB10*1000)+(AH10*100)+(AF10*10)-AI10+0.1 -> 6280.1 | AK10: =AJ10+X10 -> 6282.1
B11: 42967 | C11: 02:00. p.m. | E11: =+'PRE BABY GRUPOS'!G8 -> NOVATOS F. C. | F11: =IF(AND(G11<>"",I11<>""),IF(G11=I11,"E",IF(G11>I11,"G","P")),"") -> P | G11: 0 | H11: - | I11: 3 | J11: =IF(AND(I11<>"",G11<>""),IF(I11=G11,"E",IF(I11>G11,"G","P")),"") -> G | K11: =+'PRE BABY GRUPOS'!I8 -> ESCUELA DEPORTIVA DE FÚTBOL RAQUIRA | M11: CANCHA 1 B
P12: =" 2) " & VLOOKUP(2,$Z$10:$AI$17,2,0) -> 2) ESCUELA DE FORMACIÓN DEPORTIVA MARACANA | Q12: =VLOOKUP(2,$Z$10:$AI$17,3,0) -> 4 | R12: =+SUM(S12:U13) -> 3 | S12: =VLOOKUP(2,$Z$10:$AI$17,4,0) -> 1 | T12: =VLOOKUP(2,$Z$10:$AI$17,5,0) -> 1 | U12: =VLOOKUP(2,$Z$10:$AI$17,6,0) -> 1 | V12: =VLOOKUP(2,$Z$10:$AI$17,7,0) -> 17 | W12: =VLOOKUP(2,$Z$10:$AI$17,8,0) -> 5 | X12: =VLOOKUP(2,$Z$10:$AH$17,9,0) -> 12 | Y12: =VLOOKUP(2,$Z$10:$AI$17,10,0) -> 0 | Z12: =RANK(AJ12,$AJ$10:$AJ$17,0) -> 3 | AA12: =+'PRE BABY GRUPOS'!G8 -> NOVATOS F. C. | AB12: =(AC12*3)+AD12 -> 0 | AC12: =COUNTIF(Q59:T59,"G") -> 0 | AD12: =COUNTIF(Q59:T59,"E") -> 0 | AE12: =COUNTIF(Q59:T59,"P") -> 3 | AF12: =+I20+G32+I26+G11 -> 1 | AG12: =+G20+I32+G26+I11 -> 21 | AH12: =AF12-AG12 -> -20 | AI12: =+N20+N26+A32+A11 -> 0 | AJ12: =(AB12*1000)+(AH12*100)+(AF12*10)-AI12+0.2 -> -1989.8 | AK12: =AJ12+X12 -> -1977.8
B14: 42967 | C14: 02:55. p.m. | E14: =+'PRE BABY GRUPOS'!G9 -> ESCUELA DE FORMACIÓN DEPORTIVA MARACANA | F14: =IF(AND(G14<>"",I14<>""),IF(G14=I14,"E",IF(G14>I14,"G","P")),"") -> E | G14: 3 | H14: - | I14: 3 | J14: =IF(AND(I14<>"",G14<>""),IF(I14=G14,"E",IF(I14>G14,"G","P")),"") -> E | K14: =+'PRE BABY GRUPOS'!I9 -> CORDOBA Y SERRANO F. C. | M14: CANCHA 1 A | P14: =" 3) " & VLOOKUP(3,$Z$10:$AI$17,2,0) -> 3) NOVATOS F. C. | Q14: =VLOOKUP(3,$Z$10:$AI$17,3,0) -> 0 | R14: =+SUM(S14:U15) -> 3 | S14: =VLOOKUP(3,$Z$10:$AI$17,4,0) -> 0 | T14: =VLOOKUP(3,$Z$10:$AI$17,5,0) -> 0 | U14: =VLOOKUP(3,$Z$10:$AI$17,6,0) -> 3 | V14: =VLOOKUP(3,$Z$10:$AI$17,7,0) -> 1 | W14: =VLOOKUP(3,$Z$10:$AI$17,8,0) -> 21 | X14: =VLOOKUP(3,$Z$10:$AI$17,9,0) -> -20 | Y14: =VLOOKUP(3,$Z$10:$AI$17,10,0) -> 0 | Z14: =RANK(AJ14,$AJ$10:$AJ$17,0) -> 2 | AA14: =+'PRE BABY GRUPOS'!G9 -> ESCUELA DE FORMACIÓN DEPORTIVA MARACANA | AB14: =(AC14*3)+AD14 -> 4 | AC14: =COUNTIF(Q60:T60,"G") -> 1 | AD14: =COUNTIF(Q60:T60,"E") -> 1 | AE14: =COUNTIF(Q60:T60,"P") -> 1 | AF14: =+I23+I29+I32+G14 -> 17 | AG14: =+G23+G29+G32+I14 -> 5 | AH14: =AF14-AG14 -> 12 | AI14: =+N23+N29+N32+A14 -> 0 | AJ14: =(AB14*1000)+(AH14*100)+(AF14*10)-AI14+0.3 -> 5370.3 | AK14: =+X14 -> -20
B17: =+'GRUPO A'!B20 -> 42966 | C17: =+'GRUPO A'!C20 -> 11:45. a.m. | F17: =IF(AND(G17<>"",I17<>""),IF(G17=I17,"E",IF(G17>I17,"G","P")),"") | H17: - | J17: =IF(AND(I17<>"",G17<>""),IF(I17=G17,"E",IF(I17>G17,"G","P")),"") | M17: =+'GRUPO A'!M20 -> CANCHA 1 A
B20: =+'GRUPO A'!B23 -> 42966 | C20: =+'GRUPO A'!C23 -> 11:45. a.m. | F20: =IF(AND(G20<>"",I20<>""),IF(G20=I20,"E",IF(G20>I20,"G","P")),"") | H20: - | J20: =IF(AND(I20<>"",G20<>""),IF(I20=G20,"E",IF(I20>G20,"G","P")),"") | M20: =+'GRUPO A'!M23 -> CANCHA 1 B
B23: =+'GRUPO A'!B26 -> 42966 | C23: =+'GRUPO A'!C26 -> 12:40. p.m. | F23: =IF(AND(G23<>"",I23<>""),IF(G23=I23,"E",IF(G23>I23,"G","P")),"") | H23: - | J23: =IF(AND(I23<>"",G23<>""),IF(I23=G23,"E",IF(I23>G23,"G","P")),"") | M23: =+'GRUPO A'!M26 -> CANCHA 1 C
B26: 42966 | C26: 03:50. p.m. | E26: =+'PRE BABY GRUPOS'!G7 -> GRAMA F. C. | F26: =IF(AND(G26<>"",I26<>""),IF(G26=I26,"E",IF(G26>I26,"G","P")),"") -> G | G26: 5 | H26: - | I26: 1 | J26: =IF(AND(I26<>"",G26<>""),IF(I26=G26,"E",IF(I26>G26,"G","P")),"") -> P | K26: =+'PRE BABY GRUPOS'!G8 -> NOVATOS F. C. | M26: CANCHA 1 C
B29: 42965 | C29: 12:50. p.m. | E29: =+'PRE BABY GRUPOS'!G7 -> GRAMA F. C. | F29: =IF(AND(G29<>"",I29<>""),IF(G29=I29,"E",IF(G29>I29,"G","P")),"") -> G | G29: 2 | H29: - | I29: 1 | J29: =IF(AND(I29<>"",G29<>""),IF(I29=G29,"E",IF(I29>G29,"G","P")),"") -> P | K29: =+'PRE BABY GRUPOS'!G9 -> ESCUELA DE FORMACIÓN DEPORTIVA MARACANA | M29: CANCHA 1 A
B32: 42967 | C32: 09:50. a.m. | E32: =+'PRE BABY GRUPOS'!G8 -> NOVATOS F. C. | F32: =IF(AND(G32<>"",I32<>""),IF(G32=I32,"E",IF(G32>I32,"G","P")),"") -> P | G32: 0 | H32: - | I32: 13 | J32: =IF(AND(I32<>"",G32<>""),IF(I32=G32,"E",IF(I32>G32,"G","P")),"") -> G | K32: =+'PRE BABY GRUPOS'!G9 -> ESCUELA DE FORMACIÓN DEPORTIVA MARACANA | M32: CANCHA 1 C
W34: =IF(AJ8=1,IF(P33="","",P33),IF(SUM(Q10:Q17)>0,VLOOKUP(1,Z10:AA17,2,0),"")) -> GRAMA F. C.
W35: =IF(AJ8=1,IF(P36="","",P36),IF(SUM(Q10:Q17)>0,VLOOKUP(2,Z10:AA17,2,0),"")) -> ESCUELA DE FORMACIÓN DEPORTIVA MARACANA
J43: =IF(AG8=1,"Indique el primero y segundo equipos clasificados de la serie:","") | L43: =IF(AG8=1,"Primero:","")
J46: =IF(AG8=1,"(Debido a la paridad de los resultados, no pueden deducirse de forma automática.)","") | L46: =IF(AG8=1,"Segundo:","")
P58: =+'PRE BABY GRUPOS'!G7 -> GRAMA F. C. | Q58: =+F8 -> P | R58: =+J17 | S58: =+F26 -> G | T58: =+F29 -> G
P59: =+'PRE BABY GRUPOS'!G8 -> NOVATOS F. C. | Q59: =+F11 -> P | R59: =+J20 | S59: =+J26 -> P | T59: =+F32 -> P
P60: =+'PRE BABY GRUPOS'!G9 -> ESCUELA DE FORMACIÓN DEPORTIVA MARACANA | Q60: =+F14 -> E | R60: =+J23 | S60: =+J29 -> P | T60: =+J32 -> G

Sheet GRUPO D
A1: =+'PRE BABY GRUPOS'!C1 -> XVIII Festival Nacional Fútbol Infantil
A2: “COPA FUTURO TALENTO”
B3: =+'PRE BABY GRUPOS'!#REF! -> #REF! | F3: =+'PRE BABY GRUPOS'!C3 -> NACIDOS 2012 2013
B4: =+'PRE BABY GRUPOS'!I6 -> GRUPO D
B6: PARTIDOS | P6: POSICIONES | AJ6: =COUNT(G20,I20,G23,I23,G26,I26,G29,I29,G32,I32,G35,I35) -> 6
A7: Tj | N7: Tj
B8: =+'GRUPO C'!B8 -> 42967 | C8: =+'GRUPO C'!C8 -> 02:00. p.m. | E8: =+'GRUPO C'!E8:E9 -> GRAMA F. C. | F8: =IF(AND(G8<>"",I8<>""),IF(G8=I8,"E",IF(G8>I8,"G","P")),"") -> P | G8: 1 | H8: - | I8: 4 | J8: =IF(AND(I8<>"",G8<>""),IF(I8=G8,"E",IF(I8>G8,"G","P")),"") -> G | K8: =+'GRUPO C'!K8:K8 -> CLUB CAMPESTRE IBAGUE DOS | M8: =+'GRUPO C'!M8 -> CANCHA 1 C | Q8: Pts. | R8: PJ | S8: Gan. | T8: Emp. | U8: Per. | V8: GF | W8: GC | X8: Dif. | Y8: Tj | AJ8: =IF(AJ6=12,IF(INDEX(Z10:AK17,MATCH(2,Z10:Z17,0),11)=INDEX(Z10:AK17,MATCH(1,Z10:Z17,0),11),1,0),0) -> 0
P10: =" 1) " & VLOOKUP(1,$Z$10:$AI$17,2,0) -> 1) CLUB CAMPESTRE IBAGUE DOS | Q10: =VLOOKUP(1,$Z$10:$AI$17,3,0) -> 7 | R10: =+SUM(S10:U11) -> 3 | S10: =VLOOKUP(1,$Z$10:$AI$17,4,0) -> 2 | T10: =VLOOKUP(1,$Z$10:$AI$17,5,0) -> 1 | U10: =VLOOKUP(1,$Z$10:$AI$17,6,0) -> 0 | V10: =VLOOKUP(1,$Z$10:$AI$17,7,0) -> 12 | W10: =VLOOKUP(1,$Z$10:$AI$17,8,0) -> 9 | X10: =VLOOKUP(1,$Z$10:$AH$17,9,0) -> 3 | Y10: =VLOOKUP(1,$Z$10:$AI$17,10,0) -> 0 | Z10: =RANK(AJ10,$AJ$10:$AJ$17,0) -> 1 | AA10: =+'PRE BABY GRUPOS'!I7 -> CLUB CAMPESTRE IBAGUE DOS | AB10: =(AC10*3)+AD10 -> 7 | AC10: =COUNTIF(Q59:T59,"G") -> 2 | AD10: =COUNTIF(Q59:T59,"E") -> 1 | AE10: =COUNTIF(Q59:T59,"P") -> 0 | AF10: =+I8+I26+G32+I20 -> 12 | AG10: =+G17+I26+I32+G8 -> 9 | AH10: =AF10-AG10 -> 3 | AI10: =+N17+A26+A29+N8 -> 0 | AJ10: =(AB10*1000)+(AH10*100)+(AF10*10)-AI10+0.1 -> 7420.1 | AK10: =AJ10+X10 -> 7423.1
B11: =+'GRUPO C'!B11 -> 42967 | C11: =+'GRUPO C'!C11 -> 02:00. p.m. | E11: =+'GRUPO C'!E11:E12 -> NOVATOS F. C. | F11: =IF(AND(G11<>"",I11<>""),IF(G11=I11,"E",IF(G11>I11,"G","P")),"") -> P | G11: 0 | H11: - | I11: 3 | J11: =IF(AND(I11<>"",G11<>""),IF(I11=G11,"E",IF(I11>G11,"G","P")),"") -> G | K11: =+'GRUPO C'!K11:K12 -> ESCUELA DEPORTIVA DE FÚTBOL RAQUIRA | M11: =+'GRUPO C'!M11 -> CANCHA 1 B
P12: =" 2) " & VLOOKUP(2,$Z$10:$AI$17,2,0) -> 2) CORDOBA Y SERRANO F. C. | Q12: =VLOOKUP(2,$Z$10:$AI$17,3,0) -> 5 | R12: =+SUM(S12:U13) -> 3 | S12: =VLOOKUP(2,$Z$10:$AI$17,4,0) -> 1 | T12: =VLOOKUP(2,$Z$10:$AI$17,5,0) -> 2 | U12: =VLOOKUP(2,$Z$10:$AI$17,6,0) -> 0 | V12: =VLOOKUP(2,$Z$10:$AI$17,7,0) -> 18 | W12: =VLOOKUP(2,$Z$10:$AI$17,8,0) -> 6 | X12: =VLOOKUP(2,$Z$10:$AH$17,9,0) -> 12 | Y12: =VLOOKUP(2,$Z$10:$AI$17,10,0) -> 0 | Z12: =RANK(AJ12,$AJ$10:$AJ$17,0) -> 3 | AA12: =+'PRE BABY GRUPOS'!I8 -> ESCUELA DEPORTIVA DE FÚTBOL RAQUIRA | AB12: =(AC12*3)+AD12 -> 3 | AC12: =COUNTIF(Q58:T58,"G") -> 1 | AD12: =COUNTIF(Q58:T58,"E") -> 0 | AE12: =COUNTIF(Q58:T58,"P") -> 2 | AF12: =+I17+G26+G29+I11 -> 5 | AG12: =+G20+I26+I29+G11 -> 17 | AH12: =AF12-AG12 -> -12 | AI12: =+N20+N26+A32+N11 -> 0 | AJ12: =(AB12*1000)+(AH12*100)+(AF12*10)-AI12+0.2 -> 1850.2 | AK12: =AJ12+X12 -> 1862.2
B14: =+'GRUPO C'!B14 -> 42967 | C14: =+'GRUPO C'!C14 -> 02:55. p.m. | E14: =+'GRUPO C'!E14:E15 -> ESCUELA DE FORMACIÓN DEPORTIVA MARACANA | F14: =IF(AND(G14<>"",I14<>""),IF(G14=I14,"E",IF(G14>I14,"G","P")),"") -> E | G14: 3 | H14: - | I14: 3 | J14: =IF(AND(I14<>"",G14<>""),IF(I14=G14,"E",IF(I14>G14,"G","P")),"") -> E | K14: =+'GRUPO C'!K14:K15 -> CORDOBA Y SERRANO F. C. | M14: =+'GRUPO C'!M14 -> CANCHA 1 A | P14: =" 3) " & VLOOKUP(3,$Z$10:$AI$17,2,0) -> 3) ESCUELA DEPORTIVA DE FÚTBOL RAQUIRA | Q14: =VLOOKUP(3,$Z$10:$AI$17,3,0) -> 3 | R14: =+SUM(S14:U15) -> 3 | S14: =VLOOKUP(3,$Z$10:$AI$17,4,0) -> 1 | T14: =VLOOKUP(3,$Z$10:$AI$17,5,0) -> 0 | U14: =VLOOKUP(3,$Z$10:$AI$17,6,0) -> 2 | V14: =VLOOKUP(3,$Z$10:$AI$17,7,0) -> 5 | W14: =VLOOKUP(3,$Z$10:$AI$17,8,0) -> 17 | X14: =VLOOKUP(3,$Z$10:$AI$17,9,0) -> -12 | Y14: =VLOOKUP(3,$Z$10:$AI$17,10,0) -> 0 | Z14: =RANK(AJ14,$AJ$10:$AJ$17,0) -> 2 | AA14: =+'PRE BABY GRUPOS'!I9 -> CORDOBA Y SERRANO F. C. | AB14: =(AC14*3)+AD14 -> 5 | AC14: =COUNTIF(Q60:T60,"G") -> 1 | AD14: =COUNTIF(Q60:T60,"E") -> 2 | AE14: =COUNTIF(Q60:T60,"P") -> 0 | AF14: =+I23+I29+I32+I14 -> 18 | AG14: =+G23+G29+G32+G14 -> 6 | AH14: =AF14-AG14 -> 12 | AI14: =+N23+N29+N32+N14 -> 0 | AJ14: =(AB14*1000)+(AH14*100)+(AF14*10)-AI14+0.3 -> 6380.3 | AK14: =+X14 -> -12
B17: =+'GRUPO B'!B20 -> 42966 | C17: =+'GRUPO B'!C20 -> 11:45. a.m. | F17: =IF(AND(G17<>"",I17<>""),IF(G17=I17,"E",IF(G17>I17,"G","P")),"") | H17: - | J17: =IF(AND(I17<>"",G17<>""),IF(I17=G17,"E",IF(I17>G17,"G","P")),"") | M17: =+'GRUPO B'!M20 -> CANCHA 1 C
B20: =+'GRUPO B'!B23 -> 42966 | C20: =+'GRUPO B'!C23 -> 04:40. a.m. | F20: =IF(AND(G20<>"",I20<>""),IF(G20=I20,"E",IF(G20>I20,"G","P")),"") | H20: - | J20: =IF(AND(I20<>"",G20<>""),IF(I20=G20,"E",IF(I20>G20,"G","P")),"") | M20: =+'GRUPO B'!M23 -> CANCHA 1 A
B23: =+'GRUPO B'!B26 -> 42966 | C23: =+'GRUPO B'!C26 -> 04:40. p.m. | F23: =IF(AND(G23<>"",I23<>""),IF(G23=I23,"E",IF(G23>I23,"G","P")),"") | H23: - | J23: =IF(AND(I23<>"",G23<>""),IF(I23=G23,"E",IF(I23>G23,"G","P")),"") | M23: =+'GRUPO B'!M26 -> CANCHA 1 B
B26: 42967 | C26: 09:50. a.m. | E26: =+'PRE BABY GRUPOS'!I8 -> ESCUELA DEPORTIVA DE FÚTBOL RAQUIRA | F26: =IF(AND(G26<>"",I26<>""),IF(G26=I26,"E",IF(G26>I26,"G","P")),"") -> P | G26: 2 | H26: - | I26: 5 | J26: =IF(AND(I26<>"",G26<>""),IF(I26=G26,"E",IF(I26>G26,"G","P")),"") -> G | K26: =+'PRE BABY GRUPOS'!I7 -> CLUB CAMPESTRE IBAGUE DOS | M26: CANCHA 1 B
B29: 42965 | C29: 11:55. a.m. | E29: =+'PRE BABY GRUPOS'!I8 -> ESCUELA DEPORTIVA DE FÚTBOL RAQUIRA | F29: =IF(AND(G29<>"",I29<>""),IF(G29=I29,"E",IF(G29>I29,"G","P")),"") -> P | G29: 0 | H29: - | I29: 12 | J29: =IF(AND(I29<>"",G29<>""),IF(I29=G29,"E",IF(I29>G29,"G","P")),"") -> G | K29: =+'PRE BABY GRUPOS'!I9 -> CORDOBA Y SERRANO F. C. | M29: CANCHA 1 A
B32: 42966 | C32: 12:40. p.m. | E32: =+'PRE BABY GRUPOS'!I7 -> CLUB CAMPESTRE IBAGUE DOS | F32: =IF(AND(G32<>"",I32<>""),IF(G32=I32,"E",IF(G32>I32,"G","P")),"") -> E | G32: 3 | H32: - | I32: 3 | J32: =IF(AND(I32<>"",G32<>""),IF(I32=G32,"E",IF(I32>G32,"G","P")),"") -> E | K32: =+'PRE BABY GRUPOS'!I9 -> CORDOBA Y SERRANO F. C. | M32: CANCHA 1 A
W34: =IF(AJ8=1,IF(P33="","",P33),IF(SUM(Q10:Q17)>0,VLOOKUP(1,Z10:AA17,2,0),"")) -> CLUB CAMPESTRE IBAGUE DOS
W35: =IF(AJ8=1,IF(P36="","",P36),IF(SUM(Q10:Q17)>0,VLOOKUP(2,Z10:AA17,2,0),"")) -> CORDOBA Y SERRANO F. C.
J43: =IF(AG8=1,"Indique el primero y segundo equipos clasificados de la serie:","") | L43: =IF(AG8=1,"Primero:","")
J46: =IF(AG8=1,"(Debido a la paridad de los resultados, no pueden deducirse de forma automática.)","") | L46: =IF(AG8=1,"Segundo:","")
P58: =+'PRE BABY GRUPOS'!I8 -> ESCUELA DEPORTIVA DE FÚTBOL RAQUIRA | Q58: =+J11 -> G | R58: =+J17 | S58: =+F26 -> P | T58: =+F29 -> P
P59: =+'PRE BABY GRUPOS'!I7 -> CLUB CAMPESTRE IBAGUE DOS | Q59: =+J8 -> G | R59: =+J20 | S59: =+J26 -> G | T59: =+F32 -> E
P60: =+'PRE BABY GRUPOS'!I9 -> CORDOBA Y SERRANO F. C. | Q60: =+J14 -> E | R60: =+J23 | S60: =+J29 -> G | T60: =+J32 -> E

Sheet CUARTOS DE FINAL.
H1: Campeonato Nacional de Futbol
B2: CUARTOS DE FINAL | H2: “COPA FUTURO TALENTO”
B3: Observación: Si el partido se define por penales, éstos deben sumarse al resultado.
B4: PARTIDOS | P4: Ganador
B6: 42596 | C6: LLAVE A | D6: 03:00. p.m. | F6: =IF(AND(H6<>"",J6<>""),IF(H6=J6,"E",IF(H6>J6,"G","P")),"") -> P | G6: =+'GRUPO A'!$W$34 -> #N/A | H6: 1 | I6: - | J6: 2 | K6: =IF(AND(J6<>"",H6<>""),IF(J6=H6,"E",IF(J6>H6,"G","P")),"") -> G | L6: =+'GRUPO C'!$W$35 -> ESCUELA DE FORMACIÓN DEPORTIVA MARACANA | N6: PALMARA | P6: =IF(OR(F6="E",F6=""),"",IF(F6="G",G6,L6)) -> ESCUELA DE FORMACIÓN DEPORTIVA MARACANA
B9: 42596 | C9: LLAVE B | D9: 04:20. p.m. | F9: =IF(AND(H9<>"",J9<>""),IF(H9=J9,"E",IF(H9>J9,"G","P")),"") -> G | G9: =+'GRUPO B'!$W$34 -> CLUB ARIEL ARMEL | H9: 2 | I9: - | J9: 1 | K9: =IF(AND(J9<>"",H9<>""),IF(J9=H9,"E",IF(J9>H9,"G","P")),"") -> P | L9: =+'GRUPO D'!$W$35 -> CORDOBA Y SERRANO F. C. | N9: CANCHA 2 | P9: =IF(OR(F9="E",F9=""),"",IF(F9="G",G9,L9)) -> CLUB ARIEL ARMEL
B12: 42596 | C12: LLAVE C | D12: 03:00. p.m. | F12: =IF(AND(H12<>"",J12<>""),IF(H12=J12,"E",IF(H12>J12,"G","P")),"") -> P | G12: =+'GRUPO C'!W34 -> GRAMA F. C. | H12: 1 | I12: - | J12: 2 | K12: =IF(AND(J12<>"",H12<>""),IF(J12=H12,"E",IF(J12>H12,"G","P")),"") -> G | L12: =+'GRUPO A'!$W$35 -> #N/A | N12: CANCHA 2 | P12: =IF(OR(F12="E",F12=""),"",IF(F12="G",G12,L12)) -> #N/A
B15: 42596 | C15: LLAVE D | D15: 04:20. p.m. | F15: =IF(AND(H15<>"",J15<>""),IF(H15=J15,"E",IF(H15>J15,"G","P")),"") -> G | G15: =+'GRUPO D'!$W$34 -> CLUB CAMPESTRE IBAGUE DOS | H15: 2 | I15: - | J15: 1 | K15: =IF(AND(J15<>"",H15<>""),IF(J15=H15,"E",IF(J15>H15,"G","P")),"") -> P | L15: =+'GRUPO B'!W35 -> CENTAUROS DEL ARIARI | N15: PALMARA | P15: =IF(OR(F15="E",F15=""),"",IF(F15="G",G15,L15)) -> CLUB CAMPESTRE IBAGUE DOS
B18: =+'PRE BABY GRUPOS'!#REF! -> #REF!
B21: =+'PRE BABY GRUPOS'!C3 -> NACIDOS 2012 2013

Sheet DEFINICION
A1: =+'PRE BABY GRUPOS'!C1 -> XVIII Festival Nacional Fútbol Infantil
A2: “COPA FUTURO TALENTO”
A3: =+'PRE BABY GRUPOS'!#REF! -> #REF!
A4: =+'PRE BABY GRUPOS'!C3 -> NACIDOS 2012 2013
B5: SEMIFINALES
B6: Observación: Si el partido se define por penales, éstos deben sumarse al resultado.
B7: SEMIFINALES | Q7: Ganador
I8: 2 | K8: 2
B9: 43090 | C9: LLAVE A | D9: 08:20 a.m. | F9: =+'GRUPO A'!$W$34 -> #N/A | G9: =IF(AND(I9<>"",K9<>""),IF(I9=K9,"E",IF(I9>K9,"G","P")),"") -> G | I9: 5 | J9: - | K9: 4 | L9: =IF(AND(K9<>"",I9<>""),IF(K9=I9,"E",IF(K9>I9,"G","P")),"") -> P | M9: =+'GRUPO D'!$W$34 -> CLUB CAMPESTRE IBAGUE DOS | O9: CANCHA 2 | Q9: =IF(OR(G9="E",G9=""),"",IF(G9="G",F9,M9)) -> #N/A | S9: =IF(OR(G9="E",G9=""),"",IF(G9="P",F9,M9)) -> CLUB CAMPESTRE IBAGUE DOS
B12: 43090 | C12: LLAVE B | D12: 09:30 a.m. | F12: =+'GRUPO B'!$W$34 -> CLUB ARIEL ARMEL | G12: =IF(AND(I12<>"",K12<>""),IF(I12=K12,"E",IF(I12>K12,"G","P")),"") -> G | I12: 3 | J12: - | K12: 0 | L12: =IF(AND(K12<>"",I12<>""),IF(K12=I12,"E",IF(K12>I12,"G","P")),"") -> P | M12: =+'GRUPO C'!$W$34 -> GRAMA F. C. | O12: CANCHA 2 | Q12: =IF(OR(G12="E",G12=""),"",IF(G12="G",F12,M12)) -> CLUB ARIEL ARMEL | S12: =IF(OR(G12="E",G12=""),"",IF(G12="P",F12,M12)) -> GRAMA F. C.

Sheet FINAL
A1: =+DEFINICION!A1 -> XVIII Festival Nacional Fútbol Infantil
A2: =+DEFINICION!A2 -> “COPA FUTURO TALENTO”
A3: =+'PRE BABY GRUPOS'!#REF! -> #REF!
A4: =+'PRE BABY GRUPOS'!C3 -> NACIDOS 2012 2013
B5: FINAL DEL TORNEO
B6: Observación: Si el partido se define por penales, éstos deben sumarse al resultado.
B7: Partido por el TERCER PUESTO | Q7: TERCER PUESTO
Q8: =IF(OR(G9="E",G9=""),"",IF(G9="G",H9,M9))
B9: 43090 | D9: 2:50 p.m. | G9: =IF(AND(I9<>"",K9<>""),IF(I9=K9,"E",IF(I9>K9,"G","P")),"") | H9: =+DEFINICION!S9 -> CLUB CAMPESTRE IBAGUE DOS | J9: - | L9: =IF(AND(K9<>"",I9<>""),IF(K9=I9,"E",IF(K9>I9,"G","P")),"") | M9: =+DEFINICION!S12 -> GRAMA F. C. | O9: CANCHA 2
B13: FINAL DEL CAMPEONATO | Q13: SEGUNDO PUESTO
Q14: =IF(OR(G15="E",G15=""),"",IF(G15="P",H15,M15))
B15: 43090 | D15: 4:00 p.m. | G15: =IF(AND(I15<>"",K15<>""),IF(I15=K15,"E",IF(I15>K15,"G","P")),"") | H15: =+DEFINICION!Q9 -> #N/A | J15: - | L15: =IF(AND(K15<>"",I15<>""),IF(K15=I15,"E",IF(K15>I15,"G","P")),"") | M15: =+DEFINICION!Q12 -> CLUB ARIEL ARMEL | O15: CANCHA 2
C19: CAMPEÓN “COPA FUTURO TALENTO”
C21: =IF(OR(G15="E",G15=""),"",IF(G15="G",H15,M15))

Sheet IMPRIMIR
A1: Campeonato Nacional de Futbol
A2: “COPA FUTURO TALENTO”
B4: =+'PRE BABY GRUPOS'!C6 -> GRUPO A | D4: =+'PRE BABY GRUPOS'!E6 -> GRUPO B | G4: =+'PRE BABY GRUPOS'!G6 -> GRUPO C | N4: =+'PRE BABY GRUPOS'!I6 -> GRUPO D
B5: =+'PRE BABY GRUPOS'!C7 -> COLEGIO NEIL ARMSTRONG | D5: =+'PRE BABY GRUPOS'!E7 -> COLEGIO PRINCIPADO DE MONACO | G5: =+'PRE BABY GRUPOS'!G7 -> GRAMA F. C. | N5: =+'PRE BABY GRUPOS'!I8 -> ESCUELA DEPORTIVA DE FÚTBOL RAQUIRA
B6: =+'PRE BABY GRUPOS'!C8 -> CLUB LOS PAPETICOS | D6: =+'PRE BABY GRUPOS'!E8 -> CLUB ARIEL ARMEL | G6: =+'PRE BABY GRUPOS'!G8 -> NOVATOS F. C. | N6: =+'PRE BABY GRUPOS'!I7 -> CLUB CAMPESTRE IBAGUE DOS
B7: =+'PRE BABY GRUPOS'!C9 -> CLUB CAMPESTRE IBAGUE UNO | D7: =+'PRE BABY GRUPOS'!E9 -> CENTAUROS DEL ARIARI | G7: =+'PRE BABY GRUPOS'!G9 -> ESCUELA DE FORMACIÓN DEPORTIVA MARACANA | N7: =+'PRE BABY GRUPOS'!I9 -> CORDOBA Y SERRANO F. C.
B8: =+'PRE BABY GRUPOS'!#REF! -> #REF! | D8: =+'PRE BABY GRUPOS'!#REF! -> #REF! | G8: =+'PRE BABY GRUPOS'!#REF! -> #REF! | N8: =+'PRE BABY GRUPOS'!I10 -> 0
B10: =+'PRE BABY GRUPOS'!#REF! -> #REF! | N10: =+'PRE BABY GRUPOS'!C10 -> 0
B11: =+'PRE BABY GRUPOS'!C3 -> NACIDOS 2012 2013
A12: =+'GRUPO A'!B4 -> GRUPO A
A14: PARTIDOS fecha 1
A16: =+'GRUPO A'!B20 -> 42966 | B16: =+'GRUPO A'!C20 -> 11:45. a.m. | D16: =+'GRUPO A'!E20 -> 0 | F16: =IF(AND(G16<>"",I16<>""),IF(G16=I16,"E",IF(G16>I16,"G","P")),"") | H16: - | J16: =IF(AND(I16<>"",G16<>""),IF(I16=G16,"E",IF(I16>G16,"G","P")),"") | K16: =+'GRUPO A'!K20 -> 0 | O16: =+'GRUPO A'!M20 -> CANCHA 1 A
A18: =+'GRUPO A'!B23 -> 42966 | B18: =+'GRUPO A'!C23 -> 11:45. a.m. | D18: =+'GRUPO A'!E23 -> 0 | F18: =IF(AND(G18<>"",I18<>""),IF(G18=I18,"E",IF(G18>I18,"G","P")),"") | H18: - | J18: =IF(AND(I18<>"",G18<>""),IF(I18=G18,"E",IF(I18>G18,"G","P")),"") | K18: =+'GRUPO A'!K23 -> 0 | O18: =+'GRUPO A'!M23 -> CANCHA 1 B
A20: =+'GRUPO B'!B4 -> GRUPO B
A22: PARTIDOS fecha 1
A24: =+'GRUPO B'!B20 -> 42966 | B24: =+'GRUPO B'!C20 -> 11:45. a.m. | D24: =+'GRUPO B'!E20 -> 0 | F24: =IF(AND(G24<>"",I24<>""),IF(G24=I24,"E",IF(G24>I24,"G","P")),"") | H24: - | J24: =IF(AND(I24<>"",G24<>""),IF(I24=G24,"E",IF(I24>G24,"G","P")),"") | K24: =+'GRUPO B'!K20 -> 0 | O24: =+'GRUPO B'!M20 -> CANCHA 1 C
A26: =+'GRUPO B'!B23 -> 42966 | B26: =+'GRUPO B'!C23 -> 04:40. a.m. | D26: =+'GRUPO B'!E23 -> 0 | F26: =IF(AND(G26<>"",I26<>""),IF(G26=I26,"E",IF(G26>I26,"G","P")),"") | H26: - | J26: =IF(AND(I26<>"",G26<>""),IF(I26=G26,"E",IF(I26>G26,"G","P")),"") | K26: =+'GRUPO B'!K23 -> 0 | O26: =+'GRUPO B'!M23 -> CANCHA 1 A
A27: =+'GRUPO C'!B4 -> GRUPO C
A29: PARTIDOS fecha 1
A31: =+'GRUPO C'!B20 -> 42966 | B31: =+'GRUPO C'!C20 -> 11:45. a.m. | D31: =+'GRUPO C'!E20 -> 0 | F31: =IF(AND(G31<>"",I31<>""),IF(G31=I31,"E",IF(G31>I31,"G","P")),"") | H31: - | J31: =IF(AND(I31<>"",G31<>""),IF(I31=G31,"E",IF(I31>G31,"G","P")),"") | K31: =+'GRUPO C'!K20 -> 0 | O31: =+'GRUPO C'!M20 -> CANCHA 1 B
A33: =+'GRUPO C'!B23 -> 42966 | B33: =+'GRUPO C'!C23 -> 12:40. p.m. | D33: =+'GRUPO C'!E23 -> 0 | F33: =IF(AND(G33<>"",I33<>""),IF(G33=I33,"E",IF(G33>I33,"G","P")),"") | H33: - | J33: =IF(AND(I33<>"",G33<>""),IF(I33=G33,"E",IF(I33>G33,"G","P")),"") | K33: =+'GRUPO C'!K23 -> 0 | O33: =+'GRUPO C'!M23 -> CANCHA 1 C
A34: =+'GRUPO D'!B4 -> GRUPO D
A36: PARTIDOS fecha 1
A38: =+'GRUPO D'!B20 -> 42966 | B38: =+'GRUPO D'!C20 -> 04:40. a.m. | D38: =+'GRUPO D'!E20 -> 0 | F38: =IF(AND(G38<>"",I38<>""),IF(G38=I38,"E",IF(G38>I38,"G","P")),"") | H38: - | J38: =IF(AND(I38<>"",G38<>""),IF(I38=G38,"E",IF(I38>G38,"G","P")),"") | K38: =+'GRUPO D'!K20 -> 0 | O38: =+'GRUPO D'!M20 -> CANCHA 1 A
A40: =+'GRUPO D'!B23 -> 42966 | B40: =+'GRUPO D'!C23 -> 04:40. p.m. | D40: =+'GRUPO D'!E23 -> 0 | F40: =IF(AND(G40<>"",I40<>""),IF(G40=I40,"E",IF(G40>I40,"G","P")),"") | H40: - | J40: =IF(AND(I40<>"",G40<>""),IF(I40=G40,"E",IF(I40>G40,"G","P")),"") | K40: =+'GRUPO D'!K23 -> 0 | O40: =+'GRUPO D'!M23 -> CANCHA 1 B
A41: NOTA: LA ORGANIZACIÓN DEL TORNEO NO SE HACE RESPONSABLE DE ACCIDENTES O PERDIDA DE ELEMENTOS DURANTE EL TRANSCURSO DEL TORNEO. Les recordamos traer el seguro de salud de los deportistas. Tarjeta de identidad Original, Registro Civil.
A46: Sede Administrativa Cra 13 No 6-43 Barrio La Florida
A47: Celular 310 241 33 76 Fijo 2 450 593
A48: soccermelgar@outlook.com
A49: Melgar - Tolima

Sheet IMPRIMIR 2
A1: Campeonato Nacional de Futbol
A2: “COPA FUTURO TALENTO”
B4: =+'PRE BABY GRUPOS'!C6 -> GRUPO A | D4: =+'PRE BABY GRUPOS'!E6 -> GRUPO B | G4: =+'PRE BABY GRUPOS'!G6 -> GRUPO C | N4: =+'PRE BABY GRUPOS'!I6 -> GRUPO D
B5: =+'PRE BABY GRUPOS'!C7 -> COLEGIO NEIL ARMSTRONG | D5: =+'PRE BABY GRUPOS'!E7 -> COLEGIO PRINCIPADO DE MONACO | G5: =+'PRE BABY GRUPOS'!G7 -> GRAMA F. C. | N5: =+'PRE BABY GRUPOS'!I8 -> ESCUELA DEPORTIVA DE FÚTBOL RAQUIRA
B6: =+'PRE BABY GRUPOS'!C8 -> CLUB LOS PAPETICOS | D6: =+'PRE BABY GRUPOS'!E8 -> CLUB ARIEL ARMEL | G6: =+'PRE BABY GRUPOS'!G8 -> NOVATOS F. C. | N6: =+'PRE BABY GRUPOS'!I7 -> CLUB CAMPESTRE IBAGUE DOS
B7: =+'PRE BABY GRUPOS'!C9 -> CLUB CAMPESTRE IBAGUE UNO | D7: =+'PRE BABY GRUPOS'!E9 -> CENTAUROS DEL ARIARI | G7: =+'PRE BABY GRUPOS'!G9 -> ESCUELA DE FORMACIÓN DEPORTIVA MARACANA | N7: =+'PRE BABY GRUPOS'!I9 -> CORDOBA Y SERRANO F. C.
B8: =+'PRE BABY GRUPOS'!#REF! -> #REF! | D8: =+'PRE BABY GRUPOS'!#REF! -> #REF! | G8: =+'PRE BABY GRUPOS'!#REF! -> #REF! | N8: =+'PRE BABY GRUPOS'!I10 -> 0
B10: =+'PRE BABY GRUPOS'!#REF! -> #REF! | N10: =+'PRE BABY GRUPOS'!C10 -> 0
B11: =+'PRE BABY GRUPOS'!C3 -> NACIDOS 2012 2013
A12: =+'GRUPO A'!B4 -> GRUPO A
A14: PARTIDOS fecha 2
A16: =+'GRUPO A'!B26 -> 42966 | B16: =+'GRUPO A'!C26 -> 12:40. p.m. | D16: =+'GRUPO A'!E26 -> 0 | F16: =IF(AND(G16<>"",I16<>""),IF(G16=I16,"E",IF(G16>I16,"G","P")),"") | H16: - | J16: =IF(AND(I16<>"",G16<>""),IF(I16=G16,"E",IF(I16>G16,"G","P")),"") | K16: =+'GRUPO A'!K26 -> 0 | O16: =+'GRUPO A'!M26 -> CANCHA 1 C
A18: =+'GRUPO A'!B29 -> 42965 | B18: =+'GRUPO A'!C29 -> 12:50. p.m. | D18: =+'GRUPO A'!E29 -> COLEGIO NEIL ARMSTRONG | F18: =IF(AND(G18<>"",I18<>""),IF(G18=I18,"E",IF(G18>I18,"G","P")),"") | H18: - | J18: =IF(AND(I18<>"",G18<>""),IF(I18=G18,"E",IF(I18>G18,"G","P")),"") | K18: =+'GRUPO A'!K29 -> CLUB CAMPESTRE IBAGUE UNO | O18: =+'GRUPO A'!M29 -> CANCHA 1 C
A20: =+'GRUPO B'!B4 -> GRUPO B
A22: PARTIDOS fecha 2
A24: =+'GRUPO B'!B26 -> 42966 | B24: =+'GRUPO B'!C26 -> 04:40. p.m. | D24: =+'GRUPO B'!E26 -> 0 | F24: =IF(AND(G24<>"",I24<>""),IF(G24=I24,"E",IF(G24>I24,"G","P")),"") | H24: - | J24: =IF(AND(I24<>"",G24<>""),IF(I24=G24,"E",IF(I24>G24,"G","P")),"") | K24: =+'GRUPO B'!K26 -> 0 | O24: =+'GRUPO B'!M26 -> CANCHA 1 B
A26: =+'GRUPO B'!B29 -> 42967 | B26: =+'GRUPO B'!C29 -> 10:50. a.m. | D26: =+'GRUPO B'!E29 -> COLEGIO PRINCIPADO DE MONACO | F26: =IF(AND(G26<>"",I26<>""),IF(G26=I26,"E",IF(G26>I26,"G","P")),"") | H26: - | J26: =IF(AND(I26<>"",G26<>""),IF(I26=G26,"E",IF(I26>G26,"G","P")),"") | K26: =+'GRUPO B'!K29 -> CENTAUROS DEL ARIARI | O26: =+'GRUPO B'!M29 -> CANCHA 1 A
A27: =+'GRUPO C'!B4 -> GRUPO C
A29: PARTIDOS fecha 2
A31: =+'GRUPO C'!B26 -> 42966 | B31: =+'GRUPO C'!C26 -> 03:50. p.m. | D31: =+'GRUPO C'!E26 -> GRAMA F. C. | F31: =IF(AND(G31<>"",I31<>""),IF(G31=I31,"E",IF(G31>I31,"G","P")),"") | H31: - | J31: =IF(AND(I31<>"",G31<>""),IF(I31=G31,"E",IF(I31>G31,"G","P")),"") | K31: =+'GRUPO C'!K26 -> NOVATOS F. C. | O31: =+'GRUPO C'!M26 -> CANCHA 1 C
A33: =+'GRUPO C'!B29 -> 42965 | B33: =+'GRUPO C'!C29 -> 12:50. p.m. | D33: =+'GRUPO C'!E29 -> GRAMA F. C. | F33: =IF(AND(G33<>"",I33<>""),IF(G33=I33,"E",IF(G33>I33,"G","P")),"") | H33: - | J33: =IF(AND(I33<>"",G33<>""),IF(I33=G33,"E",IF(I33>G33,"G","P")),"") | K33: =+'GRUPO C'!K29 -> ESCUELA DE FORMACIÓN DEPORTIVA MARACANA | O33: =+'GRUPO C'!M29 -> CANCHA 1 A
A34: =+'GRUPO D'!B4 -> GRUPO D
A36: PARTIDOS fecha 2
A38: =+'GRUPO D'!B26 -> 42967 | B38: =+'GRUPO D'!C26 -> 09:50. a.m. | D38: =+'GRUPO D'!E26 -> ESCUELA DEPORTIVA DE FÚTBOL RAQUIRA | F38: =IF(AND(G38<>"",I38<>""),IF(G38=I38,"E",IF(G38>I38,"G","P")),"") | H38: - | J38: =IF(AND(I38<>"",G38<>""),IF(I38=G38,"E",IF(I38>G38,"G","P")),"") | K38: =+'GRUPO D'!K26 -> CLUB CAMPESTRE IBAGUE DOS | O38: =+'GRUPO D'!M26 -> CANCHA 1 B
A40: =+'GRUPO D'!B29 -> 42965 | B40: =+'GRUPO D'!C29 -> 11:55. a.m. | D40: =+'GRUPO D'!E29 -> ESCUELA DEPORTIVA DE FÚTBOL RAQUIRA | F40: =IF(AND(G40<>"",I40<>""),IF(G40=I40,"E",IF(G40>I40,"G","P")),"") | H40: - | J40: =IF(AND(I40<>"",G40<>""),IF(I40=G40,"E",IF(I40>G40,"G","P")),"") | K40: =+'GRUPO D'!K29 -> CORDOBA Y SERRANO F. C. | O40: =+'GRUPO D'!M29 -> CANCHA 1 A
A41: NOTA: LA ORGANIZACIÓN DEL TORNEO NO SE HACE RESPONSABLE DE ACCIDENTES O PERDIDA DE ELEMENTOS DURANTE EL TRANSCURSO DEL TORNEO. Les recordamos traer el seguro de salud de los deportistas. Tarjeta de identidad Original, Registro Civil.
A46: Sede Administrativa Cra 13 No 6-43 Barrio La Florida
A47: Celular 310 241 33 76 Fijo 2 450 593
A48: soccermelgar@outlook.com
A49: Melgar - Tolima

Sheet IMPRIMIR 3
B1: Campeonato Nacional de Futbol
B2: “COPA FUTURO TALENTO”
G3: =+'PRE BABY GRUPOS'!#REF! -> #REF!
G4: =+'PRE BABY GRUPOS'!C3 -> NACIDOS 2012 2013
B6: =+'PRE BABY GRUPOS'!C6 -> GRUPO A | D6: =+'GRUPO A'!Q20:Q21 -> #VALUE! | E6: =+'GRUPO A'!R20:R21 -> #VALUE! | F6: =+'GRUPO A'!S20:S21 -> #VALUE! | G6: =+'GRUPO A'!T20:T21 -> #VALUE! | H6: =+'GRUPO A'!U20:U21 -> #VALUE! | I6: =+'GRUPO A'!V20:V21 -> #VALUE! | J6: =+'GRUPO A'!W20:W21 -> #VALUE! | K6: =+'GRUPO A'!X20:X21 -> #VALUE! | L6: =+'GRUPO A'!Y20:Y21 -> #VALUE!
B8: =+'GRUPO A'!P22:P23 -> #VALUE! | D8: =+'GRUPO A'!Q22:Q23 -> #VALUE! | E8: =+'GRUPO A'!R22:R23 -> #VALUE! | F8: =+'GRUPO A'!S22:S23 -> #VALUE! | G8: =+'GRUPO A'!T22:T23 -> #VALUE! | H8: =+'GRUPO A'!U22:U23 -> #VALUE! | I8: =+'GRUPO A'!V22:V23 -> #VALUE! | J8: =+'GRUPO A'!W22:W23 -> #VALUE! | K8: =+'GRUPO A'!X22:X23 -> #VALUE! | L8: =+'GRUPO A'!Y22:Y23 -> #VALUE!
B10: =+'GRUPO A'!P24:P25 -> #VALUE! | D10: =+'GRUPO A'!Q24:Q25 -> #VALUE! | E10: =+'GRUPO A'!R24:R25 -> #VALUE! | F10: =+'GRUPO A'!S24:S25 -> #VALUE! | G10: =+'GRUPO A'!T24:T25 -> #VALUE! | H10: =+'GRUPO A'!U24:U25 -> #VALUE! | I10: =+'GRUPO A'!V24:V25 -> #VALUE! | J10: =+'GRUPO A'!W24:W25 -> #VALUE! | K10: =+'GRUPO A'!X24:X25 -> #VALUE! | L10: =+'GRUPO A'!Y24:Y25 -> #VALUE!
B12: =+'GRUPO A'!P26:P27 -> #VALUE! | D12: =+'GRUPO A'!Q26:Q27 -> #VALUE! | E12: =+'GRUPO A'!R26:R27 -> #VALUE! | F12: =+'GRUPO A'!S26:S27 -> #VALUE! | G12: =+'GRUPO A'!T26:T27 -> #VALUE! | H12: =+'GRUPO A'!U26:U27 -> #VALUE! | I12: =+'GRUPO A'!V26:V27 -> #VALUE! | J12: =+'GRUPO A'!W26:W27 -> #VALUE! | K12: =+'GRUPO A'!X26:X27 -> #VALUE! | L12: =+'GRUPO A'!Y26:Y27 -> #VALUE!
B14: =+'GRUPO A'!P28:P29 -> #VALUE! | D14: =+'GRUPO A'!Q28:Q29 -> #VALUE! | E14: =+'GRUPO A'!R28:R29 -> #VALUE! | F14: =+'GRUPO A'!S28:S29 -> #VALUE! | G14: =+'GRUPO A'!T28:T29 -> #VALUE! | H14: =+'GRUPO A'!U28:U29 -> #VALUE! | I14: =+'GRUPO A'!V28:V29 -> #VALUE! | J14: =+'GRUPO A'!W28:W29 -> #VALUE! | K14: =+'GRUPO A'!X28:X29 -> #VALUE! | L14: =+'GRUPO A'!Y28:Y29 -> #VALUE!
A17: PARTIDOS fecha 3 ULTIMA
A19: =+'GRUPO A'!B32 -> 42967 | B19: =+'GRUPO A'!C32 -> 09:50. a.m. | C19: =+'GRUPO A'!E32 -> CLUB LOS PAPETICOS | E19: - | G19: =+'GRUPO A'!K32 -> CLUB CAMPESTRE IBAGUE UNO | K19: =+'GRUPO A'!M32 -> CANCHA 1 A
A21: =+'GRUPO A'!B35 -> 0 | B21: =+'GRUPO A'!C35 -> 0 | C21: =+'GRUPO A'!E35 -> 0 | E21: - | G21: =+'GRUPO A'!K35 -> 0 | K21: =+'GRUPO A'!M35 -> 0
B23: =+'PRE BABY GRUPOS'!E6 -> GRUPO B | D23: =+'GRUPO B'!Q8 -> Pts. | E23: =+'GRUPO B'!R8 -> PJ | F23: =+'GRUPO B'!S8 -> Gan. | G23: =+'GRUPO B'!T8 -> Emp. | H23: =+'GRUPO B'!U8 -> Per. | I23: =+'GRUPO B'!V8 -> GF | J23: =+'GRUPO B'!W8 -> GC | K23: =+'GRUPO B'!X8 -> Dif. | L23: =+'GRUPO B'!Y8 -> Tj
B25: =+'GRUPO B'!P10 -> 1) CLUB ARIEL ARMEL | D25: =+'GRUPO B'!Q10 -> 4 | E25: =+'GRUPO B'!R10 -> 3 | F25: =+'GRUPO B'!S10 -> 1 | G25: =+'GRUPO B'!T10 -> 1 | H25: =+'GRUPO B'!U10 -> 1 | I25: =+'GRUPO B'!V10 -> 7 | J25: =+'GRUPO B'!W10 -> 4 | K25: =+'GRUPO B'!X10 -> 3 | L25: =+'GRUPO B'!Y10 -> 0
B27: =+'GRUPO B'!P12 -> 2) CENTAUROS DEL ARIARI | D27: =+'GRUPO B'!Q12 -> 3 | E27: =+'GRUPO B'!R12 -> 3 | F27: =+'GRUPO B'!S12 -> 1 | G27: =+'GRUPO B'!T12 -> 0 | H27: =+'GRUPO B'!U12 -> 2 | I27: =+'GRUPO B'!V12 -> 4 | J27: =+'GRUPO B'!W12 -> 5 | K27: =+'GRUPO B'!X12 -> -1 | L27: =+'GRUPO B'!Y12 -> 0
B29: =+'GRUPO B'!P14 -> 3) COLEGIO PRINCIPADO DE MONACO | D29: =+'GRUPO B'!Q14 -> 1 | E29: =+'GRUPO B'!R14 -> 3 | F29: =+'GRUPO B'!S14 -> 0 | G29: =+'GRUPO B'!T14 -> 1 | H29: =+'GRUPO B'!U14 -> 2 | I29: =+'GRUPO B'!V14 -> 7 | J29: =+'GRUPO B'!W14 -> 12 | K29: =+'GRUPO B'!X14 -> -5 | L29: =+'GRUPO B'!Y14 -> 0
B31: =+'GRUPO B'!P16 -> 0 | D31: =+'GRUPO B'!Q16 -> 0 | E31: =+'GRUPO B'!R16 -> 0 | F31: =+'GRUPO B'!S16 -> 0 | G31: =+'GRUPO B'!T16 -> 0 | H31: =+'GRUPO B'!U16 -> 0 | I31: =+'GRUPO B'!V16 -> 0 | J31: =+'GRUPO B'!W16 -> 0 | K31: =+'GRUPO B'!X16 -> 0 | L31: =+'GRUPO B'!Y16 -> 0
A34: PARTIDOS fecha 3 ULTIMA
A36: =+'GRUPO B'!B32 -> 42965 | B36: =+'GRUPO B'!C32 -> 04:30. p.m. | C36: =+'GRUPO B'!E32 -> CLUB ARIEL ARMEL | E36: - | G36: =+'GRUPO B'!K32 -> CENTAUROS DEL ARIARI | K36: =+'GRUPO B'!M32 -> CANCHA 1 A
A38: =+'GRUPO B'!B35 -> 0 | B38: =+'GRUPO B'!C32 -> 04:30. p.m. | C38: =+'GRUPO B'!E35 -> 0 | E38: - | G38: =+'GRUPO B'!K35 -> 0 | K38: =+'GRUPO B'!M35 -> 0
B41: =+'PRE BABY GRUPOS'!G6 -> GRUPO C | D41: =+'GRUPO B'!Q8 -> Pts. | E41: =+'GRUPO B'!R8 -> PJ | F41: =+'GRUPO B'!S8 -> Gan. | G41: =+'GRUPO B'!T8 -> Emp. | H41: =+'GRUPO B'!U8 -> Per. | I41: =+'GRUPO B'!V8 -> GF | J41: =+'GRUPO B'!W8 -> GC | K41: =+'GRUPO B'!X8 -> Dif. | L41: =+'GRUPO B'!Y8 -> Tj
B43: =+'GRUPO B'!P10 -> 1) CLUB ARIEL ARMEL | D43: =+'GRUPO B'!Q10 -> 4 | E43: =+'GRUPO B'!R10 -> 3 | F43: =+'GRUPO B'!S10 -> 1 | G43: =+'GRUPO B'!T10 -> 1 | H43: =+'GRUPO B'!U10 -> 1 | I43: =+'GRUPO B'!V10 -> 7 | J43: =+'GRUPO B'!W10 -> 4 | K43: =+'GRUPO B'!X10 -> 3 | L43: =+'GRUPO B'!Y10 -> 0
B45: =+'GRUPO B'!P12 -> 2) CENTAUROS DEL ARIARI | D45: =+'GRUPO B'!Q12 -> 3 | E45: =+'GRUPO B'!R12 -> 3 | F45: =+'GRUPO B'!S12 -> 1 | G45: =+'GRUPO B'!T12 -> 0 | H45: =+'GRUPO B'!U12 -> 2 | I45: =+'GRUPO B'!V12 -> 4 | J45: =+'GRUPO B'!W12 -> 5 | K45: =+'GRUPO B'!X12 -> -1 | L45: =+'GRUPO B'!Y12 -> 0
B47: =+'GRUPO B'!P14 -> 3) COLEGIO PRINCIPADO DE MONACO | D47: =+'GRUPO B'!Q14 -> 1 | E47: =+'GRUPO B'!R14 -> 3 | F47: =+'GRUPO B'!S14 -> 0 | G47: =+'GRUPO B'!T14 -> 1 | H47: =+'GRUPO B'!U14 -> 2 | I47: =+'GRUPO B'!V14 -> 7 | J47: =+'GRUPO B'!W14 -> 12 | K47: =+'GRUPO B'!X14 -> -5 | L47: =+'GRUPO B'!Y14 -> 0
B49: =+'GRUPO B'!P16 -> 0 | D49: =+'GRUPO B'!Q16 -> 0 | E49: =+'GRUPO B'!R16 -> 0 | F49: =+'GRUPO B'!S16 -> 0 | G49: =+'GRUPO B'!T16 -> 0 | H49: =+'GRUPO B'!U16 -> 0 | I49: =+'GRUPO B'!V16 -> 0 | J49: =+'GRUPO B'!W16 -> 0 | K49: =+'GRUPO B'!X16 -> 0 | L49: =+'GRUPO B'!Y16 -> 0
A52: PARTIDOS fecha 3 ULTIMA
A54: =+'GRUPO C'!B32 -> 42967 | B54: =+'GRUPO C'!C32 -> 09:50. a.m. | C54: =+'GRUPO C'!E32 -> NOVATOS F. C. | E54: - | G54: =+'GRUPO C'!K32 -> ESCUELA DE FORMACIÓN DEPORTIVA MARACANA | K54: =+'GRUPO C'!M32 -> CANCHA 1 C
A56: =+'GRUPO C'!B35 -> 0 | B56: =+'GRUPO C'!C35 -> 0 | C56: =+'GRUPO C'!E35 -> 0 | E56: - | G56: =+'GRUPO C'!K35 -> 0 | K56: =+'GRUPO C'!M35 -> 0
B59: =+'PRE BABY GRUPOS'!I6 -> GRUPO D | D59: =+'GRUPO D'!Q8 -> Pts. | E59: =+'GRUPO D'!R8 -> PJ | F59: =+'GRUPO D'!S8 -> Gan. | G59: =+'GRUPO D'!T8 -> Emp. | H59: =+'GRUPO D'!U8 -> Per. | I59: =+'GRUPO D'!V8 -> GF | J59: =+'GRUPO D'!W8 -> GC | K59: =+'GRUPO D'!X8 -> Dif. | L59: =+'GRUPO D'!Y8 -> Tj
B61: =+'GRUPO D'!P10 -> 1) CLUB CAMPESTRE IBAGUE DOS | D61: =+'GRUPO D'!Q10 -> 7 | E61: =+'GRUPO D'!R10 -> 3 | F61: =+'GRUPO D'!S10 -> 2 | G61: =+'GRUPO D'!T10 -> 1 | H61: =+'GRUPO D'!U10 -> 0 | I61: =+'GRUPO D'!V10 -> 12 | J61: =+'GRUPO D'!W10 -> 9 | K61: =+'GRUPO D'!X10 -> 3 | L61: =+'GRUPO D'!Y10 -> 0
B63: =+'GRUPO D'!P12 -> 2) CORDOBA Y SERRANO F. C. | D63: =+'GRUPO D'!Q12 -> 5 | E63: =+'GRUPO D'!R12 -> 3 | F63: =+'GRUPO D'!S12 -> 1 | G63: =+'GRUPO D'!T12 -> 2 | H63: =+'GRUPO D'!U12 -> 0 | I63: =+'GRUPO D'!V12 -> 18 | J63: =+'GRUPO D'!W12 -> 6 | K63: =+'GRUPO D'!X12 -> 12 | L63: =+'GRUPO D'!Y12 -> 0
B65: =+'GRUPO D'!P14 -> 3) ESCUELA DEPORTIVA DE FÚTBOL RAQUIRA | D65: =+'GRUPO D'!Q14 -> 3 | E65: =+'GRUPO D'!R14 -> 3 | F65: =+'GRUPO D'!S14 -> 1 | G65: =+'GRUPO D'!T14 -> 0 | H65: =+'GRUPO D'!U14 -> 2 | I65: =+'GRUPO D'!V14 -> 5 | J65: =+'GRUPO D'!W14 -> 17 | K65: =+'GRUPO D'!X14 -> -12 | L65: =+'GRUPO D'!Y14 -> 0
B67: =+'GRUPO D'!P16 -> 0 | D67: =+'GRUPO D'!Q16 -> 0 | E67: =+'GRUPO D'!R16 -> 0 | F67: =+'GRUPO D'!S16 -> 0 | G67: =+'GRUPO D'!T16 -> 0 | H67: =+'GRUPO D'!U16 -> 0 | I67: =+'GRUPO D'!V16 -> 0 | J67: =+'GRUPO D'!W16 -> 0 | K67: =+'GRUPO D'!X16 -> 0 | L67: =+'GRUPO D'!Y16 -> 0
A70: PARTIDOS fecha 3 ULTIMA
A72: =+'GRUPO D'!B32 -> 42966 | B72: =+'GRUPO D'!C32 -> 12:40. p.m. | C72: =+'GRUPO D'!E32 -> CLUB CAMPESTRE IBAGUE DOS | E72: - | G72: =+'GRUPO D'!K32 -> CORDOBA Y SERRANO F. C. | K72: =+'GRUPO D'!M32 -> CANCHA 1 A
A74: =+'GRUPO D'!B35 -> 0 | B74: =+'GRUPO D'!C32 -> 12:40. p.m. | C74: =+'GRUPO D'!E35 -> 0 | E74: - | G74: =+'GRUPO D'!K35 -> 0 | K74: =+'GRUPO D'!M35 -> 0
A75: La organización no se hace responsable de las posibles lesiones ocasionadas dentro y fuera del campo de juego, accidentes o perdidas de elementos durante el transcurso del torneo.
A78: Sede Administrativa Cra 13 No 6-43 Barrio La Florida
A79: Celular 310 241 33 76 Fijo 2 450 593
A80: soccermelgar@outlook.com
...

Sheet IMPRIMIR 3 (2)
B1: Campeonato Nacional de Futbol
B2: “COPA FUTURO TALENTO”
G3: =+'PRE BABY GRUPOS'!#REF! -> #REF!
G4: =+'PRE BABY GRUPOS'!C3 -> NACIDOS 2012 2013
B6: =+'PRE BABY GRUPOS'!C6 -> GRUPO A | D6: =+'GRUPO A'!Q20:Q21 -> #VALUE! | E6: =+'GRUPO A'!R20:R21 -> #VALUE! | F6: =+'GRUPO A'!S20:S21 -> #VALUE! | G6: =+'GRUPO A'!T20:T21 -> #VALUE! | H6: =+'GRUPO A'!U20:U21 -> #VALUE! | I6: =+'GRUPO A'!V20:V21 -> #VALUE! | J6: =+'GRUPO A'!W20:W21 -> #VALUE! | K6: =+'GRUPO A'!X20:X21 -> #VALUE! | L6: =+'GRUPO A'!Y20:Y21 -> #VALUE!
B8: =+'GRUPO A'!P22:P23 -> #VALUE! | D8: =+'GRUPO A'!Q22:Q23 -> #VALUE! | E8: =+'GRUPO A'!R22:R23 -> #VALUE! | F8: =+'GRUPO A'!S22:S23 -> #VALUE! | G8: =+'GRUPO A'!T22:T23 -> #VALUE! | H8: =+'GRUPO A'!U22:U23 -> #VALUE! | I8: =+'GRUPO A'!V22:V23 -> #VALUE! | J8: =+'GRUPO A'!W22:W23 -> #VALUE! | K8: =+'GRUPO A'!X22:X23 -> #VALUE! | L8: =+'GRUPO A'!Y22:Y23 -> #VALUE!
B10: =+'GRUPO A'!P24:P25 -> #VALUE! | D10: =+'GRUPO A'!Q24:Q25 -> #VALUE! | E10: =+'GRUPO A'!R24:R25 -> #VALUE! | F10: =+'GRUPO A'!S24:S25 -> #VALUE! | G10: =+'GRUPO A'!T24:T25 -> #VALUE! | H10: =+'GRUPO A'!U24:U25 -> #VALUE! | I10: =+'GRUPO A'!V24:V25 -> #VALUE! | J10: =+'GRUPO A'!W24:W25 -> #VALUE! | K10: =+'GRUPO A'!X24:X25 -> #VALUE! | L10: =+'GRUPO A'!Y24:Y25 -> #VALUE!
B12: =+'GRUPO A'!P26:P27 -> #VALUE! | D12: =+'GRUPO A'!Q26:Q27 -> #VALUE! | E12: =+'GRUPO A'!R26:R27 -> #VALUE! | F12: =+'GRUPO A'!S26:S27 -> #VALUE! | G12: =+'GRUPO A'!T26:T27 -> #VALUE! | H12: =+'GRUPO A'!U26:U27 -> #VALUE! | I12: =+'GRUPO A'!V26:V27 -> #VALUE! | J12: =+'GRUPO A'!W26:W27 -> #VALUE! | K12: =+'GRUPO A'!X26:X27 -> #VALUE! | L12: =+'GRUPO A'!Y26:Y27 -> #VALUE!
B14: =+'GRUPO A'!P28:P29 -> #VALUE! | D14: =+'GRUPO A'!Q28:Q29 -> #VALUE! | E14: =+'GRUPO A'!R28:R29 -> #VALUE! | F14: =+'GRUPO A'!S28:S29 -> #VALUE! | G14: =+'GRUPO A'!T28:T29 -> #VALUE! | H14: =+'GRUPO A'!U28:U29 -> #VALUE! | I14: =+'GRUPO A'!V28:V29 -> #VALUE! | J14: =+'GRUPO A'!W28:W29 -> #VALUE! | K14: =+'GRUPO A'!X28:X29 -> #VALUE! | L14: =+'GRUPO A'!Y28:Y29 -> #VALUE!
A17: PARTIDOS fecha 3 ULTIMA
A19: =+'GRUPO A'!B32 -> 42967 | B19: =+'GRUPO A'!C32 -> 09:50. a.m. | C19: =+'GRUPO A'!E32 -> CLUB LOS PAPETICOS | E19: - | G19: =+'GRUPO A'!K32 -> CLUB CAMPESTRE IBAGUE UNO | K19: =+'GRUPO A'!M32 -> CANCHA 1 A
A21: =+'GRUPO A'!B35 -> 0 | B21: =+'GRUPO A'!C35 -> 0 | C21: =+'GRUPO A'!E35 -> 0 | E21: - | G21: =+'GRUPO A'!K35 -> 0 | K21: =+'GRUPO A'!M35 -> 0
B23: =+'PRE BABY GRUPOS'!E6 -> GRUPO B | D23: =+'GRUPO B'!Q8 -> Pts. | E23: =+'GRUPO B'!R8 -> PJ | F23: =+'GRUPO B'!S8 -> Gan. | G23: =+'GRUPO B'!T8 -> Emp. | H23: =+'GRUPO B'!U8 -> Per. | I23: =+'GRUPO B'!V8 -> GF | J23: =+'GRUPO B'!W8 -> GC | K23: =+'GRUPO B'!X8 -> Dif. | L23: =+'GRUPO B'!Y8 -> Tj
B25: =+'GRUPO B'!P10 -> 1) CLUB ARIEL ARMEL | D25: =+'GRUPO B'!Q10 -> 4 | E25: =+'GRUPO B'!R10 -> 3 | F25: =+'GRUPO B'!S10 -> 1 | G25: =+'GRUPO B'!T10 -> 1 | H25: =+'GRUPO B'!U10 -> 1 | I25: =+'GRUPO B'!V10 -> 7 | J25: =+'GRUPO B'!W10 -> 4 | K25: =+'GRUPO B'!X10 -> 3 | L25: =+'GRUPO B'!Y10 -> 0
B27: =+'GRUPO B'!P12 -> 2) CENTAUROS DEL ARIARI | D27: =+'GRUPO B'!Q12 -> 3 | E27: =+'GRUPO B'!R12 -> 3 | F27: =+'GRUPO B'!S12 -> 1 | G27: =+'GRUPO B'!T12 -> 0 | H27: =+'GRUPO B'!U12 -> 2 | I27: =+'GRUPO B'!V12 -> 4 | J27: =+'GRUPO B'!W12 -> 5 | K27: =+'GRUPO B'!X12 -> -1 | L27: =+'GRUPO B'!Y12 -> 0
B29: =+'GRUPO B'!P14 -> 3) COLEGIO PRINCIPADO DE MONACO | D29: =+'GRUPO B'!Q14 -> 1 | E29: =+'GRUPO B'!R14 -> 3 | F29: =+'GRUPO B'!S14 -> 0 | G29: =+'GRUPO B'!T14 -> 1 | H29: =+'GRUPO B'!U14 -> 2 | I29: =+'GRUPO B'!V14 -> 7 | J29: =+'GRUPO B'!W14 -> 12 | K29: =+'GRUPO B'!X14 -> -5 | L29: =+'GRUPO B'!Y14 -> 0
B31: =+'GRUPO B'!P16 -> 0 | D31: =+'GRUPO B'!Q16 -> 0 | E31: =+'GRUPO B'!R16 -> 0 | F31: =+'GRUPO B'!S16 -> 0 | G31: =+'GRUPO B'!T16 -> 0 | H31: =+'GRUPO B'!U16 -> 0 | I31: =+'GRUPO B'!V16 -> 0 | J31: =+'GRUPO B'!W16 -> 0 | K31: =+'GRUPO B'!X16 -> 0 | L31: =+'GRUPO B'!Y16 -> 0
A34: PARTIDOS fecha 3 ULTIMA
A36: =+'GRUPO B'!B32 -> 42965 | B36: =+'GRUPO B'!C32 -> 04:30. p.m. | C36: =+'GRUPO B'!E32 -> CLUB ARIEL ARMEL | E36: - | G36: =+'GRUPO B'!K32 -> CENTAUROS DEL ARIARI | K36: =+'GRUPO B'!M32 -> CANCHA 1 A
A38: =+'GRUPO B'!B35 -> 0 | B38: =+'GRUPO B'!C32 -> 04:30. p.m. | C38: =+'GRUPO B'!E35 -> 0 | E38: - | G38: =+'GRUPO B'!K35 -> 0 | K38: =+'GRUPO B'!M35 -> 0
B41: =+'PRE BABY GRUPOS'!G6 -> GRUPO C | D41: =+'GRUPO B'!Q8 -> Pts. | E41: =+'GRUPO B'!R8 -> PJ | F41: =+'GRUPO B'!S8 -> Gan. | G41: =+'GRUPO B'!T8 -> Emp. | H41: =+'GRUPO B'!U8 -> Per. | I41: =+'GRUPO B'!V8 -> GF | J41: =+'GRUPO B'!W8 -> GC | K41: =+'GRUPO B'!X8 -> Dif. | L41: =+'GRUPO B'!Y8 -> Tj
B43: =+'GRUPO B'!P10 -> 1) CLUB ARIEL ARMEL | D43: =+'GRUPO B'!Q10 -> 4 | E43: =+'GRUPO B'!R10 -> 3 | F43: =+'GRUPO B'!S10 -> 1 | G43: =+'GRUPO B'!T10 -> 1 | H43: =+'GRUPO B'!U10 -> 1 | I43: =+'GRUPO B'!V10 -> 7 | J43: =+'GRUPO B'!W10 -> 4 | K43: =+'GRUPO B'!X10 -> 3 | L43: =+'GRUPO B'!Y10 -> 0
B45: =+'GRUPO B'!P12 -> 2) CENTAUROS DEL ARIARI | D45: =+'GRUPO B'!Q12 -> 3 | E45: =+'GRUPO B'!R12 -> 3 | F45: =+'GRUPO B'!S12 -> 1 | G45: =+'GRUPO B'!T12 -> 0 | H45: =+'GRUPO B'!U12 -> 2 | I45: =+'GRUPO B'!V12 -> 4 | J45: =+'GRUPO B'!W12 -> 5 | K45: =+'GRUPO B'!X12 -> -1 | L45: =+'GRUPO B'!Y12 -> 0
B47: =+'GRUPO B'!P14 -> 3) COLEGIO PRINCIPADO DE MONACO | D47: =+'GRUPO B'!Q14 -> 1 | E47: =+'GRUPO B'!R14 -> 3 | F47: =+'GRUPO B'!S14 -> 0 | G47: =+'GRUPO B'!T14 -> 1 | H47: =+'GRUPO B'!U14 -> 2 | I47: =+'GRUPO B'!V14 -> 7 | J47: =+'GRUPO B'!W14 -> 12 | K47: =+'GRUPO B'!X14 -> -5 | L47: =+'GRUPO B'!Y14 -> 0
B49: =+'GRUPO B'!P16 -> 0 | D49: =+'GRUPO B'!Q16 -> 0 | E49: =+'GRUPO B'!R16 -> 0 | F49: =+'GRUPO B'!S16 -> 0 | G49: =+'GRUPO B'!T16 -> 0 | H49: =+'GRUPO B'!U16 -> 0 | I49: =+'GRUPO B'!V16 -> 0 | J49: =+'GRUPO B'!W16 -> 0 | K49: =+'GRUPO B'!X16 -> 0 | L49: =+'GRUPO B'!Y16 -> 0
A52: PARTIDOS fecha 3 ULTIMA
A54: =+'GRUPO C'!B32 -> 42967 | B54: =+'GRUPO C'!C32 -> 09:50. a.m. | C54: =+'GRUPO C'!E32 -> NOVATOS F. C. | E54: - | G54: =+'GRUPO C'!K32 -> ESCUELA DE FORMACIÓN DEPORTIVA MARACANA | K54: =+'GRUPO C'!M32 -> CANCHA 1 C
A56: =+'GRUPO C'!B35 -> 0 | B56: =+'GRUPO C'!C35 -> 0 | C56: =+'GRUPO C'!E35 -> 0 | E56: - | G56: =+'GRUPO C'!K35 -> 0 | K56: =+'GRUPO C'!M35 -> 0
B59: =+'PRE BABY GRUPOS'!I6 -> GRUPO D | D59: =+'GRUPO D'!Q8 -> Pts. | E59: =+'GRUPO D'!R8 -> PJ | F59: =+'GRUPO D'!S8 -> Gan. | G59: =+'GRUPO D'!T8 -> Emp. | H59: =+'GRUPO D'!U8 -> Per. | I59: =+'GRUPO D'!V8 -> GF | J59: =+'GRUPO D'!W8 -> GC | K59: =+'GRUPO D'!X8 -> Dif. | L59: =+'GRUPO D'!Y8 -> Tj
B61: =+'GRUPO D'!P10 -> 1) CLUB CAMPESTRE IBAGUE DOS | D61: =+'GRUPO D'!Q10 -> 7 | E61: =+'GRUPO D'!R10 -> 3 | F61: =+'GRUPO D'!S10 -> 2 | G61: =+'GRUPO D'!T10 -> 1 | H61: =+'GRUPO D'!U10 -> 0 | I61: =+'GRUPO D'!V10 -> 12 | J61: =+'GRUPO D'!W10 -> 9 | K61: =+'GRUPO D'!X10 -> 3 | L61: =+'GRUPO D'!Y10 -> 0
B63: =+'GRUPO D'!P12 -> 2) CORDOBA Y SERRANO F. C. | D63: =+'GRUPO D'!Q12 -> 5 | E63: =+'GRUPO D'!R12 -> 3 | F63: =+'GRUPO D'!S12 -> 1 | G63: =+'GRUPO D'!T12 -> 2 | H63: =+'GRUPO D'!U12 -> 0 | I63: =+'GRUPO D'!V12 -> 18 | J63: =+'GRUPO D'!W12 -> 6 | K63: =+'GRUPO D'!X12 -> 12 | L63: =+'GRUPO D'!Y12 -> 0
B65: =+'GRUPO D'!P14 -> 3) ESCUELA DEPORTIVA DE FÚTBOL RAQUIRA | D65: =+'GRUPO D'!Q14 -> 3 | E65: =+'GRUPO D'!R14 -> 3 | F65: =+'GRUPO D'!S14 -> 1 | G65: =+'GRUPO D'!T14 -> 0 | H65: =+'GRUPO D'!U14 -> 2 | I65: =+'GRUPO D'!V14 -> 5 | J65: =+'GRUPO D'!W14 -> 17 | K65: =+'GRUPO D'!X14 -> -12 | L65: =+'GRUPO D'!Y14 -> 0
B67: =+'GRUPO D'!P16 -> 0 | D67: =+'GRUPO D'!Q16 -> 0 | E67: =+'GRUPO D'!R16 -> 0 | F67: =+'GRUPO D'!S16 -> 0 | G67: =+'GRUPO D'!T16 -> 0 | H67: =+'GRUPO D'!U16 -> 0 | I67: =+'GRUPO D'!V16 -> 0 | J67: =+'GRUPO D'!W16 -> 0 | K67: =+'GRUPO D'!X16 -> 0 | L67: =+'GRUPO D'!Y16 -> 0
A70: PARTIDOS fecha 3 ULTIMA
A72: =+'GRUPO D'!B32 -> 42966 | B72: =+'GRUPO D'!C32 -> 12:40. p.m. | C72: =+'GRUPO D'!E32 -> CLUB CAMPESTRE IBAGUE DOS | E72: - | G72: =+'GRUPO D'!K32 -> CORDOBA Y SERRANO F. C. | K72: =+'GRUPO D'!M32 -> CANCHA 1 A
A74: =+'GRUPO D'!B35 -> 0 | B74: =+'GRUPO D'!C32 -> 12:40. p.m. | C74: =+'GRUPO D'!E35 -> 0 | E74: - | G74: =+'GRUPO D'!K35 -> 0 | K74: =+'GRUPO D'!M35 -> 0
A75: La organización no se hace responsable de las posibles lesiones ocasionadas dentro y fuera del campo de juego, accidentes o perdidas de elementos durante el transcurso del torneo.
A78: Sede Administrativa Cra 13 No 6-43 Barrio La Florida
A79: Celular 310 241 33 76 Fijo 2 450 593
A80: soccermelgar@outlook.com
...

Sheet CUARTOS DE FINAL
H1: Campeonato Nacional de Futbol
B2: CUARTOS DE FINAL | H2: “COPA FUTURO TALENTO”
B3: Observación: Si el partido se define por penales, éstos deben sumarse al resultado.
B4: PARTIDOS | P4: Ganador
B6: =+'CUARTOS DE FINAL.'!B6:B7 -> 42596 | C6: =+'CUARTOS DE FINAL.'!C6:C7 -> LLAVE A | D6: =+'CUARTOS DE FINAL.'!D6:D7 -> 03:00. p.m. | F6: =IF(AND(H6<>"",J6<>""),IF(H6=J6,"E",IF(H6>J6,"G","P")),"") -> E | G6: =+'CUARTOS DE FINAL.'!G6:G7 -> #N/A | H6: . | I6: - | J6: . | K6: =IF(AND(J6<>"",H6<>""),IF(J6=H6,"E",IF(J6>H6,"G","P")),"") -> E | L6: =+'CUARTOS DE FINAL.'!L6:L7 -> ESCUELA DE FORMACIÓN DEPORTIVA MARACANA | N6: =+'CUARTOS DE FINAL.'!N6:N7 -> PALMARA | P6: =IF(OR(F6="E",F6=""),"",IF(F6="G",G6,L6))
B9: =+'CUARTOS DE FINAL.'!B9:B10 -> 42596 | C9: =+'CUARTOS DE FINAL.'!C9:C10 -> LLAVE B | D9: =+'CUARTOS DE FINAL.'!D9:D10 -> 04:20. p.m. | F9: =IF(AND(H9<>"",J9<>""),IF(H9=J9,"E",IF(H9>J9,"G","P")),"") -> E | G9: =+'CUARTOS DE FINAL.'!G9:G10 -> CLUB ARIEL ARMEL | H9: . | I9: - | J9: . | K9: =IF(AND(J9<>"",H9<>""),IF(J9=H9,"E",IF(J9>H9,"G","P")),"") -> E | L9: =+'CUARTOS DE FINAL.'!L9:L10 -> CORDOBA Y SERRANO F. C. | N9: =+'CUARTOS DE FINAL.'!N9:N10 -> CANCHA 2 | P9: =IF(OR(F9="E",F9=""),"",IF(F9="G",G9,L9))
B12: =+'CUARTOS DE FINAL.'!B12:B13 -> 42596 | C12: =+'CUARTOS DE FINAL.'!C12:C13 -> LLAVE C | D12: =+'CUARTOS DE FINAL.'!D12:D13 -> 03:00. p.m. | F12: =IF(AND(H12<>"",J12<>""),IF(H12=J12,"E",IF(H12>J12,"G","P")),"") -> E | G12: =+'CUARTOS DE FINAL.'!G12:G13 -> GRAMA F. C. | H12: . | I12: - | J12: . | K12: =IF(AND(J12<>"",H12<>""),IF(J12=H12,"E",IF(J12>H12,"G","P")),"") -> E | L12: =+'CUARTOS DE FINAL.'!L12:L13 -> #N/A | N12: =+'CUARTOS DE FINAL.'!N12:N13 -> CANCHA 2 | P12: =IF(OR(F12="E",F12=""),"",IF(F12="G",G12,L12))
