Workbook

Sheet NACIDOS 2010 - 2011
A2: PLANILLA DE INSCRIPCION | M2: COMO DILIGENCIAR LA PLANILLA DE INSCRIPCIONES
A3: =+XEZ3 -> XVII Campeonato Nacional de Fútbol | M3: Escriba unicamente en los espacios de color gris. | XEZ3: XVII Campeonato Nacional de Fútbol
A4: =+XEZ4 -> “COPA SOCCER MELGAR” | M4: No copie Ni peque la informacion. | XEZ4: “COPA SOCCER MELGAR”
A5: =+XEZ5 -> NACIDOS 2010 2011 | M5: DILIGENCIAR TODO EN MAYUSCULA | XEZ5: NACIDOS 2010 2011
M6: En el espacio de fecha de nacimiento, favor hacerlo de la sigueinte manera
A7: NOMBRE DEL EQUIPO: | I7: DELEGADO | M7: EJ: 24 marzo 1983 | N7: NO UTILIZAR SIGNOS / - _
A8: CAPITAN | G8: TÉCNICO | M8: Diligenciar las casillas que corresponda
A9: EMAIL: | H9: CIUDAD: | M9: =+A5 -> NACIDOS 2010 2011 | N9: OPRIMA
A11: No | C11: NUMERO CAMISETA | D11: NOMBRES Y APELLIDOS | H11: No DOCUMENTO | J11: EDAD | K11: FECHA NACIMIENTO DIA MES AÑO | R11: 42823
A12: 1 | J12: =IF(ISBLANK(K12),"",DATEDIF(K12,TODAY(),"Y"))&" AÑOS" -> AÑOS | M12: LINK PARA IMPRIMIR CARNET
A13: 2 | J13: =IF(ISBLANK(K13),"",DATEDIF(K13,TODAY(),"Y"))&" AÑOS" -> AÑOS
A14: 3 | J14: =IF(ISBLANK(K14),"",DATEDIF(K14,TODAY(),"Y"))&" AÑOS" -> AÑOS | M14: LINK PARA IMPRIMIR PRE PLANILLA
A15: 4 | J15: =IF(ISBLANK(K15),"",DATEDIF(K15,TODAY(),"Y"))&" AÑOS" -> AÑOS
A16: 5 | J16: =IF(ISBLANK(K16),"",DATEDIF(K16,TODAY(),"Y"))&" AÑOS" -> AÑOS | M16: Imprimir a FULL COLOR
A17: 6 | J17: =IF(ISBLANK(K17),"",DATEDIF(K17,TODAY(),"Y"))&" AÑOS" -> AÑOS | M17: RECORTAR LOS CARNET
A18: 7 | J18: =IF(ISBLANK(K18),"",DATEDIF(K18,TODAY(),"Y"))&" AÑOS" -> AÑOS | M18: NO LAMINAR
A19: 8 | J19: =IF(ISBLANK(K19),"",DATEDIF(K19,TODAY(),"Y"))&" AÑOS" -> AÑOS | M19: CARNET DEBEN TENER FOTO
A20: 9 | J20: =IF(ISBLANK(K20),"",DATEDIF(K20,TODAY(),"Y"))&" AÑOS" -> AÑOS
A21: 10 | J21: =IF(ISBLANK(K21),"",DATEDIF(K21,TODAY(),"Y"))&" AÑOS" -> AÑOS
A22: 11 | J22: =IF(ISBLANK(K22),"",DATEDIF(K22,TODAY(),"Y"))&" AÑOS" -> AÑOS
A23: 12 | J23: =IF(ISBLANK(K23),"",DATEDIF(K23,TODAY(),"Y"))&" AÑOS" -> AÑOS
A24: 13 | J24: =IF(ISBLANK(K24),"",DATEDIF(K24,TODAY(),"Y"))&" AÑOS" -> AÑOS
A25: 14 | J25: =IF(ISBLANK(K25),"",DATEDIF(K25,TODAY(),"Y"))&" AÑOS" -> AÑOS
A26: 15 | J26: =IF(ISBLANK(K26),"",DATEDIF(K26,TODAY(),"Y"))&" AÑOS" -> AÑOS
A27: 16 | J27: =IF(ISBLANK(K27),"",DATEDIF(K27,TODAY(),"Y"))&" AÑOS" -> AÑOS
A28: 17 | J28: =IF(ISBLANK(K28),"",DATEDIF(K28,TODAY(),"Y"))&" AÑOS" -> AÑOS
A29: 18 | J29: =IF(ISBLANK(K29),"",DATEDIF(K29,TODAY(),"Y"))&" AÑOS" -> AÑOS
A30: 19 | J30: =IF(ISBLANK(K30),"",DATEDIF(K30,TODAY(),"Y"))&" AÑOS" -> AÑOS
A31: 20 | J31: =IF(ISBLANK(K31),"",DATEDIF(K31,TODAY(),"Y"))&" AÑOS" -> AÑOS
A32: Los equipos asumen directamente la responsabilidad, en caso de ser necesaria la Atención médica – hospitalaria, por las lesiones que se puedan producir a los jugadores producto de la competencia o alguna eventualidad, antes, durante y después del Campeonato. Eventos Deportivos Soccer Melgar y ninguno de sus miembros directivos tendrá responsabilidad civil o jurídica en caso de accidente o lesiones de los deportistas en el terreno de juego o fuera de él, es importante que los deportistas tengan su servicio médico vigente en caso de ser necesario.
A36: LA ORGANIZACIÓN DEL TORNEO NO SE HACE RESPONSABLE PERDIDA DE ELEMENTOS DURANTE EL TRANSCURSO DEL TORNEO.
A38: La presente planilla de inscripción es un documento público, cualquier falsedad es causal de las sanciones contempladas en la ley y en los reglamentos que rigen este campeonato.
A40: Sede Administrativa Cra 13 No 6-43 Barrio La Florida
A41: Celular 310 241 33 76 Fijo 2 450 593
A42: soccermelgar@outlook.com
A43: Melgar - Tolima

Sheet CARNET 2010 2011
A1: CATEGORIA | B1: =+'NACIDOS 2010 - 2011'!$A$5 -> NACIDOS 2010 2011 | E1: CATEGORIA | F1: =+'NACIDOS 2010 - 2011'!$A$5 -> NACIDOS 2010 2011 | H1: A11
A2: NOMBRE DEPORTISTA | B2: =+'NACIDOS 2010 - 2011'!$D12 -> 0 | E2: NOMBRE DEPORTISTA | F2: =+'NACIDOS 2010 - 2011'!D13 -> 0 | H2: D2.. | J2: COMO DILIGENCIAR LA PLANILLA DE INSCRIPCIONES
A3: NOMBRE DEL EQUIPO | B3: =+'NACIDOS 2010 - 2011'!$D$7 -> 0 | E3: NOMBRE DEL EQUIPO | F3: =+'NACIDOS 2010 - 2011'!$D$7 -> 0 | H3: H2..
A4: FECHA NACIMIENTO | B4: =+'NACIDOS 2010 - 2011'!K12 -> 0 | E4: FECHA NACIMIENTO | F4: =+'NACIDOS 2010 - 2011'!K13 -> 0 | H4: C2.. | J4: Escriba unicamente en los espacios de color gris.
A5: FOTO 3 X 4 | E5: FOTO 3 X 4 | H5: E13 | J5: No copie Ni peque la informacion.
B6: CIUDAD | C6: =+'NACIDOS 2010 - 2011'!$I$9 -> 0 | F6: CIUDAD | G6: =+'NACIDOS 2010 - 2011'!$I$9 -> 0 | H6: H14 | J6: En el espacio de fecha de nacimiento, favor hacerlo de la sigueinte manera
B7: NUMERO DOCUMENTO | C7: =+'NACIDOS 2010 - 2011'!H12 -> 0 | F7: NUMERO DOCUMENTO | G7: =+'NACIDOS 2010 - 2011'!H13 -> 0 | H7: I16 | J7: EJ: 24 marzo de 1983
B8: NOMBRE DEL DT | C8: =+'NACIDOS 2010 - 2011'!$H$8 -> 0 | F8: NOMBRE DEL DT | G8: =+'NACIDOS 2010 - 2011'!$H$8 -> 0 | H8: K21 | J8: Diligenciar las casillas que corresponda
B9: =+'NACIDOS 2010 - 2011'!$A$3 -> XVII Campeonato Nacional de Fútbol | F9: =+'NACIDOS 2010 - 2011'!$A$3 -> XVII Campeonato Nacional de Fútbol | J9: Cuando termine de diligenciar la informacion busque en la parte inferior
B10: =+'NACIDOS 2010 - 2011'!$A$4 -> “COPA SOCCER MELGAR” | F10: =+'NACIDOS 2010 - 2011'!$A$4 -> “COPA SOCCER MELGAR” | J10: CARNET 2010 2011 | L10: OPRIMA
J11: En esta pagina estaran los CARNETS totalmente diligenciados
B12: FIRMA DEL DELEGADO | F12: FIRMA DEL DELEGADO | J12: Favor Imprimir la PLANILLA DE INSCRIPCION Y LOS CARNETS
A14: CATEGORIA | B14: =+'NACIDOS 2010 - 2011'!$A$5 -> NACIDOS 2010 2011 | E14: CATEGORIA | F14: =+'NACIDOS 2010 - 2011'!$A$5 -> NACIDOS 2010 2011 | H14: A11 | J14: Imprimir a FULL COLOR
A15: NOMBRE DEPORTISTA | B15: =+'NACIDOS 2010 - 2011'!$D14 -> 0 | E15: NOMBRE DEPORTISTA | F15: =+'NACIDOS 2010 - 2011'!D15 -> 0 | H15: D2..
A16: NOMBRE DEL EQUIPO | B16: =+'NACIDOS 2010 - 2011'!$D$7 -> 0 | E16: NOMBRE DEL EQUIPO | F16: =+'NACIDOS 2010 - 2011'!$D$7 -> 0 | H16: H2..
A17: FECHA NACIMIENTO | B17: =+'NACIDOS 2010 - 2011'!K14 -> 0 | E17: FECHA NACIMIENTO | F17: =+'NACIDOS 2010 - 2011'!K15 -> 0 | H17: C2..
A18: FOTO 3 X 4 | E18: FOTO 3 X 4 | H18: E13 | J18: LINK PARA IMPRIMIR PRE PLANILLA
B19: CIUDAD | C19: =+'NACIDOS 2010 - 2011'!$I$9 -> 0 | F19: CIUDAD | G19: =+'NACIDOS 2010 - 2011'!$I$9 -> 0 | H19: H14
B20: NUMERO DOCUMENTO | C20: =+'NACIDOS 2010 - 2011'!H14 -> 0 | F20: NUMERO DOCUMENTO | G20: =+'NACIDOS 2010 - 2011'!H15 -> 0 | H20: I16 | J20: Imprimir a FULL COLOR
B21: NOMBRE DEL DT | C21: =+'NACIDOS 2010 - 2011'!$H$8 -> 0 | F21: NOMBRE DEL DT | G21: =+'NACIDOS 2010 - 2011'!$H$8 -> 0 | H21: K21 | J21: RECORTAR LOS CARNET | T21: MELGAR
B22: =+'NACIDOS 2010 - 2011'!$A$3 -> XVII Campeonato Nacional de Fútbol | F22: =+'NACIDOS 2010 - 2011'!$A$3 -> XVII Campeonato Nacional de Fútbol | J22: NO LAMINAR
B23: =+'NACIDOS 2010 - 2011'!$A$4 -> “COPA SOCCER MELGAR” | F23: =+'NACIDOS 2010 - 2011'!$A$4 -> “COPA SOCCER MELGAR” | J23: CARNET DEBEN TENER FOTO
B25: FIRMA DEL DELEGADO | F25: FIRMA DEL DELEGADO
A27: CATEGORIA | B27: =+'NACIDOS 2010 - 2011'!$A$5 -> NACIDOS 2010 2011 | E27: CATEGORIA | F27: =+'NACIDOS 2010 - 2011'!$A$5 -> NACIDOS 2010 2011 | H27: A11
A28: NOMBRE DEPORTISTA | B28: =+'NACIDOS 2010 - 2011'!$D16 -> 0 | E28: NOMBRE DEPORTISTA | F28: =+'NACIDOS 2010 - 2011'!D17 -> 0 | H28: D2..
A29: NOMBRE DEL EQUIPO | B29: =+'NACIDOS 2010 - 2011'!$D$7 -> 0 | E29: NOMBRE DEL EQUIPO | F29: =+'NACIDOS 2010 - 2011'!$D$7 -> 0 | H29: H2..
A30: FECHA NACIMIENTO | B30: =+'NACIDOS 2010 - 2011'!K16 -> 0 | E30: FECHA NACIMIENTO | F30: =+'NACIDOS 2010 - 2011'!K17 -> 0 | H30: C2..
A31: FOTO 3 X 4 | E31: FOTO 3 X 4 | H31: E13
B32: CIUDAD | C32: =+'NACIDOS 2010 - 2011'!$I$9 -> 0 | F32: CIUDAD | G32: =+'NACIDOS 2010 - 2011'!$I$9 -> 0 | H32: H14
B33: NUMERO DOCUMENTO | C33: =+'NACIDOS 2010 - 2011'!H16 -> 0 | F33: NUMERO DOCUMENTO | G33: =+'NACIDOS 2010 - 2011'!H17 -> 0 | H33: I16
B34: NOMBRE DEL DT | C34: =+'NACIDOS 2010 - 2011'!$H$8 -> 0 | F34: NOMBRE DEL DT | G34: =+'NACIDOS 2010 - 2011'!$H$8 -> 0 | H34: K21
B35: =+'NACIDOS 2010 - 2011'!$A$3 -> XVII Campeonato Nacional de Fútbol | F35: =+'NACIDOS 2010 - 2011'!$A$3 -> XVII Campeonato Nacional de Fútbol
B36: =+'NACIDOS 2010 - 2011'!$A$4 -> “COPA SOCCER MELGAR” | F36: =+'NACIDOS 2010 - 2011'!$A$4 -> “COPA SOCCER MELGAR”
B38: FIRMA DEL DELEGADO | F38: FIRMA DEL DELEGADO
A40: CATEGORIA | B40: =+'NACIDOS 2010 - 2011'!$A$5 -> NACIDOS 2010 2011 | E40: CATEGORIA | F40: =+'NACIDOS 2010 - 2011'!$A$5 -> NACIDOS 2010 2011 | H40: A11
A41: NOMBRE DEPORTISTA | B41: =+'NACIDOS 2010 - 2011'!$D18 -> 0 | E41: NOMBRE DEPORTISTA | F41: =+'NACIDOS 2010 - 2011'!D19 -> 0 | H41: D2..
A42: NOMBRE DEL EQUIPO | B42: =+'NACIDOS 2010 - 2011'!$D$7 -> 0 | E42: NOMBRE DEL EQUIPO | F42: =+'NACIDOS 2010 - 2011'!$D$7 -> 0 | H42: H2..
A43: FECHA NACIMIENTO | B43: =+'NACIDOS 2010 - 2011'!K18 -> 0 | E43: FECHA NACIMIENTO | F43: =+'NACIDOS 2010 - 2011'!K19 -> 0 | H43: C2..
A44: FOTO 3 X 4 | E44: FOTO 3 X 4 | H44: E13
B45: CIUDAD | C45: =+'NACIDOS 2010 - 2011'!$I$9 -> 0 | F45: CIUDAD | G45: =+'NACIDOS 2010 - 2011'!$I$9 -> 0 | H45: H14
...

Sheet IMPRIM Y PRESENTAR EN CADA PART
B2: FECHA 1 | M2: FECHA 2 | X2: SE DEBEN IMPRIMIR | AE2: ThiagoMalaver123
B3: =+'NACIDOS 2010 - 2011'!A3&Z4&'NACIDOS 2010 - 2011'!A4 -> XVII Campeonato Nacional de Fútbol “COPA SOCCER MELGAR” | M3: =+B3 -> XVII Campeonato Nacional de Fútbol “COPA SOCCER MELGAR” | X3: LOS TRES JUEGOS DE
B4: =+'NACIDOS 2010 - 2011'!A7&Z4&'NACIDOS 2010 - 2011'!D7 -> NOMBRE DEL EQUIPO: | M4: =+B4 -> NOMBRE DEL EQUIPO: | X4: PRE PLANILLAS
B5: =+'CARNET 2010 2011'!A14&Z4&'NACIDOS 2010 - 2011'!A5 -> CATEGORIA NACIDOS 2010 2011 | M5: =+B5 -> CATEGORIA NACIDOS 2010 2011 | X5: FECHA 1 Y FECHA 2
B6: HORA DEL ENCUENTRO | M6: HORA DEL ENCUENTRO | X6: FECHA 3 Y FECHA 4
B7: CANCHA | M7: CANCHA | X7: FECHA SEMIFINAL Y FECHA FINAL
B8: =+'NACIDOS 2010 - 2011'!G8&Z4&'NACIDOS 2010 - 2011'!H8 -> TÉCNICO | M8: =+B8 -> TÉCNICO
B9: FAVOR MARCAR CON UNA X LOS TITULARES | M9: FAVOR MARCAR CON UNA X LOS TITULARES
B10: LISTADO OFICIAL JUGADORES | M10: LISTADO OFICIAL JUGADORES
C11: # DOCUMENTO | D11: TITULAR | E11: NUMERO CAMISETA | F11: NOMBRE DEPORTISTA | G11: GOL | H11: T.A. | I11: T.R. | J11: TEMPERATURA | N11: # DOCUMENTO | O11: TITULAR | P11: NUMERO CAMISETA | Q11: NOMBRE DEPORTISTA | R11: GOL | S11: T.A. | T11: T.R. | U11: TEMPERATURA
B12: 1 | C12: =+'NACIDOS 2010 - 2011'!H12 -> 0 | E12: =+'NACIDOS 2010 - 2011'!C12 -> 0 | F12: =+'NACIDOS 2010 - 2011'!D12 -> 0 | M12: 1 | N12: =+C12 -> 0 | P12: =+E12 -> 0 | Q12: =+F12 -> 0
B13: 2 | C13: =+'NACIDOS 2010 - 2011'!H13 -> 0 | E13: =+'NACIDOS 2010 - 2011'!C13 -> 0 | F13: =+'NACIDOS 2010 - 2011'!D13 -> 0 | M13: 2 | N13: =+C13 -> 0 | P13: =+E13 -> 0 | Q13: =+F13 -> 0
B14: 3 | C14: =+'NACIDOS 2010 - 2011'!H14 -> 0 | E14: =+'NACIDOS 2010 - 2011'!C14 -> 0 | F14: =+'NACIDOS 2010 - 2011'!D14 -> 0 | M14: 3 | N14: =+C14 -> 0 | P14: =+E14 -> 0 | Q14: =+F14 -> 0
B15: 4 | C15: =+'NACIDOS 2010 - 2011'!H15 -> 0 | E15: =+'NACIDOS 2010 - 2011'!C15 -> 0 | F15: =+'NACIDOS 2010 - 2011'!D15 -> 0 | M15: 4 | N15: =+C15 -> 0 | P15: =+E15 -> 0 | Q15: =+F15 -> 0
B16: 5 | C16: =+'NACIDOS 2010 - 2011'!H16 -> 0 | E16: =+'NACIDOS 2010 - 2011'!C16 -> 0 | F16: =+'NACIDOS 2010 - 2011'!D16 -> 0 | M16: 5 | N16: =+C16 -> 0 | P16: =+E16 -> 0 | Q16: =+F16 -> 0
B17: 6 | C17: =+'NACIDOS 2010 - 2011'!H17 -> 0 | E17: =+'NACIDOS 2010 - 2011'!C17 -> 0 | F17: =+'NACIDOS 2010 - 2011'!D17 -> 0 | M17: 6 | N17: =+C17 -> 0 | P17: =+E17 -> 0 | Q17: =+F17 -> 0
B18: 7 | C18: =+'NACIDOS 2010 - 2011'!H18 -> 0 | E18: =+'NACIDOS 2010 - 2011'!C18 -> 0 | F18: =+'NACIDOS 2010 - 2011'!D18 -> 0 | M18: 7 | N18: =+C18 -> 0 | P18: =+E18 -> 0 | Q18: =+F18 -> 0
B19: 8 | C19: =+'NACIDOS 2010 - 2011'!H19 -> 0 | E19: =+'NACIDOS 2010 - 2011'!C19 -> 0 | F19: =+'NACIDOS 2010 - 2011'!D19 -> 0 | M19: 8 | N19: =+C19 -> 0 | P19: =+E19 -> 0 | Q19: =+F19 -> 0
B20: 9 | C20: =+'NACIDOS 2010 - 2011'!H20 -> 0 | E20: =+'NACIDOS 2010 - 2011'!C20 -> 0 | F20: =+'NACIDOS 2010 - 2011'!D20 -> 0 | M20: 9 | N20: =+C20 -> 0 | P20: =+E20 -> 0 | Q20: =+F20 -> 0
B21: 10 | C21: =+'NACIDOS 2010 - 2011'!H21 -> 0 | E21: =+'NACIDOS 2010 - 2011'!C21 -> 0 | F21: =+'NACIDOS 2010 - 2011'!D21 -> 0 | M21: 10 | N21: =+C21 -> 0 | P21: =+E21 -> 0 | Q21: =+F21 -> 0
B22: 11 | C22: =+'NACIDOS 2010 - 2011'!H22 -> 0 | E22: =+'NACIDOS 2010 - 2011'!C22 -> 0 | F22: =+'NACIDOS 2010 - 2011'!D22 -> 0 | M22: 11 | N22: =+C22 -> 0 | P22: =+E22 -> 0 | Q22: =+F22 -> 0
B23: 12 | C23: =+'NACIDOS 2010 - 2011'!H23 -> 0 | E23: =+'NACIDOS 2010 - 2011'!C23 -> 0 | F23: =+'NACIDOS 2010 - 2011'!D23 -> 0 | M23: 12 | N23: =+C23 -> 0 | P23: =+E23 -> 0 | Q23: =+F23 -> 0
... B31: 20 | C31: =+'NACIDOS 2010 - 2011'!H31 -> 0 | E31: =+'NACIDOS 2010 - 2011'!C31 -> 0 | F31: =+'NACIDOS 2010 - 2011'!D31 -> 0 | M31: 20 | N31: =+C31 -> 0 | P31: =+E31 -> 0 | Q31: =+F31 -> 0
B32: FAVOR ENTREGAR LISTADO DE JUGADORES - 30 MINUTOS ANTES DE INICIAR EL ENCUENTRO. | M32: FAVOR ENTREGAR LISTADO DE JUGADORES - 30 MINUTOS ANTES DE INICIAR EL ENCUENTRO.
B33: CARNET Y DOCUMENTO ORIGINAL PARA VALIDACION. | M33: CARNET Y DOCUMENTO ORIGINAL PARA VALIDACION.
B37: FECHA 3 | M37: FECHA 4
B38: =+B3 -> XVII Campeonato Nacional de Fútbol “COPA SOCCER MELGAR” | M38: =+M3 -> XVII Campeonato Nacional de Fútbol “COPA SOCCER MELGAR”
B39: =+B4 -> NOMBRE DEL EQUIPO: | M39: =+M4 -> NOMBRE DEL EQUIPO:
B40: =+B5 -> CATEGORIA NACIDOS 2010 2011 | M40: =+M5 -> CATEGORIA NACIDOS 2010 2011
B41: HORA DEL ENCUENTRO | M41: HORA DEL ENCUENTRO
B42: CANCHA | M42: CANCHA
B43: =+B8 -> TÉCNICO | M43: =+M8 -> TÉCNICO
C44: FAVOR MARCAR CON UNA X LOS TITULARES | N44: FAVOR MARCAR CON UNA X LOS TITULARES
C45: LISTADO OFICIAL JUGADORES | N45: LISTADO OFICIAL JUGADORES
C46: # DOCUMENTO | D46: TITULAR | E46: NUMERO CAMISETA | F46: NOMBRE DEPORTISTA | G46: GOL | H46: T.A. | I46: T.R. | J46: TEMPERATURA | N46: # DOCUMENTO | O46: TITULAR | P46: NUMERO CAMISETA | Q46: NOMBRE DEPORTISTA | R46: GOL | S46: T.A. | T46: T.R. | U46: TEMPERATURA
B47: 1 | C47: =+C12 -> 0 | E47: =+E12 -> 0 | F47: =+F12 -> 0 | M47: 1 | N47: =+C12 -> 0 | P47: =+E12 -> 0 | Q47: =+F12 -> 0
B48: 2 | C48: =+C13 -> 0 | E48: =+E13 -> 0 | F48: =+F13 -> 0 | M48: 2 | N48: =+C13 -> 0 | P48: =+E13 -> 0 | Q48: =+F13 -> 0
B49: 3 | C49: =+C14 -> 0 | E49: =+E14 -> 0 | F49: =+F14 -> 0 | M49: 3 | N49: =+C14 -> 0 | P49: =+E14 -> 0 | Q49: =+F14 -> 0
B50: 4 | C50: =+C15 -> 0 | E50: =+E15 -> 0 | F50: =+F15 -> 0 | M50: 4 | N50: =+C15 -> 0 | P50: =+E15 -> 0 | Q50: =+F15 -> 0
B51: 5 | C51: =+C16 -> 0 | E51: =+E16 -> 0 | F51: =+F16 -> 0 | M51: 5 | N51: =+C16 -> 0 | P51: =+E16 -> 0 | Q51: =+F16 -> 0
...

Sheet BABY FUTBOL CARNET
A5: CATEGORIA | B5: =+#REF! -> #REF! | D5: CATEGORIA | E5: =+#REF! -> #REF! | F5: A11
A6: DIRECTOR TECNICO | B6: =+#REF! -> #REF! | D6: DELEGADO | E6: =+#REF! -> #REF! | F6: D2..
F7: H2..
F8: C2..
A9: NOMBRE DEL EQUIPO | B9: =+#REF! -> #REF! | D9: NOMBRE DEL EQUIPO | E9: =+#REF! -> #REF! | F9: E13
D10: NOMBRE DEL DT | E10: =+#REF! -> #REF! | F10: H14
A11: CIUDAD | B11: =+#REF! -> #REF! | D11: CIUDAD | E11: =+#REF! -> #REF! | F11: I16
F12: K21
A13: FIRMA DEL DELEGADO _________________________________ | D13: FIRMA DEL DELEGADO _________________________________
A14: V Campeonato Nacional de Fútbol | D14: V Campeonato Nacional de Fútbol
A15: “COPA FUTURO TALENTO” | D15: “COPA FUTURO TALENTO”
A17: "Yo hago lo que usted no puede, | D17: "Yo hago lo que usted no puede,
A18: y usted hace lo que yo no puedo.... | D18: y usted hace lo que yo no puedo....
A19: Juntos podemos hacer grandes cosas." | D19: Juntos podemos hacer grandes cosas."
A20: Madre Teresa de Calcuta | D20: Madre Teresa de Calcuta
A26: CATEGORIA | B26: =+#REF! -> #REF! | D26: CATEGORIA | E26: =+#REF! -> #REF! | F26: A11
A27: NOMBRE DEPORTISTA | B27: =+#REF! -> #REF! | D27: NOMBRE DEPORTISTA | E27: =+#REF! -> #REF! | F27: D2..
A28: NUMERO DOCUMENTO | B28: =+#REF! -> #REF! | D28: NUMERO DOCUMENTO | E28: =+#REF! -> #REF! | F28: H2..
A29: NUMERO CAMISETA | B29: =+#REF! -> #REF! | D29: NUMERO CAMISETA | E29: =+#REF! -> #REF! | F29: C2..
A30: NOMBRE DEL EQUIPO | B30: =+#REF! -> #REF! | D30: NOMBRE DEL EQUIPO | E30: =+#REF! -> #REF! | F30: E13
A31: NOMBRE DEL DT | B31: =+#REF! -> #REF! | D31: NOMBRE DEL DT | E31: =+#REF! -> #REF! | F31: H14
A32: CIUDAD | B32: =+#REF! -> #REF! | D32: CIUDAD | E32: =+#REF! -> #REF! | F32: I16
A33: FECHA NACIMIENTO | B33: =+#REF! -> #REF! | D33: FECHA NACIMIENTO | E33: =+#REF! -> #REF! | F33: K21
A34: FIRMA DEL DELEGADO _________________________________ | D34: FIRMA DEL DELEGADO _________________________________
A35: V Campeonato Nacional de Fútbol | D35: V Campeonato Nacional de Fútbol
A36: “COPA FUTURO TALENTO” | D36: “COPA FUTURO TALENTO”
A38: "Yo hago lo que usted no puede, | D38: "Yo hago lo que usted no puede,
A39: y usted hace lo que yo no puedo.... | D39: y usted hace lo que yo no puedo....
A40: Juntos podemos hacer grandes cosas." | D40: Juntos podemos hacer grandes cosas."
A41: Madre Teresa de Calcuta | D41: Madre Teresa de Calcuta
A47: CATEGORIA | B47: =+#REF! -> #REF! | D47: CATEGORIA | E47: =+#REF! -> #REF! | F47: A11
A48: NOMBRE DEPORTISTA | B48: =+#REF! -> #REF! | D48: NOMBRE DEPORTISTA | E48: =+#REF! -> #REF! | F48: D2..
A49: NUMERO DOCUMENTO | B49: =+#REF! -> #REF! | D49: NUMERO DOCUMENTO | E49: =+#REF! -> #REF! | F49: H2..
A50: NUMERO CAMISETA | B50: =+#REF! -> #REF! | D50: NUMERO CAMISETA | E50: =+#REF! -> #REF! | F50: C2..
A51: NOMBRE DEL EQUIPO | B51: =+#REF! -> #REF! | D51: NOMBRE DEL EQUIPO | E51: =+#REF! -> #REF! | F51: E13
A52: NOMBRE DEL DT | B52: =+#REF! -> #REF! | D52: NOMBRE DEL DT | E52: =+#REF! -> #REF! | F52: H14
A53: CIUDAD | B53: =+#REF! -> #REF! | D53: CIUDAD | E53: =+#REF! -> #REF! | F53: I16
A54: FECHA NACIMIENTO | B54: =+#REF! -> #REF! | D54: FECHA NACIMIENTO | E54: =+#REF! -> #REF! | F54: K21
A55: FIRMA DEL DELEGADO _________________________________ | D55: FIRMA DEL DELEGADO _________________________________
A56: V Campeonato Nacional de Fútbol | D56: V Campeonato Nacional de Fútbol
...

Sheet PRE INFANTIL CARNET
A5: CATEGORIA | B5: =+#REF! -> #REF! | D5: CATEGORIA | E5: =+#REF! -> #REF! | F5: A11
A6: TECNICO | B6: =+#REF! -> #REF! | D6: DELEGADO | E6: =+#REF! -> #REF! | F6: D2..
F7: H2..
F8: C2..
A9: NOMBRE DEL EQUIPO | B9: =+#REF! -> #REF! | D9: NOMBRE DEL EQUIPO | E9: =+#REF! -> #REF! | F9: E13
D10: NOMBRE DEL DT | E10: =+#REF! -> #REF! | F10: H14
A11: CIUDAD | B11: =+#REF! -> #REF! | D11: CIUDAD | E11: =+#REF! -> #REF! | F11: I16
F12: K21
A13: FIRMA DEL DELEGADO _________________________________ | D13: FIRMA DEL DELEGADO _________________________________
A14: V Campeonato Nacional de Fútbol | D14: V Campeonato Nacional de Fútbol
A15: “COPA FUTURO TALENTO” | D15: “COPA FUTURO TALENTO”
A17: "Yo hago lo que usted no puede, | D17: "Yo hago lo que usted no puede,
A18: y usted hace lo que yo no puedo.... | D18: y usted hace lo que yo no puedo....
A19: Juntos podemos hacer grandes cosas." | D19: Juntos podemos hacer grandes cosas."
A20: Madre Teresa de Calcuta | D20: Madre Teresa de Calcuta
A26: CATEGORIA | B26: =+#REF! -> #REF! | D26: CATEGORIA | E26: =+#REF! -> #REF! | F26: A11
A27: NOMBRE DEPORTISTA | B27: =+#REF! -> #REF! | D27: NOMBRE DEPORTISTA | E27: =+#REF! -> #REF! | F27: D2..
A28: NUMERO DOCUMENTO | B28: =+#REF! -> #REF! | D28: NUMERO DOCUMENTO | E28: =+#REF! -> #REF! | F28: H2..
A29: NUMERO CAMISETA | B29: =+#REF! -> #REF! | D29: NUMERO CAMISETA | E29: =+#REF! -> #REF! | F29: C2..
A30: NOMBRE DEL EQUIPO | B30: =+#REF! -> #REF! | D30: NOMBRE DEL EQUIPO | E30: =+#REF! -> #REF! | F30: E13
A31: NOMBRE DEL DT | B31: =+#REF! -> #REF! | D31: NOMBRE DEL DT | E31: =+#REF! -> #REF! | F31: H14
A32: CIUDAD | B32: =+#REF! -> #REF! | D32: CIUDAD | E32: =+#REF! -> #REF! | F32: I16
A33: FECHA NACIMIENTO | B33: =+#REF! -> #REF! | D33: FECHA NACIMIENTO | E33: =+#REF! -> #REF! | F33: K21
A34: FIRMA DEL DELEGADO _________________________________ | D34: FIRMA DEL DELEGADO _________________________________
A35: V Campeonato Nacional de Fútbol | D35: V Campeonato Nacional de Fútbol
A36: “COPA FUTURO TALENTO” | D36: “COPA FUTURO TALENTO”
A38: "Yo hago lo que usted no puede, | D38: "Yo hago lo que usted no puede,
A39: y usted hace lo que yo no puedo.... | D39: y usted hace lo que yo no puedo....
A40: Juntos podemos hacer grandes cosas." | D40: Juntos podemos hacer grandes cosas."
A41: Madre Teresa de Calcuta | D41: Madre Teresa de Calcuta
A47: CATEGORIA | B47: =+#REF! -> #REF! | D47: CATEGORIA | E47: =+#REF! -> #REF! | F47: A11
A48: NOMBRE DEPORTISTA | B48: =+#REF! -> #REF! | D48: NOMBRE DEPORTISTA | E48: =+#REF! -> #REF! | F48: D2..
A49: NUMERO DOCUMENTO | B49: =+#REF! -> #REF! | D49: NUMERO DOCUMENTO | E49: =+#REF! -> #REF! | F49: H2..
A50: NUMERO CAMISETA | B50: =+#REF! -> #REF! | D50: NUMERO CAMISETA | E50: =+#REF! -> #REF! | F50: C2..
A51: NOMBRE DEL EQUIPO | B51: =+#REF! -> #REF! | D51: NOMBRE DEL EQUIPO | E51: =+#REF! -> #REF! | F51: E13
A52: NOMBRE DEL DT | B52: =+#REF! -> #REF! | D52: NOMBRE DEL DT | E52: =+#REF! -> #REF! | F52: H14
A53: CIUDAD | B53: =+#REF! -> #REF! | D53: CIUDAD | E53: =+#REF! -> #REF! | F53: I16
A54: FECHA NACIMIENTO | B54: =+#REF! -> #REF! | D54: FECHA NACIMIENTO | E54: =+#REF! -> #REF! | F54: K21
A55: FIRMA DEL DELEGADO _________________________________ | D55: FIRMA DEL DELEGADO _________________________________
A56: V Campeonato Nacional de Fútbol | D56: V Campeonato Nacional de Fútbol
...

Sheet INFANTIL CARNET
A5: CATEGORIA | B5: =+#REF! -> #REF! | D5: CATEGORIA | E5: =+#REF! -> #REF! | F5: A11
A6: TECNICO | B6: =+#REF! -> #REF! | D6: DELEGADO | E6: =+#REF! -> #REF! | F6: D2..
F7: H2..
F8: C2..
A9: NOMBRE DEL EQUIPO | B9: =+#REF! -> #REF! | D9: NOMBRE DEL EQUIPO | E9: =+#REF! -> #REF! | F9: E13
D10: NOMBRE DEL DT | E10: =+#REF! -> #REF! | F10: H14
A11: CIUDAD | B11: =+#REF! -> #REF! | D11: CIUDAD | E11: =+#REF! -> #REF!
F12: K21
A13: FIRMA DEL DELEGADO _________________________________ | D13: FIRMA DEL DELEGADO _________________________________
A14: V Campeonato Nacional de Fútbol | D14: V Campeonato Nacional de Fútbol
A15: “COPA FUTURO TALENTO” | D15: “COPA FUTURO TALENTO”
A17: "Yo hago lo que usted no puede, | D17: "Yo hago lo que usted no puede,
A18: y usted hace lo que yo no puedo.... | D18: y usted hace lo que yo no puedo....
A19: Juntos podemos hacer grandes cosas." | D19: Juntos podemos hacer grandes cosas."
A20: Madre Teresa de Calcuta | D20: Madre Teresa de Calcuta
A26: CATEGORIA | B26: =+#REF! -> #REF! | D26: CATEGORIA | E26: =+#REF! -> #REF! | F26: A11
A27: NOMBRE DEPORTISTA | B27: =+#REF! -> #REF! | D27: NOMBRE DEPORTISTA | E27: =+#REF! -> #REF! | F27: D2..
A28: NUMERO DOCUMENTO | B28: =+#REF! -> #REF! | D28: NUMERO DOCUMENTO | E28: =+#REF! -> #REF! | F28: H2..
A29: NUMERO CAMISETA | B29: =+#REF! -> #REF! | D29: NUMERO CAMISETA | E29: =+#REF! -> #REF! | F29: C2..
A30: NOMBRE DEL EQUIPO | B30: =+#REF! -> #REF! | D30: NOMBRE DEL EQUIPO | E30: =+#REF! -> #REF! | F30: E13
A31: NOMBRE DEL DT | B31: =+#REF! -> #REF! | D31: NOMBRE DEL DT | E31: =+#REF! -> #REF! | F31: H14
A32: CIUDAD | B32: =+#REF! -> #REF! | D32: CIUDAD | E32: =+#REF! -> #REF!
A33: FECHA NACIMIENTO | B33: =+#REF! -> #REF! | D33: FECHA NACIMIENTO | E33: =+#REF! -> #REF! | F33: K21
A34: FIRMA DEL DELEGADO _________________________________ | D34: FIRMA DEL DELEGADO _________________________________
A35: V Campeonato Nacional de Fútbol | D35: V Campeonato Nacional de Fútbol
A36: “COPA FUTURO TALENTO” | D36: “COPA FUTURO TALENTO”
A38: "Yo hago lo que usted no puede, | D38: "Yo hago lo que usted no puede,
A39: y usted hace lo que yo no puedo.... | D39: y usted hace lo que yo no puedo....
A40: Juntos podemos hacer grandes cosas." | D40: Juntos podemos hacer grandes cosas."
A41: Madre Teresa de Calcuta | D41: Madre Teresa de Calcuta
A47: CATEGORIA | B47: =+#REF! -> #REF! | D47: CATEGORIA | E47: =+#REF! -> #REF! | F47: A11
A48: NOMBRE DEPORTISTA | B48: =+#REF! -> #REF! | D48: NOMBRE DEPORTISTA | E48: =+#REF! -> #REF! | F48: D2..
A49: NUMERO DOCUMENTO | B49: =+#REF! -> #REF! | D49: NUMERO DOCUMENTO | E49: =+#REF! -> #REF! | F49: H2..
A50: NUMERO CAMISETA | B50: =+#REF! -> #REF! | D50: NUMERO CAMISETA | E50: =+#REF! -> #REF! | F50: C2..
A51: NOMBRE DEL EQUIPO | B51: =+#REF! -> #REF! | D51: NOMBRE DEL EQUIPO | E51: =+#REF! -> #REF! | F51: E13
A52: NOMBRE DEL DT | B52: =+#REF! -> #REF! | D52: NOMBRE DEL DT | E52: =+#REF! -> #REF! | F52: H14
A53: CIUDAD | B53: =+#REF! -> #REF! | D53: CIUDAD | E53: =+#REF! -> #REF! | F53: I16
A54: FECHA NACIMIENTO | B54: =+#REF! -> #REF! | D54: FECHA NACIMIENTO | E54: =+#REF! -> #REF! | F54: K21
A55: FIRMA DEL DELEGADO _________________________________ | D55: FIRMA DEL DELEGADO _________________________________
A56: V Campeonato Nacional de Fútbol | D56: V Campeonato Nacional de Fútbol
...
